Workbook

Sheet 개요
B2: SCK 분석시스템 구축 POC - YMS 테이블 명세서
B4: 대상 시스템 | C4: DACrux DMS / YMS (SCK 분석시스템 구축 POC)
B5: 영역 | C5: YMS - 수율 관리 (Lot / Wafer / Bin / Program / Map / Spec) + Program 별 Die 측정 데이터(TD_*)
B6: 기준 DB | C6: 로컬 개발 DB (Oracle 19c, 스키마 DMSMGR, 문자셋 AL32UTF8)
B7: 조회 일자 | C7: 2026-10-15
B8: 작성 근거 | C8: DB 메타데이터 (컬럼 / 주석 / 제약 / 인덱스 / 시퀀스) + Query XML (DMS/08_DBQuery/ORACLE) / C# 소스 + 같은 제품을 쓴 다른 프로젝트의 테이블 정의서 + 이 프로젝트 설계 문서
B9: 대상 범위 | C9: 테이블 23개 (이름 접두어 TQP_ / TD_). POC 신규 테이블(TQP_GDS_*)은 POC 테이블 명세서에 따로 있다.
B10: 제외 | C10: 소스(Query XML / C#)에서 쓰지 않는 테이블: TQP_ZONE
B12: 집계 | C12: 값
B13: 테이블 수 | C13: =COUNTA('테이블 목록'!B4:B26) -> 23
B14: 컬럼 수 | C14: ='테이블 목록'!E27 -> 677
B15: 근거: 설계 문서 | C15: ='테이블 목록'!I27 -> 9
B16: 근거: 소스 | C16: ='테이블 목록'!J27 -> 255
B17: 근거: 이름 추정 | C17: ='테이블 목록'!K27 -> 96
B19: 시트 | C19: 내용
B20: 테이블 목록 | C20: 테이블 요약 (테이블명을 누르면 해당 시트로 이동, 근거별 행 수)
B21: 테이블별 시트 | C21: 컬럼 / 제약 조건 / 인덱스
B22: 관계(논리) | C22: Query XML / 소스의 조인으로 확인한 테이블 관계 (DB FK 없음)
B23: 시퀀스 | C23: 이 영역 테이블이 쓰는 시퀀스
B25: 표기 기준 | C25: 설명
B26: 데이터 타입 | C26: VARCHAR2(n CHAR) = 글자 수 기준, VARCHAR2(n) = byte 기준
B27: NULL / PK | C27: NULL: N = NOT NULL (필수), Y = NULL 허용. PK: 기본 키 안 순서 (노란 행)
B28: 반복 컬럼 | C28: 같은 접두어 + 번호가 이어지는 컬럼은 한 줄로 묶었다 (회색 행, 예: BIN001 ~ BIN151). No 는 첫 ~ 끝 컬럼 순번
B29: 참조 (논리) | C29: 조인으로 확인한 부모 테이블. DB FK 는 없다
B30: 근거 | C30: 설계 문서 = 이 프로젝트 설계 문서 (문서/설계) / 소스 = Query XML / C# 소스에서 쓰임을 확인 / 이름 추정 = 근거 자료 없이 컬럼 이름과 값으로 추정 - 확인 필요
B32: 참고 | C32: 내용
... B39: 참고 7 | C39: DB 에 기본 키(PK)가 없는 테이블 4개: TD_52PX, TQP_FOI_IMAGES, TQP_MAPDEF, TQP_VISUALINSPSPEC

Sheet 테이블 목록
A1: YMS 테이블 목록
A3: No | B3: 테이블명 | C3: 테이블 설명 | D3: 기본 키 (PK) | E3: 컬럼 수 | F3: 사용 기능 | G3: 관련 테이블 (논리) | H3: Query XML | I3: 근거: 설계 문서 | J3: 근거: 소스 | K3: 근거: 이름 추정
A4: 1 | B4: TD_08EYP1 | C4: Program 08EYP1 Die 데이터 (POSTLASER, Device EY08, PST 파일) | D4: WAFER_SEQ, DIE_NUM | E4: =TD_08EYP1!E5 -> 6 | F4: CP DataService 적재 (PST 파일), TEST Analysis 화면 (Map View / Gallery / Report) | G4: TQP_BINDESC, TQP_WAFER | I4: =COUNTIF(TD_08EYP1!I9:I14,"설계 문서") -> 0 | J4: =COUNTIF(TD_08EYP1!I9:I14,"소스") -> 6 | K4: =COUNTIF(TD_08EYP1!I9:I14,"이름 추정") -> 0
A5: 2 | B5: TD_52PX | C5: Program 52PX Die 데이터 (POSTLASER, Device PX52, PST 파일) | E5: =TD_52PX!E5 -> 6 | F5: CP DataService 적재 (PST 파일), TEST Analysis 화면 (Map View / Gallery / Report) | G5: TQP_BINDESC, TQP_WAFER | I5: =COUNTIF(TD_52PX!I9:I14,"설계 문서") -> 0 | J5: =COUNTIF(TD_52PX!I9:I14,"소스") -> 6 | K5: =COUNTIF(TD_52PX!I9:I14,"이름 추정") -> 0
A6: 3 | B6: TD_89CP | C6: Program 89CP Die 데이터 (MULTIPROBE, Device CP89, CP3 파일) | D6: WAFER_SEQ, DIE_NUM | E6: =TD_89CP!E5 -> 6 | F6: CP DataService 적재 (CP3 파일), TEST Analysis 화면 (Map View / Gallery / Report) | G6: TQP_BINDESC, TQP_WAFER | I6: =COUNTIF(TD_89CP!I9:I14,"설계 문서") -> 0 | J6: =COUNTIF(TD_89CP!I9:I14,"소스") -> 6 | K6: =COUNTIF(TD_89CP!I9:I14,"이름 추정") -> 0
A7: 4 | B7: TD_KA36_CP2 | C7: Program KA36_CP2 Die 데이터 (MULTIPROBE, Device KA36, CP3 파일) | D7: WAFER_SEQ, DIE_NUM | E7: =TD_KA36_CP2!E5 -> 6 | F7: CP DataService 적재 (CP3 파일), TEST Analysis 화면 (Map View / Gallery / Report) | G7: TQP_BINDESC, TQP_WAFER | I7: =COUNTIF(TD_KA36_CP2!I9:I14,"설계 문서") -> 0 | J7: =COUNTIF(TD_KA36_CP2!I9:I14,"소스") -> 6 | K7: =COUNTIF(TD_KA36_CP2!I9:I14,"이름 추정") -> 0
A8: 5 | B8: TQP_BINDESC | C8: Program 별 Bin 정의 (Bin 이름 / 양품 여부 / Map 색) | D8: PROGRAM, BIN | E8: =TQP_BINDESC!E5 -> 11 | F8: Bin Define (frmSetupBin), 요약 수율 Good Bin, Map Bin 색 / 분포, E-Test YMS 적재 Bin 등록, DMS Defect-Test 매칭 | G8: TD_08EYP1, TD_52PX, TD_89CP, TD_KA36_CP2, TD_OMM_TSVET, TQP_FOI_DIE, TQP_PROGRAM, TQP_WAFER_SUM | H8: TQP_BINDESC.xml | I8: =COUNTIF(TQP_BINDESC!I9:I19,"설계 문서") -> 0 | J8: =COUNTIF(TQP_BINDESC!I9:I19,"소스") -> 11 | K8: =COUNTIF(TQP_BINDESC!I9:I19,"이름 추정") -> 0
A9: 6 | B9: TQP_CHANGE_HIS | C9: YMS Test 데이터 수정 / 삭제 이력 | D9: TRAN_KEY | E9: =TQP_CHANGE_HIS!E5 -> 15 | F9: TEST Data Maint (frmTestDataMaint) 변경 이력 기록 / 조회 | H9: TQP_CHANGE_HIS.xml | I9: =COUNTIF(TQP_CHANGE_HIS!I9:I23,"설계 문서") -> 0 | J9: =COUNTIF(TQP_CHANGE_HIS!I9:I23,"소스") -> 15 | K9: =COUNTIF(TQP_CHANGE_HIS!I9:I23,"이름 추정") -> 0
A10: 7 | B10: TQP_CUSTOMER | C10: 고객 정보 (이전 MAP Parser 용, 현재 데이터 / 화면 없음) | D10: CUSTOMER_ID | E10: =TQP_CUSTOMER!E5 -> 15 | F10: YMS MAP Parser (YMSFileMonitor) 고객 조회, ProbeAdmin 고객 관리 함수 (화면 호출 없음) | H10: TQP_CUSTOMER.xml | I10: =COUNTIF(TQP_CUSTOMER!I9:I23,"설계 문서") -> 0 | J10: =COUNTIF(TQP_CUSTOMER!I9:I23,"소스") -> 1 | K10: =COUNTIF(TQP_CUSTOMER!I9:I23,"이름 추정") -> 14
A11: 8 | B11: TQP_DATA_TABLES | C11: Program 별 Die 측정 데이터 테이블(TD_*) 목록 | D11: FACTORY, PROGRAM, TABLE_NAME | E11: =TQP_DATA_TABLES!E5 -> 3 | F11: TD 테이블 생성 때 등록 (TD_TABLE.CreateNewTable), Wafer 데이터 조회 / 삭제 때 TD 테이블 찾기 | G11: TQP_PARASPEC, TQP_WAFER | H11: TQP_DATA_TABLES.xml | I11: =COUNTIF(TQP_DATA_TABLES!I9:I11,"설계 문서") -> 0 | J11: =COUNTIF(TQP_DATA_TABLES!I9:I11,"소스") -> 3 | K11: =COUNTIF(TQP_DATA_TABLES!I9:I11,"이름 추정") -> 0
A12: 9 | B12: TQP_FOI_DIE | C12: AVI / Scope 외관검사 Die 결과 (Die 별 Bin / 이미지) | D12: WAFER_SEQ, DIE_NUM | E12: =TQP_FOI_DIE!E5 -> 12 | F12: AVI DataService 적재, Scope 수동 업로드 (TestCommon.ScopeDataSet), AVI Cum Map / FOI Cum Report 조회 | G12: TQP_BINDESC, TQP_WAFER, TQP_WAFER_SUM | H12: TQP_FOI_DIE.xml | I12: =COUNTIF(TQP_FOI_DIE!I9:I20,"설계 문서") -> 0 | J12: =COUNTIF(TQP_FOI_DIE!I9:I20,"소스") -> 12 | K12: =COUNTIF(TQP_FOI_DIE!I9:I20,"이름 추정") -> 0
A13: 10 | B13: TQP_FOI_IMAGES | C13: Scope 외관검사 이미지 목록 (Die 위치 별) | E13: =TQP_FOI_IMAGES!E5 -> 8 | F13: Scope 수동 업로드 (TestCommon.ScopeDataSet), FOI 이미지 조회 (ProbeMapAnalysis) | G13: TQP_WAFER_SUM | H13: TQP_FOI_IMAGES.xml | I13: =COUNTIF(TQP_FOI_IMAGES!I9:I16,"설계 문서") -> 0 | J13: =COUNTIF(TQP_FOI_IMAGES!I9:I16,"소스") -> 8 | K13: =COUNTIF(TQP_FOI_IMAGES!I9:I16,"이름 추정") -> 0
A14: 11 | B14: TQP_LOT | C14: YMS Test Lot 정보 (Factory + TestArea + Lot + Program 당 1건) | D14: FACTORY, LOT_SEQ | E14: =TQP_LOT!E5 -> 26 | F14: CP / PCM / AVI DataService 적재, E-Test 업로드 YMS 적재, TEST Data Maint, TEST Analysis 조회 조건, RPNet TSK Map 생성 | G14: TQC_LOT_STS, TQP_LOT_SUM, TQP_MAPDEF, TQP_PRODUCT, TQP_WAFER, TQP_WAFER_SUM | H14: TQP_LOT.xml | I14: =COUNTIF(TQP_LOT!I9:I30,"설계 문서") -> 0 | J14: =COUNTIF(TQP_LOT!I9:I30,"소스") -> 11 | K14: =COUNTIF(TQP_LOT!I9:I30,"이름 추정") -> 11
A15: 12 | B15: TQP_LOT_SUM | C15: Lot 별 Test 요약 (Wafer 요약을 Lot 으로 집계) | D15: LOT_SEQ | E15: =TQP_LOT_SUM!E5 -> 168 | F15: 적재 후 요약 생성 (TestCommon.SummaryData), Wafer 삭제 후 재생성 (TestDataMaint), Lot 목록 조회 (DataSelect.GetLotList) | G15: TQP_LOT | H15: TQP_LOT_SUM.xml | I15: =COUNTIF(TQP_LOT_SUM!I9:I26,"설계 문서") -> 0 | J15: =COUNTIF(TQP_LOT_SUM!I9:I26,"소스") -> 17 | K15: =COUNTIF(TQP_LOT_SUM!I9:I26,"이름 추정") -> 1
A16: 13 | B16: TQP_MAPCFG | C16: Map 좌표 보정 설정 (TestArea + Device + Program 별 방향 / 회전 / 이동) | D16: MAP_CFG_SEQ | E16: =TQP_MAPCFG!E5 -> 15 | F16: Map Control 저장 (ProbeMapAnalysis), Map Control Update (frmMapConfigUpdate), CP 적재 좌표 보정 (GetCorrectionData) | G16: TQP_WAFER, TQP_WAFER_SUM | H16: TQP_MAPCFG.xml | I16: =COUNTIF(TQP_MAPCFG!I9:I23,"설계 문서") -> 0 | J16: =COUNTIF(TQP_MAPCFG!I9:I23,"소스") -> 15 | K16: =COUNTIF(TQP_MAPCFG!I9:I23,"이름 추정") -> 0
A17: 14 | B17: TQP_MAPDEF | C17: Wafer Map 기준 정보 (Map ID 별 Wafer / Die 크기 / 원점 / 방향) | E17: =TQP_MAPDEF!E5 -> 37 | F17: Map Define, File Map Setup, Wafer Map View, TEST Map 그리기, Wafer 요약 NETDIE, KLARF 업로드 Map 기준, RPNet TSK Map 생성 | G17: TQP_LOT, TQP_MAPDEF_DIE, TQP_PRODUCT, TQP_USEMAP, TQP_WAFER_SUM | H17: TQP_MAPDEF.xml | I17: =COUNTIF(TQP_MAPDEF!I9:I45,"설계 문서") -> 9 | J17: =COUNTIF(TQP_MAPDEF!I9:I45,"소스") -> 21 | K17: =COUNTIF(TQP_MAPDEF!I9:I45,"이름 추정") -> 7
A18: 15 | B18: TQP_MAPDEF_DIE | C18: Map 정의 Die / Shot 위치 (Mark Die 표시 / Shot Map 용) | D18: FACTORY, MAPID, DIE_TYPE, DIE_NO | E18: =TQP_MAPDEF_DIE!E5 -> 6 | F18: TEST Map View / Map Edit Mark Die 표시, Shot Map View, DMS Defect Map (GET_MAPDEF_DIE_DM) | G18: TQP_MAPDEF | I18: =COUNTIF(TQP_MAPDEF_DIE!I9:I14,"설계 문서") -> 0 | J18: =COUNTIF(TQP_MAPDEF_DIE!I9:I14,"소스") -> 6 | K18: =COUNTIF(TQP_MAPDEF_DIE!I9:I14,"이름 추정") -> 0
A19: 16 | B19: TQP_PARASPEC | C19: Program 별 Parameter 정의와 Spec (TD 테이블 컬럼 목록 겸용) | D19: FACTORY, PROGRAM, PROGRAM_REV, PARAM_NAME | E19: =TQP_PARASPEC!E5 -> 30 | F19: TD 컬럼 자동 등록 (TD_TABLE), Program Parameter Spec Define, Map View / Param Analysis / PCM Report Spec 표시, E-Test LSL / USL 보정 | G19: TQP_DATA_TABLES, TQP_WAFER | H19: TQP_PARASPEC.xml | I19: =COUNTIF(TQP_PARASPEC!I9:I38,"설계 문서") -> 0 | J19: =COUNTIF(TQP_PARASPEC!I9:I38,"소스") -> 27 | K19: =COUNTIF(TQP_PARASPEC!I9:I38,"이름 추정") -> 3
A20: 17 | B20: TQP_PCM_INPUT_HIS | C20: PCM 설비 Probe Card / 작업자 입력 이력 | D20: FACTORY, EQUIP_ID, INPUT_TIME | E20: =TQP_PCM_INPUT_HIS!E5 -> 11 | F20: PCM Equip Status (frmPcmEquipStatus) 입력 / 조회, Probe Card 사용 시간 계산 (TQC_EQUIP.xml) | G20: TQC_EQUIP | H20: TQP_PCM_INPUT_HIS.xml | I20: =COUNTIF(TQP_PCM_INPUT_HIS!I9:I15,"설계 문서") -> 0 | J20: =COUNTIF(TQP_PCM_INPUT_HIS!I9:I15,"소스") -> 6 | K20: =COUNTIF(TQP_PCM_INPUT_HIS!I9:I15,"이름 추정") -> 1
A21: 18 | B21: TQP_PRODUCT | C21: Wafer Map 별 Product 관리 (Product 와 Map ID 연결) | D21: FACTORY, PRODUCT | E21: =TQP_PRODUCT!E5 -> 6 | F21: 적재 때 자동 등록 (TestCommon.InsertProductInfo), Device 조회 조건, Wafer 조회 (SELECT_WAFER_INFO_05 / 06), YMS MAP Parser | G21: TQP_LOT, TQP_MAPDEF, TQP_PROGRAM | H21: TQP_PRODUCT.xml | I21: =COUNTIF(TQP_PRODUCT!I9:I14,"설계 문서") -> 0 | J21: =COUNTIF(TQP_PRODUCT!I9:I14,"소스") -> 5 | K21: =COUNTIF(TQP_PRODUCT!I9:I14,"이름 추정") -> 1
A22: 19 | B22: TQP_PROGRAM | C22: Test Program 정보 (Program 별 TestArea / Device) | D22: FACTORY, PROGRAM, TESTAREA, DEVICE | E22: =TQP_PROGRAM!E5 -> 18 | F22: 적재 때 자동 등록 (TestCommon.InsertProgramInfo), TestArea / Program 조회 조건 목록, Program Define, Standard Report | G22: TQP_BINDESC, TQP_PRODUCT | H22: TQP_PROGRAM.xml | I22: =COUNTIF(TQP_PROGRAM!I9:I17,"설계 문서") -> 0 | J22: =COUNTIF(TQP_PROGRAM!I9:I17,"소스") -> 6 | K22: =COUNTIF(TQP_PROGRAM!I9:I17,"이름 추정") -> 3
A23: 20 | B23: TQP_USEMAP | C23: Map 의 Die 목록 (Die Index / 사용 구분) | D23: FACTORY, MAPID, PROGRAM_REV, X, Y | E23: =TQP_USEMAP!E5 -> 7 | F23: Map Define / File Map Setup 저장 (CreateUseMap), Wafer Map View, KLARF 업로드 Map 기준, AVI Map 조회 | G23: TQP_MAPDEF | H23: TQP_USEMAP.xml | I23: =COUNTIF(TQP_USEMAP!I9:I15,"설계 문서") -> 0 | J23: =COUNTIF(TQP_USEMAP!I9:I15,"소스") -> 7 | K23: =COUNTIF(TQP_USEMAP!I9:I15,"이름 추정") -> 0
A24: 21 | B24: TQP_VISUALINSPSPEC | C24: 육안 / 외관검사 불량 코드(Bin) 정의 (검사 유형 별) | E24: =TQP_VISUALINSPSPEC!E5 -> 8 | F24: Visual Inspection Define (frmVisualInspDefine), 육안검사 Map 편집 단축키, AVI / IQC Bin 분포 (T_AVI_TABLE.xml) | H24: TQP_VISUALINSPSPEC.xml | I24: =COUNTIF(TQP_VISUALINSPSPEC!I9:I16,"설계 문서") -> 0 | J24: =COUNTIF(TQP_VISUALINSPSPEC!I9:I16,"소스") -> 6 | K24: =COUNTIF(TQP_VISUALINSPSPEC!I9:I16,"이름 추정") -> 2
A25: 22 | B25: TQP_WAFER | C25: YMS Test Wafer 정보 (Wafer 1회 측정 = 1건, 재측정은 PROBE_CNT 로 구분) | D25: FACTORY, WAFER_SEQ | E25: =TQP_WAFER!E5 -> 81 | F25: CP / PCM / AVI DataService 적재, E-Test 업로드 YMS 적재, Scope 수동 업로드, TEST Data Maint, Param Analysis / Test Report 조회, RPNet TSK Map 생성 | G25: TD_08EYP1, TD_52PX, TD_89CP, TD_KA36_CP2, TD_OMM_TSVET, TQP_DATA_TABLES, TQP_FOI_DIE, TQP_LOT, TQP_MAPCFG, TQP_PARASPEC, TQP_WAFER_SUM | H25: TQP_WAFER.xml | I25: =COUNTIF(TQP_WAFER!I9:I89,"설계 문서") -> 0 | J25: =COUNTIF(TQP_WAFER!I9:I89,"소스") -> 30 | K25: =COUNTIF(TQP_WAFER!I9:I89,"이름 추정") -> 51
A26: 23 | B26: TQP_WAFER_SUM | C26: Wafer 별 Test 요약 (수율 / Bin 별 Die 수, 분석 화면 Wafer 목록) | D26: FACILITY, WAFER_SEQ | E26: =TQP_WAFER_SUM!E5 -> 176 | F26: 적재 후 요약 생성 (TestCommon.SummaryData), TEST Analysis Wafer 선택 목록, Yield / Wafer Cum / Wafer Bin Report, Map Control Update, DMS Defect-Test 매칭 | G26: TQP_BINDESC, TQP_FOI_DIE, TQP_FOI_IMAGES, TQP_LOT, TQP_MAPCFG, TQP_MAPDEF, TQP_WAFER | H26: TQP_WAFER_SUM.xml | I26: =COUNTIF(TQP_WAFER_SUM!I9:I34,"설계 문서") -> 0 | J26: =COUNTIF(TQP_WAFER_SUM!I9:I34,"소스") -> 24 | K26: =COUNTIF(TQP_WAFER_SUM!I9:I34,"이름 추정") -> 2
D27: 합계 | E27: =SUM(E4:E26) -> 677 | I27: =SUM(I4:I26) -> 9 | J27: =SUM(J4:J26) -> 255 | K27: =SUM(K4:K26) -> 96

Sheet TD_08EYP1
A1: 테이블 명세서
I2: <- 테이블 목록
A3: 테이블명 | C3: TD_08EYP1 | D3: 영역 | E3: YMS | G3: 스키마 | H3: DMSMGR
A4: 테이블 설명 | C4: Program 08EYP1 Die 데이터 (POSTLASER, Device EY08, PST 파일)
A5: 기본 키 (PK) | C5: SYS_C008190 (WAFER_SEQ, DIE_NUM) | D5: 컬럼 수 | E5: =SUM(J9:J14) -> 6 | G5: Query XML
A6: 사용 기능 | C6: CP DataService 적재 (PST 파일), TEST Analysis 화면 (Map View / Gallery / Report)
A8: No | B8: 컬럼명 | C8: 컬럼 설명 | D8: 데이터 타입 | E8: NULL | F8: PK | G8: 참조 (논리) | H8: 기본값 | I8: 근거
A9: 1 | B9: WAFER_SEQ | C9: Wafer 번호 (TQP_WAFER.WAFER_SEQ) | D9: NUMBER | E9: N | F9: 1 | G9: TQP_WAFER | I9: 소스 | J9: 1
A10: 2 | B10: DIE_NUM | C10: Die 순번 (파일 Die 행 순서 1 ~ N) | D10: NUMBER | E10: N | F10: 2 | I10: 소스 | J10: 1
A11: 3 | B11: DIEPROBE_CNT | C11: Die 재측정 순번 (적재 때 0) | D11: NUMBER | E11: Y | I11: 소스 | J11: 1
A12: 4 | B12: X | C12: Die X Index (CP 파일 좌표, Map 보정 설정이 있으면 적용) | D12: NUMBER | E12: Y | I12: 소스 | J12: 1
A13: 5 | B13: Y | C13: Die Y Index (CP 파일 좌표, Map 보정 설정이 있으면 적용) | D13: NUMBER | E13: Y | I13: 소스 | J13: 1
A14: 6 | B14: BIN | C14: Die Bin 번호 (TQP_BINDESC.BIN, 요약은 0 ~ 99 만 집계) | D14: NUMBER | E14: Y | G14: TQP_BINDESC | I14: 소스 | J14: 1
A16: 제약 조건
A17: No | B17: 구분 | C17: 제약 이름 | D17: 컬럼 | G17: 내용
A18: 1 | B18: PK | C18: SYS_C008190 | D18: WAFER_SEQ, DIE_NUM | G18: 기본 키
A20: 인덱스
A21: No | B21: 유일 | C21: 인덱스 이름 | D21: 컬럼 | G21: 용도
A22: 1 | B22: UNIQUE | C22: SYS_C008190 | D22: WAFER_SEQ, DIE_NUM | G22: 기본 키

Sheet TD_52PX
A1: 테이블 명세서
I2: <- 테이블 목록
A3: 테이블명 | C3: TD_52PX | D3: 영역 | E3: YMS | G3: 스키마 | H3: DMSMGR
A4: 테이블 설명 | C4: Program 52PX Die 데이터 (POSTLASER, Device PX52, PST 파일)
A5: 기본 키 (PK) | C5: (없음) | D5: 컬럼 수 | E5: =SUM(J9:J14) -> 6 | G5: Query XML
A6: 사용 기능 | C6: CP DataService 적재 (PST 파일), TEST Analysis 화면 (Map View / Gallery / Report)
A8: No | B8: 컬럼명 | C8: 컬럼 설명 | D8: 데이터 타입 | E8: NULL | F8: PK | G8: 참조 (논리) | H8: 기본값 | I8: 근거
A9: 1 | B9: WAFER_SEQ | C9: Wafer 번호 (TQP_WAFER.WAFER_SEQ) | D9: NUMBER | E9: Y | G9: TQP_WAFER | I9: 소스 | J9: 1
A10: 2 | B10: DIE_NUM | C10: Die 순번 (파일 Die 행 순서 1 ~ N) | D10: NUMBER | E10: Y | I10: 소스 | J10: 1
A11: 3 | B11: DIEPROBE_CNT | C11: Die 재측정 순번 (적재 때 0) | D11: NUMBER | E11: Y | I11: 소스 | J11: 1
A12: 4 | B12: X | C12: Die X Index (CP 파일 좌표, Map 보정 설정이 있으면 적용) | D12: NUMBER | E12: Y | I12: 소스 | J12: 1
A13: 5 | B13: Y | C13: Die Y Index (CP 파일 좌표, Map 보정 설정이 있으면 적용) | D13: NUMBER | E13: Y | I13: 소스 | J13: 1
A14: 6 | B14: BIN | C14: Die Bin 번호 (TQP_BINDESC.BIN, 요약은 0 ~ 99 만 집계) | D14: NUMBER | E14: Y | G14: TQP_BINDESC | I14: 소스 | J14: 1
A16: 제약 조건
A17: No | B17: 구분 | C17: 제약 이름 | D17: 컬럼 | G17: 내용
A18: - | B18: - | C18: (없음)
A20: 인덱스
A21: No | B21: 유일 | C21: 인덱스 이름 | D21: 컬럼 | G21: 용도
A22: - | B22: - | C22: (없음)

Sheet TD_89CP
A1: 테이블 명세서
I2: <- 테이블 목록
A3: 테이블명 | C3: TD_89CP | D3: 영역 | E3: YMS | G3: 스키마 | H3: DMSMGR
A4: 테이블 설명 | C4: Program 89CP Die 데이터 (MULTIPROBE, Device CP89, CP3 파일)
A5: 기본 키 (PK) | C5: SYS_C008142 (WAFER_SEQ, DIE_NUM) | D5: 컬럼 수 | E5: =SUM(J9:J14) -> 6 | G5: Query XML
A6: 사용 기능 | C6: CP DataService 적재 (CP3 파일), TEST Analysis 화면 (Map View / Gallery / Report)
A8: No | B8: 컬럼명 | C8: 컬럼 설명 | D8: 데이터 타입 | E8: NULL | F8: PK | G8: 참조 (논리) | H8: 기본값 | I8: 근거
A9: 1 | B9: WAFER_SEQ | C9: Wafer 번호 (TQP_WAFER.WAFER_SEQ) | D9: NUMBER | E9: N | F9: 1 | G9: TQP_WAFER | I9: 소스 | J9: 1
A10: 2 | B10: DIE_NUM | C10: Die 순번 (파일 Die 행 순서 1 ~ N) | D10: NUMBER | E10: N | F10: 2 | I10: 소스 | J10: 1
A11: 3 | B11: DIEPROBE_CNT | C11: Die 재측정 순번 (적재 때 0) | D11: NUMBER | E11: Y | I11: 소스 | J11: 1
A12: 4 | B12: X | C12: Die X Index (CP 파일 좌표, Map 보정 설정이 있으면 적용) | D12: NUMBER | E12: Y | I12: 소스 | J12: 1
A13: 5 | B13: Y | C13: Die Y Index (CP 파일 좌표, Map 보정 설정이 있으면 적용) | D13: NUMBER | E13: Y | I13: 소스 | J13: 1
A14: 6 | B14: BIN | C14: Die Bin 번호 (TQP_BINDESC.BIN, 요약은 0 ~ 99 만 집계) | D14: NUMBER | E14: Y | G14: TQP_BINDESC | I14: 소스 | J14: 1
A16: 제약 조건
A17: No | B17: 구분 | C17: 제약 이름 | D17: 컬럼 | G17: 내용
A18: 1 | B18: PK | C18: SYS_C008142 | D18: WAFER_SEQ, DIE_NUM | G18: 기본 키
A20: 인덱스
A21: No | B21: 유일 | C21: 인덱스 이름 | D21: 컬럼 | G21: 용도
A22: 1 | B22: UNIQUE | C22: SYS_C008142 | D22: WAFER_SEQ, DIE_NUM | G22: 기본 키

Sheet TD_KA36_CP2
A1: 테이블 명세서
I2: <- 테이블 목록
A3: 테이블명 | C3: TD_KA36_CP2 | D3: 영역 | E3: YMS | G3: 스키마 | H3: DMSMGR
A4: 테이블 설명 | C4: Program KA36_CP2 Die 데이터 (MULTIPROBE, Device KA36, CP3 파일)
A5: 기본 키 (PK) | C5: SYS_C008120 (WAFER_SEQ, DIE_NUM) | D5: 컬럼 수 | E5: =SUM(J9:J14) -> 6 | G5: Query XML
A6: 사용 기능 | C6: CP DataService 적재 (CP3 파일), TEST Analysis 화면 (Map View / Gallery / Report)
A8: No | B8: 컬럼명 | C8: 컬럼 설명 | D8: 데이터 타입 | E8: NULL | F8: PK | G8: 참조 (논리) | H8: 기본값 | I8: 근거
A9: 1 | B9: WAFER_SEQ | C9: Wafer 번호 (TQP_WAFER.WAFER_SEQ) | D9: NUMBER | E9: N | F9: 1 | G9: TQP_WAFER | I9: 소스 | J9: 1
A10: 2 | B10: DIE_NUM | C10: Die 순번 (파일 Die 행 순서 1 ~ N) | D10: NUMBER | E10: N | F10: 2 | I10: 소스 | J10: 1
A11: 3 | B11: DIEPROBE_CNT | C11: Die 재측정 순번 (적재 때 0) | D11: NUMBER | E11: Y | I11: 소스 | J11: 1
A12: 4 | B12: X | C12: Die X Index (CP 파일 좌표, Map 보정 설정이 있으면 적용) | D12: NUMBER | E12: Y | I12: 소스 | J12: 1
A13: 5 | B13: Y | C13: Die Y Index (CP 파일 좌표, Map 보정 설정이 있으면 적용) | D13: NUMBER | E13: Y | I13: 소스 | J13: 1
A14: 6 | B14: BIN | C14: Die Bin 번호 (TQP_BINDESC.BIN, 요약은 0 ~ 99 만 집계) | D14: NUMBER | E14: Y | G14: TQP_BINDESC | I14: 소스 | J14: 1
A16: 제약 조건
A17: No | B17: 구분 | C17: 제약 이름 | D17: 컬럼 | G17: 내용
A18: 1 | B18: PK | C18: SYS_C008120 | D18: WAFER_SEQ, DIE_NUM | G18: 기본 키
A20: 인덱스
A21: No | B21: 유일 | C21: 인덱스 이름 | D21: 컬럼 | G21: 용도
A22: 1 | B22: UNIQUE | C22: SYS_C008120 | D22: WAFER_SEQ, DIE_NUM | G22: 기본 키

Sheet TQP_BINDESC
A1: 테이블 명세서
I2: <- 테이블 목록
A3: 테이블명 | C3: TQP_BINDESC | D3: 영역 | E3: YMS | G3: 스키마 | H3: DMSMGR
A4: 테이블 설명 | C4: Program 별 Bin 정의 (Bin 이름 / 양품 여부 / Map 색)
A5: 기본 키 (PK) | C5: PK_TQP_BINDESC (PROGRAM, BIN) | D5: 컬럼 수 | E5: =SUM(J9:J19) -> 11 | G5: Query XML | H5: TQP_BINDESC.xml
A6: 사용 기능 | C6: Bin Define (frmSetupBin), 요약 수율 Good Bin, Map Bin 색 / 분포, E-Test YMS 적재 Bin 등록, DMS Defect-Test 매칭
A8: No | B8: 컬럼명 | C8: 컬럼 설명 | D8: 데이터 타입 | E8: NULL | F8: PK | G8: 참조 (논리) | H8: 기본값 | I8: 근거
A9: 1 | B9: PROGRAM | C9: Test Program (TQP_PROGRAM.PROGRAM, AVI 는 'AVI') | D9: VARCHAR2(50) | E9: N | F9: 1 | G9: TQP_PROGRAM | I9: 소스 | J9: 1
A10: 2 | B10: BIN | C10: Bin 번호 (TD 테이블 BIN 값) | D10: NUMBER | E10: N | F10: 2 | I10: 소스 | J10: 1
A11: 3 | B11: BIN_GROUP | C11: Bin 그룹 (옛 조회 쿼리 주석상 Hard Bin, 현재 저장 안 함) | D11: NUMBER | E11: Y | I11: 소스 | J11: 1
A12: 4 | B12: BIN_NAME | C12: Bin 이름 (E-Test 는 'HW2 SW2001' 형식) | D12: VARCHAR2(30) | E12: Y | I12: 소스 | J12: 1
A13: 5 | B13: CHAR_BIN | C13: Map 표시 문자 (AVI 는 원본 Bin 문자) | D13: VARCHAR2(30) | E13: Y | I13: 소스 | J13: 1
A14: 6 | B14: HIGH_GEC | C14: 양품 Bin 여부 (Y = Good, 수율 GEC 계산) | D14: CHAR(1) | E14: Y | I14: 소스 | J14: 1
A15: 7 | B15: DISPLAY | C15: 표시 여부 (Y / N) | D15: CHAR(1) | E15: Y | I15: 소스 | J15: 1
A16: 8 | B16: UPPER_LIMIT_CNT | C16: Bin Die 수 상한 (Bin 분포 조회에 표시) | D16: NUMBER | E16: Y | I16: 소스 | J16: 1
A17: 9 | B17: LOWER_LIMIT_CNT | C17: Bin Die 수 하한 (Bin 분포 조회에 표시) | D17: NUMBER | E17: Y | I17: 소스 | J17: 1
A18: 10 | B18: COLOR | C18: Map 표시 색 (HTML '#RRGGBB') | D18: VARCHAR2(9) | E18: Y | I18: 소스 | J18: 1
A19: 11 | B19: DESCRIPTION | C19: Bin 설명 (E-Test 는 HW / SW Bin 설명) | D19: VARCHAR2(100) | E19: Y | I19: 소스 | J19: 1
A21: 제약 조건
A22: No | B22: 구분 | C22: 제약 이름 | D22: 컬럼 | G22: 내용
A23: 1 | B23: PK | C23: PK_TQP_BINDESC | D23: PROGRAM, BIN | G23: 기본 키
A25: 인덱스
A26: No | B26: 유일 | C26: 인덱스 이름 | D26: 컬럼 | G26: 용도
A27: 1 | B27: UNIQUE | C27: PK_TQP_BINDESC | D27: PROGRAM, BIN | G27: 기본 키

Sheet TQP_CHANGE_HIS
A1: 테이블 명세서
I2: <- 테이블 목록
A3: 테이블명 | C3: TQP_CHANGE_HIS | D3: 영역 | E3: YMS | G3: 스키마 | H3: DMSMGR
A4: 테이블 설명 | C4: YMS Test 데이터 수정 / 삭제 이력
A5: 기본 키 (PK) | C5: PK_TQP_CHANGE_HIS (TRAN_KEY) | D5: 컬럼 수 | E5: =SUM(J9:J23) -> 15 | G5: Query XML | H5: TQP_CHANGE_HIS.xml
A6: 사용 기능 | C6: TEST Data Maint (frmTestDataMaint) 변경 이력 기록 / 조회
A8: No | B8: 컬럼명 | C8: 컬럼 설명 | D8: 데이터 타입 | E8: NULL | F8: PK | G8: 참조 (논리) | H8: 기본값 | I8: 근거
A9: 1 | B9: TRAN_KEY | C9: 이력 키 = 변경 시각 (SYSTIMESTAMP 'YYYYMMDDHH24MISSFF') | D9: VARCHAR2(20) | E9: N | F9: 1 | I9: 소스 | J9: 1
A10: 2 | B10: FACTORY | C10: Factory (로그인 Factory) | D10: VARCHAR2(50) | E10: N | I10: 소스 | J10: 1
A11: 3 | B11: TESTAREA | C11: TestArea (화면 선택값) | D11: VARCHAR2(50) | E11: N | I11: 소스 | J11: 1
A12: 4 | B12: PRODUCT | C12: Device (화면 선택값) | D12: VARCHAR2(50) | E12: Y | I12: 소스 | J12: 1
A13: 5 | B13: PROGRAM | C13: Test Program (화면 선택값) | D13: VARCHAR2(50) | E13: Y | I13: 소스 | J13: 1
A14: 6 | B14: LOT_ID | C14: Lot ID (화면 선택값) | D14: VARCHAR2(50) | E14: N | I14: 소스 | J14: 1
A15: 7 | B15: WAFER_ID | C15: Wafer ID (화면 표시 'ID (재측정 순번)' 형식) | D15: VARCHAR2(50) | E15: Y | I15: 소스 | J15: 1
A16: 8 | B16: TRAN_USER | C16: 변경한 사용자 ID | D16: VARCHAR2(50) | E16: N | I16: 소스 | J16: 1
A17: 9 | B17: TRAN_USER_IP | C17: 변경한 PC IP | D17: VARCHAR2(50) | E17: N | I17: 소스 | J17: 1
A18: 10 | B18: TRAN_CATEGORY | C18: 변경 대상 (RAWDATA / WAFER / LOT / FILE_UPLOAD) | D18: VARCHAR2(50) | E18: N | I18: 소스 | J18: 1
A19: 11 | B19: TRAN_TYPE | C19: 변경 유형 (INSERT / UPDATE / DELETE / CHANGE_PROGRAM) | D19: VARCHAR2(50) | E19: N | I19: 소스 | J19: 1
A20: 12 | B20: TRAN_COUNT | C20: 변경 건수 (RAWDATA 는 수정 행 수, 그 외 1) | D20: NUMBER | E20: Y | I20: 소스 | J20: 1
A21: 13 | B21: PREV_VALUE | C21: 변경 전 값 (Lot / Wafer ID, Program 등) | D21: VARCHAR2(50) | E21: Y | I21: 소스 | J21: 1
... A23: 15 | B23: USER_COMMENT | C23: 사용자 입력 변경 사유 | D23: VARCHAR2(200) | E23: Y | I23: 소스 | J23: 1
A25: 제약 조건
A26: No | B26: 구분 | C26: 제약 이름 | D26: 컬럼 | G26: 내용
A27: 1 | B27: PK | C27: PK_TQP_CHANGE_HIS | D27: TRAN_KEY | G27: 기본 키
A29: 인덱스
A30: No | B30: 유일 | C30: 인덱스 이름 | D30: 컬럼 | G30: 용도
A31: 1 | B31: UNIQUE | C31: PK_TQP_CHANGE_HIS | D31: TRAN_KEY | G31: 기본 키

Sheet TQP_CUSTOMER
A1: 테이블 명세서
I2: <- 테이블 목록
A3: 테이블명 | C3: TQP_CUSTOMER | D3: 영역 | E3: YMS | G3: 스키마 | H3: DMSMGR
A4: 테이블 설명 | C4: 고객 정보 (이전 MAP Parser 용, 현재 데이터 / 화면 없음)
A5: 기본 키 (PK) | C5: PK_TQP_CUSTOMER (CUSTOMER_ID) | D5: 컬럼 수 | E5: =SUM(J9:J23) -> 15 | G5: Query XML | H5: TQP_CUSTOMER.xml
A6: 사용 기능 | C6: YMS MAP Parser (YMSFileMonitor) 고객 조회, ProbeAdmin 고객 관리 함수 (화면 호출 없음)
A8: No | B8: 컬럼명 | C8: 컬럼 설명 | D8: 데이터 타입 | E8: NULL | F8: PK | G8: 참조 (논리) | H8: 기본값 | I8: 근거
A9: 1 | B9: CUSTOMER_ID | C9: 고객 ID (MAP Parser 가 TQP_PRODUCT.CUSTOMER_ID 로 복사) | D9: VARCHAR2(30) | E9: N | F9: 1 | I9: 소스 | J9: 1
A10: 2 | B10: CUSTOMER_NAME | C10: 고객 이름 | D10: VARCHAR2(30) | E10: N | I10: 이름 추정 | J10: 1
A11: 3 | B11: CUSTOMER_DESC | C11: 고객 설명 | D11: VARCHAR2(100) | E11: Y | I11: 이름 추정 | J11: 1
A12: 4 | B12: DATA_SERVICE | C12: Data 서비스 사용 여부 (숫자 1자리) | D12: NUMBER(1) | E12: Y | I12: 이름 추정 | J12: 1
A13: 5 | B13: USER_COUNT | C13: 사용자 수 | D13: NUMBER(2) | E13: Y | I13: 이름 추정 | J13: 1
A14: 6 | B14: EXPIRE_DATE | C14: 만료 일자 | D14: DATE | E14: Y | I14: 이름 추정 | J14: 1
A15: 7 | B15: FTPSITE | C15: FTP 서버 주소 | D15: VARCHAR2(30) | E15: Y | I15: 이름 추정 | J15: 1
A16: 8 | B16: FTPUSER | C16: FTP 사용자 | D16: VARCHAR2(30) | E16: Y | I16: 이름 추정 | J16: 1
A17: 9 | B17: FTPPASSWORD | C17: FTP 비밀번호 (평문 컬럼) | D17: VARCHAR2(30) | E17: Y | I17: 이름 추정 | J17: 1
A18: 10 | B18: FTPPATH | C18: FTP 경로 | D18: VARCHAR2(100) | E18: Y | I18: 이름 추정 | J18: 1
A19: 11 | B19: SENDTIME | C19: 전송 시각 설정 | D19: VARCHAR2(100) | E19: Y | I19: 이름 추정 | J19: 1
A20: 12 | B20: AVIFORMAT | C20: AVI 결과 파일 형식 | D20: VARCHAR2(100) | E20: Y | I20: 이름 추정 | J20: 1
A21: 13 | B21: EDSFORMAT | C21: EDS 결과 파일 형식 | D21: VARCHAR2(100) | E21: Y | I21: 이름 추정 | J21: 1
... A23: 15 | B23: RAWDATA | C23: Raw Data 형식 / 경로 | D23: VARCHAR2(100) | E23: Y | I23: 이름 추정 | J23: 1
A25: 제약 조건
A26: No | B26: 구분 | C26: 제약 이름 | D26: 컬럼 | G26: 내용
A27: 1 | B27: PK | C27: PK_TQP_CUSTOMER | D27: CUSTOMER_ID | G27: 기본 키
A29: 인덱스
A30: No | B30: 유일 | C30: 인덱스 이름 | D30: 컬럼 | G30: 용도
A31: 1 | B31: UNIQUE | C31: PK_TQP_CUSTOMER | D31: CUSTOMER_ID | G31: 기본 키

Sheet TQP_DATA_TABLES
A1: 테이블 명세서
I2: <- 테이블 목록
A3: 테이블명 | C3: TQP_DATA_TABLES | D3: 영역 | E3: YMS | G3: 스키마 | H3: DMSMGR
A4: 테이블 설명 | C4: Program 별 Die 측정 데이터 테이블(TD_*) 목록
A5: 기본 키 (PK) | C5: PK_TQP_DATA_TABLES (FACTORY, PROGRAM, TABLE_NAME) | D5: 컬럼 수 | E5: =SUM(J9:J11) -> 3 | G5: Query XML | H5: TQP_DATA_TABLES.xml
A6: 사용 기능 | C6: TD 테이블 생성 때 등록 (TD_TABLE.CreateNewTable), Wafer 데이터 조회 / 삭제 때 TD 테이블 찾기
A8: No | B8: 컬럼명 | C8: 컬럼 설명 | D8: 데이터 타입 | E8: NULL | F8: PK | G8: 참조 (논리) | H8: 기본값 | I8: 근거
A9: 1 | B9: FACTORY | C9: Factory (예 SCK) | D9: VARCHAR2(14) | E9: N | F9: 1 | I9: 소스 | J9: 1
A10: 2 | B10: PROGRAM | C10: Test Program (TQP_PROGRAM.PROGRAM) | D10: VARCHAR2(50) | E10: N | F10: 2 | I10: 소스 | J10: 1
A11: 3 | B11: TABLE_NAME | C11: TD 테이블 이름 (TD_<PROGRAM>, 900 컬럼 넘으면 A / B 접미어) | D11: VARCHAR2(50) | E11: N | F11: 3 | I11: 소스 | J11: 1
A13: 제약 조건
A14: No | B14: 구분 | C14: 제약 이름 | D14: 컬럼 | G14: 내용
A15: 1 | B15: PK | C15: PK_TQP_DATA_TABLES | D15: FACTORY, PROGRAM, TABLE_NAME | G15: 기본 키
A17: 인덱스
A18: No | B18: 유일 | C18: 인덱스 이름 | D18: 컬럼 | G18: 용도
A19: 1 | B19: UNIQUE | C19: PK_TQP_DATA_TABLES | D19: FACTORY, PROGRAM, TABLE_NAME | G19: 기본 키

Sheet TQP_FOI_DIE
A1: 테이블 명세서
I2: <- 테이블 목록
A3: 테이블명 | C3: TQP_FOI_DIE | D3: 영역 | E3: YMS | G3: 스키마 | H3: DMSMGR
A4: 테이블 설명 | C4: AVI / Scope 외관검사 Die 결과 (Die 별 Bin / 이미지)
A5: 기본 키 (PK) | C5: TQP_FOI_DIE_PK (WAFER_SEQ, DIE_NUM) | D5: 컬럼 수 | E5: =SUM(J9:J20) -> 12 | G5: Query XML | H5: TQP_FOI_DIE.xml
A6: 사용 기능 | C6: AVI DataService 적재, Scope 수동 업로드 (TestCommon.ScopeDataSet), AVI Cum Map / FOI Cum Report 조회
A8: No | B8: 컬럼명 | C8: 컬럼 설명 | D8: 데이터 타입 | E8: NULL | F8: PK | G8: 참조 (논리) | H8: 기본값 | I8: 근거
A9: 1 | B9: WAFER_SEQ | C9: Wafer 번호 (TQP_WAFER.WAFER_SEQ) | D9: NUMBER | E9: N | F9: 1 | G9: TQP_WAFER, TQP_WAFER_SUM | I9: 소스 | J9: 1
A10: 2 | B10: DIE_NUM | C10: Die 순번 (적재 행 순서 1 ~ N) | D10: NUMBER | E10: N | F10: 2 | I10: 소스 | J10: 1
A11: 3 | B11: TEST_AREA | C11: TestArea ('AVI' 고정) | D11: VARCHAR2(20) | E11: Y | I11: 소스 | J11: 1
A12: 4 | B12: DIEPROBE_CNT | C12: Die 재측정 순번 (0 고정) | D12: NUMBER | E12: N | I12: 소스 | J12: 1
A13: 5 | B13: X | C13: Die X Index | D13: NUMBER | E13: N | I13: 소스 | J13: 1
A14: 6 | B14: Y | C14: Die Y Index | D14: NUMBER | E14: N | I14: 소스 | J14: 1
A15: 7 | B15: BIN | C15: 외관검사 Bin (숫자 아닌 원본 Bin 은 99, Scope Bin 우선) | D15: NUMBER | E15: Y | G15: TQP_BINDESC | I15: 소스 | J15: 1
A16: 8 | B16: BIN_CHAR | C16: 원본 Bin 문자 | D16: VARCHAR2(20) | E16: Y | I16: 소스 | J16: 1
A17: 9 | B17: IMAGE_PATH | C17: Scope 이미지 경로 | D17: VARCHAR2(200) | E17: Y | I17: 소스 | J17: 1
A18: 10 | B18: THUMB_PATH | C18: 썸네일 경로 (현재 비움) | D18: VARCHAR2(200) | E18: Y | I18: 소스 | J18: 1
A19: 11 | B19: IMAGE_FILE_NAME | C19: Scope 이미지 파일 이름 | D19: VARCHAR2(200) | E19: Y | I19: 소스 | J19: 1
A20: 12 | B20: THUMB_FILENAME | C20: 썸네일 파일 이름 (현재 비움) | D20: VARCHAR2(200) | E20: Y | I20: 소스 | J20: 1
A22: 제약 조건
A23: No | B23: 구분 | C23: 제약 이름 | D23: 컬럼 | G23: 내용
A24: 1 | B24: PK | C24: TQP_FOI_DIE_PK | D24: WAFER_SEQ, DIE_NUM | G24: 기본 키
A26: 인덱스
A27: No | B27: 유일 | C27: 인덱스 이름 | D27: 컬럼 | G27: 용도
A28: 1 | B28: - | C28: IDX_TQP_FOI_DIE_01 | D28: WAFER_SEQ
A29: 2 | B29: UNIQUE | C29: TQP_FOI_DIE_PK | D29: WAFER_SEQ, DIE_NUM | G29: 기본 키

Sheet TQP_FOI_IMAGES
A1: 테이블 명세서
I2: <- 테이블 목록
A3: 테이블명 | C3: TQP_FOI_IMAGES | D3: 영역 | E3: YMS | G3: 스키마 | H3: DMSMGR
A4: 테이블 설명 | C4: Scope 외관검사 이미지 목록 (Die 위치 별)
A5: 기본 키 (PK) | C5: (없음) | D5: 컬럼 수 | E5: =SUM(J9:J16) -> 8 | G5: Query XML | H5: TQP_FOI_IMAGES.xml
A6: 사용 기능 | C6: Scope 수동 업로드 (TestCommon.ScopeDataSet), FOI 이미지 조회 (ProbeMapAnalysis)
A8: No | B8: 컬럼명 | C8: 컬럼 설명 | D8: 데이터 타입 | E8: NULL | F8: PK | G8: 참조 (논리) | H8: 기본값 | I8: 근거
A9: 1 | B9: WAFER_SEQ | C9: Wafer 번호 (TQP_WAFER.WAFER_SEQ) | D9: NUMBER | E9: N | G9: TQP_WAFER_SUM | I9: 소스 | J9: 1
A10: 2 | B10: X | C10: Die X Index | D10: NUMBER | E10: N | I10: 소스 | J10: 1
A11: 3 | B11: Y | C11: Die Y Index | D11: NUMBER | E11: N | I11: 소스 | J11: 1
A12: 4 | B12: BIN | C12: 이미지 Die 의 Bin | D12: NUMBER | E12: Y | I12: 소스 | J12: 1
A13: 5 | B13: IMAGE_PATH | C13: 서버 이미지 경로 | D13: VARCHAR2(200) | E13: Y | I13: 소스 | J13: 1
A14: 6 | B14: THUMB_PATH | C14: 썸네일 경로 (현재 비움) | D14: VARCHAR2(200) | E14: Y | I14: 소스 | J14: 1
A15: 7 | B15: IMAGE_FILE_NAME | C15: 로컬 이미지 파일 이름 | D15: VARCHAR2(200) | E15: Y | I15: 소스 | J15: 1
A16: 8 | B16: THUMB_FILENAME | C16: 썸네일 파일 이름 (현재 비움) | D16: VARCHAR2(200) | E16: Y | I16: 소스 | J16: 1
A18: 제약 조건
A19: No | B19: 구분 | C19: 제약 이름 | D19: 컬럼 | G19: 내용
A20: - | B20: - | C20: (없음)
A22: 인덱스
A23: No | B23: 유일 | C23: 인덱스 이름 | D23: 컬럼 | G23: 용도
A24: 1 | B24: - | C24: IDX_TQP_FOI_IMAGES_01 | D24: WAFER_SEQ

Sheet TQP_LOT
A1: 테이블 명세서
I2: <- 테이블 목록
A3: 테이블명 | C3: TQP_LOT | D3: 영역 | E3: YMS | G3: 스키마 | H3: DMSMGR
A4: 테이블 설명 | C4: YMS Test Lot 정보 (Factory + TestArea + Lot + Program 당 1건)
A5: 기본 키 (PK) | C5: PK_TQP_LOT (FACTORY, LOT_SEQ) | D5: 컬럼 수 | E5: =SUM(J9:J30) -> 26 | G5: Query XML | H5: TQP_LOT.xml
A6: 사용 기능 | C6: CP / PCM / AVI DataService 적재, E-Test 업로드 YMS 적재, TEST Data Maint, TEST Analysis 조회 조건, RPNet TSK Map 생성
A8: No | B8: 컬럼명 | C8: 컬럼 설명 | D8: 데이터 타입 | E8: NULL | F8: PK | G8: 참조 (논리) | H8: 기본값 | I8: 근거
A9: 1 | B9: FACTORY | C9: Factory (서비스 / 로그인 Factory, 예 SCK) | D9: VARCHAR2(10) | E9: N | F9: 1 | G9: TQP_MAPDEF, TQP_PRODUCT | I9: 소스 | J9: 1
A10: 2 | B10: LOT_SEQ | C10: Lot 번호 (LOT_SEQ 시퀀스, DMS TQD_LOT 과 같은 시퀀스) | D10: NUMBER(15) | E10: N | F10: 2 | I10: 소스 | J10: 1
A11: 3 | B11: LOT_ID | C11: Lot ID (STDF MIR.LOT_ID) | D11: VARCHAR2(20) | E11: N | G11: TQC_LOT_STS | I11: 소스 | J11: 1
A12: 4 | B12: LOT_TYPE | C12: Lot 유형 (이관 컬럼, 현재 값 없음) | D12: VARCHAR2(20) | E12: Y | I12: 이름 추정 | J12: 1
A13: 5 | B13: FABLOT | C13: Fab Lot ID (이관 데이터만 값 있음) | D13: VARCHAR2(20) | E13: Y | I13: 이름 추정 | J13: 1
A14: 6 | B14: TEST_AREA | C14: Test 공정 (MULTIPROBE / PARAMETRIC / POSTLASER / AVI / TSVET 등) | D14: VARCHAR2(30) | E14: Y | I14: 소스 | J14: 1
A15: 7 | B15: TEST_TYPE | C15: Test 유형 (이관 데이터만, STDF MIR.TEST_COD) | D15: VARCHAR2(30) | E15: Y | I15: 이름 추정 | J15: 1
A16: 8 | B16: LOG_POINT | C16: Log Point (이관 데이터만 값 있음) | D16: VARCHAR2(30) | E16: Y | I16: 이름 추정 | J16: 1
A17: 9 | B17: OPERATION | C17: 공정 Operation (현재 값 없음) | D17: VARCHAR2(30) | E17: Y | I17: 이름 추정 | J17: 1
A18: 10 | B18: PROGRAM | C18: Test Program (TQP_PROGRAM.PROGRAM, E-Test 는 Device_공정) | D18: VARCHAR2(50) | E18: Y | I18: 소스 | J18: 1
A19: 11 | B19: DEVICE | C19: Device (CP / PCM: MES MAT_ID, E-Test: 파일 Device) | D19: VARCHAR2(30) | E19: Y | I19: 소스 | J19: 1
A20: 12 | B20: SMS_DEVICE | C20: SMS Device (이관 데이터만 값 있음) | D20: VARCHAR2(30) | E20: Y | I20: 이름 추정 | J20: 1
A21: 13 | B21: SMS_ITEM_ID | C21: SMS Item ID (이관 컬럼) | D21: VARCHAR2(30) | E21: Y | I21: 이름 추정 | J21: 1
A22: 14 | B22: DEVICE_ALIAS | C22: Device Alias = Map ID (CP: MES MASK_ID, E-Test: Map ID) | D22: VARCHAR2(30) | E22: Y | G22: TQP_MAPDEF, TQP_PRODUCT | I22: 소스 | J22: 1
A23: 15 | B23: FAMILY | C23: Device Family (STDF MIR.FAMLY_ID, 현재 값 없음) | D23: VARCHAR2(30) | E23: Y | I23: 이름 추정 | J23: 1
A24: 16 | B24: START_TIME | C24: Lot 시작 일시 (처음 적재한 Wafer 의 시작 일시) | D24: DATE | E24: Y | I24: 소스 | J24: 1
A25: 17 | B25: END_TIME | C25: Lot 종료 일시 (마지막 적재 Wafer 의 종료 일시로 갱신) | D25: DATE | E25: Y | I25: 소스 | J25: 1
A26: 18 | B26: WAFER_DIAM | C26: Wafer 지름 mm (200 / 300, E-Test 는 Map WAFER_SIZE / 1000) | D26: NUMBER | E26: Y | I26: 소스 | J26: 1
A27: 19 | B27: COMMENTS | C27: 비고 (이관 컬럼, 현재 값 없음) | D27: VARCHAR2(40) | E27: Y | I27: 이름 추정 | J27: 1
A28: 20 | B28: MERGE_FLAG | C28: Merge 여부 (이관 컬럼, 현재 값 없음) | D28: CHAR(1) | E28: Y | I28: 이름 추정 | J28: 1
A29: 21 ~ 25 | B29: CMF_FIELD01 ~ CMF_FIELD05 (5개) | C29: 사용자 정의 필드 01 ~ 05 (현재 미사용) | D29: VARCHAR2(50) | E29: Y | I29: 이름 추정 | J29: 5
A30: 26 | B30: OLD_LOT_SEQ | C30: 이전 YMS LOT_SEQ (이관 원본 LOT.LOT_SEQ) | D30: NUMBER(10) | E30: Y | I30: 소스 | J30: 1
A32: 제약 조건
A33: No | B33: 구분 | C33: 제약 이름 | D33: 컬럼 | G33: 내용
A34: 1 | B34: PK | C34: PK_TQP_LOT | D34: FACTORY, LOT_SEQ | G34: 기본 키
A36: 인덱스
A37: No | B37: 유일 | C37: 인덱스 이름 | D37: 컬럼 | G37: 용도
A38: 1 | B38: - | C38: IDX_TQP_LOT_01 | D38: LOT_ID
A39: 2 | B39: - | C39: IDX_TQP_LOT_02 | D39: END_TIME, TEST_AREA
A40: 3 | B40: UNIQUE | C40: PK_TQP_LOT | D40: FACTORY, LOT_SEQ | G40: 기본 키

Sheet TQP_LOT_SUM
A1: 테이블 명세서
I2: <- 테이블 목록
A3: 테이블명 | C3: TQP_LOT_SUM | D3: 영역 | E3: YMS | G3: 스키마 | H3: DMSMGR
A4: 테이블 설명 | C4: Lot 별 Test 요약 (Wafer 요약을 Lot 으로 집계)
A5: 기본 키 (PK) | C5: PK_TQP_LOT_SUM (LOT_SEQ) | D5: 컬럼 수 | E5: =SUM(J9:J26) -> 168 | G5: Query XML | H5: TQP_LOT_SUM.xml
A6: 사용 기능 | C6: 적재 후 요약 생성 (TestCommon.SummaryData), Wafer 삭제 후 재생성 (TestDataMaint), Lot 목록 조회 (DataSelect.GetLotList)
A8: No | B8: 컬럼명 | C8: 컬럼 설명 | D8: 데이터 타입 | E8: NULL | F8: PK | G8: 참조 (논리) | H8: 기본값 | I8: 근거
A9: 1 | B9: CUSTOMER | C9: 고객 (생성 때 'DB', CP 적재는 MES Lot 고객으로 갱신) | D9: VARCHAR2(30) | E9: N | I9: 소스 | J9: 1
A10: 2 | B10: FACILITY | C10: Factory (예 SCK) | D10: VARCHAR2(30) | E10: N | I10: 소스 | J10: 1
A11: 3 | B11: PRODUCT | C11: Device (TQP_LOT.DEVICE) | D11: VARCHAR2(30) | E11: N | I11: 소스 | J11: 1
A12: 4 | B12: DEVICE_ALIAS | C12: Device Alias = Map ID | D12: VARCHAR2(30) | E12: N | I12: 소스 | J12: 1
A13: 5 | B13: TESTAREA | C13: TestArea | D13: VARCHAR2(30) | E13: N | I13: 소스 | J13: 1
A14: 6 | B14: PROGRAM | C14: Test Program | D14: VARCHAR2(50) | E14: N | I14: 소스 | J14: 1
A15: 7 | B15: MOTHER_LOT_ID | C15: 모 Lot ID (LOT_ID 와 같은 값 저장) | D15: VARCHAR2(30) | E15: Y | I15: 소스 | J15: 1
A16: 8 | B16: LOT_ID | C16: Lot ID | D16: VARCHAR2(30) | E16: N | I16: 소스 | J16: 1
A17: 9 | B17: LOT_SEQ | C17: Lot 번호 (TQP_LOT.LOT_SEQ) | D17: NUMBER(15) | E17: N | F17: 1 | G17: TQP_LOT | I17: 소스 | J17: 1
A18: 10 | B18: START_TIME | C18: Lot 첫 Wafer 시작 일시 (Wafer 요약 MIN) | D18: DATE | E18: N | I18: 소스 | J18: 1
A19: 11 | B19: END_TIME | C19: Lot 마지막 Wafer 종료 일시 (Wafer 요약 MAX) | D19: DATE | E19: N | I19: 소스 | J19: 1
A20: 12 | B20: LOSS_DIE | C20: Loss Die 수 합 (Wafer 요약 LOSS_DIE 합) | D20: NUMBER(10) | E20: Y | I20: 소스 | J20: 1
A21: 13 | B21: TESTED_DIE | C21: 측정 Die 수 합 | D21: NUMBER | E21: Y | I21: 소스 | J21: 1
A22: 14 | B22: YIELD | C22: Lot 수율 % (BIN1 합 / 측정 Die 합 x 100) | D22: NUMBER | E22: Y | I22: 소스 | J22: 1
A23: 15 | B23: FTA | C23: FTA 수치 (용도 미확인, 값 없음) | D23: NUMBER | E23: Y | I23: 이름 추정 | J23: 1
A24: 16 | B24: GEC | C24: Good Die 수 합 | D24: NUMBER(10) | E24: Y | I24: 소스 | J24: 1
A25: 17 | B25: WAFERS | C25: Wafer 수 (PROBE_CNT 0 기준) | D25: NUMBER(10) | E25: Y | I25: 소스 | J25: 1
A26: 18 ~ 168 | B26: BIN0 ~ BIN150 (151개) | C26: Bin 번호별 Die 수 합 (BIN0 ~ BIN150, 생성 때 Bin 0 ~ 99 만 채움) | D26: NUMBER(10) | E26: Y | I26: 소스 | J26: 151
A28: 제약 조건
A29: No | B29: 구분 | C29: 제약 이름 | D29: 컬럼 | G29: 내용
A30: 1 | B30: PK | C30: PK_TQP_LOT_SUM | D30: LOT_SEQ | G30: 기본 키
A32: 인덱스
A33: No | B33: 유일 | C33: 인덱스 이름 | D33: 컬럼 | G33: 용도
A34: 1 | B34: UNIQUE | C34: PK_TQP_LOT_SUM | D34: LOT_SEQ | G34: 기본 키

Sheet TQP_MAPCFG
A1: 테이블 명세서
I2: <- 테이블 목록
A3: 테이블명 | C3: TQP_MAPCFG | D3: 영역 | E3: YMS | G3: 스키마 | H3: DMSMGR
A4: 테이블 설명 | C4: Map 좌표 보정 설정 (TestArea + Device + Program 별 방향 / 회전 / 이동)
A5: 기본 키 (PK) | C5: TQP_MAPCFG_PK (MAP_CFG_SEQ) | D5: 컬럼 수 | E5: =SUM(J9:J23) -> 15 | G5: Query XML | H5: TQP_MAPCFG.xml
A6: 사용 기능 | C6: Map Control 저장 (ProbeMapAnalysis), Map Control Update (frmMapConfigUpdate), CP 적재 좌표 보정 (GetCorrectionData)
A8: No | B8: 컬럼명 | C8: 컬럼 설명 | D8: 데이터 타입 | E8: NULL | F8: PK | G8: 참조 (논리) | H8: 기본값 | I8: 근거
A9: 1 | B9: MAP_CFG_SEQ | C9: 보정 설정 번호 (MAP_CFG_SEQ 시퀀스) | D9: NUMBER(15) | E9: N | F9: 1 | I9: 소스 | J9: 1
A10: 2 | B10: REV_NO | C10: 보정 설정 Revision (같은 TestArea / Device / Program 안) | D10: NUMBER(15) | E10: N | I10: 소스 | J10: 1
A11: 3 | B11: TESTAREA | C11: 적용 TestArea | D11: VARCHAR2(30) | E11: N | I11: 소스 | J11: 1
A12: 4 | B12: DEVICE_ALIAS | C12: 적용 Device Alias (Map ID) | D12: VARCHAR2(30) | E12: N | I12: 소스 | J12: 1
A13: 5 | B13: PROGRAM | C13: 적용 Program ('%' 패턴 가능, 'ALL' = 전체) | D13: VARCHAR2(50) | E13: N | I13: 소스 | J13: 1
A14: 6 | B14: ALTER_DIRECTION | C14: 좌표 뒤집기 (LL 그대로 / TL Y 반전 / LR X 반전 / TR X / Y 반전) | D14: VARCHAR2(10) | E14: Y | I14: 소스 | J14: 1
A15: 7 | B15: ALTER_ANGLE | C15: 회전 각도 (0 / 90 / 270) | D15: NUMBER | E15: N | I15: 소스 | J15: 1
A16: 8 | B16: ALTER_INDEX_X | C16: X Index 이동량 | D16: NUMBER | E16: N | I16: 소스 | J16: 1
A17: 9 | B17: ALTER_INDEX_Y | C17: Y Index 이동량 | D17: NUMBER | E17: N | I17: 소스 | J17: 1
A18: 10 | B18: CREATE_USER | C18: 생성 사용자 ID | D18: VARCHAR2(30) | E18: Y | I18: 소스 | J18: 1
A19: 11 | B19: CREATE_TIME | C19: 생성 일시 | D19: DATE | E19: Y | I19: 소스 | J19: 1
A20: 12 | B20: UPDATE_USER | C20: 수정 사용자 ID | D20: VARCHAR2(30) | E20: Y | I20: 소스 | J20: 1
A21: 13 | B21: UPDATE_TIME | C21: 수정 일시 | D21: DATE | E21: Y | I21: 소스 | J21: 1
A22: 14 | B22: USER_COMMENT | C22: 사용자 설명 (삭제 때 사유 기록) | D22: VARCHAR2(500) | E22: Y | I22: 소스 | J22: 1
A23: 15 | B23: DELETE_FLAG | C23: 삭제 여부 (Y 삭제, 기본 N) | D23: VARCHAR2(1) | E23: Y | H23: 'N' | I23: 소스 | J23: 1
A25: 제약 조건
A26: No | B26: 구분 | C26: 제약 이름 | D26: 컬럼 | G26: 내용
A27: 1 | B27: PK | C27: TQP_MAPCFG_PK | D27: MAP_CFG_SEQ | G27: 기본 키
A29: 인덱스
A30: No | B30: 유일 | C30: 인덱스 이름 | D30: 컬럼 | G30: 용도
A31: 1 | B31: - | C31: IDX_TQP_MAPCFG_01 | D31: TESTAREA, DEVICE_ALIAS, PROGRAM
A32: 2 | B32: - | C32: PK_TQP_MAPCFG | D32: MAP_CFG_SEQ | G32: 기본 키

Sheet TQP_MAPDEF
A1: 테이블 명세서
I2: <- 테이블 목록
A3: 테이블명 | C3: TQP_MAPDEF | D3: 영역 | E3: YMS | G3: 스키마 | H3: DMSMGR
A4: 테이블 설명 | C4: Wafer Map 기준 정보 (Map ID 별 Wafer / Die 크기 / 원점 / 방향)
A5: 기본 키 (PK) | C5: (없음) | D5: 컬럼 수 | E5: =SUM(J9:J45) -> 37 | G5: Query XML | H5: TQP_MAPDEF.xml
A6: 사용 기능 | C6: Map Define, File Map Setup, Wafer Map View, TEST Map 그리기, Wafer 요약 NETDIE, KLARF 업로드 Map 기준, RPNet TSK Map 생성
A8: No | B8: 컬럼명 | C8: 컬럼 설명 | D8: 데이터 타입 | E8: NULL | F8: PK | G8: 참조 (논리) | H8: 기본값 | I8: 근거
A9: 1 | B9: FACTORY | C9: Factory (기본값 'SCK') | D9: VARCHAR2(30) | E9: Y | H9: 'SCK' | I9: 소스 | J9: 1
A10: 2 | B10: MAPID | C10: Map ID (= TQP_LOT.DEVICE_ALIAS / TQP_PRODUCT.MAPID) | D10: VARCHAR2(30) | E10: Y | I10: 소스 | J10: 1
A11: 3 | B11: WAFER_SIZE | C11: Wafer 지름 µm (200000 / 300000) | D11: NUMBER | E11: Y | I11: 설계 문서 | J11: 1
A12: 4 | B12: CHIP_SIZE_X | C12: Die 크기(Pitch) X, µm | D12: NUMBER | E12: Y | I12: 설계 문서 | J12: 1
A13: 5 | B13: CHIP_SIZE_Y | C13: Die 크기(Pitch) Y, µm | D13: NUMBER | E13: Y | I13: 설계 문서 | J13: 1
A14: 6 | B14: ORIGIN_MICRO_X | C14: 원점 위치 X, µm (KLARF SampleCenterLocation X) | D14: NUMBER | E14: Y | I14: 소스 | J14: 1
A15: 7 | B15: ORIGIN_MICRO_Y | C15: 원점 Y 저장값 µm (= CHIP_SIZE_Y - 원점 Y, 조회 때 되돌림) | D15: NUMBER | E15: Y | I15: 소스 | J15: 1
A16: 8 | B16: ORIGIN_INDEX_X | C16: 원점 Die X Index (TQD_SETUP.DIE_ORIGIN_X 와 같음) | D16: NUMBER | E16: Y | I16: 설계 문서 | J16: 1
A17: 9 | B17: ORIGIN_INDEX_Y | C17: 원점 Die Y Index (TQD_SETUP.DIE_ORIGIN_Y 와 같음) | D17: NUMBER | E17: Y | I17: 설계 문서 | J17: 1
A18: 10 | B18: FIRST_MICRO_X | C18: 첫 Die 위치 X, µm (첫 Die Index x Die 크기) | D18: NUMBER | E18: Y | I18: 소스 | J18: 1
A19: 11 | B19: FIRST_MICRO_Y | C19: 첫 Die 위치 Y, µm (첫 Die Index x Die 크기) | D19: NUMBER | E19: Y | I19: 소스 | J19: 1
A20: 12 | B20: FIRST_INDEX_X | C20: 첫 Die X Index | D20: NUMBER | E20: Y | I20: 소스 | J20: 1
A21: 13 | B21: FIRST_INDEX_Y | C21: 첫 Die Y Index | D21: NUMBER | E21: Y | I21: 소스 | J21: 1
... A36: 28 | B36: DIE_INDEX_MAX_Y | C36: Die Y Index 최대값 (Wafer 전체 격자) | D36: NUMBER | E36: Y | I36: 설계 문서 | J36: 1
A37: 29 | B37: XY_DIRECTION | C37: Index 방향 (0 LeftTop / 1 LeftBottom / 2 RightBottom / 3 RightTop) | D37: NUMBER | E37: Y | H37: 0 | I37: 소스 | J37: 1
A38: 30 | B38: REFERENCEDIE_SETTING | C38: 기준 Die 설정 (TSK Map 헤더 값, 원점 계산 방식, 기본 2) | D38: NUMBER | E38: Y | H38: 2 | I38: 소스 | J38: 1
A39: 31 | B39: DELETE_FLAG | C39: 삭제 여부 (Y 삭제 또는 사용자 Map, 기본 N) | D39: CHAR(1) | E39: Y | H39: 'N' | I39: 소스 | J39: 1
A40: 32 | B40: INSERT_TIME | C40: 생성 일시 | D40: DATE | E40: Y | I40: 소스 | J40: 1
A41: 33 | B41: INSERT_USER | C41: 생성 사용자 ID | D41: VARCHAR2(30) | E41: Y | I41: 소스 | J41: 1
A42: 34 | B42: UPDATE_TIME | C42: 수정 일시 | D42: DATE | E42: Y | I42: 소스 | J42: 1
A43: 35 | B43: UPDATE_USER | C43: 수정 사용자 ID | D43: VARCHAR2(30) | E43: Y | I43: 소스 | J43: 1
A44: 36 | B44: USER_REF_X | C44: 사용자 지정 X Ref Vector, mm (RPNet TSK Map 생성, 없으면 계산) | D44: NUMBER(15,5) | E44: Y | I44: 소스 | J44: 1
A45: 37 | B45: USER_REF_Y | C45: 사용자 지정 Y Ref Vector, mm (RPNet TSK Map 생성, 없으면 계산) | D45: NUMBER(15,5) | E45: Y | I45: 소스 | J45: 1
A47: 제약 조건
A48: No | B48: 구분 | C48: 제약 이름 | D48: 컬럼 | G48: 내용
A49: - | B49: - | C49: (없음)
A51: 인덱스
A52: No | B52: 유일 | C52: 인덱스 이름 | D52: 컬럼 | G52: 용도
A53: - | B53: - | C53: (없음)

Sheet TQP_MAPDEF_DIE
A1: 테이블 명세서
I2: <- 테이블 목록
A3: 테이블명 | C3: TQP_MAPDEF_DIE | D3: 영역 | E3: YMS | G3: 스키마 | H3: DMSMGR
A4: 테이블 설명 | C4: Map 정의 Die / Shot 위치 (Mark Die 표시 / Shot Map 용)
A5: 기본 키 (PK) | C5: PK_TQP_MAPDEF_DIE (FACTORY, MAPID, DIE_TYPE, DIE_NO) | D5: 컬럼 수 | E5: =SUM(J9:J14) -> 6 | G5: Query XML
A6: 사용 기능 | C6: TEST Map View / Map Edit Mark Die 표시, Shot Map View, DMS Defect Map (GET_MAPDEF_DIE_DM)
A8: No | B8: 컬럼명 | C8: 컬럼 설명 | D8: 데이터 타입 | E8: NULL | F8: PK | G8: 참조 (논리) | H8: 기본값 | I8: 근거
A9: 1 | B9: FACTORY | C9: Factory (예 SCK) | D9: VARCHAR2(30) | E9: N | F9: 1 | I9: 소스 | J9: 1
A10: 2 | B10: MAPID | C10: Map ID (TQP_MAPDEF.MAPID) | D10: VARCHAR2(30) | E10: N | F10: 2 | G10: TQP_MAPDEF | I10: 소스 | J10: 1
A11: 3 | B11: DIE_TYPE | C11: 구분 (DIE = Map Die / SHOT = Shot) | D11: VARCHAR2(30) | E11: N | F11: 3 | I11: 소스 | J11: 1
A12: 4 | B12: DIE_NO | C12: Die / Shot 번호 | D12: NUMBER | E12: N | F12: 4 | I12: 소스 | J12: 1
A13: 5 | B13: INDEX_X | C13: Die X Index | D13: NUMBER | E13: Y | I13: 소스 | J13: 1
A14: 6 | B14: INDEX_Y | C14: Die Y Index | D14: NUMBER | E14: Y | I14: 소스 | J14: 1
A16: 제약 조건
A17: No | B17: 구분 | C17: 제약 이름 | D17: 컬럼 | G17: 내용
A18: 1 | B18: PK | C18: PK_TQP_MAPDEF_DIE | D18: FACTORY, MAPID, DIE_TYPE, DIE_NO | G18: 기본 키
A20: 인덱스
A21: No | B21: 유일 | C21: 인덱스 이름 | D21: 컬럼 | G21: 용도
A22: 1 | B22: - | C22: IDX_TQP_MAPDEF_DIE_01 | D22: MAPID
A23: 2 | B23: UNIQUE | C23: PK_TQP_MAPDEF_DIE | D23: FACTORY, MAPID, DIE_TYPE, DIE_NO | G23: 기본 키

Sheet TQP_PARASPEC
A1: 테이블 명세서
I2: <- 테이블 목록
A3: 테이블명 | C3: TQP_PARASPEC | D3: 영역 | E3: YMS | G3: 스키마 | H3: DMSMGR
A4: 테이블 설명 | C4: Program 별 Parameter 정의와 Spec (TD 테이블 컬럼 목록 겸용)
A5: 기본 키 (PK) | C5: PK_TQP_PARASPEC (FACTORY, PROGRAM, PROGRAM_REV, PARAM_NAME) | D5: 컬럼 수 | E5: =SUM(J9:J38) -> 30 | G5: Query XML | H5: TQP_PARASPEC.xml
A6: 사용 기능 | C6: TD 컬럼 자동 등록 (TD_TABLE), Program Parameter Spec Define, Map View / Param Analysis / PCM Report Spec 표시, E-Test LSL / USL 보정
A8: No | B8: 컬럼명 | C8: 컬럼 설명 | D8: 데이터 타입 | E8: NULL | F8: PK | G8: 참조 (논리) | H8: 기본값 | I8: 근거
A9: 1 | B9: FACTORY | C9: Factory (예 SCK) | D9: VARCHAR2(10) | E9: N | F9: 1 | I9: 소스 | J9: 1
A10: 2 | B10: PROGRAM | C10: Test Program (TQP_PROGRAM.PROGRAM) | D10: VARCHAR2(50) | E10: N | F10: 2 | G10: TQP_DATA_TABLES | I10: 소스 | J10: 1
A11: 3 | B11: PROGRAM_REV | C11: Parameter 정의 Revision (현재 0, TQP_WAFER.PROGRAM_REV 와 연결) | D11: NUMBER | E11: N | F11: 3 | I11: 소스 | J11: 1
A12: 4 | B12: PARAM_INDEX | C12: TD 테이블 안 컬럼 순번 (1부터, 이관 데이터는 X -1 / Y 0) | D12: NUMBER(10) | E12: N | I12: 소스 | J12: 1
A13: 5 | B13: PARAM_NAME | C13: Parameter 이름 = TD 테이블 컬럼 이름 (X / Y / BIN 포함) | D13: VARCHAR2(50) | E13: N | F13: 4 | I13: 소스 | J13: 1
A14: 6 | B14: USER_PROGRAM_NAME | C14: 사용자 Parameter 이름 (화면 'User Parameter Name', 값 없음) | D14: VARCHAR2(50) | E14: Y | I14: 소스 | J14: 1
A15: 7 | B15: PARAM_TYPE | C15: 값 형식 (FLOAT / INT, X / Y / BIN 은 INT) | D15: VARCHAR2(50) | E15: Y | I15: 소스 | J15: 1
A16: 8 | B16: PARAM_DESC | C16: Parameter 설명 (E-Test 는 파일 헤더 원문) | D16: VARCHAR2(200) | E16: Y | I16: 소스 | J16: 1
A17: 9 | B17: CREATE_TIME | C17: 생성 일시 | D17: DATE | E17: Y | I17: 소스 | J17: 1
A18: 10 | B18: CREATE_USER | C18: 생성 사용자 ID | D18: VARCHAR2(30) | E18: Y | I18: 소스 | J18: 1
A19: 11 | B19: UPDATE_TIME | C19: 수정 일시 | D19: DATE | E19: Y | I19: 소스 | J19: 1
A20: 12 | B20: UPDATE_USER | C20: 수정 사용자 ID | D20: VARCHAR2(30) | E20: Y | I20: 소스 | J20: 1
A21: 13 | B21: TABLE_NAME | C21: Parameter 컬럼이 있는 TD 테이블 이름 | D21: VARCHAR2(50) | E21: Y | G21: TQP_DATA_TABLES | I21: 소스 | J21: 1
A22: 14 | B22: DECIMAL_PLACES | C22: 표시 소수 자리수 (자동 등록 0) | D22: NUMBER(10) | E22: Y | I22: 소스 | J22: 1
A23: 15 | B23: RUNTIME_DEFINED | C23: 적재 중 자동 등록 여부 (자동 등록 1) | D23: NUMBER | E23: Y | I23: 소스 | J23: 1
A24: 16 | B24: UOM | C24: 단위 (예 V / uA) | D24: VARCHAR2(30) | E24: Y | I24: 소스 | J24: 1
A25: 17 | B25: LSL | C25: Spec 하한 (Map Spec 색 / 차트 선) | D25: NUMBER | E25: Y | I25: 소스 | J25: 1
A26: 18 | B26: TARGET | C26: 목표값 (PCM Report 표시) | D26: NUMBER | E26: Y | I26: 소스 | J26: 1
A27: 19 | B27: USL | C27: Spec 상한 (Map Spec 색 / 차트 선) | D27: NUMBER | E27: Y | I27: 소스 | J27: 1
A28: 20 | B28: LCL | C28: 관리 하한 (Map View / PCM Report 표시) | D28: NUMBER | E28: Y | I28: 소스 | J28: 1
A29: 21 | B29: UCL | C29: 관리 상한 (Map View / PCM Report 표시) | D29: NUMBER | E29: Y | I29: 소스 | J29: 1
A30: 22 | B30: LOL | C30: Outlier 하한 추정 (설정 화면 속성만, 값 없음) | D30: NUMBER | E30: Y | I30: 이름 추정 | J30: 1
A31: 23 | B31: UOL | C31: Outlier 상한 추정 (설정 화면 속성만, 값 없음) | D31: NUMBER | E31: Y | I31: 이름 추정 | J31: 1
A32: 24 | B32: LTL | C32: Test Limit 하한 (Map View 표시, FAB2 PCM 재측정 값 치환 판정) | D32: NUMBER | E32: Y | I32: 소스 | J32: 1
A33: 25 | B33: UTL | C33: Test Limit 상한 (Map View 표시, FAB2 PCM 재측정 값 치환 판정) | D33: NUMBER | E33: Y | I33: 소스 | J33: 1
... A36: 28 | B36: PPD_SEQ | C36: 이전 YMS Parameter 정의 번호 (이관 원본 PROGRAM_PARM_DEF.PPD_SEQ) | D36: NUMBER | E36: Y | I36: 소스 | J36: 1
A37: 29 | B37: USE_FLAG | C37: 사용 여부 (Y / N, 기본 Y) | D37: CHAR(1) | E37: Y | H37: 'Y' | I37: 소스 | J37: 1
A38: 30 | B38: ITEM_LEVEL | C38: Parameter 등급 (이관 값 WAC / IWAC / ENG / MON, 소스 미사용) | D38: VARCHAR2(5) | E38: Y | I38: 이름 추정 | J38: 1
A40: 제약 조건
A41: No | B41: 구분 | C41: 제약 이름 | D41: 컬럼 | G41: 내용
A42: 1 | B42: PK | C42: PK_TQP_PARASPEC | D42: FACTORY, PROGRAM, PROGRAM_REV, PARAM_NAME | G42: 기본 키
A44: 인덱스
A45: No | B45: 유일 | C45: 인덱스 이름 | D45: 컬럼 | G45: 용도
...

Sheet TQP_PCM_INPUT_HIS
A1: 테이블 명세서
I2: <- 테이블 목록
A3: 테이블명 | C3: TQP_PCM_INPUT_HIS | D3: 영역 | E3: YMS | G3: 스키마 | H3: DMSMGR
A4: 테이블 설명 | C4: PCM 설비 Probe Card / 작업자 입력 이력
A5: 기본 키 (PK) | C5: PK_TQP_PCM_INPUT_HIS (FACTORY, EQUIP_ID, INPUT_TIME) | D5: 컬럼 수 | E5: =SUM(J9:J15) -> 11 | G5: Query XML | H5: TQP_PCM_INPUT_HIS.xml
A6: 사용 기능 | C6: PCM Equip Status (frmPcmEquipStatus) 입력 / 조회, Probe Card 사용 시간 계산 (TQC_EQUIP.xml)
A8: No | B8: 컬럼명 | C8: 컬럼 설명 | D8: 데이터 타입 | E8: NULL | F8: PK | G8: 참조 (논리) | H8: 기본값 | I8: 근거
A9: 1 | B9: FACTORY | C9: Factory (로그인 Factory) | D9: VARCHAR2(20) | E9: N | F9: 1 | I9: 소스 | J9: 1
A10: 2 | B10: EQUIP_ID | C10: PCM 설비 ID (TQC_EQUIP.EQUIP_ID) | D10: VARCHAR2(20) | E10: N | F10: 2 | G10: TQC_EQUIP | I10: 소스 | J10: 1
A11: 3 | B11: INPUT_TIME | C11: 입력 일시 (SYSDATE) | D11: DATE | E11: N | F11: 3 | I11: 소스 | J11: 1
A12: 4 | B12: PROBE_CARD | C12: 입력한 Probe Card ID | D12: VARCHAR2(50) | E12: Y | I12: 소스 | J12: 1
A13: 5 | B13: OPERATOR | C13: 입력한 작업자 | D13: VARCHAR2(50) | E13: Y | I13: 소스 | J13: 1
A14: 6 | B14: INPUT_USER_ID | C14: 입력한 로그인 사용자 ID | D14: VARCHAR2(50) | E14: Y | I14: 소스 | J14: 1
A15: 7 ~ 11 | B15: CMF_01 ~ CMF_05 (5개) | C15: 사용자 정의 필드 01 ~ 05 (현재 미사용) | D15: VARCHAR2(50) | E15: Y | I15: 이름 추정 | J15: 5
A17: 제약 조건
A18: No | B18: 구분 | C18: 제약 이름 | D18: 컬럼 | G18: 내용
A19: 1 | B19: PK | C19: PK_TQP_PCM_INPUT_HIS | D19: FACTORY, EQUIP_ID, INPUT_TIME | G19: 기본 키
A21: 인덱스
A22: No | B22: 유일 | C22: 인덱스 이름 | D22: 컬럼 | G22: 용도
A23: 1 | B23: UNIQUE | C23: PK_TQP_PCM_INPUT_HIS | D23: FACTORY, EQUIP_ID, INPUT_TIME | G23: 기본 키

Sheet TQP_PRODUCT
A1: 테이블 명세서
I2: <- 테이블 목록
A3: 테이블명 | C3: TQP_PRODUCT | D3: 영역 | E3: YMS | G3: 스키마 | H3: DMSMGR
A4: 테이블 설명 | C4: Wafer Map 별 Product 관리 (Product 와 Map ID 연결)
A5: 기본 키 (PK) | C5: PK_TQP_PRODUCT (FACTORY, PRODUCT) | D5: 컬럼 수 | E5: =SUM(J9:J14) -> 6 | G5: Query XML | H5: TQP_PRODUCT.xml
A6: 사용 기능 | C6: 적재 때 자동 등록 (TestCommon.InsertProductInfo), Device 조회 조건, Wafer 조회 (SELECT_WAFER_INFO_05 / 06), YMS MAP Parser
A8: No | B8: 컬럼명 | C8: 컬럼 설명 | D8: 데이터 타입 | E8: NULL | F8: PK | G8: 참조 (논리) | H8: 기본값 | I8: 근거
A9: 1 | B9: FACTORY | C9: Factory (예 SCK) | D9: VARCHAR2(30) | E9: N | F9: 1 | I9: 소스 | J9: 1
A10: 2 | B10: PRODUCT | C10: Product (보통 Device Alias = MES MASK_ID, E-Test: Device) | D10: VARCHAR2(30) | E10: N | F10: 2 | I10: 소스 | J10: 1
A11: 3 | B11: CUSTOMER_ID | C11: 고객 ID (MAP Parser 만 채움, 현재 값 없음) | D11: VARCHAR2(30) | E11: Y | I11: 소스 | J11: 1
A12: 4 | B12: CUSTOMER_PROD | C12: 고객 제품명 (현재 값 없음) | D12: VARCHAR2(30) | E12: Y | I12: 이름 추정 | J12: 1
A13: 5 | B13: MAPID | C13: Wafer Map ID (TQP_MAPDEF.MAPID, 보통 PRODUCT 와 같음) | D13: VARCHAR2(30) | E13: Y | G13: TQP_MAPDEF | I13: 소스 | J13: 1
A14: 6 | B14: DELETE_FLAG | C14: 삭제(숨김) 여부 (Y 숨김, 기본 N) | D14: CHAR(1) | E14: Y | H14: 'N' | I14: 소스 | J14: 1
A16: 제약 조건
A17: No | B17: 구분 | C17: 제약 이름 | D17: 컬럼 | G17: 내용
A18: 1 | B18: PK | C18: PK_TQP_PRODUCT | D18: FACTORY, PRODUCT | G18: 기본 키
A20: 인덱스
A21: No | B21: 유일 | C21: 인덱스 이름 | D21: 컬럼 | G21: 용도
A22: 1 | B22: UNIQUE | C22: PK_TQP_PRODUCT | D22: FACTORY, PRODUCT | G22: 기본 키

Sheet TQP_PROGRAM
A1: 테이블 명세서
I2: <- 테이블 목록
A3: 테이블명 | C3: TQP_PROGRAM | D3: 영역 | E3: YMS | G3: 스키마 | H3: DMSMGR
A4: 테이블 설명 | C4: Test Program 정보 (Program 별 TestArea / Device)
A5: 기본 키 (PK) | C5: PK_TQP_PROGRAM (FACTORY, PROGRAM, TESTAREA, DEVICE) | D5: 컬럼 수 | E5: =SUM(J9:J17) -> 18 | G5: Query XML | H5: TQP_PROGRAM.xml
A6: 사용 기능 | C6: 적재 때 자동 등록 (TestCommon.InsertProgramInfo), TestArea / Program 조회 조건 목록, Program Define, Standard Report
A8: No | B8: 컬럼명 | C8: 컬럼 설명 | D8: 데이터 타입 | E8: NULL | F8: PK | G8: 참조 (논리) | H8: 기본값 | I8: 근거
A9: 1 | B9: FACTORY | C9: Factory (예 SCK) | D9: VARCHAR2(14) | E9: N | F9: 1 | I9: 소스 | J9: 1
A10: 2 | B10: PROGRAM | C10: Test Program 이름 (TD 테이블 = TD_<PROGRAM>) | D10: VARCHAR2(50) | E10: N | F10: 2 | I10: 소스 | J10: 1
A11: 3 | B11: TESTAREA | C11: TestArea (MULTIPROBE / PARAMETRIC / TSVET 등) | D11: VARCHAR2(50) | E11: N | F11: 3 | I11: 소스 | J11: 1
A12: 4 | B12: DEVICE | C12: Device (TQP_PRODUCT.PRODUCT, CP / PCM 은 MES MASK_ID) | D12: VARCHAR2(50) | E12: N | F12: 4 | G12: TQP_PRODUCT | I12: 소스 | J12: 1
A13: 5 | B13: CREATE_TIME | C13: 생성 일시 | D13: DATE | E13: Y | I13: 소스 | J13: 1
A14: 6 | B14: CREATE_USER | C14: 생성 사용자 ID | D14: VARCHAR2(100) | E14: Y | I14: 소스 | J14: 1
A15: 7 | B15: UPDATE_TIME | C15: 수정 일시 | D15: DATE | E15: Y | I15: 이름 추정 | J15: 1
A16: 8 | B16: UPDATE_USER | C16: 수정 사용자 ID | D16: VARCHAR2(40) | E16: Y | I16: 이름 추정 | J16: 1
A17: 9 ~ 18 | B17: CMF_FIELD01 ~ CMF_FIELD10 (10개) | C17: 사용자 정의 필드 (01 ~ 05 문자, 06 ~ 10 숫자, 미사용) | D17: NUMBER / VARCHAR2(40) | E17: Y | I17: 이름 추정 | J17: 10
A19: 제약 조건
A20: No | B20: 구분 | C20: 제약 이름 | D20: 컬럼 | G20: 내용
A21: 1 | B21: PK | C21: PK_TQP_PROGRAM | D21: FACTORY, PROGRAM, TESTAREA, DEVICE | G21: 기본 키
A23: 인덱스
A24: No | B24: 유일 | C24: 인덱스 이름 | D24: 컬럼 | G24: 용도
A25: 1 | B25: UNIQUE | C25: PK_TQP_PROGRAM | D25: FACTORY, PROGRAM, TESTAREA, DEVICE | G25: 기본 키

Sheet TQP_USEMAP
A1: 테이블 명세서
I2: <- 테이블 목록
A3: 테이블명 | C3: TQP_USEMAP | D3: 영역 | E3: YMS | G3: 스키마 | H3: DMSMGR
A4: 테이블 설명 | C4: Map 의 Die 목록 (Die Index / 사용 구분)
A5: 기본 키 (PK) | C5: TQP_USEMAP_PK (FACTORY, MAPID, PROGRAM_REV, X, Y) | D5: 컬럼 수 | E5: =SUM(J9:J15) -> 7 | G5: Query XML | H5: TQP_USEMAP.xml
A6: 사용 기능 | C6: Map Define / File Map Setup 저장 (CreateUseMap), Wafer Map View, KLARF 업로드 Map 기준, AVI Map 조회
A8: No | B8: 컬럼명 | C8: 컬럼 설명 | D8: 데이터 타입 | E8: NULL | F8: PK | G8: 참조 (논리) | H8: 기본값 | I8: 근거
A9: 1 | B9: FACTORY | C9: Factory (로그인 Factory) | D9: VARCHAR2(20) | E9: N | F9: 1 | I9: 소스 | J9: 1
A10: 2 | B10: MAPID | C10: Map ID (TQP_MAPDEF.MAPID) | D10: VARCHAR2(50) | E10: N | F10: 2 | G10: TQP_MAPDEF | I10: 소스 | J10: 1
A11: 3 | B11: PROGRAM_REV | C11: Program Revision (저장 때 0 고정) | D11: NUMBER(10) | E11: N | F11: 3 | I11: 소스 | J11: 1
A12: 4 | B12: X | C12: Die X Index (TQP_MAPDEF.XY_DIRECTION 기준 번호) | D12: NUMBER(10) | E12: N | F12: 4 | I12: 소스 | J12: 1
A13: 5 | B13: Y | C13: Die Y Index (TQP_MAPDEF.XY_DIRECTION 기준 번호) | D13: NUMBER(10) | E13: N | F13: 5 | I13: 소스 | J13: 1
A14: 6 | B14: USECODE | C14: Die 사용 구분 (1 사용 / -1 제거 / 0 Skip / 2 Mark) | D14: NUMBER(10) | E14: Y | I14: 소스 | J14: 1
A15: 7 | B15: DIE_NUM | C15: Die 순번 (저장 행 순서 1 ~ N, 방향 순서 아님) | D15: NUMBER(10) | E15: Y | I15: 소스 | J15: 1
A17: 제약 조건
A18: No | B18: 구분 | C18: 제약 이름 | D18: 컬럼 | G18: 내용
A19: 1 | B19: PK | C19: TQP_USEMAP_PK | D19: FACTORY, MAPID, PROGRAM_REV, X, Y | G19: 기본 키
A21: 인덱스
A22: No | B22: 유일 | C22: 인덱스 이름 | D22: 컬럼 | G22: 용도
A23: 1 | B23: UNIQUE | C23: TQP_USEMAP_PK | D23: FACTORY, MAPID, PROGRAM_REV, X, Y | G23: 기본 키

Sheet TQP_VISUALINSPSPEC
A1: 테이블 명세서
I2: <- 테이블 목록
A3: 테이블명 | C3: TQP_VISUALINSPSPEC | D3: 영역 | E3: YMS | G3: 스키마 | H3: DMSMGR
A4: 테이블 설명 | C4: 육안 / 외관검사 불량 코드(Bin) 정의 (검사 유형 별)
A5: 기본 키 (PK) | C5: (없음) | D5: 컬럼 수 | E5: =SUM(J9:J16) -> 8 | G5: Query XML | H5: TQP_VISUALINSPSPEC.xml
A6: 사용 기능 | C6: Visual Inspection Define (frmVisualInspDefine), 육안검사 Map 편집 단축키, AVI / IQC Bin 분포 (T_AVI_TABLE.xml)
A8: No | B8: 컬럼명 | C8: 컬럼 설명 | D8: 데이터 타입 | E8: NULL | F8: PK | G8: 참조 (논리) | H8: 기본값 | I8: 근거
A9: 1 | B9: INSPTYPE | C9: 검사 유형 (기본 VI, IQC / OQC / AVI) | D9: VARCHAR2(30) | E9: N | I9: 소스 | J9: 1
A10: 2 | B10: BIN | C10: 불량 코드 Bin 번호 | D10: NUMBER | E10: N | I10: 소스 | J10: 1
A11: 3 | B11: BIN_NAME | C11: Bin 이름 ('NOTUSE' 는 목록 제외) | D11: VARCHAR2(30) | E11: Y | I11: 소스 | J11: 1
A12: 4 | B12: COLOR | C12: Map 표시 색 | D12: VARCHAR2(9) | E12: Y | I12: 소스 | J12: 1
A13: 5 | B13: CREATE_DATE | C13: 생성 일시 | D13: DATE | E13: N | I13: 이름 추정 | J13: 1
A14: 6 | B14: EDIT_DATE | C14: 수정 일시 | D14: DATE | E14: N | I14: 이름 추정 | J14: 1
A15: 7 | B15: DESCRIPTION | C15: Bin 설명 (Map 편집 콤보 표시) | D15: VARCHAR2(100) | E15: Y | I15: 소스 | J15: 1
A16: 8 | B16: KEYMAP | C16: Map 편집 단축키 (1 ~ 0 / F1 ~ F9) | D16: VARCHAR2(10) | E16: Y | I16: 소스 | J16: 1
A18: 제약 조건
A19: No | B19: 구분 | C19: 제약 이름 | D19: 컬럼 | G19: 내용
A20: 1 | B20: UNIQUE | C20: SYS_C008141 | D20: INSPTYPE, BIN | G20: 중복 금지
A22: 인덱스
A23: No | B23: 유일 | C23: 인덱스 이름 | D23: 컬럼 | G23: 용도
A24: 1 | B24: UNIQUE | C24: SYS_C008141 | D24: INSPTYPE, BIN | G24: 중복 금지

Sheet TQP_WAFER
A1: 테이블 명세서
I2: <- 테이블 목록
A3: 테이블명 | C3: TQP_WAFER | D3: 영역 | E3: YMS | G3: 스키마 | H3: DMSMGR
A4: 테이블 설명 | C4: YMS Test Wafer 정보 (Wafer 1회 측정 = 1건, 재측정은 PROBE_CNT 로 구분)
A5: 기본 키 (PK) | C5: PK_TQP_WAFER (FACTORY, WAFER_SEQ) | D5: 컬럼 수 | E5: =SUM(J9:J89) -> 81 | G5: Query XML | H5: TQP_WAFER.xml
A6: 사용 기능 | C6: CP / PCM / AVI DataService 적재, E-Test 업로드 YMS 적재, Scope 수동 업로드, TEST Data Maint, Param Analysis / Test Report 조회, RPNet TSK Map 생성
A8: No | B8: 컬럼명 | C8: 컬럼 설명 | D8: 데이터 타입 | E8: NULL | F8: PK | G8: 참조 (논리) | H8: 기본값 | I8: 근거
A9: 1 | B9: FACTORY | C9: Factory (예 SCK) | D9: VARCHAR2(14) | E9: N | F9: 1 | G9: TQP_LOT, TQP_PARASPEC | I9: 소스 | J9: 1
A10: 2 | B10: WAFER_SEQ | C10: Wafer 번호 (WAFER_SEQ 시퀀스, DMS TQD_WAFER 와 같은 시퀀스) | D10: NUMBER(15) | E10: N | F10: 2 | I10: 소스 | J10: 1
A11: 3 | B11: LOT_SEQ | C11: Lot 번호 (TQP_LOT.LOT_SEQ) | D11: NUMBER(15) | E11: N | G11: TQP_LOT | I11: 소스 | J11: 1
A12: 4 | B12: WAFER_ID | C12: Wafer ID (Lot ID-Slot 2자리, 예 188648-17) | D12: VARCHAR2(30) | E12: N | I12: 소스 | J12: 1
A13: 5 | B13: PROBE_CNT | C13: 재측정 순번 (0 = 최신, 새 측정이 들어오면 이전 행 +1) | D13: NUMBER | E13: N | I13: 소스 | J13: 1
A14: 6 | B14: START_TIME | C14: Wafer 시험 시작 일시 (STDF WIR.START_T) | D14: DATE | E14: N | I14: 소스 | J14: 1
A15: 7 | B15: END_TIME | C15: Wafer 시험 종료 일시 (STDF WRR.FINISH_T) | D15: DATE | E15: Y | I15: 소스 | J15: 1
A16: 8 | B16: LOAD_TIME | C16: YMS 적재 일시 (MERGE 때 SYSDATE) | D16: DATE | E16: Y | I16: 소스 | J16: 1
A17: 9 | B17: TESTER | C17: Tester ID (CP: 파일 Tester 또는 설비 ID, PCM: 설비 ID) | D17: VARCHAR2(30) | E17: Y | I17: 소스 | J17: 1
A18: 10 | B18: PROBER | C18: Prober ID (CP 파일 값 / PCM ProbeID) | D18: VARCHAR2(50) | E18: Y | I18: 소스 | J18: 1
A19: 11 | B19: PROBE_CARD | C19: Probe Card ID (STDF SDR.CARD_ID) | D19: VARCHAR2(50) | E19: Y | I19: 소스 | J19: 1
A20: 12 | B20: HANDLER_ID | C20: Handler ID (이관 데이터만, STDF SDR.HAND_ID) | D20: VARCHAR2(30) | E20: Y | I20: 이름 추정 | J20: 1
A21: 13 | B21: OPERATOR | C21: 작업자 (STDF MIR.OPER_NAM, AVI 는 'Parser') | D21: VARCHAR2(30) | E21: Y | I21: 소스 | J21: 1
A22: 14 | B22: PROGRAM | C22: Test Program (TQP_PROGRAM.PROGRAM, STDF MIR.JOB_NAM) | D22: VARCHAR2(50) | E22: Y | G22: TQP_PARASPEC, TQP_DATA_TABLES | I22: 소스 | J22: 1
A23: 15 | B23: PROGRAM_REV | C23: Parameter 정의 Revision (TQP_PARASPEC.PROGRAM_REV, 현재 0) | D23: NUMBER | E23: Y | G23: TQP_PARASPEC | I23: 소스 | J23: 1
A24: 16 | B24: START_QTY | C24: 시작 수량 (CP / AVI: 측정 Die 수, PCM / E-Test: -1) | D24: NUMBER | E24: Y | I24: 소스 | J24: 1
A25: 17 | B25: PARENT | C25: 부모 Wafer (이관 컬럼, 값 없음) | D25: VARCHAR2(30) | E25: Y | I25: 이름 추정 | J25: 1
A26: 18 | B26: FLAGS | C26: Wafer Flag (이관 데이터 0) | D26: NUMBER | E26: Y | I26: 이름 추정 | J26: 1
A27: 19 | B27: SCREEN_FLAG | C27: Screen 여부 (이관 컬럼, 값 없음) | D27: CHAR(1) | E27: Y | I27: 이름 추정 | J27: 1
A28: 20 | B28: SCRAP_FLAG | C28: Scrap 여부 (이관 컬럼, 값 없음) | D28: CHAR(1) | E28: Y | I28: 이름 추정 | J28: 1
A29: 21 | B29: DGRADE_FLAG | C29: Downgrade 여부 (이관 컬럼, 값 없음) | D29: CHAR(1) | E29: Y | I29: 이름 추정 | J29: 1
A30: 22 | B30: VENDOR_ID | C30: Vendor ID (AVI / Scope 는 'Unknown', 그 외 비움) | D30: VARCHAR2(30) | E30: Y | I30: 이름 추정 | J30: 1
A31: 23 | B31: LOADBD | C31: Load Board ID (STDF SDR.LOAD_ID) | D31: VARCHAR2(30) | E31: Y | I31: 이름 추정 | J31: 1
A32: 24 | B32: HOSTNAME | C32: Tester Host 이름 (STDF MIR.NODE_NAM, 이관 값 EDAS) | D32: VARCHAR2(30) | E32: Y | I32: 이름 추정 | J32: 1
A33: 25 | B33: TESTHEAD | C33: Test Head 번호 (STDF WIR.HEAD_NUM, 이관 값 1) | D33: VARCHAR2(30) | E33: Y | I33: 이름 추정 | J33: 1
A34: 26 | B34: SW_REV | C34: Tester S/W 버전 (STDF MIR.EXEC_VER) | D34: VARCHAR2(30) | E34: Y | I34: 이름 추정 | J34: 1
A35: 27 | B35: USP_REV | C35: 사용자 Program Revision (STDF MIR.JOB_REV 대응 추정) | D35: VARCHAR2(30) | E35: Y | I35: 이름 추정 | J35: 1
... A88: 80 | B88: OLD_WAFER_SEQ | C88: 이전 YMS WAFER_SEQ (이관 원본 WAFER.WAFER_SEQ) | D88: NUMBER(10) | E88: Y | I88: 소스 | J88: 1
A89: 81 | B89: MAP_CFG_SEQ | C89: 적용한 Map 보정 설정 번호 (TQP_MAPCFG.MAP_CFG_SEQ) | D89: NUMBER | E89: Y | G89: TQP_MAPCFG | I89: 소스 | J89: 1
A91: 제약 조건
A92: No | B92: 구분 | C92: 제약 이름 | D92: 컬럼 | G92: 내용
A93: 1 | B93: PK | C93: PK_TQP_WAFER | D93: FACTORY, WAFER_SEQ | G93: 기본 키
A94: 2 | B94: UNIQUE | C94: SYS_C008135 | D94: LOT_SEQ, WAFER_ID, START_TIME, PROBE_CNT | G94: 중복 금지
...

Sheet TQP_WAFER_SUM
A1: 테이블 명세서
I2: <- 테이블 목록
A3: 테이블명 | C3: TQP_WAFER_SUM | D3: 영역 | E3: YMS | G3: 스키마 | H3: DMSMGR
A4: 테이블 설명 | C4: Wafer 별 Test 요약 (수율 / Bin 별 Die 수, 분석 화면 Wafer 목록)
A5: 기본 키 (PK) | C5: PK_TQP_WAFER_SUM (FACILITY, WAFER_SEQ) | D5: 컬럼 수 | E5: =SUM(J9:J34) -> 176 | G5: Query XML | H5: TQP_WAFER_SUM.xml
A6: 사용 기능 | C6: 적재 후 요약 생성 (TestCommon.SummaryData), TEST Analysis Wafer 선택 목록, Yield / Wafer Cum / Wafer Bin Report, Map Control Update, DMS Defect-Test 매칭
A8: No | B8: 컬럼명 | C8: 컬럼 설명 | D8: 데이터 타입 | E8: NULL | F8: PK | G8: 참조 (논리) | H8: 기본값 | I8: 근거
A9: 1 | B9: CUSTOMER | C9: 고객 (생성 때 'DB', CP 적재는 MES Lot 고객으로 갱신) | D9: VARCHAR2(30) | E9: N | I9: 소스 | J9: 1
A10: 2 | B10: FACILITY | C10: Factory (TQP_WAFER.FACTORY, 예 SCK) | D10: VARCHAR2(30) | E10: N | F10: 1 | G10: TQP_LOT | I10: 소스 | J10: 1
A11: 3 | B11: PRODUCT | C11: Device (TQP_LOT.DEVICE) | D11: VARCHAR2(30) | E11: N | I11: 소스 | J11: 1
A12: 4 | B12: DEVICE_ALIAS | C12: Device Alias = Map ID (TQP_LOT 값, CP 는 MES MASK_ID 로 갱신) | D12: VARCHAR2(30) | E12: N | G12: TQP_MAPDEF | I12: 소스 | J12: 1
A13: 5 | B13: TESTAREA | C13: TestArea (TQP_LOT.TEST_AREA) | D13: VARCHAR2(30) | E13: N | I13: 소스 | J13: 1
A14: 6 | B14: PROGRAM | C14: Test Program (TQP_LOT.PROGRAM) | D14: VARCHAR2(50) | E14: N | G14: TQP_BINDESC | I14: 소스 | J14: 1
A15: 7 | B15: MOTHER_LOT_ID | C15: 모 Lot ID (LOT_ID 와 같은 값 저장) | D15: VARCHAR2(30) | E15: Y | I15: 소스 | J15: 1
A16: 8 | B16: LOT_ID | C16: Lot ID | D16: VARCHAR2(30) | E16: N | I16: 소스 | J16: 1
A17: 9 | B17: LOT_SEQ | C17: Lot 번호 (TQP_LOT.LOT_SEQ) | D17: NUMBER(15) | E17: N | G17: TQP_WAFER, TQP_LOT | I17: 소스 | J17: 1
A18: 10 | B18: WAFER_ID | C18: Wafer ID | D18: VARCHAR2(30) | E18: N | I18: 소스 | J18: 1
A19: 11 | B19: WAFER_SEQ | C19: Wafer 번호 (TQP_WAFER.WAFER_SEQ) | D19: NUMBER(15) | E19: N | F19: 2 | G19: TQP_WAFER | I19: 소스 | J19: 1
A20: 12 | B20: TESTER | C20: Tester ID (TQP_WAFER 값) | D20: VARCHAR2(30) | E20: Y | I20: 소스 | J20: 1
A21: 13 | B21: PROBE_CARD | C21: Probe Card ID (TQP_WAFER 값) | D21: VARCHAR2(50) | E21: Y | I21: 소스 | J21: 1
A22: 14 | B22: OPERATOR | C22: 작업자 (TQP_WAFER 값) | D22: VARCHAR2(30) | E22: Y | I22: 소스 | J22: 1
A23: 15 | B23: PROBE_CNT | C23: 재측정 순번 (0 = 최신, 목록은 0 만 조회) | D23: NUMBER(10) | E23: Y | I23: 소스 | J23: 1
