Workbook

Sheet 개요
B2: SCK 분석시스템 구축 POC - DMS 테이블 명세서
B4: 대상 시스템 | C4: DACrux DMS / YMS (SCK 분석시스템 구축 POC)
B5: 영역 | C5: DMS - Defect 관리 (검사 Step / Wafer / Setup / Defect / Image / 검사 요약)
B6: 기준 DB | C6: 로컬 개발 DB (Oracle 19c, 스키마 DMSMGR, 문자셋 AL32UTF8)
B7: 조회 일자 | C7: 2026-10-15
B8: 작성 근거 | C8: DB 메타데이터 (컬럼 / 주석 / 제약 / 인덱스 / 시퀀스) + Query XML (DMS/08_DBQuery/ORACLE) / C# 소스 + 같은 제품을 쓴 다른 프로젝트의 테이블 정의서 + 이 프로젝트 설계 문서
B9: 대상 범위 | C9: 테이블 16개 (이름 접두어 TQD_). POC 신규 테이블(TQP_GDS_*)은 POC 테이블 명세서에 따로 있다.
B10: 제외 | C10: 소스(Query XML / C#)에서 쓰지 않는 테이블: TQD_DEFECT_DIE_SUM
B12: 집계 | C12: 값
B13: 테이블 수 | C13: =COUNTA('테이블 목록'!B4:B19) -> 16
B14: 컬럼 수 | C14: ='테이블 목록'!E20 -> 515
B15: 근거: 소스 | C15: ='테이블 목록'!I20 -> 233
B16: 근거: 이름 추정 | C16: ='테이블 목록'!J20 -> 27
B18: 시트 | C18: 내용
B19: 테이블 목록 | C19: 테이블 요약 (테이블명을 누르면 해당 시트로 이동, 근거별 행 수)
B20: 테이블별 시트 | C20: 컬럼 / 제약 조건 / 인덱스
B21: 관계(논리) | C21: Query XML / 소스의 조인으로 확인한 테이블 관계 (DB FK 없음)
B22: 시퀀스 | C22: 이 영역 테이블이 쓰는 시퀀스
B24: 표기 기준 | C24: 설명
B25: 데이터 타입 | C25: VARCHAR2(n CHAR) = 글자 수 기준, VARCHAR2(n) = byte 기준
B26: NULL / PK | C26: NULL: N = NOT NULL (필수), Y = NULL 허용. PK: 기본 키 안 순서 (노란 행)
B27: 반복 컬럼 | C27: 같은 접두어 + 번호가 이어지는 컬럼은 한 줄로 묶었다 (회색 행, 예: BIN001 ~ BIN151). No 는 첫 ~ 끝 컬럼 순번
B28: 참조 (논리) | C28: 조인으로 확인한 부모 테이블. DB FK 는 없다
B29: 근거 | C29: 소스 = Query XML / C# 소스에서 쓰임을 확인 / 이름 추정 = 근거 자료 없이 컬럼 이름과 값으로 추정 - 확인 필요
B31: 참고 | C31: 내용
... B38: 참고 7 | C38: TQD_SETUP.SETUP_ID 는 로컬 DB 에서 VARCHAR2(128) 로 늘렸다 (2026-10-07, 고객 KLARF SetupID 46자). 고객 DB 에도 같은 변경이 필요하다.

Sheet 테이블 목록
A1: DMS 테이블 목록
A3: No | B3: 테이블명 | C3: 테이블 설명 | D3: 기본 키 (PK) | E3: 컬럼 수 | F3: 사용 기능 | G3: 관련 테이블 (논리) | H3: Query XML | I3: 근거: 소스 | J3: 근거: 이름 추정
A4: 1 | B4: TQD_COLORBYSIZE | C4: 사용자별 Defect Size(DSIZE) 구간 표시 색 설정 | D4: USER_ID, SIZE_SEQ | E4: =TQD_COLORBYSIZE!E5 -> 5 | F4: Defect Coloring 화면 / Defect Map Viewer / Chart Analysis Size 구간 | H4: TQD_COLORBYSIZE.xml | I4: =COUNTIF(TQD_COLORBYSIZE!I9:I13,"소스") -> 5 | J4: =COUNTIF(TQD_COLORBYSIZE!I9:I13,"이름 추정") -> 0
A5: 2 | B5: TQD_DATA_MAINT_HIS | C5: Defect Data Maint 변경 / 삭제 이력 (처리 1건 = 1행) | D5: TRAN_KEY | E5: =TQD_DATA_MAINT_HIS!E5 -> 13 | F5: Defect Data Maint 화면 (이력 저장 / 조회) | H5: TQD_DATA_MAINT_HIS.xml | I5: =COUNTIF(TQD_DATA_MAINT_HIS!I9:I21,"소스") -> 13 | J5: =COUNTIF(TQD_DATA_MAINT_HIS!I9:I21,"이름 추정") -> 0
A6: 3 | B6: TQD_DEFECT | C6: Defect 1건 (KLARF DefectList 1행) 의 좌표 / 크기 / 분류 | D6: STEP_SEQ, DEFECTID | E6: =TQD_DEFECT!E5 -> 32 | F6: KLARF 자동 적재 / Review 적재 / KLARF 업로드 / Defect Map Viewer / Gallery / Chart / GDS Correlation | G6: TQD_DEFECT_DIE, TQD_DEFECT_TYPE, TQD_IMAGES, TQD_INSP_INFO, TQD_STEP | H6: TQD_DEFECT.xml | I6: =COUNTIF(TQD_DEFECT!I9:I40,"소스") -> 21 | J6: =COUNTIF(TQD_DEFECT!I9:I40,"이름 추정") -> 11
A7: 4 | B7: TQD_DEFECT_DIE | C7: YMS Test Die 와 같은 위치 Defect 의 매칭 결과 (Die x Defect) | D7: TEST_WAFER_SEQ, TEST_DIE_NUM, DM_STEP_SEQ, DM_DEFECTID | E7: =TQD_DEFECT_DIE!E5 -> 8 | F7: YMS CP / PCM DataService 매칭 적재 / Killing Rate 리포트 | G7: TQD_DEFECT, TQD_STEP, TQP_WAFER | H7: TQD_DEFECT_DIE.xml | I7: =COUNTIF(TQD_DEFECT_DIE!I9:I16,"소스") -> 8 | J7: =COUNTIF(TQD_DEFECT_DIE!I9:I16,"이름 추정") -> 0
A8: 5 | B8: TQD_DEFECT_GROUP | C8: Defect Class 그룹 기준정보 | D8: GROUP_ID | E8: =TQD_DEFECT_GROUP!E5 -> 7 | F8: Defect Group Define 화면 / Defect Type Define 조회 | G8: TQD_DEFECT_TYPE | H8: TQD_DEFECT_GROUP.xml | I8: =COUNTIF(TQD_DEFECT_GROUP!I9:I15,"소스") -> 7 | J8: =COUNTIF(TQD_DEFECT_GROUP!I9:I15,"이름 추정") -> 0
A9: 6 | B9: TQD_DEFECT_TYPE | C9: Defect Class 기준정보 (CLASSNUMBER 별 이름 / 색 / 그룹) | D9: CLASSNUMBER | E9: =TQD_DEFECT_TYPE!E5 -> 10 | F9: Defect Type Define 화면 / Map Viewer Class 이름과 색 / Killing Rate / 설비 Defect Trend | G9: TQD_DEFECT, TQD_DEFECT_GROUP | H9: TQD_DEFECT_TYPE.xml | I9: =COUNTIF(TQD_DEFECT_TYPE!I9:I18,"소스") -> 10 | J9: =COUNTIF(TQD_DEFECT_TYPE!I9:I18,"이름 추정") -> 0
A10: 7 | B10: TQD_IMAGES | C10: Defect 이미지 파일 1건 (원본 / 썸네일 경로) | D10: STEP_SEQ, DEFECTID, IMAGE_ID | E10: =TQD_IMAGES!E5 -> 12 | F10: KLARF / Review 적재 / KLARF 업로드 / Map Viewer 이미지 / Image Gallery / Data Maint 이미지 삭제 | G10: TQD_DEFECT | H10: TQD_IMAGES.xml | I10: =COUNTIF(TQD_IMAGES!I9:I20,"소스") -> 12 | J10: =COUNTIF(TQD_IMAGES!I9:I20,"이름 추정") -> 0
A11: 8 | B11: TQD_INSP_INFO | C11: 검사 결과 요약 1건 (Step x Test), Lot / Wafer / Step 값을 펼친 형태 | D11: STEP_SEQ, TEST | E11: =TQD_INSP_INFO!E5 -> 45 | F11: 왼쪽 Wafer 조회 / Map Viewer / Gallery / Chart / DMS 리포트 / Review 매칭 / KLARF 업로드 / GDS Correlation | G11: TQD_DEFECT, TQD_SETUP, TQD_STEP, TQP_MAPDEF, TQP_WAFER_SUM | H11: TQD_INSP_INFO.xml | I11: =COUNTIF(TQD_INSP_INFO!I9:I53,"소스") -> 37 | J11: =COUNTIF(TQD_INSP_INFO!I9:I53,"이름 추정") -> 8
A12: 9 | B12: TQD_INSP_SUM | C12: Step 별 Defect 집계 (Random / Cluster / Size 구간 / New Defect) | D12: STEP_SEQ | E12: =TQD_INSP_SUM!E5 -> 59 | F12: KLARF 적재 (Step 12) / KLARF 업로드 / Data Maint / Data Sheet / 설비 Defect Trend | G12: TQD_STEP | H12: TQD_INSP_SUM.xml | I12: =COUNTIF(TQD_INSP_SUM!I9:I67,"소스") -> 53 | J12: =COUNTIF(TQD_INSP_SUM!I9:I67,"이름 추정") -> 6
A13: 10 | B13: TQD_LOT | C13: Lot 기준정보 (Product + Lot ID) | D13: LOT_SEQ | E13: =TQD_LOT!E5 -> 4 | F13: KLARF 적재 / KLARF 업로드 / Data Maint Lot 변경 / 기존 등록 확인 | G13: TQD_PRODUCT, TQD_WAFER | H13: TQD_LOT.xml | I13: =COUNTIF(TQD_LOT!I9:I12,"소스") -> 4 | J13: =COUNTIF(TQD_LOT!I9:I12,"이름 추정") -> 0
A14: 11 | B14: TQD_PRODUCT | C14: Product(Device) 기준정보, 처음 적재된 KLARF 의 Wafer / Die 값 | D14: PRODUCT | E14: =TQD_PRODUCT!E5 -> 14 | F14: KLARF 적재 / KLARF 업로드 (Device 최초 등록) / Data Maint Product 복사 | G14: TQD_LOT | H14: TQD_PRODUCT.xml | I14: =COUNTIF(TQD_PRODUCT!I9:I22,"소스") -> 14 | J14: =COUNTIF(TQD_PRODUCT!I9:I22,"이름 추정") -> 0
A15: 12 | B15: TQD_REVIEW_SUM | C15: Step 별 Defect Class(CLASSNUMBER) 개수 집계 | D15: STEP_SEQ | E15: =TQD_REVIEW_SUM!E5 -> 257 | F15: Review DataService / Data Maint (생성만, 조회 쿼리 없음) | G15: TQD_STEP | H15: TQD_REVIEW_SUM.xml | I15: =COUNTIF(TQD_REVIEW_SUM!I9:I10,"소스") -> 2 | J15: =COUNTIF(TQD_REVIEW_SUM!I9:I10,"이름 추정") -> 0
A16: 13 | B16: TQD_SETUP | C16: 검사 Setup(Recipe) 별 Wafer / Die 좌표 기준 (KLARF SetupID 단위) | D16: SETUP_SEQ | E16: =TQD_SETUP!E5 -> 15 | F16: KLARF 적재 / KLARF 업로드 / Map 표시 (Map Viewer, GDS Correlation) / Origin Die Index 조회 | G16: TQD_INSP_INFO, TQD_SETUP_MAP, TQD_STEP | H16: TQD_SETUP.xml | I16: =COUNTIF(TQD_SETUP!I9:I23,"소스") -> 13 | J16: =COUNTIF(TQD_SETUP!I9:I23,"이름 추정") -> 2
A17: 14 | B17: TQD_SETUP_MAP | C17: Setup + Test 별 검사 Die 목록 (Die Index) | D17: SETUP_SEQ, TEST, INDEX_X, INDEX_Y | E17: =TQD_SETUP_MAP!E5 -> 4 | F17: KLARF 적재 / KLARF 업로드 / Map 검사 Die 표시 / Defect Density / GDS Correlation | G17: TQD_SETUP | H17: TQD_SETUP_MAP.xml | I17: =COUNTIF(TQD_SETUP_MAP!I9:I12,"소스") -> 4 | J17: =COUNTIF(TQD_SETUP_MAP!I9:I12,"이름 추정") -> 0
A18: 15 | B18: TQD_STEP | C18: 검사 Step 1건 (KLARF 파일 1개 x Wafer 1장 의 헤더) | D18: STEP_SEQ | E18: =TQD_STEP!E5 -> 25 | F18: KLARF 적재 / Review 적재 / KLARF 업로드 / Data Maint / Inspection Detail 리포트 | G18: TQC_EQUIP, TQD_DEFECT, TQD_DEFECT_DIE, TQD_INSP_INFO, TQD_INSP_SUM, TQD_REVIEW_SUM, TQD_SETUP, TQD_WAFER | H18: TQD_STEP.xml | I18: =COUNTIF(TQD_STEP!I9:I33,"소스") -> 25 | J18: =COUNTIF(TQD_STEP!I9:I33,"이름 추정") -> 0
A19: 16 | B19: TQD_WAFER | C19: Wafer 기준정보 (Lot + Wafer ID / Slot) | D19: WAFER_SEQ | E19: =TQD_WAFER!E5 -> 5 | F19: KLARF 적재 / KLARF 업로드 / Data Maint (Lot 변경 시 WAFER_ID 갱신) | G19: TQD_LOT, TQD_STEP | H19: TQD_WAFER.xml | I19: =COUNTIF(TQD_WAFER!I9:I13,"소스") -> 5 | J19: =COUNTIF(TQD_WAFER!I9:I13,"이름 추정") -> 0
D20: 합계 | E20: =SUM(E4:E19) -> 515 | I20: =SUM(I4:I19) -> 233 | J20: =SUM(J4:J19) -> 27

Sheet TQD_COLORBYSIZE
A1: 테이블 명세서
I2: <- 테이블 목록
A3: 테이블명 | C3: TQD_COLORBYSIZE | D3: 영역 | E3: DMS | G3: 스키마 | H3: DMSMGR
A4: 테이블 설명 | C4: 사용자별 Defect Size(DSIZE) 구간 표시 색 설정
A5: 기본 키 (PK) | C5: PK_TQD_COLORBYSIZE (USER_ID, SIZE_SEQ) | D5: 컬럼 수 | E5: =SUM(J9:J13) -> 5 | G5: Query XML | H5: TQD_COLORBYSIZE.xml
A6: 사용 기능 | C6: Defect Coloring 화면 / Defect Map Viewer / Chart Analysis Size 구간
A8: No | B8: 컬럼명 | C8: 컬럼 설명 | D8: 데이터 타입 | E8: NULL | F8: PK | G8: 참조 (논리) | H8: 기본값 | I8: 근거
A9: 1 | B9: USER_ID | C9: 사용자 ID ('ADMIN' 행 = 공통 기본, 조회 시 본인 + ADMIN) | D9: VARCHAR2(40) | E9: N | F9: 1 | I9: 소스 | J9: 1
A10: 2 | B10: SIZE_SEQ | C10: Size 구간 순번 (사용자별) | D10: NUMBER(10) | E10: N | F10: 2 | I10: 소스 | J10: 1
A11: 3 | B11: SIZE_FROM | C11: 구간 시작 Defect Size (DSIZE, um, 이상) | D11: NUMBER(13,3) | E11: N | I11: 소스 | J11: 1
A12: 4 | B12: SIZE_TO | C12: 구간 끝 Defect Size (DSIZE, um, 이하) | D12: NUMBER(13,3) | E12: N | I12: 소스 | J12: 1
A13: 5 | B13: COLOR | C13: 구간 표시 색 (HTML 색, 예 #FF0080) | D13: VARCHAR2(9) | E13: N | I13: 소스 | J13: 1
A15: 제약 조건
A16: No | B16: 구분 | C16: 제약 이름 | D16: 컬럼 | G16: 내용
A17: 1 | B17: PK | C17: PK_TQD_COLORBYSIZE | D17: USER_ID, SIZE_SEQ | G17: 기본 키
A19: 인덱스
A20: No | B20: 유일 | C20: 인덱스 이름 | D20: 컬럼 | G20: 용도
A21: 1 | B21: UNIQUE | C21: PK_TQD_COLORBYSIZE | D21: USER_ID, SIZE_SEQ | G21: 기본 키

Sheet TQD_DATA_MAINT_HIS
A1: 테이블 명세서
I2: <- 테이블 목록
A3: 테이블명 | C3: TQD_DATA_MAINT_HIS | D3: 영역 | E3: DMS | G3: 스키마 | H3: DMSMGR
A4: 테이블 설명 | C4: Defect Data Maint 변경 / 삭제 이력 (처리 1건 = 1행)
A5: 기본 키 (PK) | C5: TQD_DATA_MAINT_HIS_PK (TRAN_KEY) | D5: 컬럼 수 | E5: =SUM(J9:J21) -> 13 | G5: Query XML | H5: TQD_DATA_MAINT_HIS.xml
A6: 사용 기능 | C6: Defect Data Maint 화면 (이력 저장 / 조회)
A8: No | B8: 컬럼명 | C8: 컬럼 설명 | D8: 데이터 타입 | E8: NULL | F8: PK | G8: 참조 (논리) | H8: 기본값 | I8: 근거
A9: 1 | B9: TRAN_KEY | C9: 처리 키 = 처리 시각 (SYSTIMESTAMP 'YYYYMMDDHH24MISSFF') | D9: VARCHAR2(20) | E9: N | F9: 1 | I9: 소스 | J9: 1
A10: 2 | B10: LOT_ID | C10: 대상 Lot ID | D10: VARCHAR2(40) | E10: Y | I10: 소스 | J10: 1
A11: 3 | B11: PRODUCT | C11: 대상 Product | D11: VARCHAR2(50) | E11: Y | I11: 소스 | J11: 1
A12: 4 | B12: STEP_ID | C12: 대상 Step ID | D12: VARCHAR2(50) | E12: Y | I12: 소스 | J12: 1
A13: 5 | B13: SLOT_ID | C13: 대상 Slot 번호 (Lot 변경 이력은 빈 값) | D13: NUMBER | E13: Y | I13: 소스 | J13: 1
A14: 6 | B14: WAFER_ID | C14: 대상 Wafer ID (Lot 변경 이력은 빈 값) | D14: VARCHAR2(50) | E14: Y | I14: 소스 | J14: 1
A15: 7 | B15: TRAN_USER | C15: 처리 사용자 ID | D15: VARCHAR2(30) | E15: Y | I15: 소스 | J15: 1
A16: 8 | B16: TRAN_USER_IP | C16: 처리 PC IP 주소 | D16: VARCHAR2(30) | E16: Y | I16: 소스 | J16: 1
A17: 9 | B17: PREV_VALUE | C17: 변경 전 값 (예 'Lot, Slot, WaferID, StepID, Product') | D17: VARCHAR2(200) | E17: Y | I17: 소스 | J17: 1
A18: 10 | B18: CURR_VALUE | C18: 변경 후 값 또는 작업 이름 (Delete Wafer Base / Delete Lot Base 등) | D18: VARCHAR2(200) | E18: Y | I18: 소스 | J18: 1
A19: 11 | B19: PREV_STEP_SEQ | C19: 변경 전 STEP_SEQ (여러 개면 쉼표 구분) | D19: VARCHAR2(20) | E19: Y | I19: 소스 | J19: 1
A20: 12 | B20: CURR_STEP_SEQ | C20: 변경 후 STEP_SEQ (Wafer / Step 변경 시 새 번호) | D20: VARCHAR2(20) | E20: Y | I20: 소스 | J20: 1
A21: 13 | B21: USER_COMMENT | C21: 사용자 입력 사유 (삭제는 'Data Delete :' + 사유) | D21: VARCHAR2(300) | E21: Y | I21: 소스 | J21: 1
A23: 제약 조건
A24: No | B24: 구분 | C24: 제약 이름 | D24: 컬럼 | G24: 내용
A25: 1 | B25: PK | C25: TQD_DATA_MAINT_HIS_PK | D25: TRAN_KEY | G25: 기본 키
A27: 인덱스
A28: No | B28: 유일 | C28: 인덱스 이름 | D28: 컬럼 | G28: 용도
A29: 1 | B29: - | C29: IDX_TQD_DATA_MAINT_HIS_01 | D29: LOT_ID
A30: 2 | B30: UNIQUE | C30: TQD_DATA_MAINT_HIS_PK | D30: TRAN_KEY | G30: 기본 키

Sheet TQD_DEFECT
A1: 테이블 명세서
I2: <- 테이블 목록
A3: 테이블명 | C3: TQD_DEFECT | D3: 영역 | E3: DMS | G3: 스키마 | H3: DMSMGR
A4: 테이블 설명 | C4: Defect 1건 (KLARF DefectList 1행) 의 좌표 / 크기 / 분류
A5: 기본 키 (PK) | C5: PK_TQD_DEFECT (STEP_SEQ, DEFECTID) | D5: 컬럼 수 | E5: =SUM(J9:J40) -> 32 | G5: Query XML | H5: TQD_DEFECT.xml
A6: 사용 기능 | C6: KLARF 자동 적재 / Review 적재 / KLARF 업로드 / Defect Map Viewer / Gallery / Chart / GDS Correlation
A8: No | B8: 컬럼명 | C8: 컬럼 설명 | D8: 데이터 타입 | E8: NULL | F8: PK | G8: 참조 (논리) | H8: 기본값 | I8: 근거
A9: 1 | B9: STEP_SEQ | C9: 검사 Step 번호 (TQD_STEP.STEP_SEQ) | D9: NUMBER | E9: N | F9: 1 | G9: TQD_STEP, TQD_INSP_INFO | I9: 소스 | J9: 1
A10: 2 | B10: DEFECTID | C10: Defect ID (KLARF DEFECTID, Step 안에서 고유) | D10: NUMBER(10) | E10: N | F10: 2 | I10: 소스 | J10: 1
A11: 3 | B11: WAFER_SEQ | C11: Wafer 번호 (TQD_WAFER.WAFER_SEQ) | D11: NUMBER | E11: Y | G11: TQD_INSP_INFO | I11: 소스 | J11: 1
A12: 4 | B12: X | C12: Wafer 중심 기준 X 좌표 (um, XINDEX*DiePitch+XREL-SampleCenter) | D12: NUMBER(20,10) | E12: N | I12: 소스 | J12: 1
A13: 5 | B13: Y | C13: Wafer 중심 기준 Y 좌표 (um, YINDEX*DiePitch+YREL-SampleCenter) | D13: NUMBER(20,10) | E13: N | I13: 소스 | J13: 1
A14: 6 | B14: XREL | C14: Die 안 X 좌표 (um, KLARF XREL, Die 좌하단 기준) | D14: NUMBER(20,10) | E14: N | I14: 소스 | J14: 1
A15: 7 | B15: YREL | C15: Die 안 Y 좌표 (um, KLARF YREL, Die 좌하단 기준) | D15: NUMBER(20,10) | E15: N | I15: 소스 | J15: 1
A16: 8 | B16: XINDEX | C16: Defect Die X Index (좌하단 기준 = KLARF Index + Origin Die Index) | D16: NUMBER(10) | E16: N | I16: 소스 | J16: 1
A17: 9 | B17: YINDEX | C17: Defect Die Y Index (좌하단 기준 = KLARF Index + Origin Die Index) | D17: NUMBER(10) | E17: N | I17: 소스 | J17: 1
A18: 10 | B18: XSIZE | C18: Defect X 크기 (um, KLARF XSIZE) | D18: NUMBER(20,10) | E18: N | I18: 소스 | J18: 1
A19: 11 | B19: YSIZE | C19: Defect Y 크기 (um, KLARF YSIZE) | D19: NUMBER(20,10) | E19: N | I19: 소스 | J19: 1
A20: 12 | B20: DEFECTAREA | C20: Defect 면적 (um², KLARF DEFECTAREA) | D20: NUMBER(28,10) | E20: N | I20: 소스 | J20: 1
A21: 13 | B21: DSIZE | C21: Defect 크기 (um, KLARF DSIZE) | D21: NUMBER(20,10) | E21: N | I21: 소스 | J21: 1
A22: 14 | B22: CLASSNUMBER | C22: Defect Class 번호 (KLARF CLASSNUMBER, 0 = 미분류) | D22: NUMBER(10) | E22: N | G22: TQD_DEFECT_TYPE | I22: 소스 | J22: 1
A23: 15 | B23: TEST | C23: 검사 Test 번호 (KLARF TEST) | D23: NUMBER(10) | E23: N | G23: TQD_INSP_INFO | I23: 소스 | J23: 1
A24: 16 | B24: CLUSTERNUMBER | C24: Cluster 번호 (0 = Random, 설비 CMF03='Y' 면 적재 시 재계산) | D24: NUMBER(10) | E24: N | I24: 소스 | J24: 1
A25: 17 | B25: ROUGHBINNUMBER | C25: Rough Bin 분류 코드 (KLARF ROUGHBINNUMBER) | D25: NUMBER(10) | E25: N | I25: 소스 | J25: 1
A26: 18 | B26: FINEBINNUMBER | C26: Fine Bin 분류 코드 (KLARF FINEBINNUMBER) | D26: NUMBER(10) | E26: N | I26: 소스 | J26: 1
A27: 19 | B27: REVIEWSAMPLE | C27: Review 대상 표시 (KLARF REVIEWSAMPLE, Review 적재 시 갱신) | D27: NUMBER(10) | E27: N | I27: 소스 | J27: 1
A28: 20 | B28: IMAGECOUNT | C28: Defect 이미지 수 (적재 후 TQD_IMAGES 건수로 갱신) | D28: NUMBER(10) | E28: N | I28: 소스 | J28: 1
A29: 21 | B29: ADDER | C29: New Defect 여부 (1 = 같은 Wafer 이전 Step 에 없던 위치, 허용오차 비교) | D29: NUMBER(10) | E29: Y | I29: 소스 | J29: 1
A30: 22 | B30: FIRST_STEP | C30: 처음 발견된 Step (KLARF 같은 이름 항목만 저장, 로컬 값 없음) | D30: VARCHAR2(40) | E30: Y | I30: 이름 추정 | J30: 1
A31: 23 | B31: RETICLE_REPEAT_ID | C31: Reticle 반복 Defect ID (적재 값 0) | D31: NUMBER(10) | E31: N | H31: 0 | I31: 이름 추정 | J31: 1
A32: 24 | B32: DIE_REPEAT_ID | C32: Die 반복 Defect ID (적재 값 0) | D32: NUMBER(10) | E32: N | H32: 0 | I32: 이름 추정 | J32: 1
A33: 25 | B33: MAN_OPT_CLASS | C33: Optical 수동 분류 Class (적재 값 0) | D33: NUMBER(10) | E33: N | H33: 0 | I33: 이름 추정 | J33: 1
A34: 26 | B34: AUTO_OPT_CLASS | C34: Optical 자동 분류 Class (적재 값 0) | D34: NUMBER(10) | E34: N | H34: 0 | I34: 이름 추정 | J34: 1
A35: 27 | B35: MAN_SEM_CLASS | C35: SEM 수동 분류 Class (적재 값 0) | D35: NUMBER(10) | E35: N | H35: 0 | I35: 이름 추정 | J35: 1
A36: 28 | B36: AUTO_SEM_CLASS | C36: SEM 자동 분류 Class (적재 값 0) | D36: NUMBER(10) | E36: N | H36: 0 | I36: 이름 추정 | J36: 1
A37: 29 | B37: OLD_XINDEX | C37: 변경 전 XINDEX (사용 소스 없음, 로컬 값 없음) | D37: NUMBER(10) | E37: Y | I37: 이름 추정 | J37: 1
A38: 30 | B38: OLD_YINDEX | C38: 변경 전 YINDEX (사용 소스 없음, 로컬 값 없음) | D38: NUMBER(10) | E38: Y | I38: 이름 추정 | J38: 1
A39: 31 | B39: TEST_WAFER_SEQ | C39: 연결 YMS Test Wafer 번호 (사용 소스 없음, 로컬 값 없음) | D39: NUMBER | E39: Y | I39: 이름 추정 | J39: 1
A40: 32 | B40: DIE_NUM | C40: 연결 YMS Die 번호 (사용 소스 없음, 로컬 값 없음) | D40: NUMBER | E40: Y | I40: 이름 추정 | J40: 1
A42: 제약 조건
...

Sheet TQD_DEFECT_DIE
A1: 테이블 명세서
I2: <- 테이블 목록
A3: 테이블명 | C3: TQD_DEFECT_DIE | D3: 영역 | E3: DMS | G3: 스키마 | H3: DMSMGR
A4: 테이블 설명 | C4: YMS Test Die 와 같은 위치 Defect 의 매칭 결과 (Die x Defect)
A5: 기본 키 (PK) | C5: PK_TQD_DEFECT_DIE (TEST_WAFER_SEQ, TEST_DIE_NUM, DM_STEP_SEQ, DM_DEFECTID) | D5: 컬럼 수 | E5: =SUM(J9:J16) -> 8 | G5: Query XML | H5: TQD_DEFECT_DIE.xml
A6: 사용 기능 | C6: YMS CP / PCM DataService 매칭 적재 / Killing Rate 리포트
A8: No | B8: 컬럼명 | C8: 컬럼 설명 | D8: 데이터 타입 | E8: NULL | F8: PK | G8: 참조 (논리) | H8: 기본값 | I8: 근거
A9: 1 | B9: TEST_WAFER_SEQ | C9: YMS Test Wafer 번호 (TQP_WAFER.WAFER_SEQ) | D9: NUMBER(20) | E9: N | F9: 1 | G9: TQP_WAFER | I9: 소스 | J9: 1
A10: 2 | B10: TEST_DIE_NUM | C10: YMS Die 번호 (Program Bin 테이블 DIE_NUM) | D10: NUMBER(10) | E10: N | F10: 2 | I10: 소스 | J10: 1
A11: 3 | B11: DM_STEP_SEQ | C11: DMS 검사 Step 번호 (TQD_INSP_INFO.STEP_SEQ, TEST 1) | D11: NUMBER(20) | E11: N | F11: 3 | G11: TQD_DEFECT, TQD_STEP | I11: 소스 | J11: 1
A12: 4 | B12: DM_DEFECTID | C12: Defect ID (TQD_DEFECT.DEFECTID) | D12: NUMBER(10) | E12: N | F12: 4 | G12: TQD_DEFECT | I12: 소스 | J12: 1
A13: 5 | B13: X | C13: YMS Die X 좌표 (Program Bin 테이블 X) | D13: NUMBER(10) | E13: Y | I13: 소스 | J13: 1
A14: 6 | B14: Y | C14: YMS Die Y 좌표 (Program Bin 테이블 Y) | D14: NUMBER(10) | E14: Y | I14: 소스 | J14: 1
A15: 7 | B15: BIN | C15: 해당 Die 의 Test Bin | D15: NUMBER(10) | E15: Y | I15: 소스 | J15: 1
A16: 8 | B16: CLASSNUMBER | C16: Defect Class 번호 (TQD_DEFECT.CLASSNUMBER) | D16: NUMBER(10) | E16: Y | I16: 소스 | J16: 1
A18: 제약 조건
A19: No | B19: 구분 | C19: 제약 이름 | D19: 컬럼 | G19: 내용
A20: 1 | B20: PK | C20: PK_TQD_DEFECT_DIE | D20: TEST_WAFER_SEQ, TEST_DIE_NUM, DM_STEP_SEQ, DM_DEFECTID | G20: 기본 키
A22: 인덱스
A23: No | B23: 유일 | C23: 인덱스 이름 | D23: 컬럼 | G23: 용도
A24: 1 | B24: - | C24: IDX_TQD_DEFECT_DIE_01 | D24: TEST_WAFER_SEQ
A25: 2 | B25: UNIQUE | C25: PK_TQD_DEFECT_DIE | D25: TEST_WAFER_SEQ, TEST_DIE_NUM, DM_STEP_SEQ, DM_DEFECTID | G25: 기본 키

Sheet TQD_DEFECT_GROUP
A1: 테이블 명세서
I2: <- 테이블 목록
A3: 테이블명 | C3: TQD_DEFECT_GROUP | D3: 영역 | E3: DMS | G3: 스키마 | H3: DMSMGR
A4: 테이블 설명 | C4: Defect Class 그룹 기준정보
A5: 기본 키 (PK) | C5: SYS_C008139 (GROUP_ID) | D5: 컬럼 수 | E5: =SUM(J9:J15) -> 7 | G5: Query XML | H5: TQD_DEFECT_GROUP.xml
A6: 사용 기능 | C6: Defect Group Define 화면 / Defect Type Define 조회
A8: No | B8: 컬럼명 | C8: 컬럼 설명 | D8: 데이터 타입 | E8: NULL | F8: PK | G8: 참조 (논리) | H8: 기본값 | I8: 근거
A9: 1 | B9: GROUP_ID | C9: Defect Group 번호 | D9: NUMBER(10) | E9: N | F9: 1 | I9: 소스 | J9: 1
A10: 2 | B10: GROUP_NAME | C10: Defect Group 이름 | D10: VARCHAR2(40) | E10: N | I10: 소스 | J10: 1
A11: 3 | B11: DELETE_FLAG | C11: 삭제 표시 (Y / N, 기본 N, Type 조회는 N 만 조인) | D11: CHAR(1) | E11: N | H11: 'N' | I11: 소스 | J11: 1
A12: 4 | B12: CREATE_TIME | C12: 생성 일시 | D12: DATE | E12: Y | I12: 소스 | J12: 1
A13: 5 | B13: CREATE_USER | C13: 생성 사용자 ID | D13: VARCHAR2(30) | E13: Y | I13: 소스 | J13: 1
A14: 6 | B14: UPDATE_TIME | C14: 수정 일시 | D14: DATE | E14: Y | I14: 소스 | J14: 1
A15: 7 | B15: UPDATE_USER | C15: 수정 사용자 ID | D15: VARCHAR2(30) | E15: Y | I15: 소스 | J15: 1
A17: 제약 조건
A18: No | B18: 구분 | C18: 제약 이름 | D18: 컬럼 | G18: 내용
A19: 1 | B19: PK | C19: SYS_C008139 | D19: GROUP_ID | G19: 기본 키
A21: 인덱스
A22: No | B22: 유일 | C22: 인덱스 이름 | D22: 컬럼 | G22: 용도
A23: 1 | B23: UNIQUE | C23: SYS_C008139 | D23: GROUP_ID | G23: 기본 키

Sheet TQD_DEFECT_TYPE
A1: 테이블 명세서
I2: <- 테이블 목록
A3: 테이블명 | C3: TQD_DEFECT_TYPE | D3: 영역 | E3: DMS | G3: 스키마 | H3: DMSMGR
A4: 테이블 설명 | C4: Defect Class 기준정보 (CLASSNUMBER 별 이름 / 색 / 그룹)
A5: 기본 키 (PK) | C5: SYS_C008149 (CLASSNUMBER) | D5: 컬럼 수 | E5: =SUM(J9:J18) -> 10 | G5: Query XML | H5: TQD_DEFECT_TYPE.xml
A6: 사용 기능 | C6: Defect Type Define 화면 / Map Viewer Class 이름과 색 / Killing Rate / 설비 Defect Trend
A8: No | B8: 컬럼명 | C8: 컬럼 설명 | D8: 데이터 타입 | E8: NULL | F8: PK | G8: 참조 (논리) | H8: 기본값 | I8: 근거
A9: 1 | B9: CLASSNUMBER | C9: Defect Class 번호 (KLARF CLASSNUMBER, 0 = Uncategorized) | D9: NUMBER(10) | E9: N | F9: 1 | I9: 소스 | J9: 1
A10: 2 | B10: NAME | C10: Class 이름 (화면 표시 '이름(번호)') | D10: VARCHAR2(40) | E10: N | I10: 소스 | J10: 1
A11: 3 | B11: DESCRIPTION | C11: Class 설명 | D11: VARCHAR2(200) | E11: Y | I11: 소스 | J11: 1
A12: 4 | B12: GROUP_ID | C12: Defect Group 번호 (TQD_DEFECT_GROUP.GROUP_ID, 기본 0) | D12: NUMBER(10) | E12: N | G12: TQD_DEFECT_GROUP | H12: 0 | I12: 소스 | J12: 1
A13: 5 | B13: DELETE_FLAG | C13: 사용 안 함 표시 (Y / N, 기본 N, Class 목록은 N 만) | D13: CHAR(1) | E13: N | H13: 'N' | I13: 소스 | J13: 1
A14: 6 | B14: DEFECT_COLOR | C14: Map 표시 색 (#RRGGBB, 없으면 화면은 #FF0000) | D14: VARCHAR2(7) | E14: N | I14: 소스 | J14: 1
A15: 7 | B15: CREATE_TIME | C15: 생성 일시 | D15: DATE | E15: Y | I15: 소스 | J15: 1
A16: 8 | B16: CREATE_USER | C16: 생성 사용자 ID | D16: VARCHAR2(30) | E16: Y | I16: 소스 | J16: 1
A17: 9 | B17: UPDATE_TIME | C17: 수정 일시 | D17: DATE | E17: Y | I17: 소스 | J17: 1
A18: 10 | B18: UPDATE_USER | C18: 수정 사용자 ID | D18: VARCHAR2(30) | E18: Y | I18: 소스 | J18: 1
A20: 제약 조건
A21: No | B21: 구분 | C21: 제약 이름 | D21: 컬럼 | G21: 내용
A22: 1 | B22: PK | C22: SYS_C008149 | D22: CLASSNUMBER | G22: 기본 키
A24: 인덱스
A25: No | B25: 유일 | C25: 인덱스 이름 | D25: 컬럼 | G25: 용도
A26: 1 | B26: UNIQUE | C26: SYS_C008149 | D26: CLASSNUMBER | G26: 기본 키

Sheet TQD_IMAGES
A1: 테이블 명세서
I2: <- 테이블 목록
A3: 테이블명 | C3: TQD_IMAGES | D3: 영역 | E3: DMS | G3: 스키마 | H3: DMSMGR
A4: 테이블 설명 | C4: Defect 이미지 파일 1건 (원본 / 썸네일 경로)
A5: 기본 키 (PK) | C5: PK_TQD_IMAGES (STEP_SEQ, DEFECTID, IMAGE_ID) | D5: 컬럼 수 | E5: =SUM(J9:J20) -> 12 | G5: Query XML | H5: TQD_IMAGES.xml
A6: 사용 기능 | C6: KLARF / Review 적재 / KLARF 업로드 / Map Viewer 이미지 / Image Gallery / Data Maint 이미지 삭제
A8: No | B8: 컬럼명 | C8: 컬럼 설명 | D8: 데이터 타입 | E8: NULL | F8: PK | G8: 참조 (논리) | H8: 기본값 | I8: 근거
A9: 1 | B9: STEP_SEQ | C9: 검사 Step 번호 (TQD_DEFECT.STEP_SEQ) | D9: NUMBER(15) | E9: N | F9: 1 | G9: TQD_DEFECT | H9: (0) | I9: 소스 | J9: 1
A10: 2 | B10: DEFECTID | C10: Defect ID (TQD_DEFECT.DEFECTID) | D10: NUMBER | E10: N | F10: 2 | G10: TQD_DEFECT | H10: (0) | I10: 소스 | J10: 1
A11: 3 | B11: IMAGE_ID | C11: Defect 안 이미지 순번 (0부터, 기존 최대값 + 1) | D11: NUMBER | E11: N | F11: 3 | H11: (0) | I11: 소스 | J11: 1
A12: 4 | B12: WAFER_SEQ | C12: Wafer 번호 (TQD_WAFER.WAFER_SEQ) | D12: NUMBER(15) | E12: N | H12: (0) | I12: 소스 | J12: 1
A13: 5 | B13: TEST | C13: 검사 Test 번호 (Defect 의 TEST) | D13: NUMBER | E13: N | H13: (0) | I13: 소스 | J13: 1
A14: 6 | B14: IMAGE_TYPE | C14: 이미지 파일 확장자 (예 .jpg) | D14: VARCHAR2(10) | E14: N | H14: (' ') | I14: 소스 | J14: 1
A15: 7 | B15: IMAGE_PATH | C15: 이미지 폴더 경로 (FTP 상대 경로, 예 FTP/SCK/20261013/{Lot}) | D15: VARCHAR2(200) | E15: N | H15: (' ') | I15: 소스 | J15: 1
A16: 8 | B16: IMAGE_FILENAME | C16: 이미지 파일명 (KLARF TiffFileName) | D16: VARCHAR2(200) | E16: N | H16: (' ') | I16: 소스 | J16: 1
A17: 9 | B17: IMAGE_SERVER | C17: 이미지 서버 (적재 시 ' ' 고정) | D17: VARCHAR2(40) | E17: N | H17: (' ') | I17: 소스 | J17: 1
A18: 10 | B18: THUMB_PATH | C18: 썸네일 폴더 경로 (IMAGE_PATH 와 같음) | D18: VARCHAR2(200) | E18: N | H18: (' ') | I18: 소스 | J18: 1
A19: 11 | B19: THUMB_FILENAME | C19: 썸네일 파일명 ('thumb_' + 이미지 파일명) | D19: VARCHAR2(200) | E19: N | H19: (' ') | I19: 소스 | J19: 1
A20: 12 | B20: UPLOAD | C20: 적재 경로 (INSP 검사 / REVIEW 리뷰 / UPLOAD KLARF 업로드) | D20: VARCHAR2(200) | E20: N | H20: (' ') | I20: 소스 | J20: 1
A22: 제약 조건
A23: No | B23: 구분 | C23: 제약 이름 | D23: 컬럼 | G23: 내용
A24: 1 | B24: PK | C24: PK_TQD_IMAGES | D24: STEP_SEQ, DEFECTID, IMAGE_ID | G24: 기본 키
A26: 인덱스
A27: No | B27: 유일 | C27: 인덱스 이름 | D27: 컬럼 | G27: 용도
A28: 1 | B28: UNIQUE | C28: PK_TQD_IMAGES | D28: STEP_SEQ, DEFECTID, IMAGE_ID | G28: 기본 키

Sheet TQD_INSP_INFO
A1: 테이블 명세서
I2: <- 테이블 목록
A3: 테이블명 | C3: TQD_INSP_INFO | D3: 영역 | E3: DMS | G3: 스키마 | H3: DMSMGR
A4: 테이블 설명 | C4: 검사 결과 요약 1건 (Step x Test), Lot / Wafer / Step 값을 펼친 형태
A5: 기본 키 (PK) | C5: TQD_INSP_INFO_PK (STEP_SEQ, TEST) | D5: 컬럼 수 | E5: =SUM(J9:J53) -> 45 | G5: Query XML | H5: TQD_INSP_INFO.xml
A6: 사용 기능 | C6: 왼쪽 Wafer 조회 / Map Viewer / Gallery / Chart / DMS 리포트 / Review 매칭 / KLARF 업로드 / GDS Correlation
A8: No | B8: 컬럼명 | C8: 컬럼 설명 | D8: 데이터 타입 | E8: NULL | F8: PK | G8: 참조 (논리) | H8: 기본값 | I8: 근거
A9: 1 | B9: STEP_SEQ | C9: 검사 Step 번호 (TQD_STEP.STEP_SEQ) | D9: NUMBER | E9: N | F9: 1 | G9: TQD_STEP | I9: 소스 | J9: 1
A10: 2 | B10: WAFER_SEQ | C10: Wafer 번호 (TQD_WAFER.WAFER_SEQ) | D10: NUMBER | E10: N | G10: TQD_STEP | I10: 소스 | J10: 1
A11: 3 | B11: RESULTTIMESTAMP | C11: 검사 시각 (KLARF ResultTimestamp), Wafer 조회 기간 기준 | D11: TIMESTAMP(6) | E11: N | I11: 소스 | J11: 1
A12: 4 | B12: FILETIMESTAMP | C12: KLARF 파일 생성 시각 (KLARF FileTimestamp) | D12: TIMESTAMP(6) | E12: N | I12: 소스 | J12: 1
A13: 5 | B13: FACTORY | C13: Factory (적재 서비스 설정 FACTORY / 업로드는 로그인 Factory) | D13: VARCHAR2(40) | E13: Y | G13: TQP_MAPDEF | I13: 소스 | J13: 1
A14: 6 | B14: TECHNOLOGY | C14: Technology (적재 시 'NONE' 고정) | D14: VARCHAR2(40) | E14: Y | I14: 소스 | J14: 1
A15: 7 | B15: PRODUCT | C15: Product = KLARF DeviceID (TQD_PRODUCT.PRODUCT 와 같은 값) | D15: VARCHAR2(40) | E15: N | G15: TQP_MAPDEF | I15: 소스 | J15: 1
A16: 8 | B16: LOT_ID | C16: Lot ID (TQD_LOT.LOT_ID 와 같은 값) | D16: VARCHAR2(40) | E16: N | G16: TQP_WAFER_SUM | I16: 소스 | J16: 1
A17: 9 | B17: WAFER_ID | C17: Wafer ID ({LOT_ID}-{Slot 2자리}, TQD_WAFER.WAFER_ID 와 같은 값) | D17: VARCHAR2(40) | E17: N | G17: TQP_WAFER_SUM | I17: 소스 | J17: 1
A18: 10 | B18: STEP_ID | C18: 검사 Step ID (TQD_STEP.STEP_ID 와 같은 값) | D18: VARCHAR2(40) | E18: N | I18: 소스 | J18: 1
A19: 11 | B19: TEST | C19: 검사 Test 번호 (KLARF InspectionTest, Test 마다 1행) | D19: NUMBER(10) | E19: N | F19: 2 | I19: 소스 | J19: 1
A20: 12 | B20: SLOT_ID | C20: Slot 번호 (KLARF Slot) | D20: NUMBER(10) | E20: N | I20: 소스 | J20: 1
A21: 13 | B21: SETUP_SEQ | C21: Setup 번호 (TQD_SETUP.SETUP_SEQ) | D21: NUMBER | E21: N | G21: TQD_SETUP | I21: 소스 | J21: 1
A22: 14 | B22: STATUS | C22: 적재 / 마지막 변경 처리 시각 (yyyyMMddHHmmss 문자열) | D22: VARCHAR2(40) | E22: Y | I22: 소스 | J22: 1
A23: 15 | B23: MAIN_EQ | C23: 공정 설비 ID (옛 KtoD 는 MES 이력, DataService 는 검사 설비) | D23: VARCHAR2(40) | E23: Y | I23: 소스 | J23: 1
A24: 16 | B24: ROUTE | C24: MES Route (옛 KtoD 만 MES 이력에서 채움, DataService 빈 값) | D24: VARCHAR2(40) | E24: Y | I24: 소스 | J24: 1
A25: 17 | B25: OPER | C25: MES Operation (옛 KtoD 만 MES MAIN_OPER, DataService 빈 값) | D25: VARCHAR2(40) | E25: Y | I25: 소스 | J25: 1
A26: 18 | B26: INSPECTION_EQ | C26: 검사 설비 ID (적재 Handler 의 TQC_EQUIP 설비, 업로드는 화면 값) | D26: VARCHAR2(40) | E26: Y | I26: 소스 | J26: 1
A27: 19 | B27: INSPECTION_PARAM | C27: KLARF DefectRecordSpec 항목 이름 목록 (쉼표 구분) | D27: VARCHAR2(256) | E27: Y | I27: 소스 | J27: 1
A28: 20 | B28: DEFECTS | C28: 해당 Test 의 Defect 수 | D28: NUMBER(10) | E28: N | I28: 소스 | J28: 1
A29: 21 | B29: CLASSIFIED_DEFECTS | C29: 분류된 Defect 수 (CLASSNUMBER > 0, Review 적재 시 재계산) | D29: NUMBER(10) | E29: N | I29: 소스 | J29: 1
A30: 22 | B30: KILLER_DEFECTS | C30: Killer Defect 수 (적재 시 0 고정) | D30: NUMBER(10) | E30: N | I30: 이름 추정 | J30: 1
A31: 23 | B31: RANDOM_DEFECTS | C31: Random Defect 수 (CLUSTERNUMBER = 0) | D31: NUMBER(10) | E31: N | I31: 소스 | J31: 1
A32: 24 | B32: ADDER_KILLER_DEFECT | C32: New Killer Defect 수 (적재 시 0 고정) | D32: NUMBER(10) | E32: N | I32: 이름 추정 | J32: 1
A33: 25 | B33: ADDER_RANDOM_DEFECT | C33: New(ADDER > 0) Random Defect 수 | D33: NUMBER(10) | E33: N | I33: 소스 | J33: 1
... A53: 45 | B53: SUMMARY_FLAG | C53: 요약 처리 표시 (용도 미확인, 업로드는 ' ') | D53: CHAR(1) | E53: N | I53: 이름 추정 | J53: 1
A55: 제약 조건
A56: No | B56: 구분 | C56: 제약 이름 | D56: 컬럼 | G56: 내용
A57: 1 | B57: PK | C57: TQD_INSP_INFO_PK | D57: STEP_SEQ, TEST | G57: 기본 키
A59: 인덱스
A60: No | B60: 유일 | C60: 인덱스 이름 | D60: 컬럼 | G60: 용도
A61: 1 | B61: - | C61: IDX_INSP_INFO_01 | D61: WAFER_SEQ, STEP_SEQ
A62: 2 | B62: - | C62: IDX_INSP_INFO_02 | D62: PRODUCT, LOT_ID, WAFER_ID, STEP_ID
...

Sheet TQD_INSP_SUM
A1: 테이블 명세서
I2: <- 테이블 목록
A3: 테이블명 | C3: TQD_INSP_SUM | D3: 영역 | E3: DMS | G3: 스키마 | H3: DMSMGR
A4: 테이블 설명 | C4: Step 별 Defect 집계 (Random / Cluster / Size 구간 / New Defect)
A5: 기본 키 (PK) | C5: TQD_INSP_SUM_PK (STEP_SEQ) | D5: 컬럼 수 | E5: =SUM(J9:J67) -> 59 | G5: Query XML | H5: TQD_INSP_SUM.xml
A6: 사용 기능 | C6: KLARF 적재 (Step 12) / KLARF 업로드 / Data Maint / Data Sheet / 설비 Defect Trend
A8: No | B8: 컬럼명 | C8: 컬럼 설명 | D8: 데이터 타입 | E8: NULL | F8: PK | G8: 참조 (논리) | H8: 기본값 | I8: 근거
A9: 1 | B9: STEP_SEQ | C9: 검사 Step 번호 (TQD_STEP.STEP_SEQ) | D9: NUMBER | E9: N | F9: 1 | G9: TQD_STEP | I9: 소스 | J9: 1
A10: 2 | B10: TOTALDEFECT | C10: Step 전체 Defect 수 | D10: NUMBER(6) | E10: Y | I10: 소스 | J10: 1
A11: 3 | B11: TOTALCLUSTER | C11: Cluster 그룹 수 (CLUSTERNUMBER > 0 고유 개수) | D11: NUMBER(6) | E11: Y | I11: 소스 | J11: 1
A12: 4 | B12: TOTALRANDOM | C12: Random Defect 수 + Cluster 그룹 수 (Cluster 는 1개로 셈) | D12: NUMBER(6) | E12: Y | I12: 소스 | J12: 1
A13: 5 | B13: TOTAL0_5UM | C13: 전체 Defect 중 DSIZE/10 0.5 이하 인 수 | D13: NUMBER(6) | E13: Y | I13: 소스 | J13: 1
A14: 6 | B14: TOTAL0_7UM | C14: 전체 Defect 중 DSIZE/10 0.5 초과 0.7 이하 인 수 | D14: NUMBER(6) | E14: Y | I14: 소스 | J14: 1
A15: 7 | B15: TOTAL1UM | C15: 전체 Defect 중 DSIZE/10 0.7 초과 1 이하 인 수 | D15: NUMBER(6) | E15: Y | I15: 소스 | J15: 1
A16: 8 | B16: TOTAL2UM | C16: 전체 Defect 중 DSIZE/10 1 초과 2 이하 인 수 | D16: NUMBER(6) | E16: Y | I16: 소스 | J16: 1
A17: 9 | B17: TOTAL3UM | C17: 전체 Defect 중 DSIZE/10 2 초과 3 이하 인 수 | D17: NUMBER(6) | E17: Y | I17: 소스 | J17: 1
A18: 10 | B18: TOTAL4UM | C18: 전체 Defect 중 DSIZE/10 3 초과 4 이하 인 수 | D18: NUMBER(6) | E18: Y | I18: 소스 | J18: 1
A19: 11 | B19: TOTAL5UM | C19: 전체 Defect 중 DSIZE/10 4 초과 5 이하 인 수 | D19: NUMBER(6) | E19: Y | I19: 소스 | J19: 1
A20: 12 | B20: TOTAL6UM | C20: 전체 Defect 중 DSIZE/10 5 초과 6 이하 인 수 | D20: NUMBER(6) | E20: Y | I20: 소스 | J20: 1
A21: 13 | B21: TOTAL7UM | C21: 전체 Defect 중 DSIZE/10 6 초과 7 이하 인 수 | D21: NUMBER(6) | E21: Y | I21: 소스 | J21: 1
... A67: 59 | B67: NEWCLUSTERDIE | C67: New(ADDER=1) Cluster Defect 가 있는 Die 수 | D67: NUMBER(6) | E67: Y | I67: 소스 | J67: 1
A69: 제약 조건
A70: No | B70: 구분 | C70: 제약 이름 | D70: 컬럼 | G70: 내용
A71: 1 | B71: PK | C71: TQD_INSP_SUM_PK | D71: STEP_SEQ | G71: 기본 키
A73: 인덱스
A74: No | B74: 유일 | C74: 인덱스 이름 | D74: 컬럼 | G74: 용도
A75: 1 | B75: UNIQUE | C75: TQD_INSP_SUM_PK | D75: STEP_SEQ | G75: 기본 키

Sheet TQD_LOT
A1: 테이블 명세서
I2: <- 테이블 목록
A3: 테이블명 | C3: TQD_LOT | D3: 영역 | E3: DMS | G3: 스키마 | H3: DMSMGR
A4: 테이블 설명 | C4: Lot 기준정보 (Product + Lot ID)
A5: 기본 키 (PK) | C5: SYS_C0010417 (LOT_SEQ) | D5: 컬럼 수 | E5: =SUM(J9:J12) -> 4 | G5: Query XML | H5: TQD_LOT.xml
A6: 사용 기능 | C6: KLARF 적재 / KLARF 업로드 / Data Maint Lot 변경 / 기존 등록 확인
A8: No | B8: 컬럼명 | C8: 컬럼 설명 | D8: 데이터 타입 | E8: NULL | F8: PK | G8: 참조 (논리) | H8: 기본값 | I8: 근거
A9: 1 | B9: LOT_SEQ | C9: Lot 번호 (LOT_SEQ 시퀀스) | D9: NUMBER | E9: N | F9: 1 | H9: (0) | I9: 소스 | J9: 1
A10: 2 | B10: LOT_ID | C10: Lot ID (KLARF LotID 대문자, 자동 적재는 앞 'A' 제거) | D10: VARCHAR2(40) | E10: N | H10: (' ') | I10: 소스 | J10: 1
A11: 3 | B11: PRODUCT | C11: Product (TQD_PRODUCT.PRODUCT) | D11: VARCHAR2(40) | E11: N | G11: TQD_PRODUCT | H11: (' ') | I11: 소스 | J11: 1
A12: 4 | B12: COMMENT | C12: 생성 경로 (Parser / Upload / Maint Update) | D12: VARCHAR2(128) | E12: Y | H12: (' ') | I12: 소스 | J12: 1
A14: 제약 조건
A15: No | B15: 구분 | C15: 제약 이름 | D15: 컬럼 | G15: 내용
A16: 1 | B16: PK | C16: SYS_C0010417 | D16: LOT_SEQ | G16: 기본 키
A18: 인덱스
A19: No | B19: 유일 | C19: 인덱스 이름 | D19: 컬럼 | G19: 용도
A20: 1 | B20: UNIQUE | C20: SYS_C0010417 | D20: LOT_SEQ | G20: 기본 키

Sheet TQD_PRODUCT
A1: 테이블 명세서
I2: <- 테이블 목록
A3: 테이블명 | C3: TQD_PRODUCT | D3: 영역 | E3: DMS | G3: 스키마 | H3: DMSMGR
A4: 테이블 설명 | C4: Product(Device) 기준정보, 처음 적재된 KLARF 의 Wafer / Die 값
A5: 기본 키 (PK) | C5: SYS_C0055302 (PRODUCT) | D5: 컬럼 수 | E5: =SUM(J9:J22) -> 14 | G5: Query XML | H5: TQD_PRODUCT.xml
A6: 사용 기능 | C6: KLARF 적재 / KLARF 업로드 (Device 최초 등록) / Data Maint Product 복사
A8: No | B8: 컬럼명 | C8: 컬럼 설명 | D8: 데이터 타입 | E8: NULL | F8: PK | G8: 참조 (논리) | H8: 기본값 | I8: 근거
A9: 1 | B9: PRODUCT | C9: Product = KLARF DeviceID (업로드는 화면 Product) | D9: VARCHAR2(40) | E9: N | F9: 1 | H9: (' ') | I9: 소스 | J9: 1
A10: 2 | B10: FACTORY | C10: Factory (적재 서비스 설정 FACTORY / 업로드는 로그인 Factory) | D10: VARCHAR2(40) | E10: N | H10: (' ') | I10: 소스 | J10: 1
A11: 3 | B11: TECHNOLOGY | C11: Technology (적재 시 'NONE' 고정) | D11: VARCHAR2(40) | E11: N | H11: (' ') | I11: 소스 | J11: 1
A12: 4 | B12: NETDIE | C12: Net Die 수 (첫 KLARF 검사 Die 수, 업로드는 Map 사용 Die 수) | D12: NUMBER(10) | E12: N | H12: (0) | I12: 소스 | J12: 1
A13: 5 | B13: WAFER_SIZE | C13: Wafer 크기 (um, KLARF SampleSize mm x 1000) | D13: NUMBER(20,10) | E13: N | H13: (0) | I13: 소스 | J13: 1
A14: 6 | B14: ANGLE | C14: Orientation Mark 각도 (DOWN 0 / LEFT 90 / TOP 180 / RIGHT 270) | D14: NUMBER(10) | E14: N | H14: (0) | I14: 소스 | J14: 1
A15: 7 | B15: NOTCH_TYPE | C15: Orientation Mark 형태 (적재 시 'N' 고정, 'F' = Flat) | D15: CHAR(1) | E15: N | H15: (' ') | I15: 소스 | J15: 1
A16: 8 | B16: DIE_PITCH_X | C16: Die Pitch X (um, KLARF DiePitch) | D16: NUMBER(20,10) | E16: N | H16: (0) | I16: 소스 | J16: 1
A17: 9 | B17: DIE_PITCH_Y | C17: Die Pitch Y (um, KLARF DiePitch) | D17: NUMBER(20,10) | E17: N | H17: (0) | I17: 소스 | J17: 1
A18: 10 | B18: DIE_ORIGIN_X | C18: Origin Die Index X (KLARF 원점 Die 의 좌하단 기준 번호) | D18: NUMBER(10) | E18: N | H18: (0) | I18: 소스 | J18: 1
A19: 11 | B19: DIE_ORIGIN_Y | C19: Origin Die Index Y (KLARF 원점 Die 의 좌하단 기준 번호) | D19: NUMBER(10) | E19: N | H19: (0) | I19: 소스 | J19: 1
A20: 12 | B20: ORIGIN_X | C20: Wafer 중심 위치 X (um, KLARF SampleCenterLocation) | D20: NUMBER(20,10) | E20: N | H20: (0) | I20: 소스 | J20: 1
A21: 13 | B21: ORIGIN_Y | C21: Wafer 중심 위치 Y (um, KLARF SampleCenterLocation) | D21: NUMBER(20,10) | E21: N | H21: (0) | I21: 소스 | J21: 1
A22: 14 | B22: COMMENT | C22: 생성 경로 (Parser / Upload / Maint Update) | D22: VARCHAR2(128) | E22: Y | H22: (0) | I22: 소스 | J22: 1
A24: 제약 조건
A25: No | B25: 구분 | C25: 제약 이름 | D25: 컬럼 | G25: 내용
A26: 1 | B26: PK | C26: SYS_C0055302 | D26: PRODUCT | G26: 기본 키
A28: 인덱스
A29: No | B29: 유일 | C29: 인덱스 이름 | D29: 컬럼 | G29: 용도
A30: 1 | B30: UNIQUE | C30: SYS_C0055302 | D30: PRODUCT | G30: 기본 키

Sheet TQD_REVIEW_SUM
A1: 테이블 명세서
I2: <- 테이블 목록
A3: 테이블명 | C3: TQD_REVIEW_SUM | D3: 영역 | E3: DMS | G3: 스키마 | H3: DMSMGR
A4: 테이블 설명 | C4: Step 별 Defect Class(CLASSNUMBER) 개수 집계
A5: 기본 키 (PK) | C5: PK_TQD_REVIEW_SUM (STEP_SEQ) | D5: 컬럼 수 | E5: =SUM(J9:J10) -> 257 | G5: Query XML | H5: TQD_REVIEW_SUM.xml
A6: 사용 기능 | C6: Review DataService / Data Maint (생성만, 조회 쿼리 없음)
A8: No | B8: 컬럼명 | C8: 컬럼 설명 | D8: 데이터 타입 | E8: NULL | F8: PK | G8: 참조 (논리) | H8: 기본값 | I8: 근거
A9: 1 | B9: STEP_SEQ | C9: 검사 Step 번호 (TQD_STEP.STEP_SEQ) | D9: NUMBER | E9: N | F9: 1 | G9: TQD_STEP | I9: 소스 | J9: 1
A10: 2 ~ 257 | B10: CAT0 ~ CAT255 (256개) | C10: CLASSNUMBER n 인 Defect 수 (CATn, Cluster 는 1개, CAT0 은 0 고정) | D10: NUMBER(6) | E10: Y | I10: 소스 | J10: 256
A12: 제약 조건
A13: No | B13: 구분 | C13: 제약 이름 | D13: 컬럼 | G13: 내용
A14: 1 | B14: PK | C14: PK_TQD_REVIEW_SUM | D14: STEP_SEQ | G14: 기본 키
A16: 인덱스
A17: No | B17: 유일 | C17: 인덱스 이름 | D17: 컬럼 | G17: 용도
A18: 1 | B18: UNIQUE | C18: PK_TQD_REVIEW_SUM | D18: STEP_SEQ | G18: 기본 키

Sheet TQD_SETUP
A1: 테이블 명세서
I2: <- 테이블 목록
A3: 테이블명 | C3: TQD_SETUP | D3: 영역 | E3: DMS | G3: 스키마 | H3: DMSMGR
A4: 테이블 설명 | C4: 검사 Setup(Recipe) 별 Wafer / Die 좌표 기준 (KLARF SetupID 단위)
A5: 기본 키 (PK) | C5: PK_SETUP (SETUP_SEQ) | D5: 컬럼 수 | E5: =SUM(J9:J23) -> 15 | G5: Query XML | H5: TQD_SETUP.xml
A6: 사용 기능 | C6: KLARF 적재 / KLARF 업로드 / Map 표시 (Map Viewer, GDS Correlation) / Origin Die Index 조회
A8: No | B8: 컬럼명 | C8: 컬럼 설명 | D8: 데이터 타입 | E8: NULL | F8: PK | G8: 참조 (논리) | H8: 기본값 | I8: 근거
A9: 1 | B9: SETUP_SEQ | C9: Setup 번호 (SETUP_SEQ 시퀀스) | D9: NUMBER | E9: N | F9: 1 | I9: 소스 | J9: 1
A10: 2 | B10: SETUP_ID | C10: KLARF SetupID (검사 Recipe 이름, 로컬 DB 128자로 확대) | D10: VARCHAR2(128) | E10: N | I10: 소스 | J10: 1
A11: 3 | B11: STEP_ID | C11: KLARF StepID 원문 (8자리 변환 없음) | D11: VARCHAR2(40) | E11: N | I11: 소스 | J11: 1
A12: 4 | B12: SETUP_TIME | C12: KLARF SetupID 의 일시 (MM-DD-YY HH:MI:SS) | D12: TIMESTAMP(6) | E12: N | I12: 소스 | J12: 1
A13: 5 | B13: ANGLE | C13: Orientation Mark 각도 (DOWN 0 / LEFT 90 / TOP 180 / RIGHT 270) | D13: NUMBER(10) | E13: N | H13: 0 | I13: 소스 | J13: 1
A14: 6 | B14: WAFER_SIZE | C14: Wafer 크기 (um, KLARF SampleSize mm x 1000, 업로드는 Map Setup) | D14: NUMBER(20,10) | E14: N | H14: 200000 | I14: 소스 | J14: 1
A15: 7 | B15: NOTCH_TYPE | C15: Orientation Mark 형태 (적재 시 'N' 고정, 'F' = Flat) | D15: CHAR(1) | E15: N | H15: 'F' | I15: 소스 | J15: 1
A16: 8 | B16: DIE_PITCH_X | C16: Die Pitch X (um, KLARF DiePitch, 업로드는 Map Setup) | D16: NUMBER(20,10) | E16: N | H16: 0 | I16: 소스 | J16: 1
A17: 9 | B17: DIE_PITCH_Y | C17: Die Pitch Y (um, KLARF DiePitch, 업로드는 Map Setup) | D17: NUMBER(20,10) | E17: N | H17: 0 | I17: 소스 | J17: 1
A18: 10 | B18: DIE_ORIGIN_X | C18: Origin Die Index X (좌하단 기준, Index 변환에 사용) | D18: NUMBER(10) | E18: N | H18: 0 | I18: 소스 | J18: 1
A19: 11 | B19: DIE_ORIGIN_Y | C19: Origin Die Index Y (좌하단 기준, Index 변환에 사용) | D19: NUMBER(10) | E19: N | H19: 0 | I19: 소스 | J19: 1
A20: 12 | B20: ORIGIN_X | C20: Wafer 중심 위치 X (um, KLARF SampleCenterLocation) | D20: NUMBER(20,10) | E20: N | H20: 0 | I20: 소스 | J20: 1
A21: 13 | B21: ORIGIN_Y | C21: Wafer 중심 위치 Y (um, KLARF SampleCenterLocation) | D21: NUMBER(20,10) | E21: N | H21: 0 | I21: 소스 | J21: 1
A22: 14 | B22: STREET_X | C22: Street(Scribe Line) 폭 X (적재 값 0, 갱신 호출 소스 없음) | D22: NUMBER(10) | E22: N | H22: 0 | I22: 이름 추정 | J22: 1
A23: 15 | B23: STREET_Y | C23: Street(Scribe Line) 폭 Y (적재 값 0, 갱신 호출 소스 없음) | D23: NUMBER(10) | E23: N | H23: 0 | I23: 이름 추정 | J23: 1
A25: 제약 조건
A26: No | B26: 구분 | C26: 제약 이름 | D26: 컬럼 | G26: 내용
A27: 1 | B27: PK | C27: PK_SETUP | D27: SETUP_SEQ | G27: 기본 키
A29: 인덱스
A30: No | B30: 유일 | C30: 인덱스 이름 | D30: 컬럼 | G30: 용도
A31: 1 | B31: - | C31: IDX_TQD_SETUP_01 | D31: SETUP_ID, STEP_ID, SETUP_TIME
A32: 2 | B32: UNIQUE | C32: PK_TQD_SETUP | D32: SETUP_SEQ | G32: 기본 키

Sheet TQD_SETUP_MAP
A1: 테이블 명세서
I2: <- 테이블 목록
A3: 테이블명 | C3: TQD_SETUP_MAP | D3: 영역 | E3: DMS | G3: 스키마 | H3: DMSMGR
A4: 테이블 설명 | C4: Setup + Test 별 검사 Die 목록 (Die Index)
A5: 기본 키 (PK) | C5: PK_SETUP_MAP (SETUP_SEQ, TEST, INDEX_X, INDEX_Y) | D5: 컬럼 수 | E5: =SUM(J9:J12) -> 4 | G5: Query XML | H5: TQD_SETUP_MAP.xml
A6: 사용 기능 | C6: KLARF 적재 / KLARF 업로드 / Map 검사 Die 표시 / Defect Density / GDS Correlation
A8: No | B8: 컬럼명 | C8: 컬럼 설명 | D8: 데이터 타입 | E8: NULL | F8: PK | G8: 참조 (논리) | H8: 기본값 | I8: 근거
A9: 1 | B9: SETUP_SEQ | C9: Setup 번호 (TQD_SETUP.SETUP_SEQ) | D9: NUMBER | E9: N | F9: 1 | G9: TQD_SETUP | I9: 소스 | J9: 1
A10: 2 | B10: TEST | C10: 검사 Test 번호 (KLARF InspectionTest) | D10: NUMBER(10) | E10: N | F10: 2 | I10: 소스 | J10: 1
A11: 3 | B11: INDEX_X | C11: 검사 Die X Index (좌하단 기준, KLARF SampleTestPlan) | D11: NUMBER(10) | E11: N | F11: 3 | I11: 소스 | J11: 1
A12: 4 | B12: INDEX_Y | C12: 검사 Die Y Index (좌하단 기준, KLARF SampleTestPlan) | D12: NUMBER(10) | E12: N | F12: 4 | I12: 소스 | J12: 1
A14: 제약 조건
A15: No | B15: 구분 | C15: 제약 이름 | D15: 컬럼 | G15: 내용
A16: 1 | B16: PK | C16: PK_SETUP_MAP | D16: SETUP_SEQ, TEST, INDEX_X, INDEX_Y | G16: 기본 키
A18: 인덱스
A19: No | B19: 유일 | C19: 인덱스 이름 | D19: 컬럼 | G19: 용도
A20: 1 | B20: - | C20: IDX_TQD_SETUP_MAP_01 | D20: SETUP_SEQ
A21: 2 | B21: UNIQUE | C21: PK_TQD_SETUP_MAP | D21: SETUP_SEQ, TEST, INDEX_X, INDEX_Y | G21: 기본 키

Sheet TQD_STEP
A1: 테이블 명세서
I2: <- 테이블 목록
A3: 테이블명 | C3: TQD_STEP | D3: 영역 | E3: DMS | G3: 스키마 | H3: DMSMGR
A4: 테이블 설명 | C4: 검사 Step 1건 (KLARF 파일 1개 x Wafer 1장 의 헤더)
A5: 기본 키 (PK) | C5: SYS_C0010156 (STEP_SEQ) | D5: 컬럼 수 | E5: =SUM(J9:J33) -> 25 | G5: Query XML | H5: TQD_STEP.xml
A6: 사용 기능 | C6: KLARF 적재 / Review 적재 / KLARF 업로드 / Data Maint / Inspection Detail 리포트
A8: No | B8: 컬럼명 | C8: 컬럼 설명 | D8: 데이터 타입 | E8: NULL | F8: PK | G8: 참조 (논리) | H8: 기본값 | I8: 근거
A9: 1 | B9: STEP_SEQ | C9: 검사 Step 번호 (STEP_SEQ 시퀀스), Defect 조회의 기준 키 | D9: NUMBER | E9: N | F9: 1 | H9: (0) | I9: 소스 | J9: 1
A10: 2 | B10: TEST | C10: Test 번호 (자동 적재 1 고정, 옛 KtoD 는 KLARF InspectionTest) | D10: NUMBER(10) | E10: N | H10: (0) | I10: 소스 | J10: 1
A11: 3 | B11: WAFER_SEQ | C11: Wafer 번호 (TQD_WAFER.WAFER_SEQ) | D11: NUMBER | E11: N | G11: TQD_WAFER | H11: (0) | I11: 소스 | J11: 1
A12: 4 | B12: STEP_ID | C12: 검사 Step ID (KLARF StepID, 자동 적재는 8자리 아니면 SetupID '_' 뒤 값) | D12: VARCHAR2(40) | E12: N | H12: (' ') | I12: 소스 | J12: 1
A13: 5 | B13: SLOT_ID | C13: Slot 번호 (KLARF Slot) | D13: NUMBER(10) | E13: N | H13: (0) | I13: 소스 | J13: 1
A14: 6 | B14: RESULT_ID | C14: 결과 ID (자동 적재 / 업로드 = LotID, 옛 KtoD = KLARF ResultsID) | D14: VARCHAR2(40) | E14: N | H14: (' ') | I14: 소스 | J14: 1
A15: 7 | B15: INSPECTION_EQ | C15: 검사 설비 ID (적재 Handler 의 TQC_EQUIP 설비, 업로드는 화면 값) | D15: VARCHAR2(40) | E15: N | G15: TQC_EQUIP | H15: (' ') | I15: 소스 | J15: 1
A16: 8 | B16: REVIEW_EQ | C16: Review 설비 ID (Review KLARF 적재 시 기록, 기본 ' ') | D16: VARCHAR2(40) | E16: N | H16: (' ') | I16: 소스 | J16: 1
A17: 9 | B17: SETUP_SEQ | C17: Setup 번호 (TQD_SETUP.SETUP_SEQ) | D17: NUMBER | E17: N | G17: TQD_SETUP | H17: (0) | I17: 소스 | J17: 1
A18: 10 | B18: RESULTTIMESTAMP | C18: 검사 시각 (KLARF ResultTimestamp), 기존 등록 판정 키 일부 | D18: TIMESTAMP(6) | E18: N | I18: 소스 | J18: 1
A19: 11 | B19: FILETIMESTAMP | C19: KLARF 파일 생성 시각 (KLARF FileTimestamp) | D19: TIMESTAMP(6) | E19: N | I19: 소스 | J19: 1
A20: 12 | B20: MAIN_EQ | C20: 공정 설비 ID (자동 적재는 검사 설비, 없으면 'UNKNOWN') | D20: VARCHAR2(40) | E20: N | H20: (' ') | I20: 소스 | J20: 1
A21: 13 | B21: ROUTE | C21: MES Route (자동 적재 ' ') | D21: VARCHAR2(40) | E21: N | H21: (' ') | I21: 소스 | J21: 1
A22: 14 | B22: OPER | C22: MES Operation (자동 적재 ' ') | D22: VARCHAR2(40) | E22: N | H22: (' ') | I22: 소스 | J22: 1
A23: 15 | B23: SCAN_AREA | C23: 검사 면적 (옛 KtoD 만 값, 자동 적재 -1, 실제 값은 INSP_INFO) | D23: NUMBER | E23: N | H23: (0) | I23: 소스 | J23: 1
A24: 16 | B24: DEFECTIVE_DIE | C24: Defect Die 수 (옛 KtoD 만 값, 자동 적재 -1) | D24: NUMBER(10) | E24: N | H24: (0) | I24: 소스 | J24: 1
A25: 17 | B25: DEFECTS | C25: Defect 수 (옛 KtoD 만 값, 자동 적재 -1) | D25: NUMBER(10) | E25: N | H25: (0) | I25: 소스 | J25: 1
A26: 18 | B26: IMAGES | C26: 이미지 수 (Review 적재 / 업로드 시 갱신, 기본 0) | D26: NUMBER(10) | E26: N | H26: (0) | I26: 소스 | J26: 1
A27: 19 | B27: DEFECT_DD | C27: Defect Density (옛 KtoD 만 값, 자동 적재 -1) | D27: NUMBER(20,5) | E27: N | H27: (0) | I27: 소스 | J27: 1
A28: 20 | B28: INSP_FILENAME | C28: 검사 KLARF 파일명 | D28: VARCHAR2(256) | E28: N | H28: (' ') | I28: 소스 | J28: 1
A29: 21 | B29: INSP_FILEPATH | C29: KLARF 백업 폴더 FTP 상대 경로 (예 FTP/SCK/20261013/{Lot}) | D29: VARCHAR2(256) | E29: N | H29: (' ') | I29: 소스 | J29: 1
A30: 22 | B30: COMMENT | C30: 적재 구분 (Parser / UPLOAD;USER=..;FILE=..;RAW_WAFER_ID=.. 등) | D30: VARCHAR2(500) | E30: N | H30: (' ') | I30: 소스 | J30: 1
A31: 23 | B31: TEST_ORDER | C31: 같은 Wafer + Step ID 재검사 순번 (최신 1, 이전일수록 증가) | D31: NUMBER | E31: N | H31: (0) | I31: 소스 | J31: 1
... A33: 25 | B33: REVIEW_FILEPATH | C33: Review KLARF 백업 폴더 FTP 상대 경로 | D33: VARCHAR2(256) | E33: N | H33: (' ') | I33: 소스 | J33: 1
A35: 제약 조건
A36: No | B36: 구분 | C36: 제약 이름 | D36: 컬럼 | G36: 내용
A37: 1 | B37: PK | C37: SYS_C0010156 | D37: STEP_SEQ | G37: 기본 키
A39: 인덱스
A40: No | B40: 유일 | C40: 인덱스 이름 | D40: 컬럼 | G40: 용도
A41: 1 | B41: - | C41: IDX_TQD_STEP_01 | D41: WAFER_SEQ
A42: 2 | B42: UNIQUE | C42: SYS_C0010156 | D42: STEP_SEQ | G42: 기본 키

Sheet TQD_WAFER
A1: 테이블 명세서
I2: <- 테이블 목록
A3: 테이블명 | C3: TQD_WAFER | D3: 영역 | E3: DMS | G3: 스키마 | H3: DMSMGR
A4: 테이블 설명 | C4: Wafer 기준정보 (Lot + Wafer ID / Slot)
A5: 기본 키 (PK) | C5: SYS_C0010161 (WAFER_SEQ) | D5: 컬럼 수 | E5: =SUM(J9:J13) -> 5 | G5: Query XML | H5: TQD_WAFER.xml
A6: 사용 기능 | C6: KLARF 적재 / KLARF 업로드 / Data Maint (Lot 변경 시 WAFER_ID 갱신)
A8: No | B8: 컬럼명 | C8: 컬럼 설명 | D8: 데이터 타입 | E8: NULL | F8: PK | G8: 참조 (논리) | H8: 기본값 | I8: 근거
A9: 1 | B9: WAFER_SEQ | C9: Wafer 번호 (WAFER_SEQ 시퀀스) | D9: NUMBER | E9: N | F9: 1 | H9: (0) | I9: 소스 | J9: 1
A10: 2 | B10: LOT_SEQ | C10: Lot 번호 (TQD_LOT.LOT_SEQ) | D10: NUMBER | E10: N | G10: TQD_LOT | H10: (0) | I10: 소스 | J10: 1
A11: 3 | B11: WAFER_ID | C11: DMS Wafer ID = {LOT_ID}-{Slot 2자리} (KLARF WaferID 원문 아님) | D11: VARCHAR2(40) | E11: N | H11: (' ') | I11: 소스 | J11: 1
A12: 4 | B12: SLOT_ID | C12: Slot 번호 (KLARF Slot) | D12: NUMBER(2) | E12: N | H12: (0) | I12: 소스 | J12: 1
A13: 5 | B13: COMMENT | C13: 비고 (CREATE_WAFER 가 빈 값 고정) | D13: VARCHAR2(128) | E13: Y | H13: (' ') | I13: 소스 | J13: 1
A15: 제약 조건
A16: No | B16: 구분 | C16: 제약 이름 | D16: 컬럼 | G16: 내용
A17: 1 | B17: PK | C17: SYS_C0010161 | D17: WAFER_SEQ | G17: 기본 키
A19: 인덱스
A20: No | B20: 유일 | C20: 인덱스 이름 | D20: 컬럼 | G20: 용도
A21: 1 | B21: - | C21: IDX_TQD_WAFER_01 | D21: WAFER_ID
A22: 2 | B22: UNIQUE | C22: SYS_C0010161 | D22: WAFER_SEQ | G22: 기본 키

Sheet 관계(논리)
A1: 테이블 관계 (논리)
A2: 이 영역의 테이블에는 DB FK 가 없다. Query XML / 소스의 조인 조건으로 확인한 관계만 적는다. [다른 영역] = 부모 또는 자식이 이 명세서 밖의 테이블.
A4: No | B4: 자식 테이블 | C4: 자식 컬럼 | D4: 부모 테이블 | E4: 부모 컬럼 | F4: 근거 / 비고
A5: 1 | B5: TQD_LOT | C5: PRODUCT | D5: TQD_PRODUCT | E5: PRODUCT | F5: Lot 의 Product (TQD_STEP.xml CHECK_EXIST_WAFERID)
A6: 2 | B6: TQD_WAFER | C6: LOT_SEQ | D6: TQD_LOT | E6: LOT_SEQ | F6: Lot 의 Wafer (CHECK_EXIST_WAFERID / TQD_WAFER.xml SELECT_WAFER_INFO_02)
A7: 3 | B7: TQD_STEP | C7: WAFER_SEQ | D7: TQD_WAFER | E7: WAFER_SEQ | F7: Wafer 의 검사 Step (CHECK_EXIST_WAFERID / TQD_STEP_SUM.xml SELECT_STEP_INFO)
A8: 4 | B8: TQD_STEP | C8: SETUP_SEQ | D8: TQD_SETUP | E8: SETUP_SEQ | F8: Step 의 Setup (InspectionDataService Step 1 / 6 이 같은 SETUP_SEQ 저장)
A9: 5 | B9: TQD_STEP | C9: INSPECTION_EQ | D9: TQC_EQUIP | E9: EQUIP_ID | F9: [다른 영역] 검사 설비 (TQD_INSP_INFO.xml SELECT_INSP_DETAIL, UPPER(INSPECTION_EQ) 조인)
A10: 6 | B10: TQD_INSP_INFO | C10: STEP_SEQ, WAFER_SEQ | D10: TQD_STEP | E10: STEP_SEQ, WAFER_SEQ | F10: Step 의 Test 별 요약 (TQD_INSP_INFO.xml SELECT_INSP_DETAIL / SELECT_LOT_INSP_INFO)
A11: 7 | B11: TQD_INSP_INFO | C11: SETUP_SEQ | D11: TQD_SETUP | E11: SETUP_SEQ | F11: Map 좌표 기준 (SELECT_DMS_WAFER_INFO / TQD_SETUP.xml SELECT_SETUP_DUPLE)
A12: 8 | B12: TQD_INSP_INFO | C12: FACTORY, PRODUCT | D12: TQP_MAPDEF | E12: FACTORY, MAPID | F12: [다른 영역] Map Setup 정보, 외부 조인 (GET_INSP_INFO_MULTI_SEQ, SELECT_DMS_WAFER_INFO 는 PRODUCT 만)
A13: 9 | B13: TQD_INSP_INFO | C13: LOT_ID, WAFER_ID | D13: TQP_WAFER_SUM | E13: LOT_ID, WAFER_ID | F13: [다른 영역] YMS Wafer 수율 연결 (TQD_DEFECT_DIE.xml SELECT_DEFECT_DIE, Data Sheet 는 LOT_ID + SLOT_ID 외부 조인)
A14: 10 | B14: TQD_SETUP_MAP | C14: SETUP_SEQ | D14: TQD_SETUP | E14: SETUP_SEQ | F14: Setup 의 검사 Die. Map 은 INSP_INFO 의 SETUP_SEQ + TEST 로 조회 (SELECT_X_Y / GET_DENSITY)
A15: 11 | B15: TQD_DEFECT | C15: STEP_SEQ | D15: TQD_STEP | E15: STEP_SEQ | F15: Step 의 Defect 목록 (TQD_DEFECT.xml SELECT_LAST_WAFER_DEFECT)
A16: 12 | B16: TQD_DEFECT | C16: STEP_SEQ, WAFER_SEQ, TEST | D16: TQD_INSP_INFO | E16: STEP_SEQ, WAFER_SEQ, TEST | F16: Test 별 Defect (UPDATE_INSP_INFO[REVIEW_PARSER] / TQD_IMAGES.xml GET_DEFECT_IMAGE_ALL)
... A24: 20 | B24: TQD_DEFECT_DIE | C24: TEST_WAFER_SEQ | D24: TQP_WAFER | E24: WAFER_SEQ | F24: [다른 영역] YMS Test Wafer (INSERT_DATA, SELECT_TST_BIN_INFO 는 TQP_WAFER_SUM.WAFER_SEQ 와 조인)

Sheet 시퀀스
A1: 시퀀스
A3: No | B3: 시퀀스 | C3: 사용 Query XML | D3: 시작 | E3: 증가 | F3: CACHE | G3: 비고
A4: 1 | B4: LOT_SEQ | C4: TQD_LOT.xml, TQP_LOT.xml, TQP_WAFER_SUM.xml, T_AVI_TABLE.xml | D4: 1 | E4: 1 | F4: 20 | G4: DMS / YMS 가 같은 시퀀스를 쓴다 (번호가 서로 겹치지 않음)
A5: 2 | B5: SETUP_SEQ | C5: TQD_SETUP.xml | D5: 1 | E5: 1 | F5: 20
A6: 3 | B6: STEP_SEQ | C6: TQD_STEP.xml | D6: 1 | E6: 1 | F6: 20
A7: 4 | B7: WAFER_SEQ | C7: TQD_WAFER.xml, TQP_WAFER.xml, TQP_WAFER_SUM.xml, T_AVI_TABLE.xml, T_PRB.xml | D7: 1 | E7: 1 | F7: 20 | G7: DMS / YMS 가 같은 시퀀스를 쓴다 (번호가 서로 겹치지 않음)
