Workbook

Sheet 개요
B2: SCK 분석시스템 구축 POC - 추가 테이블 명세서
B4: 대상 시스템 | C4: DACrux DMS (Defect / E-Test 분석, GDS Map / Chain)
B5: 기준 DB | C5: 로컬 개발 DB (Oracle 19c, 스키마 DMSMGR, 문자셋 AL32UTF8)
B6: 조회 일자 | C6: 2026-10-15
B7: 작성 근거 | C7: DB 메타데이터 (컬럼 / 주석 / 제약 / 인덱스 / 시퀀스) + DDL 스크립트 (DMS/06_CoreLibSource/GdsMapControl/Persistence/*.sql) + 설계 문서 (문서/설계/02_GDS, 04_ETest)
B8: 대상 범위 | C8: POC 에서 새로 만든 테이블 16개 / 시퀀스 5개. 기존 테이블 구조 변경 2건과 개발 중 삭제한 테이블 8개는 [변경 이력] 시트
B10: 업무 구분 | C10: 테이블 수
B11: GDS Map | C11: =COUNTIF('테이블 목록'!B4:B19,B11) -> 5
B12: GDS Chain | C12: =COUNTIF('테이블 목록'!B4:B19,B12) -> 6
B13: E-Test | C13: =COUNTIF('테이블 목록'!B4:B19,B13) -> 5
B14: 합계 | C14: =SUM(C11:C13) -> 16
B16: 시트 | C16: 내용
B17: 테이블 목록 | C17: 테이블 16개 요약 (테이블명을 누르면 해당 시트로 이동)
B18: TQP_GDS_* | C18: 테이블별 명세: 테이블 정보 / 컬럼 / 제약 조건 / 인덱스
B19: 관계(FK) | C19: 테이블 관계도와 FK 목록 (삭제 규칙 포함)
B20: 시퀀스 | C20: 키 번호용 시퀀스 5개
B21: 변경 이력 | C21: 삭제한 테이블 / 바꾼 기존 테이블 / DDL 스크립트 이력
B23: 표기 기준 | C23: 설명
B24: 데이터 타입 | C24: VARCHAR2(n CHAR) = 글자 수 기준, VARCHAR2(n) = byte 기준. BINARY_DOUBLE = 8 byte 실수 (좌표 / 측정값)
B25: NULL | C25: N = NOT NULL (필수), Y = NULL 허용
B26: PK | C26: 기본 키 컬럼과 키 안 순서. 노란 행 = 기본 키 컬럼
B27: FK 참조 | C27: 이 컬럼이 들어 있는 FK 의 부모 테이블. 상세 컬럼 / 삭제 규칙은 테이블 시트의 제약 조건 또는 [관계(FK)] 시트
B28: 허용 값 | C28: CHECK 제약으로 정한 값. 여러 컬럼을 함께 검사하는 조건은 제약 조건 표에 원문으로 적음
... B36: 제외 | C36: TD_<Program> 테이블 (예: TD_OMM_TSVET) 은 기존 YMS 적재 방식이 Program 별로 만드는 데이터 테이블이라 대상에서 뺐다.

Sheet 테이블 목록
A1: POC 추가 테이블 목록
A3: No | B3: 업무 구분 | C3: 테이블명 | D3: 테이블 설명 | E3: 기본 키 (PK) | F3: 컬럼 수 | G3: 상위 테이블 (FK) | H3: 하위 테이블 | I3: Query XML | J3: 생성 / 변경 SQL
A4: 1 | B4: GDS Map | C4: TQP_GDS_MAP | D4: GDS Map 헤더. Factory + Device 당 1건으로 GDS 파일 / Top Structure / 단위 / 저장 상태 / 좌표 기준면(Front / Back)을 관리한다. | E4: FACTORY, DEVICE_ID | F4: =COUNTA(TQP_GDS_MAP!B9:B22) -> 14 | H4: TQP_GDS_CHAIN, TQP_GDS_IMPORT_JOB, TQP_GDS_LAYER | I4: TQP_GDS_MAP.xml | J4: 2026-10-02_tqp_gds_schema_device.sql (생성) 2026-10-06_tqp_gds_map_sha_nullable.sql (변경) 2026-10-06_tqp_gds_map_view_side.sql (변경) 2026-10-08_tqp_gds_map_drop_sha.sql (변경) 2026-10-12_tqp_gds_source_el_drop.sql (변경)
A5: 2 | B5: GDS Map | C5: TQP_GDS_LAYER | D5: GDS Map 의 Layer 정의 (Layer 번호 / 기본 색 / 표시 이름). | E5: FACTORY, DEVICE_ID, LAYER_ID | F5: =COUNTA(TQP_GDS_LAYER!B9:B13) -> 5 | G5: TQP_GDS_MAP | H5: TQP_GDS_CHAIN_LAYER, TQP_GDS_CHAIN_RULE, TQP_GDS_PLACED_EL | I5: TQP_GDS_LAYER.xml | J5: 2026-10-02_tqp_gds_schema_device.sql (생성)
A6: 3 | B6: GDS Map | C6: TQP_GDS_PLACED_EL | D6: 반복 배치(SREF)를 펼친 실제 도형. 월드 좌표 / Bounds / 좌표 배열 / TEXT 를 저장하며 Map 화면 / Chain / Label 검색 / 연관 분석이 함께 쓴다. | E6: FACTORY, DEVICE_ID, PLACED_ELEMENT_ID | F6: =COUNTA(TQP_GDS_PLACED_EL!B9:B30) -> 22 | G6: TQP_GDS_LAYER | H6: TQP_GDS_CHAIN_EDIT, TQP_GDS_CHAIN_MEMBER | I6: TQP_GDS_PLACED_EL.xml | J6: 2026-10-02_tqp_gds_schema_device.sql (생성) 2026-10-02_tqp_gds_fk_delete_rule.sql (변경) 2026-10-12_tqp_gds_source_el_drop.sql (변경)
A7: 4 | B7: GDS Map | C7: TQP_GDS_IMPORT_JOB | D7: GDS Map 대량 저장 작업. Device 당 1건으로 예상 / 수신 건수와 진행 상태를 관리한다. | E7: IMPORT_JOB_SEQ | F7: =COUNTA(TQP_GDS_IMPORT_JOB!B9:B20) -> 12 | G7: TQP_GDS_MAP | H7: TQP_GDS_IMPORT_BATCH | I7: TQP_GDS_IMPORT_JOB.xml | J7: 2026-10-02_tqp_gds_schema_device.sql (생성) 2026-10-12_tqp_gds_source_el_drop.sql (변경)
A8: 5 | B8: GDS Map | C8: TQP_GDS_IMPORT_BATCH | D8: Map 저장 작업의 배치 전송 기록 (Layer / 배치 도형). 중복 전송 판정과 완료 확인에 쓴다. | E8: IMPORT_JOB_SEQ, STREAM_KIND, BATCH_NO | F8: =COUNTA(TQP_GDS_IMPORT_BATCH!B9:B17) -> 9 | G8: TQP_GDS_IMPORT_JOB | I8: TQP_GDS_IMPORT_BATCH.xml | J8: 2026-10-02_tqp_gds_schema_device.sql (생성) 2026-10-12_tqp_gds_source_el_drop.sql (변경)
A9: 6 | B9: GDS Chain | C9: TQP_GDS_CHAIN | D9: Chain 마스터. Chain 번호 / Code / 사용 상태를 관리한다. | E9: FACTORY, DEVICE_ID, CHAIN_SEQ | F9: =COUNTA(TQP_GDS_CHAIN!B9:B18) -> 10 | G9: TQP_GDS_MAP | H9: TQP_GDS_CHAIN_VER | I9: TQP_GDS_CHAIN.xml | J9: 2026-10-02_tqp_gds_schema_device.sql (생성)
A10: 7 | B10: GDS Chain | C10: TQP_GDS_CHAIN_VER | D10: Chain 설정 (이름 / 색 / 탐색 옵션)과 저장 상태. 현재는 버전 이력 없이 VERSION_NO = 1 로 덮어쓴다. | E10: FACTORY, DEVICE_ID, CHAIN_SEQ, VERSION_NO | F10: =COUNTA(TQP_GDS_CHAIN_VER!B9:B22) -> 14 | G10: TQP_GDS_CHAIN | H10: TQP_GDS_CHAIN_EDIT, TQP_GDS_CHAIN_LAYER, TQP_GDS_CHAIN_MEMBER, TQP_GDS_CHAIN_RULE | I10: TQP_GDS_CHAIN_VER.xml | J10: 2026-10-02_tqp_gds_schema_device.sql (생성)
A11: 8 | B11: GDS Chain | C11: TQP_GDS_CHAIN_MEMBER | D11: Chain 에 포함된 도형 (Input / Output / Member)과 단자 클릭 위치. | E11: FACTORY, DEVICE_ID, CHAIN_SEQ, VERSION_NO, PLACED_ELEMENT_ID | F11: =COUNTA(TQP_GDS_CHAIN_MEMBER!B9:B17) -> 9 | G11: TQP_GDS_PLACED_EL, TQP_GDS_CHAIN_VER | I11: TQP_GDS_CHAIN_MEMBER.xml | J11: 2026-10-02_tqp_gds_schema_device.sql (생성) 2026-10-02_tqp_gds_fk_delete_rule.sql (변경)
A12: 9 | B12: GDS Chain | C12: TQP_GDS_CHAIN_LAYER | D12: Chain 탐색 때 선택한 Layer. | E12: FACTORY, DEVICE_ID, CHAIN_SEQ, VERSION_NO, LAYER_ID | F12: =COUNTA(TQP_GDS_CHAIN_LAYER!B9:B13) -> 5 | G12: TQP_GDS_LAYER, TQP_GDS_CHAIN_VER | I12: TQP_GDS_CHAIN_LAYER.xml | J12: 2026-10-02_tqp_gds_schema_device.sql (생성) 2026-10-02_tqp_gds_fk_delete_rule.sql (변경)
A13: 10 | B13: GDS Chain | C13: TQP_GDS_CHAIN_RULE | D13: Chain 탐색의 Layer 조합 연결 규칙과 허용 거리. | E13: FACTORY, DEVICE_ID, CHAIN_SEQ, VERSION_NO, FIRST_LAYER_ID, SECOND_LAYER_ID | F13: =COUNTA(TQP_GDS_CHAIN_RULE!B9:B15) -> 7 | G13: TQP_GDS_LAYER, TQP_GDS_CHAIN_VER | I13: TQP_GDS_CHAIN_RULE.xml | J13: 2026-10-02_tqp_gds_schema_device.sql (생성) 2026-10-02_tqp_gds_fk_delete_rule.sql (변경)
A14: 11 | B14: GDS Chain | C14: TQP_GDS_CHAIN_EDIT | D14: 도형 수동 추가 / 제외 / 복원 이력. 다시 탐색할 때 엔지니어가 정한 내용을 다시 적용한다. | E14: FACTORY, DEVICE_ID, CHAIN_SEQ, VERSION_NO, EDIT_SEQ | F14: =COUNTA(TQP_GDS_CHAIN_EDIT!B9:B18) -> 10 | G14: TQP_GDS_PLACED_EL, TQP_GDS_CHAIN_VER | I14: TQP_GDS_CHAIN_EDIT.xml | J14: 2026-10-02_tqp_gds_schema_device.sql (생성) 2026-10-02_tqp_gds_fk_delete_rule.sql (변경)
A15: 12 | B15: E-Test | C15: TQP_GDS_SRC_FILE | D15: E-Test 결과 파일 1개 = 1행. 파일명 해석 값 / 적재 건수 / Spec 판정 결과 / Map 좌표 계산 / YMS 반영 상태를 관리한다. | E15: SRC_FILE_SEQ | F15: =COUNTA(TQP_GDS_SRC_FILE!B9:B50) -> 42 | H15: TQP_GDS_ET_DIE | I15: TQP_GDS_SRC_FILE.xml | J15: 2026-10-07_tqp_gds_src_file.sql (생성) 2026-10-07_tqp_gds_et_result.sql (변경) 2026-10-07_tqp_gds_src_file_uq_wafer.sql (변경) 2026-10-12_tqp_gds_src_file_name_rule.sql (변경) 2026-10-12_tqp_gds_src_file_uq_wafer_test.sql (변경) 2026-10-14_tqp_gds_et_upload_registered.sql (변경) 2026-10-14_tqp_gds_et_yms.sql (변경)
A16: 13 | B16: E-Test | C16: TQP_GDS_ET_ITEM | D16: E-Test 측정 항목(Parameter) 마스터. Device + 공정 단위 등록 Parameter 와 GDS Chain 이름 연결을 관리한다. | E16: ET_ITEM_SEQ | F16: =COUNTA(TQP_GDS_ET_ITEM!B9:B34) -> 26 | H16: TQP_GDS_ET_LIMIT, TQP_GDS_ET_VALUE | I16: TQP_GDS_ET_ITEM.xml | J16: 2026-10-07_tqp_gds_et_result.sql (생성) 2026-10-14_tqp_gds_et_para_rep_chain.sql (변경) 2026-10-14_tqp_gds_et_upload_registered.sql (변경) 2026-10-14_tqp_gds_et_para_gds_chain.sql (변경)
A17: 14 | B17: E-Test | C17: TQP_GDS_ET_DIE | D17: E-Test Die 정보 (파일 행 단위). 원본 좌표 / Bin / DUT Flag / Map 좌표 / Spec 판정. | E17: SRC_FILE_SEQ, DUT_NO | F17: =COUNTA(TQP_GDS_ET_DIE!B9:B24) -> 16 | G17: TQP_GDS_SRC_FILE | H17: TQP_GDS_ET_VALUE | I17: TQP_GDS_ET_DIE.xml | J17: 2026-10-07_tqp_gds_et_result.sql (생성) 2026-10-14_tqp_gds_et_upload_registered.sql (변경)
A18: 15 | B18: E-Test | C18: TQP_GDS_ET_VALUE | D18: E-Test 측정값 (Die x 측정 항목). | E18: SRC_FILE_SEQ, DUT_NO, ET_ITEM_SEQ | F18: =COUNTA(TQP_GDS_ET_VALUE!B9:B14) -> 6 | G18: TQP_GDS_ET_DIE, TQP_GDS_ET_ITEM | I18: TQP_GDS_ET_VALUE.xml | J18: 2026-10-07_tqp_gds_et_result.sql (생성) 2026-10-14_tqp_gds_et_upload_registered.sql (변경)
A19: 16 | B19: E-Test | C19: TQP_GDS_ET_LIMIT | D19: E-Test Spec (하한 / 상한 / 사용 여부). Device + 공정 + 등록 Parameter 단위. | E19: FACTORY, DEVICE_ID, TEST_PROGRAM, ITEM_NAME | F19: =COUNTA(TQP_GDS_ET_LIMIT!B9:B22) -> 14 | G19: TQP_GDS_ET_ITEM | I19: TQP_GDS_ET_LIMIT.xml | J19: 2026-10-12_tqp_gds_et_limit_item.sql (생성) 2026-10-14_tqp_gds_et_limit_fk.sql (변경)
E20: 합계 | F20: =SUM(F4:F19) -> 221

Sheet TQP_GDS_MAP
A1: 테이블 명세서
I2: <- 테이블 목록
A3: 테이블명 | C3: TQP_GDS_MAP | D3: 업무 구분 | E3: GDS Map | G3: 스키마 | H3: DMSMGR
A4: 테이블 설명 | C4: GDS Map 헤더. Factory + Device 당 1건으로 GDS 파일 / Top Structure / 단위 / 저장 상태 / 좌표 기준면(Front / Back)을 관리한다.
A5: 기본 키 (PK) | C5: PK_GDS_MAP (FACTORY, DEVICE_ID) | D5: 컬럼 수 | E5: =COUNTA(B9:B22) -> 14 | G5: Query XML | H5: TQP_GDS_MAP.xml
A6: 생성 / 변경 SQL | C6: 2026-10-02_tqp_gds_schema_device.sql (생성) 2026-10-06_tqp_gds_map_sha_nullable.sql (변경) 2026-10-06_tqp_gds_map_view_side.sql (변경) 2026-10-08_tqp_gds_map_drop_sha.sql (변경) 2026-10-12_tqp_gds_source_el_drop.sql (변경)
A8: No | B8: 컬럼명 | C8: 컬럼 설명 | D8: 데이터 타입 | E8: NULL | F8: PK | G8: FK 참조 | H8: 기본값 | I8: 허용 값
A9: 1 | B9: FACTORY | C9: Factory (로그인 Factory, 예: SCK) | D9: VARCHAR2(30 CHAR) | E9: N | F9: 1
A10: 2 | B10: DEVICE_ID | C10: Device(제품) ID. Factory + Device 당 Map 1건 (KLARF Product / E-Test Device 와 이름으로 연결) | D10: VARCHAR2(50 CHAR) | E10: N | F10: 2
A11: 3 | B11: TOP_STRUCTURE | C11: GDS Top Structure 이름 (도형을 펼친 기준 Structure) | D11: VARCHAR2(256 CHAR) | E11: N
A12: 4 | B12: GDS_FILE_NAME | C12: 원본 GDS 파일 이름 | D12: VARCHAR2(260 CHAR) | E12: Y
A13: 5 | B13: USER_UNIT | C13: GDS User Unit (HEADER UNITS 의 첫째 값) | D13: BINARY_DOUBLE | E13: N
A14: 6 | B14: DATABASE_UNIT | C14: GDS Database Unit, 미터 단위 (HEADER UNITS 의 둘째 값) | D14: BINARY_DOUBLE | E14: N
A15: 7 | B15: ID_GENERATOR_VERSION | C15: 도형 ID(PLACED_ELEMENT_ID) 생성 규칙 버전 | D15: NUMBER(6) | E15: N | H15: 1
A16: 8 | B16: POINTS_FORMAT_VERSION | C16: 좌표 배열(TQP_GDS_PLACED_EL.POINTS_BIN) 형식 버전 | D16: NUMBER(6) | E16: N | H16: 1
A17: 9 | B17: MAP_STATUS | C17: 저장 상태. DRAFT = 저장 중 / READY = 저장 완료 (조회 / Chain / 연관 분석은 READY 만 사용) | D17: VARCHAR2(20) | E17: N | H17: 'DRAFT' | I17: DRAFT / READY
A18: 10 | B18: CREATE_USER | C18: 생성 사용자 ID | D18: VARCHAR2(30) | E18: Y
A19: 11 | B19: CREATE_TIME | C19: 생성 일시 | D19: DATE | E19: N | H19: SYSDATE
A20: 12 | B20: UPDATE_USER | C20: 수정 사용자 ID | D20: VARCHAR2(30) | E20: Y
A21: 13 | B21: UPDATE_TIME | C21: 수정 일시 (Service 가 저장할 때 기록) | D21: DATE | E21: Y
A22: 14 | B22: VIEW_SIDE | C22: PLACED 좌표 기준: FRONT = GDS 원본, BACK = GDS 원점 기준 좌우 반전(X' = -X) | D22: VARCHAR2(10) | E22: N | H22: 'FRONT' | I22: FRONT / BACK
A24: 제약 조건
A25: No | B25: 구분 | C25: 제약 이름 | D25: 컬럼 | G25: 내용
A26: 1 | B26: PK | C26: PK_GDS_MAP | D26: FACTORY, DEVICE_ID | G26: 기본 키
A27: 2 | B27: CHECK | C27: CK_GDS_MAP_FMT | G27: ID_GENERATOR_VERSION > 0 AND POINTS_FORMAT_VERSION > 0
A28: 3 | B28: CHECK | C28: CK_GDS_MAP_STATUS | G28: MAP_STATUS IN ('DRAFT','READY')
A29: 4 | B29: CHECK | C29: CK_GDS_MAP_VIEW_SIDE | G29: VIEW_SIDE IN ('FRONT', 'BACK')
A31: 인덱스
A32: No | B32: 유일 | C32: 인덱스 이름 | D32: 컬럼 / 식 | G32: 용도
A33: 1 | B33: UNIQUE | C33: PK_GDS_MAP | D33: FACTORY, DEVICE_ID | G33: 기본 키

Sheet TQP_GDS_LAYER
A1: 테이블 명세서
I2: <- 테이블 목록
A3: 테이블명 | C3: TQP_GDS_LAYER | D3: 업무 구분 | E3: GDS Map | G3: 스키마 | H3: DMSMGR
A4: 테이블 설명 | C4: GDS Map 의 Layer 정의 (Layer 번호 / 기본 색 / 표시 이름).
A5: 기본 키 (PK) | C5: PK_GDS_LAYER (FACTORY, DEVICE_ID, LAYER_ID) | D5: 컬럼 수 | E5: =COUNTA(B9:B13) -> 5 | G5: Query XML | H5: TQP_GDS_LAYER.xml
A6: 생성 / 변경 SQL | C6: 2026-10-02_tqp_gds_schema_device.sql (생성)
A8: No | B8: 컬럼명 | C8: 컬럼 설명 | D8: 데이터 타입 | E8: NULL | F8: PK | G8: FK 참조 | H8: 기본값 | I8: 허용 값
A9: 1 | B9: FACTORY | C9: Factory (로그인 Factory, 예: SCK) | D9: VARCHAR2(30 CHAR) | E9: N | F9: 1 | G9: TQP_GDS_MAP
A10: 2 | B10: DEVICE_ID | C10: Device(제품) ID. TQP_GDS_MAP 의 Device | D10: VARCHAR2(50 CHAR) | E10: N | F10: 2 | G10: TQP_GDS_MAP
A11: 3 | B11: LAYER_ID | C11: GDS Layer 번호 | D11: NUMBER(10) | E11: N | F11: 3
A12: 4 | B12: COLOR_ARGB | C12: 기본 표시 색 (ARGB 정수) | D12: NUMBER(10) | E12: N
A13: 5 | B13: DISPLAY_NAME | C13: Layer 표시 이름 | D13: VARCHAR2(100 CHAR) | E13: Y
A15: 제약 조건
A16: No | B16: 구분 | C16: 제약 이름 | D16: 컬럼 | G16: 내용
A17: 1 | B17: PK | C17: PK_GDS_LAYER | D17: FACTORY, DEVICE_ID, LAYER_ID | G17: 기본 키
A18: 2 | B18: FK | C18: FK_GDS_LAYER_MAP | D18: FACTORY, DEVICE_ID | G18: -> TQP_GDS_MAP (FACTORY, DEVICE_ID) / 삭제 규칙 CASCADE (부모 삭제 시 함께 삭제)
A20: 인덱스
A21: No | B21: 유일 | C21: 인덱스 이름 | D21: 컬럼 / 식 | G21: 용도
A22: 1 | B22: UNIQUE | C22: PK_GDS_LAYER | D22: FACTORY, DEVICE_ID, LAYER_ID | G22: 기본 키

Sheet TQP_GDS_PLACED_EL
A1: 테이블 명세서
I2: <- 테이블 목록
A3: 테이블명 | C3: TQP_GDS_PLACED_EL | D3: 업무 구분 | E3: GDS Map | G3: 스키마 | H3: DMSMGR
A4: 테이블 설명 | C4: 반복 배치(SREF)를 펼친 실제 도형. 월드 좌표 / Bounds / 좌표 배열 / TEXT 를 저장하며 Map 화면 / Chain / Label 검색 / 연관 분석이 함께 쓴다.
A5: 기본 키 (PK) | C5: PK_GDS_PLACED_EL (FACTORY, DEVICE_ID, PLACED_ELEMENT_ID) | D5: 컬럼 수 | E5: =COUNTA(B9:B30) -> 22 | G5: Query XML | H5: TQP_GDS_PLACED_EL.xml
A6: 생성 / 변경 SQL | C6: 2026-10-02_tqp_gds_schema_device.sql (생성) 2026-10-02_tqp_gds_fk_delete_rule.sql (변경) 2026-10-12_tqp_gds_source_el_drop.sql (변경)
A8: No | B8: 컬럼명 | C8: 컬럼 설명 | D8: 데이터 타입 | E8: NULL | F8: PK | G8: FK 참조 | H8: 기본값 | I8: 허용 값
A9: 1 | B9: FACTORY | C9: Factory (로그인 Factory, 예: SCK) | D9: VARCHAR2(30 CHAR) | E9: N | F9: 1 | G9: TQP_GDS_LAYER
A10: 2 | B10: DEVICE_ID | C10: Device(제품) ID. TQP_GDS_MAP 의 Device | D10: VARCHAR2(50 CHAR) | E10: N | F10: 2 | G10: TQP_GDS_LAYER
A11: 3 | B11: PLACED_ELEMENT_ID | C11: 배치 도형 ID. 펼친 배치 경로 + 원본 순번 (예: R0/E15921). Factory + Device 안에서 고유 | D11: VARCHAR2(1024) | E11: N | F11: 3
A12: 4 | B12: SOURCE_ELEMENT_ID | C12: 원본 Element ID (예: TOP/E15921). 같은 원본에서 반복 배치된 도형을 묶는 값 (원본 테이블은 2026-10-12 삭제, FK 없음) | D12: VARCHAR2(512 CHAR) | E12: N
A13: 5 | B13: LAYER_ID | C13: GDS Layer 번호 (TQP_GDS_LAYER) | D13: NUMBER(10) | E13: N | G13: TQP_GDS_LAYER
A14: 6 | B14: DATA_TYPE | C14: GDS DATATYPE 번호 | D14: NUMBER(10) | E14: N
A15: 7 | B15: ELEMENT_TYPE | C15: 도형 종류 | D15: VARCHAR2(20) | E15: N | I15: BOUNDARY / PATH / TEXT
A16: 8 | B16: CLOSED_FLAG | C16: 닫힌 도형 여부 (1 = 닫힘) | D16: NUMBER(1) | E16: N | I16: 0 / 1
A17: 9 | B17: PATH_WIDTH | C17: PATH 폭 (PATH 도형만) | D17: BINARY_DOUBLE | E17: Y
A18: 10 | B18: PATH_TYPE | C18: GDS PATHTYPE (PATH 도형만, 그 밖에는 NULL) | D18: NUMBER(3) | E18: Y
A19: 11 | B19: MIN_X | C19: 도형 외곽 최소 X (월드 좌표) | D19: BINARY_DOUBLE | E19: N
A20: 12 | B20: MIN_Y | C20: 도형 외곽 최소 Y (월드 좌표) | D20: BINARY_DOUBLE | E20: N
A21: 13 | B21: MAX_X | C21: 도형 외곽 최대 X (월드 좌표) | D21: BINARY_DOUBLE | E21: N
A22: 14 | B22: MAX_Y | C22: 도형 외곽 최대 Y (월드 좌표) | D22: BINARY_DOUBLE | E22: N
A23: 15 | B23: POINT_COUNT | C23: 좌표 점 개수 | D23: NUMBER(12) | E23: N
A24: 16 | B24: POINTS_FORMAT_VERSION | C24: 좌표 배열(POINTS_BIN) 형식 버전 | D24: NUMBER(6) | E24: N
A25: 17 | B25: POINTS_BIN | C25: 좌표 배열. 점마다 X / Y double 2개 (little-endian 16 byte) | D25: BLOB | E25: N
A26: 18 | B26: TEXT_VALUE | C26: TEXT 문자열 (TEXT 도형만) | D26: CLOB | E26: Y
A27: 19 | B27: TEXT_TYPE | C27: GDS TEXTTYPE 번호 (TEXT 도형만) | D27: NUMBER(10) | E27: Y
A28: 20 | B28: TEXT_FONT | C28: GDS TEXT 글꼴 번호 (TEXT 도형만) | D28: NUMBER(10) | E28: Y
... A30: 22 | B30: TEXT_VERTICAL | C30: TEXT 세로 정렬 (예: Middle) | D30: VARCHAR2(20) | E30: Y
A32: 제약 조건
A33: No | B33: 구분 | C33: 제약 이름 | D33: 컬럼 | G33: 내용
A34: 1 | B34: PK | C34: PK_GDS_PLACED_EL | D34: FACTORY, DEVICE_ID, PLACED_ELEMENT_ID | G34: 기본 키
A35: 2 | B35: FK | C35: FK_GDS_PLACED_LAYER | D35: FACTORY, DEVICE_ID, LAYER_ID | G35: -> TQP_GDS_LAYER (FACTORY, DEVICE_ID, LAYER_ID) / 삭제 규칙 NO ACTION (자식이 있으면 부모 삭제 불가)
A36: 3 | B36: CHECK | C36: CK_GDS_PLACED_BOUNDS | G36: MIN_X <= MAX_X AND MIN_Y <= MAX_Y
A37: 4 | B37: CHECK | C37: CK_GDS_PLACED_CLOSED | G37: CLOSED_FLAG IN (0,1)
A38: 5 | B38: CHECK | C38: CK_GDS_PLACED_PATHTYPE | G38: (ELEMENT_TYPE = 'PATH' AND PATH_TYPE BETWEEN 0 AND 255) OR (ELEMENT_TYPE <> 'PATH' AND PATH_TYPE IS NULL)
A39: 6 | B39: CHECK | C39: CK_GDS_PLACED_POINTS | G39: POINT_COUNT > 0 AND POINTS_FORMAT_VERSION > 0
A40: 7 | B40: CHECK | C40: CK_GDS_PLACED_TYPE | G40: ELEMENT_TYPE IN ('BOUNDARY','PATH','TEXT')
A42: 인덱스
A43: No | B43: 유일 | C43: 인덱스 이름 | D43: 컬럼 / 식 | G43: 용도
A44: 1 | B44: - | C44: IX_GDS_PLACED_LAYER | D44: FACTORY, DEVICE_ID, LAYER_ID, PLACED_ELEMENT_ID | G44: Layer 별 도형 순차 조회
...

Sheet TQP_GDS_IMPORT_JOB
A1: 테이블 명세서
I2: <- 테이블 목록
A3: 테이블명 | C3: TQP_GDS_IMPORT_JOB | D3: 업무 구분 | E3: GDS Map | G3: 스키마 | H3: DMSMGR
A4: 테이블 설명 | C4: GDS Map 대량 저장 작업. Device 당 1건으로 예상 / 수신 건수와 진행 상태를 관리한다.
A5: 기본 키 (PK) | C5: PK_GDS_IMPORT_JOB (IMPORT_JOB_SEQ) | D5: 컬럼 수 | E5: =COUNTA(B9:B20) -> 12 | G5: Query XML | H5: TQP_GDS_IMPORT_JOB.xml
A6: 생성 / 변경 SQL | C6: 2026-10-02_tqp_gds_schema_device.sql (생성) 2026-10-12_tqp_gds_source_el_drop.sql (변경)
A8: No | B8: 컬럼명 | C8: 컬럼 설명 | D8: 데이터 타입 | E8: NULL | F8: PK | G8: FK 참조 | H8: 기본값 | I8: 허용 값
A9: 1 | B9: IMPORT_JOB_SEQ | C9: Map 저장 작업 번호 (IMPORT_JOB_SEQ 시퀀스) | D9: NUMBER | E9: N | F9: 1
A10: 2 | B10: FACTORY | C10: Factory (로그인 Factory, 예: SCK) | D10: VARCHAR2(30 CHAR) | E10: N | G10: TQP_GDS_MAP
A11: 3 | B11: DEVICE_ID | C11: Device(제품) ID. Device 당 작업 1건 (UQ_GDS_IMPORT_MAP) | D11: VARCHAR2(50 CHAR) | E11: N | G11: TQP_GDS_MAP
A12: 4 | B12: JOB_STATUS | C12: 작업 상태. UPLOADING = 전송 중 / VALIDATING = 검증 중 / READY = 완료 / FAILED = 실패 / CANCELLED = 취소 | D12: VARCHAR2(20) | E12: N | H12: 'UPLOADING' | I12: UPLOADING / VALIDATING / READY / FAILED / CANCELLED
A13: 5 | B13: EXPECTED_PLACED_COUNT | C13: 보낼 예정인 도형 수 | D13: NUMBER(12) | E13: N
A14: 6 | B14: EXPECTED_POINT_COUNT | C14: 보낼 예정인 좌표 점 수 | D14: NUMBER(18) | E14: N
A15: 7 | B15: RECEIVED_PLACED_COUNT | C15: 받은 도형 수 | D15: NUMBER(12) | E15: N | H15: 0
A16: 8 | B16: RECEIVED_POINT_COUNT | C16: 받은 좌표 점 수 | D16: NUMBER(18) | E16: N | H16: 0
A17: 9 | B17: CREATE_USER | C17: 생성 사용자 ID | D17: VARCHAR2(30) | E17: Y
A18: 10 | B18: CREATE_TIME | C18: 생성 일시 | D18: DATE | E18: N | H18: SYSDATE
A19: 11 | B19: UPDATE_USER | C19: 수정 사용자 ID | D19: VARCHAR2(30) | E19: Y
A20: 12 | B20: UPDATE_TIME | C20: 수정 일시 (진행 상태가 바뀔 때 기록) | D20: DATE | E20: N | H20: SYSDATE
A22: 제약 조건
A23: No | B23: 구분 | C23: 제약 이름 | D23: 컬럼 | G23: 내용
A24: 1 | B24: PK | C24: PK_GDS_IMPORT_JOB | D24: IMPORT_JOB_SEQ | G24: 기본 키
A25: 2 | B25: UNIQUE | C25: UQ_GDS_IMPORT_MAP | D25: FACTORY, DEVICE_ID | G25: 중복 금지
A26: 3 | B26: FK | C26: FK_GDS_IMPORT_MAP | D26: FACTORY, DEVICE_ID | G26: -> TQP_GDS_MAP (FACTORY, DEVICE_ID) / 삭제 규칙 CASCADE (부모 삭제 시 함께 삭제)
A27: 4 | B27: CHECK | C27: CK_GDS_IMPORT_COUNTS | G27: EXPECTED_PLACED_COUNT >= 0 AND EXPECTED_POINT_COUNT >= 0 AND RECEIVED_PLACED_COUNT >= 0 AND RECEIVED_POINT_COUNT >= 0
A28: 5 | B28: CHECK | C28: CK_GDS_IMPORT_STATUS | G28: JOB_STATUS IN ('UPLOADING','VALIDATING','READY','FAILED','CANCELLED')
A30: 인덱스
A31: No | B31: 유일 | C31: 인덱스 이름 | D31: 컬럼 / 식 | G31: 용도
A32: 1 | B32: UNIQUE | C32: PK_GDS_IMPORT_JOB | D32: IMPORT_JOB_SEQ | G32: 기본 키
A33: 2 | B33: UNIQUE | C33: UQ_GDS_IMPORT_MAP | D33: FACTORY, DEVICE_ID | G33: 중복 금지 (UNIQUE 제약)

Sheet TQP_GDS_IMPORT_BATCH
A1: 테이블 명세서
I2: <- 테이블 목록
A3: 테이블명 | C3: TQP_GDS_IMPORT_BATCH | D3: 업무 구분 | E3: GDS Map | G3: 스키마 | H3: DMSMGR
A4: 테이블 설명 | C4: Map 저장 작업의 배치 전송 기록 (Layer / 배치 도형). 중복 전송 판정과 완료 확인에 쓴다.
A5: 기본 키 (PK) | C5: PK_GDS_IMPORT_BATCH (IMPORT_JOB_SEQ, STREAM_KIND, BATCH_NO) | D5: 컬럼 수 | E5: =COUNTA(B9:B17) -> 9 | G5: Query XML | H5: TQP_GDS_IMPORT_BATCH.xml
A6: 생성 / 변경 SQL | C6: 2026-10-02_tqp_gds_schema_device.sql (생성) 2026-10-12_tqp_gds_source_el_drop.sql (변경)
A8: No | B8: 컬럼명 | C8: 컬럼 설명 | D8: 데이터 타입 | E8: NULL | F8: PK | G8: FK 참조 | H8: 기본값 | I8: 허용 값
A9: 1 | B9: IMPORT_JOB_SEQ | C9: Map 저장 작업 번호 (TQP_GDS_IMPORT_JOB) | D9: NUMBER | E9: N | F9: 1 | G9: TQP_GDS_IMPORT_JOB
A10: 2 | B10: STREAM_KIND | C10: 배치 종류. LAYER = Layer / PLACED = 배치 도형 | D10: VARCHAR2(10) | E10: N | F10: 2 | I10: LAYER / PLACED
A11: 3 | B11: BATCH_NO | C11: 배치 번호 (종류별 0부터 빠짐없이) | D11: NUMBER(12) | E11: N | F11: 3
A12: 4 | B12: FORMAT_VERSION | C12: 전송 배치 형식 버전 | D12: NUMBER(6) | E12: N
A13: 5 | B13: PAYLOAD_SHA256 | C13: 배치 내용 SHA-256 (16진수 64자리). 같은 번호를 다시 받으면 이 값으로 같은 배치인지 비교 | D13: CHAR(64) | E13: N
A14: 6 | B14: ITEM_COUNT | C14: 배치 안 행 수 | D14: NUMBER(12) | E14: N
A15: 7 | B15: POINT_COUNT | C15: 배치 안 좌표 점 수 | D15: NUMBER(18) | E15: N
A16: 8 | B16: PAYLOAD_BYTES | C16: 배치 크기 (byte) | D16: NUMBER(18) | E16: N
A17: 9 | B17: COMMIT_TIME | C17: 배치 저장 확정 일시 | D17: DATE | E17: N | H17: SYSDATE
A19: 제약 조건
A20: No | B20: 구분 | C20: 제약 이름 | D20: 컬럼 | G20: 내용
A21: 1 | B21: PK | C21: PK_GDS_IMPORT_BATCH | D21: IMPORT_JOB_SEQ, STREAM_KIND, BATCH_NO | G21: 기본 키
A22: 2 | B22: FK | C22: FK_GDS_IMPORT_BATCH_JOB | D22: IMPORT_JOB_SEQ | G22: -> TQP_GDS_IMPORT_JOB (IMPORT_JOB_SEQ) / 삭제 규칙 CASCADE (부모 삭제 시 함께 삭제)
A23: 3 | B23: CHECK | C23: CK_GDS_IMPORT_BATCH_NUM | G23: BATCH_NO >= 0 AND FORMAT_VERSION > 0 AND ITEM_COUNT > 0 AND POINT_COUNT >= 0 AND PAYLOAD_BYTES > 0
A24: 4 | B24: CHECK | C24: CK_GDS_IMPORT_STREAM | G24: STREAM_KIND IN ('LAYER','PLACED')
A26: 인덱스
A27: No | B27: 유일 | C27: 인덱스 이름 | D27: 컬럼 / 식 | G27: 용도
A28: 1 | B28: UNIQUE | C28: PK_GDS_IMPORT_BATCH | D28: IMPORT_JOB_SEQ, STREAM_KIND, BATCH_NO | G28: 기본 키

Sheet TQP_GDS_CHAIN
A1: 테이블 명세서
I2: <- 테이블 목록
A3: 테이블명 | C3: TQP_GDS_CHAIN | D3: 업무 구분 | E3: GDS Chain | G3: 스키마 | H3: DMSMGR
A4: 테이블 설명 | C4: Chain 마스터. Chain 번호 / Code / 사용 상태를 관리한다.
A5: 기본 키 (PK) | C5: PK_GDS_CHAIN (FACTORY, DEVICE_ID, CHAIN_SEQ) | D5: 컬럼 수 | E5: =COUNTA(B9:B18) -> 10 | G5: Query XML | H5: TQP_GDS_CHAIN.xml
A6: 생성 / 변경 SQL | C6: 2026-10-02_tqp_gds_schema_device.sql (생성)
A8: No | B8: 컬럼명 | C8: 컬럼 설명 | D8: 데이터 타입 | E8: NULL | F8: PK | G8: FK 참조 | H8: 기본값 | I8: 허용 값
A9: 1 | B9: FACTORY | C9: Factory (로그인 Factory, 예: SCK) | D9: VARCHAR2(30 CHAR) | E9: N | F9: 1 | G9: TQP_GDS_MAP
A10: 2 | B10: DEVICE_ID | C10: Device(제품) ID. TQP_GDS_MAP 의 Device | D10: VARCHAR2(50 CHAR) | E10: N | F10: 2 | G10: TQP_GDS_MAP
A11: 3 | B11: CHAIN_SEQ | C11: Chain 번호 (CHAIN_SEQ 시퀀스). 다시 저장해도 유지 | D11: NUMBER | E11: N | F11: 3
A12: 4 | B12: CHAIN_CODE | C12: Chain Code (A, B, ... Z, AA ...). Device 안에서 고유 | D12: VARCHAR2(32 CHAR) | E12: N
A13: 5 | B13: CHAIN_STATUS | C13: Chain 상태. ACTIVE = 사용 / RETIRED = 사용 종료 (논리 삭제) | D13: VARCHAR2(20) | E13: N | H13: 'ACTIVE' | I13: ACTIVE / RETIRED
A14: 6 | B14: CREATE_USER | C14: 생성 사용자 ID | D14: VARCHAR2(30) | E14: Y
A15: 7 | B15: CREATE_TIME | C15: 생성 일시 | D15: DATE | E15: N | H15: SYSDATE
A16: 8 | B16: RETIRE_TIME | C16: 사용 종료 (RETIRED) 일시 | D16: DATE | E16: Y
A17: 9 | B17: UPDATE_USER | C17: 수정 사용자 ID | D17: VARCHAR2(30) | E17: Y
A18: 10 | B18: UPDATE_TIME | C18: 수정 일시 (Service 가 저장할 때 기록) | D18: DATE | E18: Y
A20: 제약 조건
A21: No | B21: 구분 | C21: 제약 이름 | D21: 컬럼 | G21: 내용
A22: 1 | B22: PK | C22: PK_GDS_CHAIN | D22: FACTORY, DEVICE_ID, CHAIN_SEQ | G22: 기본 키
A23: 2 | B23: UNIQUE | C23: UQ_GDS_CHAIN_CODE | D23: FACTORY, DEVICE_ID, CHAIN_CODE | G23: 중복 금지
A24: 3 | B24: FK | C24: FK_GDS_CHAIN_MAP | D24: FACTORY, DEVICE_ID | G24: -> TQP_GDS_MAP (FACTORY, DEVICE_ID) / 삭제 규칙 CASCADE (부모 삭제 시 함께 삭제)
A25: 4 | B25: CHECK | C25: CK_GDS_CHAIN_STATUS | G25: CHAIN_STATUS IN ('ACTIVE','RETIRED')
A27: 인덱스
A28: No | B28: 유일 | C28: 인덱스 이름 | D28: 컬럼 / 식 | G28: 용도
A29: 1 | B29: UNIQUE | C29: PK_GDS_CHAIN | D29: FACTORY, DEVICE_ID, CHAIN_SEQ | G29: 기본 키
A30: 2 | B30: UNIQUE | C30: UQ_GDS_CHAIN_CODE | D30: FACTORY, DEVICE_ID, CHAIN_CODE | G30: 중복 금지 (UNIQUE 제약)

Sheet TQP_GDS_CHAIN_VER
A1: 테이블 명세서
I2: <- 테이블 목록
A3: 테이블명 | C3: TQP_GDS_CHAIN_VER | D3: 업무 구분 | E3: GDS Chain | G3: 스키마 | H3: DMSMGR
A4: 테이블 설명 | C4: Chain 설정 (이름 / 색 / 탐색 옵션)과 저장 상태. 현재는 버전 이력 없이 VERSION_NO = 1 로 덮어쓴다.
A5: 기본 키 (PK) | C5: PK_GDS_CHAIN_VER (FACTORY, DEVICE_ID, CHAIN_SEQ, VERSION_NO) | D5: 컬럼 수 | E5: =COUNTA(B9:B22) -> 14 | G5: Query XML | H5: TQP_GDS_CHAIN_VER.xml
A6: 생성 / 변경 SQL | C6: 2026-10-02_tqp_gds_schema_device.sql (생성)
A8: No | B8: 컬럼명 | C8: 컬럼 설명 | D8: 데이터 타입 | E8: NULL | F8: PK | G8: FK 참조 | H8: 기본값 | I8: 허용 값
A9: 1 | B9: FACTORY | C9: Factory (로그인 Factory, 예: SCK) | D9: VARCHAR2(30 CHAR) | E9: N | F9: 1 | G9: TQP_GDS_CHAIN
A10: 2 | B10: DEVICE_ID | C10: Device(제품) ID. TQP_GDS_MAP 의 Device | D10: VARCHAR2(50 CHAR) | E10: N | F10: 2 | G10: TQP_GDS_CHAIN
A11: 3 | B11: CHAIN_SEQ | C11: Chain 번호 (TQP_GDS_CHAIN) | D11: NUMBER | E11: N | F11: 3 | G11: TQP_GDS_CHAIN
A12: 4 | B12: VERSION_NO | C12: Chain 버전 번호. 현재는 저장할 때 덮어써서 1 고정 | D12: NUMBER(10) | E12: N | F12: 4 | I12: > 0
A13: 5 | B13: CHAIN_NAME | C13: Chain 이름 (E-Test Para 설정의 GDS Chain 이름과 연결) | D13: VARCHAR2(200 CHAR) | E13: N
A14: 6 | B14: COLOR_ARGB | C14: Chain 표시 색 (ARGB 정수) | D14: NUMBER(10) | E14: N
A15: 7 | B15: APPLY_LAYER_RULES | C15: Layer 조합 규칙(TQP_GDS_CHAIN_RULE) 적용 여부 (1 = 적용) | D15: NUMBER(1) | E15: N | H15: 0 | I15: 0 / 1
A16: 8 | B16: CELL_SIZE | C16: 연결 탐색 격자 크기 (화면에서 숨김, 기본 10) | D16: NUMBER(18,4) | E16: N | I16: > 0
A17: 9 | B17: VERSION_STATUS | C17: 저장 상태. DRAFT = 저장 중 / READY = 저장 완료 / SUPERSEDED = 이전 버전 | D17: VARCHAR2(20) | E17: N | H17: 'DRAFT' | I17: DRAFT / READY / SUPERSEDED
A18: 10 | B18: IS_CURRENT | C18: 현재 버전 여부 (1 = 현재). READY 일 때만 1, Chain 당 최대 1개 | D18: NUMBER(1) | E18: N | H18: 0 | I18: 0 / 1
A19: 11 | B19: CREATE_USER | C19: 생성 사용자 ID | D19: VARCHAR2(30) | E19: Y
A20: 12 | B20: CREATE_TIME | C20: 생성 일시 | D20: DATE | E20: N | H20: SYSDATE
A21: 13 | B21: UPDATE_USER | C21: 수정 사용자 ID | D21: VARCHAR2(30) | E21: Y
A22: 14 | B22: UPDATE_TIME | C22: 수정 일시 (Service 가 저장할 때 기록) | D22: DATE | E22: Y
A24: 제약 조건
A25: No | B25: 구분 | C25: 제약 이름 | D25: 컬럼 | G25: 내용
A26: 1 | B26: PK | C26: PK_GDS_CHAIN_VER | D26: FACTORY, DEVICE_ID, CHAIN_SEQ, VERSION_NO | G26: 기본 키
A27: 2 | B27: FK | C27: FK_GDS_CHAIN_VER_MASTER | D27: FACTORY, DEVICE_ID, CHAIN_SEQ | G27: -> TQP_GDS_CHAIN (FACTORY, DEVICE_ID, CHAIN_SEQ) / 삭제 규칙 CASCADE (부모 삭제 시 함께 삭제)
A28: 3 | B28: CHECK | C28: CK_GDS_CHAIN_VER_CELL | G28: CELL_SIZE > 0
A29: 4 | B29: CHECK | C29: CK_GDS_CHAIN_VER_CURRENT | G29: IS_CURRENT IN (0,1) AND (IS_CURRENT = 0 OR VERSION_STATUS = 'READY')
A30: 5 | B30: CHECK | C30: CK_GDS_CHAIN_VER_NO | G30: VERSION_NO > 0
A31: 6 | B31: CHECK | C31: CK_GDS_CHAIN_VER_RULES | G31: APPLY_LAYER_RULES IN (0,1)
A32: 7 | B32: CHECK | C32: CK_GDS_CHAIN_VER_STATUS | G32: VERSION_STATUS IN ('DRAFT','READY','SUPERSEDED')
A34: 인덱스
A35: No | B35: 유일 | C35: 인덱스 이름 | D35: 컬럼 / 식 | G35: 용도
A36: 1 | B36: UNIQUE | C36: PK_GDS_CHAIN_VER | D36: FACTORY, DEVICE_ID, CHAIN_SEQ, VERSION_NO | G36: 기본 키
A37: 2 | B37: UNIQUE | C37: UX_GDS_CHAIN_CURRENT | D37: IS_CURRENT = 1 인 행만: FACTORY, DEVICE_ID, CHAIN_SEQ | G37: Chain 당 현재 버전 최대 1개 (함수 기반 UNIQUE)

Sheet TQP_GDS_CHAIN_MEMBER
A1: 테이블 명세서
I2: <- 테이블 목록
A3: 테이블명 | C3: TQP_GDS_CHAIN_MEMBER | D3: 업무 구분 | E3: GDS Chain | G3: 스키마 | H3: DMSMGR
A4: 테이블 설명 | C4: Chain 에 포함된 도형 (Input / Output / Member)과 단자 클릭 위치.
A5: 기본 키 (PK) | C5: PK_GDS_CHAIN_MEMBER (FACTORY, DEVICE_ID, CHAIN_SEQ, VERSION_NO, PLACED_ELEMENT_ID) | D5: 컬럼 수 | E5: =COUNTA(B9:B17) -> 9 | G5: Query XML | H5: TQP_GDS_CHAIN_MEMBER.xml
A6: 생성 / 변경 SQL | C6: 2026-10-02_tqp_gds_schema_device.sql (생성) 2026-10-02_tqp_gds_fk_delete_rule.sql (변경)
A8: No | B8: 컬럼명 | C8: 컬럼 설명 | D8: 데이터 타입 | E8: NULL | F8: PK | G8: FK 참조 | H8: 기본값 | I8: 허용 값
A9: 1 | B9: FACTORY | C9: Factory (로그인 Factory, 예: SCK) | D9: VARCHAR2(30 CHAR) | E9: N | F9: 1 | G9: TQP_GDS_PLACED_EL, TQP_GDS_CHAIN_VER
A10: 2 | B10: DEVICE_ID | C10: Device(제품) ID. TQP_GDS_MAP 의 Device | D10: VARCHAR2(50 CHAR) | E10: N | F10: 2 | G10: TQP_GDS_PLACED_EL, TQP_GDS_CHAIN_VER
A11: 3 | B11: CHAIN_SEQ | C11: Chain 번호 (TQP_GDS_CHAIN) | D11: NUMBER | E11: N | F11: 3 | G11: TQP_GDS_CHAIN_VER
A12: 4 | B12: VERSION_NO | C12: Chain 버전 번호 (TQP_GDS_CHAIN_VER, 현재 1 고정) | D12: NUMBER(10) | E12: N | F12: 4 | G12: TQP_GDS_CHAIN_VER
A13: 5 | B13: PLACED_ELEMENT_ID | C13: Chain 에 포함된 도형 ID (TQP_GDS_PLACED_EL). 한 도형이 여러 Chain 에 속할 수 있음 | D13: VARCHAR2(1024) | E13: N | F13: 5 | G13: TQP_GDS_PLACED_EL
A14: 6 | B14: ROLE_CODE | C14: 도형 역할. INPUT = 입력 단자 (1개 필수) / OUTPUT = 출력 단자 (0~1개) / MEMBER = 연결 도형 | D14: VARCHAR2(10) | E14: N | I14: INPUT / OUTPUT
A15: 7 | B15: INCLUSION_SOURCE | C15: 포함 경위. TRACE = 연결 탐색 / MANUAL = 수동 추가 / ENDPOINT = Input / Output 단자 지정 | D15: VARCHAR2(10) | E15: N | I15: TRACE / MANUAL / ENDPOINT
A16: 8 | B16: MARKER_X | C16: 단자 클릭 위치 X (INPUT / OUTPUT 만, MEMBER 는 NULL) | D16: BINARY_DOUBLE | E16: Y
A17: 9 | B17: MARKER_Y | C17: 단자 클릭 위치 Y (INPUT / OUTPUT 만, MEMBER 는 NULL) | D17: BINARY_DOUBLE | E17: Y
A19: 제약 조건
A20: No | B20: 구분 | C20: 제약 이름 | D20: 컬럼 | G20: 내용
A21: 1 | B21: PK | C21: PK_GDS_CHAIN_MEMBER | D21: FACTORY, DEVICE_ID, CHAIN_SEQ, VERSION_NO, PLACED_ELEMENT_ID | G21: 기본 키
A22: 2 | B22: FK | C22: FK_GDS_CHAIN_MEMBER_EL | D22: FACTORY, DEVICE_ID, PLACED_ELEMENT_ID | G22: -> TQP_GDS_PLACED_EL (FACTORY, DEVICE_ID, PLACED_ELEMENT_ID) / 삭제 규칙 NO ACTION (자식이 있으면 부모 삭제 불가)
A23: 3 | B23: FK | C23: FK_GDS_CHAIN_MEMBER_VER | D23: FACTORY, DEVICE_ID, CHAIN_SEQ, VERSION_NO | G23: -> TQP_GDS_CHAIN_VER (FACTORY, DEVICE_ID, CHAIN_SEQ, VERSION_NO) / 삭제 규칙 CASCADE (부모 삭제 시 함께 삭제)
A24: 4 | B24: CHECK | C24: CK_GDS_CHAIN_MEMBER_MARKER | G24: (ROLE_CODE IN ('INPUT','OUTPUT') AND MARKER_X IS NOT NULL AND MARKER_Y IS NOT NULL) OR (ROLE_CODE = 'MEMBER' AND MARKER_X IS NULL AND MARKER_Y IS NULL)
A25: 5 | B25: CHECK | C25: CK_GDS_CHAIN_MEMBER_ROLE | G25: ROLE_CODE IN ('INPUT','OUTPUT','MEMBER')
A26: 6 | B26: CHECK | C26: CK_GDS_CHAIN_MEMBER_SRC | G26: INCLUSION_SOURCE IN ('TRACE','MANUAL','ENDPOINT')
A28: 인덱스
A29: No | B29: 유일 | C29: 인덱스 이름 | D29: 컬럼 / 식 | G29: 용도
A30: 1 | B30: - | C30: IX_GDS_CHAIN_MEMBER_EL | D30: FACTORY, DEVICE_ID, PLACED_ELEMENT_ID, CHAIN_SEQ, VERSION_NO | G30: 도형 -> 소속 Chain 찾기 (연관 분석)
A31: 2 | B31: UNIQUE | C31: PK_GDS_CHAIN_MEMBER | D31: FACTORY, DEVICE_ID, CHAIN_SEQ, VERSION_NO, PLACED_ELEMENT_ID | G31: 기본 키
A32: 3 | B32: UNIQUE | C32: UX_GDS_CHAIN_ENDPOINT | D32: ROLE_CODE 가 INPUT / OUTPUT 인 행만: FACTORY, DEVICE_ID, CHAIN_SEQ, VERSION_NO, ROLE_CODE | G32: Chain 버전당 INPUT 1개 / OUTPUT 최대 1개 (함수 기반 UNIQUE)

Sheet TQP_GDS_CHAIN_LAYER
A1: 테이블 명세서
I2: <- 테이블 목록
A3: 테이블명 | C3: TQP_GDS_CHAIN_LAYER | D3: 업무 구분 | E3: GDS Chain | G3: 스키마 | H3: DMSMGR
A4: 테이블 설명 | C4: Chain 탐색 때 선택한 Layer.
A5: 기본 키 (PK) | C5: PK_GDS_CHAIN_LAYER (FACTORY, DEVICE_ID, CHAIN_SEQ, VERSION_NO, LAYER_ID) | D5: 컬럼 수 | E5: =COUNTA(B9:B13) -> 5 | G5: Query XML | H5: TQP_GDS_CHAIN_LAYER.xml
A6: 생성 / 변경 SQL | C6: 2026-10-02_tqp_gds_schema_device.sql (생성) 2026-10-02_tqp_gds_fk_delete_rule.sql (변경)
A8: No | B8: 컬럼명 | C8: 컬럼 설명 | D8: 데이터 타입 | E8: NULL | F8: PK | G8: FK 참조 | H8: 기본값 | I8: 허용 값
A9: 1 | B9: FACTORY | C9: Factory (로그인 Factory, 예: SCK) | D9: VARCHAR2(30 CHAR) | E9: N | F9: 1 | G9: TQP_GDS_LAYER, TQP_GDS_CHAIN_VER
A10: 2 | B10: DEVICE_ID | C10: Device(제품) ID. TQP_GDS_MAP 의 Device | D10: VARCHAR2(50 CHAR) | E10: N | F10: 2 | G10: TQP_GDS_LAYER, TQP_GDS_CHAIN_VER
A11: 3 | B11: CHAIN_SEQ | C11: Chain 번호 (TQP_GDS_CHAIN) | D11: NUMBER | E11: N | F11: 3 | G11: TQP_GDS_CHAIN_VER
A12: 4 | B12: VERSION_NO | C12: Chain 버전 번호 (TQP_GDS_CHAIN_VER, 현재 1 고정) | D12: NUMBER(10) | E12: N | F12: 4 | G12: TQP_GDS_CHAIN_VER
A13: 5 | B13: LAYER_ID | C13: Chain 탐색 때 선택한 GDS Layer 번호 (TQP_GDS_LAYER) | D13: NUMBER(10) | E13: N | F13: 5 | G13: TQP_GDS_LAYER
A15: 제약 조건
A16: No | B16: 구분 | C16: 제약 이름 | D16: 컬럼 | G16: 내용
A17: 1 | B17: PK | C17: PK_GDS_CHAIN_LAYER | D17: FACTORY, DEVICE_ID, CHAIN_SEQ, VERSION_NO, LAYER_ID | G17: 기본 키
A18: 2 | B18: FK | C18: FK_GDS_CHAIN_LAYER_MAP | D18: FACTORY, DEVICE_ID, LAYER_ID | G18: -> TQP_GDS_LAYER (FACTORY, DEVICE_ID, LAYER_ID) / 삭제 규칙 NO ACTION (자식이 있으면 부모 삭제 불가)
A19: 3 | B19: FK | C19: FK_GDS_CHAIN_LAYER_VER | D19: FACTORY, DEVICE_ID, CHAIN_SEQ, VERSION_NO | G19: -> TQP_GDS_CHAIN_VER (FACTORY, DEVICE_ID, CHAIN_SEQ, VERSION_NO) / 삭제 규칙 CASCADE (부모 삭제 시 함께 삭제)
A21: 인덱스
A22: No | B22: 유일 | C22: 인덱스 이름 | D22: 컬럼 / 식 | G22: 용도
A23: 1 | B23: - | C23: IX_GDS_CHAIN_LAYER_LY | D23: FACTORY, DEVICE_ID, LAYER_ID | G23: Layer -> Chain 찾기 (FK 삭제 검사)
A24: 2 | B24: UNIQUE | C24: PK_GDS_CHAIN_LAYER | D24: FACTORY, DEVICE_ID, CHAIN_SEQ, VERSION_NO, LAYER_ID | G24: 기본 키

Sheet TQP_GDS_CHAIN_RULE
A1: 테이블 명세서
I2: <- 테이블 목록
A3: 테이블명 | C3: TQP_GDS_CHAIN_RULE | D3: 업무 구분 | E3: GDS Chain | G3: 스키마 | H3: DMSMGR
A4: 테이블 설명 | C4: Chain 탐색의 Layer 조합 연결 규칙과 허용 거리.
A5: 기본 키 (PK) | C5: PK_GDS_CHAIN_RULE (FACTORY, DEVICE_ID, CHAIN_SEQ, VERSION_NO, FIRST_LAYER_ID, SECOND_LAYER_ID) | D5: 컬럼 수 | E5: =COUNTA(B9:B15) -> 7 | G5: Query XML | H5: TQP_GDS_CHAIN_RULE.xml
A6: 생성 / 변경 SQL | C6: 2026-10-02_tqp_gds_schema_device.sql (생성) 2026-10-02_tqp_gds_fk_delete_rule.sql (변경)
A8: No | B8: 컬럼명 | C8: 컬럼 설명 | D8: 데이터 타입 | E8: NULL | F8: PK | G8: FK 참조 | H8: 기본값 | I8: 허용 값
A9: 1 | B9: FACTORY | C9: Factory (로그인 Factory, 예: SCK) | D9: VARCHAR2(30 CHAR) | E9: N | F9: 1 | G9: TQP_GDS_LAYER, TQP_GDS_CHAIN_VER
A10: 2 | B10: DEVICE_ID | C10: Device(제품) ID. TQP_GDS_MAP 의 Device | D10: VARCHAR2(50 CHAR) | E10: N | F10: 2 | G10: TQP_GDS_LAYER, TQP_GDS_CHAIN_VER
A11: 3 | B11: CHAIN_SEQ | C11: Chain 번호 (TQP_GDS_CHAIN) | D11: NUMBER | E11: N | F11: 3 | G11: TQP_GDS_CHAIN_VER
A12: 4 | B12: VERSION_NO | C12: Chain 버전 번호 (TQP_GDS_CHAIN_VER, 현재 1 고정) | D12: NUMBER(10) | E12: N | F12: 4 | G12: TQP_GDS_CHAIN_VER
A13: 5 | B13: FIRST_LAYER_ID | C13: 조합 Layer 1 (작은 번호 쪽) | D13: NUMBER(10) | E13: N | F13: 5 | G13: TQP_GDS_LAYER
A14: 6 | B14: SECOND_LAYER_ID | C14: 조합 Layer 2 (큰 번호 쪽) | D14: NUMBER(10) | E14: N | F14: 6 | G14: TQP_GDS_LAYER
A15: 7 | B15: TOLERANCE | C15: 두 Layer 도형을 연결로 볼 허용 거리 (0 이상) | D15: BINARY_DOUBLE | E15: N | I15: >= 0
A17: 제약 조건
A18: No | B18: 구분 | C18: 제약 이름 | D18: 컬럼 | G18: 내용
A19: 1 | B19: PK | C19: PK_GDS_CHAIN_RULE | D19: FACTORY, DEVICE_ID, CHAIN_SEQ, VERSION_NO, FIRST_LAYER_ID, SECOND_LAYER_ID | G19: 기본 키
A20: 2 | B20: FK | C20: FK_GDS_CHAIN_RULE_L1 | D20: FACTORY, DEVICE_ID, FIRST_LAYER_ID | G20: -> TQP_GDS_LAYER (FACTORY, DEVICE_ID, LAYER_ID) / 삭제 규칙 NO ACTION (자식이 있으면 부모 삭제 불가)
A21: 3 | B21: FK | C21: FK_GDS_CHAIN_RULE_L2 | D21: FACTORY, DEVICE_ID, SECOND_LAYER_ID | G21: -> TQP_GDS_LAYER (FACTORY, DEVICE_ID, LAYER_ID) / 삭제 규칙 NO ACTION (자식이 있으면 부모 삭제 불가)
A22: 4 | B22: FK | C22: FK_GDS_CHAIN_RULE_VER | D22: FACTORY, DEVICE_ID, CHAIN_SEQ, VERSION_NO | G22: -> TQP_GDS_CHAIN_VER (FACTORY, DEVICE_ID, CHAIN_SEQ, VERSION_NO) / 삭제 규칙 CASCADE (부모 삭제 시 함께 삭제)
A23: 5 | B23: CHECK | C23: CK_GDS_CHAIN_RULE_PAIR | G23: FIRST_LAYER_ID <= SECOND_LAYER_ID
A24: 6 | B24: CHECK | C24: CK_GDS_CHAIN_RULE_TOL | G24: TOLERANCE >= 0
A26: 인덱스
A27: No | B27: 유일 | C27: 인덱스 이름 | D27: 컬럼 / 식 | G27: 용도
A28: 1 | B28: - | C28: IX_GDS_CHAIN_RULE_L1 | D28: FACTORY, DEVICE_ID, FIRST_LAYER_ID | G28: Layer -> 규칙 찾기 (FK 삭제 검사)
A29: 2 | B29: - | C29: IX_GDS_CHAIN_RULE_L2 | D29: FACTORY, DEVICE_ID, SECOND_LAYER_ID | G29: Layer -> 규칙 찾기 (FK 삭제 검사)
A30: 3 | B30: UNIQUE | C30: PK_GDS_CHAIN_RULE | D30: FACTORY, DEVICE_ID, CHAIN_SEQ, VERSION_NO, FIRST_LAYER_ID, SECOND_LAYER_ID | G30: 기본 키

Sheet TQP_GDS_CHAIN_EDIT
A1: 테이블 명세서
I2: <- 테이블 목록
A3: 테이블명 | C3: TQP_GDS_CHAIN_EDIT | D3: 업무 구분 | E3: GDS Chain | G3: 스키마 | H3: DMSMGR
A4: 테이블 설명 | C4: 도형 수동 추가 / 제외 / 복원 이력. 다시 탐색할 때 엔지니어가 정한 내용을 다시 적용한다.
A5: 기본 키 (PK) | C5: PK_GDS_CHAIN_EDIT (FACTORY, DEVICE_ID, CHAIN_SEQ, VERSION_NO, EDIT_SEQ) | D5: 컬럼 수 | E5: =COUNTA(B9:B18) -> 10 | G5: Query XML | H5: TQP_GDS_CHAIN_EDIT.xml
A6: 생성 / 변경 SQL | C6: 2026-10-02_tqp_gds_schema_device.sql (생성) 2026-10-02_tqp_gds_fk_delete_rule.sql (변경)
A8: No | B8: 컬럼명 | C8: 컬럼 설명 | D8: 데이터 타입 | E8: NULL | F8: PK | G8: FK 참조 | H8: 기본값 | I8: 허용 값
A9: 1 | B9: FACTORY | C9: Factory (로그인 Factory, 예: SCK) | D9: VARCHAR2(30 CHAR) | E9: N | F9: 1 | G9: TQP_GDS_PLACED_EL, TQP_GDS_CHAIN_VER
A10: 2 | B10: DEVICE_ID | C10: Device(제품) ID. TQP_GDS_MAP 의 Device | D10: VARCHAR2(50 CHAR) | E10: N | F10: 2 | G10: TQP_GDS_PLACED_EL, TQP_GDS_CHAIN_VER
A11: 3 | B11: CHAIN_SEQ | C11: Chain 번호 (TQP_GDS_CHAIN) | D11: NUMBER | E11: N | F11: 3 | G11: TQP_GDS_CHAIN_VER
A12: 4 | B12: VERSION_NO | C12: Chain 버전 번호 (TQP_GDS_CHAIN_VER, 현재 1 고정) | D12: NUMBER(10) | E12: N | F12: 4 | G12: TQP_GDS_CHAIN_VER
A13: 5 | B13: EDIT_SEQ | C13: 편집 순번 (1부터, ADD -> EXCLUDE 순서) | D13: NUMBER(12) | E13: N | F13: 5 | I13: > 0
A14: 6 | B14: PLACED_ELEMENT_ID | C14: 편집 대상 도형 ID (TQP_GDS_PLACED_EL) | D14: VARCHAR2(1024) | E14: N | G14: TQP_GDS_PLACED_EL
A15: 7 | B15: ACTION_CODE | C15: 편집 종류. ADD = 수동 추가 / EXCLUDE = 제외 / RESTORE = 제외 취소 | D15: VARCHAR2(10) | E15: N | I15: ADD / EXCLUDE / RESTORE
A16: 8 | B16: BATCH_EDIT_SEQ | C16: 일괄 편집 묶음 번호 (BATCH_EDIT_SEQ 시퀀스, 현재 미사용 NULL) | D16: NUMBER | E16: Y
A17: 9 | B17: CREATE_USER | C17: 생성 사용자 ID | D17: VARCHAR2(30) | E17: Y
A18: 10 | B18: CREATE_TIME | C18: 생성 일시 | D18: DATE | E18: N | H18: SYSDATE
A20: 제약 조건
A21: No | B21: 구분 | C21: 제약 이름 | D21: 컬럼 | G21: 내용
A22: 1 | B22: PK | C22: PK_GDS_CHAIN_EDIT | D22: FACTORY, DEVICE_ID, CHAIN_SEQ, VERSION_NO, EDIT_SEQ | G22: 기본 키
A23: 2 | B23: FK | C23: FK_GDS_CHAIN_EDIT_EL | D23: FACTORY, DEVICE_ID, PLACED_ELEMENT_ID | G23: -> TQP_GDS_PLACED_EL (FACTORY, DEVICE_ID, PLACED_ELEMENT_ID) / 삭제 규칙 NO ACTION (자식이 있으면 부모 삭제 불가)
A24: 3 | B24: FK | C24: FK_GDS_CHAIN_EDIT_VER | D24: FACTORY, DEVICE_ID, CHAIN_SEQ, VERSION_NO | G24: -> TQP_GDS_CHAIN_VER (FACTORY, DEVICE_ID, CHAIN_SEQ, VERSION_NO) / 삭제 규칙 CASCADE (부모 삭제 시 함께 삭제)
A25: 4 | B25: CHECK | C25: CK_GDS_CHAIN_EDIT_ACTION | G25: ACTION_CODE IN ('ADD','EXCLUDE','RESTORE')
A26: 5 | B26: CHECK | C26: CK_GDS_CHAIN_EDIT_SEQ | G26: EDIT_SEQ > 0
A28: 인덱스
A29: No | B29: 유일 | C29: 인덱스 이름 | D29: 컬럼 / 식 | G29: 용도
A30: 1 | B30: - | C30: IX_GDS_CHAIN_EDIT_EL | D30: FACTORY, DEVICE_ID, PLACED_ELEMENT_ID, CHAIN_SEQ, VERSION_NO | G30: 도형 -> 편집 이력 찾기
A31: 2 | B31: UNIQUE | C31: PK_GDS_CHAIN_EDIT | D31: FACTORY, DEVICE_ID, CHAIN_SEQ, VERSION_NO, EDIT_SEQ | G31: 기본 키

Sheet TQP_GDS_SRC_FILE
A1: 테이블 명세서
I2: <- 테이블 목록
A3: 테이블명 | C3: TQP_GDS_SRC_FILE | D3: 업무 구분 | E3: E-Test | G3: 스키마 | H3: DMSMGR
A4: 테이블 설명 | C4: E-Test 결과 파일 1개 = 1행. 파일명 해석 값 / 적재 건수 / Spec 판정 결과 / Map 좌표 계산 / YMS 반영 상태를 관리한다.
A5: 기본 키 (PK) | C5: PK_GDS_SRC_FILE (SRC_FILE_SEQ) | D5: 컬럼 수 | E5: =COUNTA(B9:B50) -> 42 | G5: Query XML | H5: TQP_GDS_SRC_FILE.xml
A6: 생성 / 변경 SQL | C6: 2026-10-07_tqp_gds_src_file.sql (생성) 2026-10-07_tqp_gds_et_result.sql (변경) 2026-10-07_tqp_gds_src_file_uq_wafer.sql (변경) 2026-10-12_tqp_gds_src_file_name_rule.sql (변경) 2026-10-12_tqp_gds_src_file_uq_wafer_test.sql (변경) 2026-10-14_tqp_gds_et_upload_registered.sql (변경) 2026-10-14_tqp_gds_et_yms.sql (변경)
A8: No | B8: 컬럼명 | C8: 컬럼 설명 | D8: 데이터 타입 | E8: NULL | F8: PK | G8: FK 참조 | H8: 기본값 | I8: 허용 값
A9: 1 | B9: SRC_FILE_SEQ | C9: E-Test 파일 번호 (SRC_FILE_SEQ 시퀀스) | D9: NUMBER | E9: N | F9: 1
A10: 2 | B10: FILE_NAME | C10: 원본 파일명 | D10: VARCHAR2(260 CHAR) | E10: N
A11: 3 | B11: FACTORY | C11: Factory (로그인 Factory, 예: SCK) | D11: VARCHAR2(30 CHAR) | E11: N
A12: 4 | B12: DEVICE_ID | C12: TQP_GDS_MAP.DEVICE_ID 와 같은 값 체계 (업로드 화면에서 선택) | D12: VARCHAR2(50 CHAR) | E12: N
A13: 5 | B13: LOT_ID | C13: 파일명 Lot (예: RH-HS2615) | D13: VARCHAR2(50 CHAR) | E13: N
A14: 6 | B14: SLOT_NO | C14: 파일명 Wafer 끝 숫자 (RH-HS2615-02 -> 2) | D14: NUMBER(3) | E14: N | I14: 1 ~ 99
A15: 7 | B15: WAFER_ID | C15: LOT_ID || '-' || 2자리 SLOT_NO (가상 컬럼) | D15: VARCHAR2(60 CHAR) | E15: Y
A16: 8 | B16: TEST_PROGRAM | C16: 파일명 5칸 Test Type = 공정 (TSVET / COWET / FT). 중복 키 FACTORY + WAFER_ID + TEST_PROGRAM | D16: VARCHAR2(50 CHAR) | E16: N
A17: 9 | B17: TEST_TIME | C17: 파일명 6칸 Test Date (yyyyMMddHHmmss) | D17: DATE | E17: N
A18: 10 | B18: FILE_PREFIX | C18: (PARSE_RULE_VER 1 만) 파일명 앞부분 원문. 2 부터는 CUSTOMER ~ WAFER_REV 로 나눠 저장 | D18: VARCHAR2(100 CHAR) | E18: Y
A19: 11 | B19: CREATE_USER | C19: 생성 사용자 ID | D19: VARCHAR2(30) | E19: Y
A20: 12 | B20: CREATE_TIME | C20: 생성 일시 | D20: DATE | E20: N | H20: SYSDATE
A21: 13 | B21: UPDATE_USER | C21: 수정 사용자 ID | D21: VARCHAR2(30) | E21: Y
A22: 14 | B22: UPDATE_TIME | C22: 수정 일시 (Service 가 저장할 때 기록) | D22: DATE | E22: Y
A23: 15 | B23: SHEET_NAME | C23: 측정값을 읽은 Sheet 이름 (예: DUT Summary) | D23: VARCHAR2(50 CHAR) | E23: Y
A24: 16 | B24: DIE_COUNT | C24: 파일의 Die 수 | D24: NUMBER(10) | E24: Y
A25: 17 | B25: ITEM_COUNT | C25: 저장한 등록 Parameter 수 (PARSE_RULE_VER 3) | D25: NUMBER(10) | E25: Y
A26: 18 | B26: VALUE_COUNT | C26: 저장된 측정값 행 수 (= DIE_COUNT x ITEM_COUNT 이어야 READY) | D26: NUMBER(10) | E26: Y
A27: 19 | B27: LOAD_STATUS | C27: LOADING = 저장 중 / READY = 건수 검증 완료 | D27: VARCHAR2(20) | E27: N | H27: 'LOADING' | I27: LOADING / READY
A28: 20 | B28: CUSTOMER | C28: 파일명 1칸 Customer (예: CAI) | D28: VARCHAR2(30 CHAR) | E28: Y
A29: 21 | B29: FILE_DEVICE | C29: 파일명 2칸 Device 원문 (예: OMM). DMS DEVICE_ID 와 별개 | D29: VARCHAR2(50 CHAR) | E29: Y
A30: 22 | B30: WAFER_TYPE | C30: 파일명 3칸 Wafer Type (예: ATV) | D30: VARCHAR2(30 CHAR) | E30: Y
A31: 23 | B31: WAFER_REV | C31: 파일명 4칸 Wafer Rev (예: A0) | D31: VARCHAR2(20 CHAR) | E31: Y
A32: 24 | B32: LOT_WAFER_NO | C32: 파일명 8칸 Lot-Wafer No 원문 (예: U9-HS2633-01) | D32: VARCHAR2(60 CHAR) | E32: Y
A33: 25 | B33: FAB_NAME | C33: 파일명 끝 $...$ 꼬리표 (예: Silterra). PARSE_RULE_VER 2 까지만 저장, 3 부터 NULL | D33: VARCHAR2(50 CHAR) | E33: Y
A34: 26 | B34: PASS_DIE_COUNT | C34: Spec 판정 Pass Die 수 (PARSE_RULE_VER 3) | D34: NUMBER(10) | E34: Y
A35: 27 | B35: FAIL_DIE_COUNT | C35: Spec 판정 Fail Die 수 (PARSE_RULE_VER 3) | D35: NUMBER(10) | E35: Y
A36: 28 | B36: NOT_TESTED_COUNT | C36: 미측정(-) 셀 수 (READY 확정 때 기록) | D36: NUMBER(10) | E36: Y
A37: 29 | B37: PARSE_RULE_VER | C37: 파일명 해석 / 저장 규칙: 1 = 뒤에서부터 분해 (2026-10-07) / 2 = 8칸 규칙 + $Fab$ (2026-10-12) / 3 = 등록 Parameter 만 저장 (2026-10-14, 현재 업로드) | D37: NUMBER(3) | E37: N | H37: 1
A38: 30 | B38: VIEW_SIDE | C38: 좌표 기준 면. PARSE_RULE_VER 2 는 BACK, 3 부터 저장하지 않음 (NULL) | D38: VARCHAR2(10) | E38: Y | I38: FRONT / BACK
A39: 31 | B39: HEADER_COUNT | C39: 파일 전체 측정 헤더 수 | D39: NUMBER(10) | E39: Y
A40: 32 | B40: DEFINED_COUNT | C40: 업로드 때 Device + 공정 등록 Parameter(사용 Y) 수 | D40: NUMBER(10) | E40: Y
A41: 33 | B41: MISSING_COUNT | C41: 등록됐는데 파일에 없는 Parameter 수 | D41: NUMBER(10) | E41: Y
...

Sheet TQP_GDS_ET_ITEM
A1: 테이블 명세서
I2: <- 테이블 목록
A3: 테이블명 | C3: TQP_GDS_ET_ITEM | D3: 업무 구분 | E3: E-Test | G3: 스키마 | H3: DMSMGR
A4: 테이블 설명 | C4: E-Test 측정 항목(Parameter) 마스터. Device + 공정 단위 등록 Parameter 와 GDS Chain 이름 연결을 관리한다.
A5: 기본 키 (PK) | C5: PK_GDS_ET_ITEM (ET_ITEM_SEQ) | D5: 컬럼 수 | E5: =COUNTA(B9:B34) -> 26 | G5: Query XML | H5: TQP_GDS_ET_ITEM.xml
A6: 생성 / 변경 SQL | C6: 2026-10-07_tqp_gds_et_result.sql (생성) 2026-10-14_tqp_gds_et_para_rep_chain.sql (변경) 2026-10-14_tqp_gds_et_upload_registered.sql (변경) 2026-10-14_tqp_gds_et_para_gds_chain.sql (변경)
A8: No | B8: 컬럼명 | C8: 컬럼 설명 | D8: 데이터 타입 | E8: NULL | F8: PK | G8: FK 참조 | H8: 기본값 | I8: 허용 값
A9: 1 | B9: ET_ITEM_SEQ | C9: 측정 항목 번호 (ET_ITEM_SEQ 시퀀스) | D9: NUMBER | E9: N | F9: 1
A10: 2 | B10: FACTORY | C10: Factory (로그인 Factory, 예: SCK) | D10: VARCHAR2(30 CHAR) | E10: N
A11: 3 | B11: DEVICE_ID | C11: Device(제품) ID. E-Test 파일 Device 와 같은 이름의 GDS Map Device | D11: VARCHAR2(50 CHAR) | E11: N
A12: 4 | B12: ITEM_NAME | C12: Parameter 저장 이름. 헤더 원문을 변환한 이름 (예: RESISTANCE_IFORCE_8P0MA_TSVDC_TR_FH, 50자 이하). Spec / YMS 컬럼 이름과 같은 값 | D12: VARCHAR2(200 CHAR) | E12: N
A13: 5 | B13: PARA_NAME | C13: Para 이름. 헤더 = 앞 부분을 변환한 이름 (예: CONNECTIVITY_IFORCE / LEAKAGE_PARALLEL) | D13: VARCHAR2(50 CHAR) | E13: N
A14: 6 | B14: COND_VALUE | C14: 헤더 = 뒤 조건 값, 대문자 (예: 1.0MA). 없으면 NULL | D14: VARCHAR2(20 CHAR) | E14: Y
A15: 7 | B15: CHAIN_NAME | C15: Chain 1 이름. 헤더 @ 뒤를 변환한 이름, Force leg 포함 (예: PIC_SERP1_M4_FH) | D15: VARCHAR2(64 CHAR) | E15: N
A16: 8 | B16: CHAIN_NAME2 | C16: Chain 2 이름 (Leakage_Serial 등 A:B 형식의 두 번째 Chain, 변환 이름). 없으면 NULL | D16: VARCHAR2(64 CHAR) | E16: Y
A17: 9 | B17: UNIT | C17: 측정 단위 (등록한 파일 기준) | D17: VARCHAR2(10 CHAR) | E17: Y
A18: 10 | B18: TEST_NO | C18: 파일 2행 Test Number | D18: NUMBER(10) | E18: Y
A19: 11 | B19: DISPLAY_ORDER | C19: 표시 순서 (처음 등록한 파일의 열 순서) | D19: NUMBER(10) | E19: Y
A20: 12 | B20: CREATE_USER | C20: 생성 사용자 ID | D20: VARCHAR2(30) | E20: Y
A21: 13 | B21: CREATE_TIME | C21: 생성 일시 | D21: DATE | E21: N | H21: SYSDATE
A22: 14 | B22: UPDATE_USER | C22: 수정 사용자 ID | D22: VARCHAR2(30) | E22: Y
A23: 15 | B23: UPDATE_TIME | C23: 수정 일시 (Service 가 저장할 때 기록) | D23: DATE | E23: Y
A24: 16 | B24: TEST_PROGRAM | C24: 공정 (Test Type: TSVET / COWET / FT), 대문자. Parameter 등록 때 지정 | D24: VARCHAR2(50 CHAR) | E24: N
A25: 17 | B25: HEADER_TEXT | C25: 등록 Parameter 의 헤더 원문 (공백 정리 / 끝 #번호 제거, 대소문자 유지). ITEM_NAME 은 DB / 소스용 변환 이름 | D25: VARCHAR2(200 CHAR) | E25: Y
A26: 18 | B26: MEAS_TYPE | C26: Measurement type (RESISTANCE / CONNECTIVITY / CONTINUITY / LEAKAGE) | D26: VARCHAR2(30 CHAR) | E26: Y
A27: 19 | B27: CHAIN_TYPE | C27: Chain 1 의 Chain type (TSVDC / C4DC / PIC_SERP ...) | D27: VARCHAR2(30 CHAR) | E27: Y
A28: 20 | B28: FORCE_LEG | C28: Chain 1 끝 Force leg (FH / FL) | D28: VARCHAR2(4 CHAR) | E28: Y | I28: FH / FL
A29: 21 | B29: FORCE_LEG2 | C29: Chain 2 끝 Force leg (FH / FL) | D29: VARCHAR2(4 CHAR) | E29: Y | I29: FH / FL
A30: 22 | B30: USE_FLAG | C30: Y / N. N 이면 다음 업로드부터 값을 저장 / 판정하지 않는다 (저장된 값은 보관) | D30: CHAR(1) | E30: N | H30: 'Y' | I30: Y / N
A31: 23 | B31: REG_SOURCE | C31: 등록 출처 FILE(결과 파일) / SPEC(고객 Spec 표) | D31: VARCHAR2(10 CHAR) | E31: Y | I31: FILE / SPEC
A32: 24 | B32: REG_FILE_NAME | C32: 등록에 쓴 파일 이름 | D32: VARCHAR2(260 CHAR) | E32: Y
A33: 25 | B33: REMARK | C33: 비고 | D33: VARCHAR2(200 CHAR) | E33: Y
A34: 26 | B34: GDS_CHAIN_NAME | C34: Chain 1 의 GDS Setup Chain 이름 (사용자 입력, GDS 대표 Device 의 TQP_GDS_CHAIN_VER.CHAIN_NAME 과 대소문자 무시 비교) | D34: VARCHAR2(200 CHAR) | E34: Y
A36: 제약 조건
A37: No | B37: 구분 | C37: 제약 이름 | D37: 컬럼 | G37: 내용
A38: 1 | B38: PK | C38: PK_GDS_ET_ITEM | D38: ET_ITEM_SEQ | G38: 기본 키
A39: 2 | B39: UNIQUE | C39: UQ_GDS_ET_ITEM_PARA | D39: FACTORY, DEVICE_ID, TEST_PROGRAM, ITEM_NAME | G39: 중복 금지
A40: 3 | B40: CHECK | C40: CK_GDS_ET_ITEM_LEG | G40: (FORCE_LEG IS NULL OR FORCE_LEG IN ('FH', 'FL')) AND (FORCE_LEG2 IS NULL OR FORCE_LEG2 IN ('FH', 'FL'))
A41: 4 | B41: CHECK | C41: CK_GDS_ET_ITEM_PARA | G41: TEST_PROGRAM IS NULL OR ( REGEXP_LIKE(TEST_PROGRAM, '^[A-Z][A-Z0-9_]*$') AND REGEXP_LIKE(ITEM_NAME, '^[A-Z][A-Z0-9_]*$') AND LENGTH(ITEM_NAME) <= 50 AND REGEXP_LIKE(CHAIN_NAME, '^[A-Z][A-Z0-9_]*$') AND (CHAIN_NAME2 IS NULL OR REGEXP_LIKE(CHAIN_NAME2, '^[A-Z][A-Z0-9_]*$')) AND HEADER_TEXT IS NOT NULL AND REG_SOURCE IS NOT NULL)
A42: 5 | B42: CHECK | C42: CK_GDS_ET_ITEM_SOURCE | G42: REG_SOURCE IS NULL OR REG_SOURCE IN ('FILE', 'SPEC')
...

Sheet TQP_GDS_ET_DIE
A1: 테이블 명세서
I2: <- 테이블 목록
A3: 테이블명 | C3: TQP_GDS_ET_DIE | D3: 업무 구분 | E3: E-Test | G3: 스키마 | H3: DMSMGR
A4: 테이블 설명 | C4: E-Test Die 정보 (파일 행 단위). 원본 좌표 / Bin / DUT Flag / Map 좌표 / Spec 판정.
A5: 기본 키 (PK) | C5: PK_GDS_ET_DIE (SRC_FILE_SEQ, DUT_NO) | D5: 컬럼 수 | E5: =COUNTA(B9:B24) -> 16 | G5: Query XML | H5: TQP_GDS_ET_DIE.xml
A6: 생성 / 변경 SQL | C6: 2026-10-07_tqp_gds_et_result.sql (생성) 2026-10-14_tqp_gds_et_upload_registered.sql (변경)
A8: No | B8: 컬럼명 | C8: 컬럼 설명 | D8: 데이터 타입 | E8: NULL | F8: PK | G8: FK 참조 | H8: 기본값 | I8: 허용 값
A9: 1 | B9: SRC_FILE_SEQ | C9: E-Test 파일 번호 (TQP_GDS_SRC_FILE) | D9: NUMBER | E9: N | F9: 1 | G9: TQP_GDS_SRC_FILE
A10: 2 | B10: DUT_NO | C10: DUT 번호 (파일 A열 #3 -> 3) | D10: NUMBER(10) | E10: N | F10: 2
A11: 3 | B11: DIE_X | C11: 파일의 Die 좌표 X (원본 그대로) | D11: NUMBER(10) | E11: N
A12: 4 | B12: DIE_Y | C12: 파일의 Die 좌표 Y (원본 그대로) | D12: NUMBER(10) | E12: N
A13: 5 | B13: HW_BIN | C13: Hardware Bin (예: Bin 1 -> 1) | D13: NUMBER(10) | E13: Y
A14: 6 | B14: SW_BIN | C14: Software Bin (예: Bin 5001 -> 5001) | D14: NUMBER(10) | E14: Y
A15: 7 | B15: PASS_FLAG | C15: 파일 DUT Flag (원본 참고, 판정 아님) | D15: CHAR(1) | E15: N | I15: P / F
A16: 8 | B16: FLAG_CODE | C16: DUT Flag 코드 (예: 0x08) | D16: VARCHAR2(10) | E16: Y
A17: 9 | B17: TEST_TIME_MS | C17: Die 시험 시간 (ms) | D17: NUMBER(10) | E17: Y
A18: 10 | B18: TESTS_EXECUTED | C18: 실행한 Test 수 | D18: NUMBER(10) | E18: Y
A19: 11 | B19: HEAD_SITE | C19: Head / Site (예: Head 1 - Site 1) | D19: VARCHAR2(30 CHAR) | E19: Y
A20: 12 | B20: MAP_X | C20: 시스템 Map 좌표 X (Map 사용 Die 가 아니거나 Map 이 없으면 NULL) | D20: NUMBER(10) | E20: Y
A21: 13 | B21: MAP_Y | C21: 시스템 Map 좌표 Y | D21: NUMBER(10) | E21: Y
A22: 14 | B22: JUDGE_FLAG | C22: Spec 판정 P / F (Fail 값이 하나라도 있으면 F) | D22: CHAR(1) | E22: Y | I22: P / F
A23: 15 | B23: FAIL_COUNT | C23: Fail 값 수 (범위 밖 + Enable Spec 의 '-') | D23: NUMBER(10) | E23: Y
A24: 16 | B24: NOT_TESTED_COUNT | C24: 저장한 Parameter 의 '-' 값 수 | D24: NUMBER(10) | E24: Y
A26: 제약 조건
A27: No | B27: 구분 | C27: 제약 이름 | D27: 컬럼 | G27: 내용
A28: 1 | B28: PK | C28: PK_GDS_ET_DIE | D28: SRC_FILE_SEQ, DUT_NO | G28: 기본 키
A29: 2 | B29: UNIQUE | C29: UQ_GDS_ET_DIE_XY | D29: SRC_FILE_SEQ, DIE_X, DIE_Y | G29: 중복 금지
A30: 3 | B30: FK | C30: FK_GDS_ET_DIE_FILE | D30: SRC_FILE_SEQ | G30: -> TQP_GDS_SRC_FILE (SRC_FILE_SEQ) / 삭제 규칙 CASCADE (부모 삭제 시 함께 삭제)
A31: 4 | B31: CHECK | C31: CK_GDS_ET_DIE_JUDGE | G31: JUDGE_FLAG IS NULL OR JUDGE_FLAG IN ('P', 'F')
A32: 5 | B32: CHECK | C32: CK_GDS_ET_DIE_PASS | G32: PASS_FLAG IN ('P', 'F')
A34: 인덱스
A35: No | B35: 유일 | C35: 인덱스 이름 | D35: 컬럼 / 식 | G35: 용도
A36: 1 | B36: UNIQUE | C36: PK_GDS_ET_DIE | D36: SRC_FILE_SEQ, DUT_NO | G36: 기본 키
A37: 2 | B37: UNIQUE | C37: UQ_GDS_ET_DIE_XY | D37: SRC_FILE_SEQ, DIE_X, DIE_Y | G37: 중복 금지 (UNIQUE 제약)

Sheet TQP_GDS_ET_VALUE
A1: 테이블 명세서
I2: <- 테이블 목록
A3: 테이블명 | C3: TQP_GDS_ET_VALUE | D3: 업무 구분 | E3: E-Test | G3: 스키마 | H3: DMSMGR
A4: 테이블 설명 | C4: E-Test 측정값 (Die x 측정 항목).
A5: 기본 키 (PK) | C5: PK_GDS_ET_VALUE (SRC_FILE_SEQ, DUT_NO, ET_ITEM_SEQ) | D5: 컬럼 수 | E5: =COUNTA(B9:B14) -> 6 | G5: Query XML | H5: TQP_GDS_ET_VALUE.xml
A6: 생성 / 변경 SQL | C6: 2026-10-07_tqp_gds_et_result.sql (생성) 2026-10-14_tqp_gds_et_upload_registered.sql (변경)
A8: No | B8: 컬럼명 | C8: 컬럼 설명 | D8: 데이터 타입 | E8: NULL | F8: PK | G8: FK 참조 | H8: 기본값 | I8: 허용 값
A9: 1 | B9: SRC_FILE_SEQ | C9: E-Test 파일 번호 (TQP_GDS_ET_DIE) | D9: NUMBER | E9: N | F9: 1 | G9: TQP_GDS_ET_DIE
A10: 2 | B10: DUT_NO | C10: DUT 번호 (TQP_GDS_ET_DIE) | D10: NUMBER(10) | E10: N | F10: 2 | G10: TQP_GDS_ET_DIE
A11: 3 | B11: ET_ITEM_SEQ | C11: 측정 항목 번호 (TQP_GDS_ET_ITEM) | D11: NUMBER | E11: N | F11: 3 | G11: TQP_GDS_ET_ITEM
A12: 4 | B12: MEAS_VALUE | C12: 측정값 (숫자). 값이 없으면 NULL (VALUE_STATUS 참고) | D12: BINARY_DOUBLE | E12: Y
A13: 5 | B13: VALUE_STATUS | C13: V = 숫자 / N = 미측정(-) / E = 빈 값 | D13: CHAR(1) | E13: N | I13: N / E
A14: 6 | B14: JUDGE_FLAG | C14: Spec 판정 P / F. NULL = Spec 없음 / Enable N / 빈 칸 | D14: CHAR(1) | E14: Y | I14: P / F
A16: 제약 조건
A17: No | B17: 구분 | C17: 제약 이름 | D17: 컬럼 | G17: 내용
A18: 1 | B18: PK | C18: PK_GDS_ET_VALUE | D18: SRC_FILE_SEQ, DUT_NO, ET_ITEM_SEQ | G18: 기본 키
A19: 2 | B19: FK | C19: FK_GDS_ET_VALUE_DIE | D19: SRC_FILE_SEQ, DUT_NO | G19: -> TQP_GDS_ET_DIE (SRC_FILE_SEQ, DUT_NO) / 삭제 규칙 CASCADE (부모 삭제 시 함께 삭제)
A20: 3 | B20: FK | C20: FK_GDS_ET_VALUE_ITEM | D20: ET_ITEM_SEQ | G20: -> TQP_GDS_ET_ITEM (ET_ITEM_SEQ) / 삭제 규칙 NO ACTION (자식이 있으면 부모 삭제 불가)
A21: 4 | B21: CHECK | C21: CK_GDS_ET_VALUE_JUDGE | G21: JUDGE_FLAG IS NULL OR JUDGE_FLAG IN ('P', 'F')
A22: 5 | B22: CHECK | C22: CK_GDS_ET_VALUE_NULL | G22: (VALUE_STATUS = 'V' AND MEAS_VALUE IS NOT NULL) OR (VALUE_STATUS IN ('N', 'E') AND MEAS_VALUE IS NULL)
A23: 6 | B23: CHECK | C23: CK_GDS_ET_VALUE_STATUS | G23: VALUE_STATUS IN ('V', 'N', 'E')
A25: 인덱스
A26: No | B26: 유일 | C26: 인덱스 이름 | D26: 컬럼 / 식 | G26: 용도
A27: 1 | B27: - | C27: IX_GDS_ET_VALUE_ITEM | D27: SRC_FILE_SEQ, ET_ITEM_SEQ | G27: 파일 + 측정 항목별 측정값 조회
A28: 2 | B28: - | C28: IX_GDS_ET_VALUE_ITEMONLY | D28: ET_ITEM_SEQ | G28: 측정 항목 -> 측정값 찾기 (항목 삭제 검사)
A29: 3 | B29: UNIQUE | C29: PK_GDS_ET_VALUE | D29: SRC_FILE_SEQ, DUT_NO, ET_ITEM_SEQ | G29: 기본 키

Sheet TQP_GDS_ET_LIMIT
A1: 테이블 명세서
I2: <- 테이블 목록
A3: 테이블명 | C3: TQP_GDS_ET_LIMIT | D3: 업무 구분 | E3: E-Test | G3: 스키마 | H3: DMSMGR
A4: 테이블 설명 | C4: E-Test Spec (하한 / 상한 / 사용 여부). Device + 공정 + 등록 Parameter 단위.
A5: 기본 키 (PK) | C5: PK_GDS_ET_LIMIT (FACTORY, DEVICE_ID, TEST_PROGRAM, ITEM_NAME) | D5: 컬럼 수 | E5: =COUNTA(B9:B22) -> 14 | G5: Query XML | H5: TQP_GDS_ET_LIMIT.xml
A6: 생성 / 변경 SQL | C6: 2026-10-12_tqp_gds_et_limit_item.sql (생성) 2026-10-14_tqp_gds_et_limit_fk.sql (변경)
A8: No | B8: 컬럼명 | C8: 컬럼 설명 | D8: 데이터 타입 | E8: NULL | F8: PK | G8: FK 참조 | H8: 기본값 | I8: 허용 값
A9: 1 | B9: FACTORY | C9: Factory (로그인 Factory, 예: SCK) | D9: VARCHAR2(30 CHAR) | E9: N | F9: 1 | G9: TQP_GDS_ET_ITEM
A10: 2 | B10: DEVICE_ID | C10: Device(제품) ID. E-Test 파일 Device 와 같은 이름의 GDS Map Device | D10: VARCHAR2(50 CHAR) | E10: N | F10: 2 | G10: TQP_GDS_ET_ITEM
A11: 3 | B11: TEST_PROGRAM | C11: 공정 = 파일명 Test Type (TSVET / COWET / FT), 대문자 | D11: VARCHAR2(50 CHAR) | E11: N | F11: 3 | G11: TQP_GDS_ET_ITEM
A12: 4 | B12: ITEM_NAME | C12: 등록 Parameter 저장 이름 (TQP_GDS_ET_ITEM.ITEM_NAME) | D12: VARCHAR2(200 CHAR) | E12: N | F12: 4 | G12: TQP_GDS_ET_ITEM
A13: 5 | B13: LOWER_LIMIT | C13: 하한, NULL = 없음 (값 < 하한 이면 Fail) | D13: BINARY_DOUBLE | E13: Y
A14: 6 | B14: UPPER_LIMIT | C14: 상한, NULL = 없음 (값 > 상한 이면 Fail) | D14: BINARY_DOUBLE | E14: Y
A15: 7 | B15: UNIT | C15: 단위 | D15: VARCHAR2(10 CHAR) | E15: Y
A16: 8 | B16: ENABLE_FLAG | C16: Y = 판정 / N = 값만 보관. 판정 시 '-' 값도 Fail | D16: CHAR(1) | E16: N | H16: 'Y' | I16: Y / N
A17: 9 | B17: SPEC_TEXT | C17: 고객 Spec 원문 (예: If val > 715, Fail; otherwise, Pass) | D17: VARCHAR2(200 CHAR) | E17: Y
A18: 10 | B18: REMARK | C18: 비고 | D18: VARCHAR2(200 CHAR) | E18: Y
A19: 11 | B19: CREATE_USER | C19: 생성 사용자 ID | D19: VARCHAR2(30) | E19: Y
A20: 12 | B20: CREATE_TIME | C20: 생성 일시 | D20: DATE | E20: N | H20: SYSDATE
A21: 13 | B21: UPDATE_USER | C21: 수정 사용자 ID | D21: VARCHAR2(30) | E21: Y
A22: 14 | B22: UPDATE_TIME | C22: 수정 일시 (Service 가 저장할 때 기록) | D22: DATE | E22: Y
A24: 제약 조건
A25: No | B25: 구분 | C25: 제약 이름 | D25: 컬럼 | G25: 내용
A26: 1 | B26: PK | C26: PK_GDS_ET_LIMIT | D26: FACTORY, DEVICE_ID, TEST_PROGRAM, ITEM_NAME | G26: 기본 키
A27: 2 | B27: FK | C27: FK_GDS_ET_LIMIT_PARA | D27: FACTORY, DEVICE_ID, TEST_PROGRAM, ITEM_NAME | G27: -> TQP_GDS_ET_ITEM (FACTORY, DEVICE_ID, TEST_PROGRAM, ITEM_NAME) / 삭제 규칙 CASCADE (부모 삭제 시 함께 삭제)
A28: 3 | B28: CHECK | C28: CK_GDS_ET_LIMIT_ENABLE | G28: ENABLE_FLAG IN ('Y', 'N')
A29: 4 | B29: CHECK | C29: CK_GDS_ET_LIMIT_ONE | G29: LOWER_LIMIT IS NOT NULL OR UPPER_LIMIT IS NOT NULL
A30: 5 | B30: CHECK | C30: CK_GDS_ET_LIMIT_RANGE | G30: LOWER_LIMIT IS NULL OR UPPER_LIMIT IS NULL OR LOWER_LIMIT <= UPPER_LIMIT
A31: 6 | B31: CHECK | C31: CK_GDS_ET_LIMIT_UPPER | G31: ITEM_NAME = UPPER(ITEM_NAME) AND TEST_PROGRAM = UPPER(TEST_PROGRAM)
A33: 인덱스
A34: No | B34: 유일 | C34: 인덱스 이름 | D34: 컬럼 / 식 | G34: 용도
A35: 1 | B35: UNIQUE | C35: PK_GDS_ET_LIMIT | D35: FACTORY, DEVICE_ID, TEST_PROGRAM, ITEM_NAME | G35: 기본 키

Sheet 관계(FK)
A1: 테이블 관계 (FK)
B3: TQP_GDS_MAP (Factory + Device 당 1건)
B4: +- TQP_GDS_LAYER
B5: +- TQP_GDS_PLACED_EL ........................ TQP_GDS_LAYER 참조
B6: +- TQP_GDS_IMPORT_JOB
B7: | +- TQP_GDS_IMPORT_BATCH
B8: +- TQP_GDS_CHAIN
B9: +- TQP_GDS_CHAIN_VER
B10: +- TQP_GDS_CHAIN_MEMBER .......... TQP_GDS_PLACED_EL 참조
B11: +- TQP_GDS_CHAIN_LAYER ........... TQP_GDS_LAYER 참조
B12: +- TQP_GDS_CHAIN_RULE ............ TQP_GDS_LAYER 참조 (Layer 1 / Layer 2)
B13: +- TQP_GDS_CHAIN_EDIT ............ TQP_GDS_PLACED_EL 참조
B15: TQP_GDS_SRC_FILE (E-Test 파일 1개)
... B21: E-Test 와 GDS 는 FK 없이 이름으로 연결한다: SRC_FILE / ET_ITEM 의 DEVICE_ID = TQP_GDS_MAP.DEVICE_ID, ET_ITEM.GDS_CHAIN_NAME = TQP_GDS_CHAIN_VER.CHAIN_NAME
A23: No | B23: 자식 테이블 | C23: FK 이름 | D23: 자식 컬럼 | E23: 부모 테이블 | F23: 부모 키 | G23: 삭제 규칙 | H23: 비고
A24: 1 | B24: TQP_GDS_LAYER | C24: FK_GDS_LAYER_MAP | D24: FACTORY, DEVICE_ID | E24: TQP_GDS_MAP | F24: FACTORY, DEVICE_ID | G24: CASCADE | H24: 부모를 지우면 함께 지워진다
A25: 2 | B25: TQP_GDS_PLACED_EL | C25: FK_GDS_PLACED_LAYER | D25: FACTORY, DEVICE_ID, LAYER_ID | E25: TQP_GDS_LAYER | F25: FACTORY, DEVICE_ID, LAYER_ID | G25: NO ACTION | H25: 자식이 있으면 부모를 지울 수 없다 (자식을 먼저 지워야 함)
A26: 3 | B26: TQP_GDS_IMPORT_JOB | C26: FK_GDS_IMPORT_MAP | D26: FACTORY, DEVICE_ID | E26: TQP_GDS_MAP | F26: FACTORY, DEVICE_ID | G26: CASCADE | H26: 부모를 지우면 함께 지워진다
A27: 4 | B27: TQP_GDS_IMPORT_BATCH | C27: FK_GDS_IMPORT_BATCH_JOB | D27: IMPORT_JOB_SEQ | E27: TQP_GDS_IMPORT_JOB | F27: IMPORT_JOB_SEQ | G27: CASCADE | H27: 부모를 지우면 함께 지워진다
A28: 5 | B28: TQP_GDS_CHAIN | C28: FK_GDS_CHAIN_MAP | D28: FACTORY, DEVICE_ID | E28: TQP_GDS_MAP | F28: FACTORY, DEVICE_ID | G28: CASCADE | H28: 부모를 지우면 함께 지워진다
A29: 6 | B29: TQP_GDS_CHAIN_VER | C29: FK_GDS_CHAIN_VER_MASTER | D29: FACTORY, DEVICE_ID, CHAIN_SEQ | E29: TQP_GDS_CHAIN | F29: FACTORY, DEVICE_ID, CHAIN_SEQ | G29: CASCADE | H29: 부모를 지우면 함께 지워진다
A30: 7 | B30: TQP_GDS_CHAIN_MEMBER | C30: FK_GDS_CHAIN_MEMBER_EL | D30: FACTORY, DEVICE_ID, PLACED_ELEMENT_ID | E30: TQP_GDS_PLACED_EL | F30: FACTORY, DEVICE_ID, PLACED_ELEMENT_ID | G30: NO ACTION | H30: 자식이 있으면 부모를 지울 수 없다 (자식을 먼저 지워야 함)
A31: 8 | B31: TQP_GDS_CHAIN_MEMBER | C31: FK_GDS_CHAIN_MEMBER_VER | D31: FACTORY, DEVICE_ID, CHAIN_SEQ, VERSION_NO | E31: TQP_GDS_CHAIN_VER | F31: FACTORY, DEVICE_ID, CHAIN_SEQ, VERSION_NO | G31: CASCADE | H31: 부모를 지우면 함께 지워진다
A32: 9 | B32: TQP_GDS_CHAIN_LAYER | C32: FK_GDS_CHAIN_LAYER_MAP | D32: FACTORY, DEVICE_ID, LAYER_ID | E32: TQP_GDS_LAYER | F32: FACTORY, DEVICE_ID, LAYER_ID | G32: NO ACTION | H32: 자식이 있으면 부모를 지울 수 없다 (자식을 먼저 지워야 함)
A33: 10 | B33: TQP_GDS_CHAIN_LAYER | C33: FK_GDS_CHAIN_LAYER_VER | D33: FACTORY, DEVICE_ID, CHAIN_SEQ, VERSION_NO | E33: TQP_GDS_CHAIN_VER | F33: FACTORY, DEVICE_ID, CHAIN_SEQ, VERSION_NO | G33: CASCADE | H33: 부모를 지우면 함께 지워진다
A34: 11 | B34: TQP_GDS_CHAIN_RULE | C34: FK_GDS_CHAIN_RULE_L1 | D34: FACTORY, DEVICE_ID, FIRST_LAYER_ID | E34: TQP_GDS_LAYER | F34: FACTORY, DEVICE_ID, LAYER_ID | G34: NO ACTION | H34: 자식이 있으면 부모를 지울 수 없다 (자식을 먼저 지워야 함)
A35: 12 | B35: TQP_GDS_CHAIN_RULE | C35: FK_GDS_CHAIN_RULE_L2 | D35: FACTORY, DEVICE_ID, SECOND_LAYER_ID | E35: TQP_GDS_LAYER | F35: FACTORY, DEVICE_ID, LAYER_ID | G35: NO ACTION | H35: 자식이 있으면 부모를 지울 수 없다 (자식을 먼저 지워야 함)
... A42: 19 | B42: TQP_GDS_ET_LIMIT | C42: FK_GDS_ET_LIMIT_PARA | D42: FACTORY, DEVICE_ID, TEST_PROGRAM, ITEM_NAME | E42: TQP_GDS_ET_ITEM | F42: FACTORY, DEVICE_ID, TEST_PROGRAM, ITEM_NAME | G42: CASCADE | H42: 부모를 지우면 함께 지워진다

Sheet 시퀀스
A1: 시퀀스
A3: No | B3: 시퀀스 | C3: 사용 테이블.컬럼 | D3: 시작 | E3: 증가 | F3: CACHE | G3: 생성 SQL | H3: 비고
A4: 1 | B4: IMPORT_JOB_SEQ | C4: TQP_GDS_IMPORT_JOB.IMPORT_JOB_SEQ | D4: 1 | E4: 1 | F4: 20 | G4: 2026-10-02_tqp_gds_schema_seq.sql
A5: 2 | B5: CHAIN_SEQ | C5: TQP_GDS_CHAIN.CHAIN_SEQ | D5: 1 | E5: 1 | F5: 20 | G5: 2026-10-02_tqp_gds_schema_seq.sql
A6: 3 | B6: BATCH_EDIT_SEQ | C6: TQP_GDS_CHAIN_EDIT.BATCH_EDIT_SEQ | D6: 1 | E6: 1 | F6: 20 | G6: 2026-10-02_tqp_gds_schema_seq.sql | H6: 현재 미사용 (일괄 편집 묶음용)
A7: 4 | B7: SRC_FILE_SEQ | C7: TQP_GDS_SRC_FILE.SRC_FILE_SEQ | D7: 1 | E7: 1 | F7: 20 | G7: 2026-10-07_tqp_gds_src_file.sql
A8: 5 | B8: ET_ITEM_SEQ | C8: TQP_GDS_ET_ITEM.ET_ITEM_SEQ | D8: 1 | E8: 1 | F8: 20 | G8: 2026-10-07_tqp_gds_et_result.sql
A10: 번호는 SELECT <시퀀스>.NEXTVAL FROM DUAL 로 받는다 (기존 DMS 의 STEP_SEQ 등과 같은 방식). INSERT 가 실패해도 번호가 소모되어 빈 번호가 생길 수 있다.

Sheet 변경 이력
A1: 변경 이력
A3: 1. 개발 중 만들었다가 삭제한 테이블 (현재 DB 에 없음)
A4: No | B4: 삭제일 | C4: 테이블 | D4: 생성 -> 삭제 SQL | E4: 삭제 사유 / 대체
A5: 1 | B5: 2026-10-02 | C5: TQP_GDS_MAP_REV | D5: 2026-10-01_tqp_gds_map_schema.sql -> 2026-10-02_tqp_gds_schema_device.sql | E5: Map 개정본(Revision) 관리를 하지 않기로 함. Factory + Device 1:1 헤더 TQP_GDS_MAP 으로 대체
A6: 2 | B6: 2026-10-02 | C6: TQP_GDS_MAP_ACTIVE | D6: 2026-10-01_tqp_gds_map_schema.sql -> 2026-10-02_tqp_gds_schema_device.sql | E6: 현재 사용 개정본 선택 테이블. 개정본 관리 제거로 불필요
A7: 3 | B7: 2026-10-12 | C7: TQP_GDS_SOURCE_EL | D7: 2026-10-01_tqp_gds_map_schema.sql -> 2026-10-12_tqp_gds_source_el_drop.sql | E7: GDS 원본 행. 저장만 하고 조회하는 화면 / 서비스가 없어 삭제. 도면 / Chain / Label 검색은 TQP_GDS_PLACED_EL 만 사용
A8: 4 | B8: 2026-10-12 | C8: TQP_GDS_ET_CHAIN_MAP | D8: 2026-10-12_tqp_gds_et_chain_map.sql -> 2026-10-12_tqp_gds_et_chain_group.sql | E8: E-Test Chain -> 대표 Chain 연결. 같은 날 묶음 번호 방식(TQP_GDS_ET_CHAIN_GROUP)으로 대체
A9: 5 | B9: 2026-10-14 | C9: TQP_GDS_ET_CHAIN_GROUP | D9: 2026-10-12_tqp_gds_et_chain_group.sql -> 2026-10-14_tqp_gds_et_limit_fk.sql | E9: E-Test Chain 묶음 (ET_CHAIN_GROUP_SEQ 시퀀스 포함). 대표 Chain(TQP_GDS_ET_REP_CHAIN) 방식으로 대체
A10: 6 | B10: 2026-10-14 | C10: TQP_GDS_ET_REP_CHAIN | D10: 2026-10-14_tqp_gds_et_para_rep_chain.sql -> 2026-10-14_tqp_gds_et_para_gds_chain.sql | E10: 대표 Chain. Parameter 별 GDS Chain 이름(TQP_GDS_ET_ITEM.GDS_CHAIN_NAME) 직접 입력으로 대체
A11: 7 | B11: 2026-10-14 | C11: TQP_GDS_ET_CHAIN_LINK | D11: 2026-10-14_tqp_gds_et_para_rep_chain.sql -> 2026-10-14_tqp_gds_et_para_gds_chain.sql | E11: 대표 Chain 과 E-Test Chain 연결. 위와 같은 이유로 삭제
A12: 8 | B12: 2026-10-15 | C12: TQP_GDS_MAP_SUB_DEVICE | D12: 2026-10-12_tqp_gds_map_sub_device.sql -> 2026-10-15_tqp_gds_map_sub_device_drop.sql | E12: 대표 Device / Sub Device 연결. GDS Map 복사(같은 도면을 다른 Device 이름으로 저장)로 대체
A14: 2. POC 에서 바꾼 기존 테이블 (구조 변경)
A15: No | B15: 변경일 | C15: 테이블.컬럼 | D15: SQL | E15: 변경 내용 / 사유
