Workbook

Sheet 작성방법
B2: <참고사항>
B7: * Last Update Version : 2024-05-20 (V1.2)
B8: - 24년 조직개편 반영
B9: - 경비Sheet 일부 계정 추가
B11: * Last Update Version : 2023-12-01 (V1.6)
B12: - 보증보험료 계산시트 추가
B13: - 외주비&재료비 시트의 조직선택 드롭다운목록에서 개발혁신그룹 삭제
B15: * Last Update Version : 2023-10-24
B16: - 금융팀 → 생명/증권그룹, 화재/카드그룹으로 부서단위 조정
B18: * Last Update Version : 2023-06-14
B19: - '23.05 기준 인건비단가 반영
B21: * Last Update Version : 2023-04-04
... B52: 0. input=> 뒤의 노란색 5개 시트를 차례대로 입력합니다.
C53: - 2-1. 사전영업비, 4-1 경비_보증보험료, 4-2. 해외출장 비자발급 수수료 시트는 필요 시 입력
B57: 1. 판매품의서
D58: 음영이 있는 칸만 차례대로 입력합니다.
B60: 2. 인건비
D61: 음영이 있는 칸만 아래와 같이 차례대로 입력합니다.
C62: ※ 정규 On-Site 개발 인력에 대한 M/M 입력
C63: - '25년 인건비 반영 완료, '26.03 이후 인건비는 인상률 5.0% 반영
C64: * 인건비단가 버전 : 2025.08, 관리그룹 반영 기준
C65: ① 사업구분 : 드롭다운 목록에서 솔루션 선택
C66: ② 조직 : 드롭다운 목록에서 조직 선택
C67: ③ 투입유형 : 드롭다운 목록에서 유형 선택
C68: ④ 직급 : 드롭다운 목록에서 직급 선택
C69: ⑤ 비고 : 참고사항 입력
C70: ⑥ 투입공수(M/M) : 각 월별 투입공수를 입력
B87: 2-1. 사전영업비
D88: 음영이 있는 칸만 차례대로 입력합니다.
B90: 3. 외주비&재료비
D91: 음영이 있는 칸만 차례대로 입력합니다.
C92: - 재료비는 외주비와 3'rd Party(H/W, S/W)로 구분해서 반드시 작성해야 합니다.
C93: · 도입 솔루션은 인건비와 재료비를 구분해서 분리 기표진행
B95: 4. 경비
D96: 음영이 있는 칸만 차례대로 입력합니다.
C97: ※ 각 항목별 편성 기준 및 한도를 참고하여 편성
C98: - 경비 항목에 연장근무수당 반영여부 선택 가능 ('반영'선택 시 최대 연장근무수당 3% 자동 반영됨)
C99: - 요식성경비/접대비는 대내 0.3% / 대외 0.5%
C100: · 제안을 수반한 SI사업만 가능(사전영업, SMC사업 불가)
C101: - 복리단합대회비는 전 그룹에 반영되어, 필요시 제거 가능
...

Sheet 수주품의 Check
B2: Income Statement
B4: Type | C4: Total | D4: Service | E4: H/W & S/W | F4: Acquired Solution | G4: Developed Solution
B5: Contract Amt | C5: =SUM(D5:E5) -> 24600000 | D5: =+손익시뮬레이션!G12-손익시뮬레이션!S12 -> 24600000 | E5: =+손익시뮬레이션!S12 -> 0 | F5: 0 | G5: 0
B6: Material Cost | C6: =SUM(D6:E6) -> 0 | D6: 0 | E6: =+손익시뮬레이션!S13 -> 0 | F6: 0 | G6: 0
B7: Labor Cost | C7: =SUM(D7:E7) -> 9220418 | D7: =+손익시뮬레이션!G14 -> 9220418 | E7: 0 | F7: 0 | G7: 0
B8: Outsourcing Cost | C8: =SUM(D8:E8) -> 0 | D8: =+손익시뮬레이션!G25 -> 0 | E8: 0 | F8: 0 | G8: 0
B9: Expenses | C9: =SUM(D9:E9) -> 4362567 | D9: =SUM(D10:D11) -> 4362567 | E9: 0 | F9: 0 | G9: 0
B10: 인건비성 복리후생비 | C10: =SUM(D10:E10) -> 817567 | D10: =+손익시뮬레이션!G24 -> 817567 | E10: 0
B11: 경비 | C11: =SUM(D11:E11) -> 3545000 | D11: =+손익시뮬레이션!G26 -> 3545000 | E11: 0
B12: Risk Cost | C12: =SUM(D12:E12) -> 246000 | D12: =+손익시뮬레이션!J28+손익시뮬레이션!O28 -> 246000 | E12: =+손익시뮬레이션!S28 -> 0 | F12: 0 | G12: 0
B13: Standard Cost(Direct) | C13: =SUM(D13:E13) -> 0 | D13: 0 | E13: 0 | F13: 0 | G13: 0
B14: Direct Cost | C14: =SUM(D14:E14) -> 13828985 | D14: =SUM(D6:D9,D12,D13) -> 13828985 | E14: =SUM(E6:E9,E12,E13) -> 0 | F14: 0 | G14: 0
B15: Marginal Profit | C15: =SUM(D15:E15) -> 10771015 | D15: =D5-D14 -> 10771015 | E15: =E5-E14 -> 0 | G15: 0
B16: Marginal Profit(%) | C16: =C15/C5 -> 0.43784614 | D16: =D15/D5 -> 0.43784614 | E16: =E15/E5 -> #DIV/0! | F16: 1 | G16: 0
B17: Pre Sales Cost | C17: =SUM(D17:E17) -> 0 | D17: =+손익시뮬레이션!G32 -> 0 | E17: 0 | F17: 0 | G17: 0
B18: 총간접원가 | C18: =SUM(D18:E18) -> 7550186 | D18: =+손익시뮬레이션!J44+손익시뮬레이션!O44 -> 7550186 | E18: =+손익시뮬레이션!S44 -> 0
B19: Operating Profit | C19: =SUM(D19:E19) -> 3220829 | D19: =D15-D17-D18 -> 3220829 | E19: =E15-E17-E18 -> 0 | G19: 0
B20: Operating Profit(%) | C20: =C19/C5 -> 0.13092801 | D20: =D19/D5 -> 0.13092801 | E20: =E19/E5 -> #DIV/0! | F20: 1 | G20: 0

Sheet 손익시뮬레이션
C2: ◆ 손익 시뮬레이션 | G2: PJT유형 : | I2: =IFERROR('5. 수주액 상세'!D3& '5. 수주액 상세'!D4&"-"&'5. 수주액 상세'!D5,0) -> MES서비스-국내
C4: - 프로젝트명 : | F4: ='1. 판매품의서'!F6 -> [스태츠칩팩코리아] 인천공장 Defect E-Test 자동 분석 시스템 구축 POC
S6: (단위 : 원)
C7: 구분 | G7: PJT 전체 손익 | I7: 자사공급 계 | S7: HW/ 도입솔루션
J8: 서비스 (정규+외주) | O8: 자사솔루션 | P8: 유지보수 | Q8: ITO/원격운영 | R8: ='5. 수주액 상세'!$C$17 -> MES CE 구독료
L9: 서비스 (정규) | N9: 서비스 (외주)
U10: 솔루션판매 비중
H11: (실비정산제외) | K11: (실비정산제외) | M11: (실비정산경비)
C12: 수주금액 | G12: =SUM(I12,S12) -> 24600000 | H12: =G12-M12 -> 24600000 | I12: =SUM(J12,O12,R12,P12,Q12) -> 24600000 | J12: =L12+N12 -> 24600000 | K12: =J12-M12 -> 24600000 | L12: ='5. 수주액 상세'!D11 -> 24600000 | M12: ='4. 경비(실비정산성경비)'!$E$69 -> 0 | N12: ='5. 수주액 상세'!D12 -> 0 | O12: ='5. 수주액 상세'!D13 -> 0 | P12: ='5. 수주액 상세'!D14 -> 0 | Q12: ='5. 수주액 상세'!D15 -> 0 | R12: ='5. 수주액 상세'!D17 -> 0 | S12: ='5. 수주액 상세'!D16 -> 0 | U12: 전체비중比 | V12: 서비스비중比
C13: 직접 원가 | D13: 재료비 | G13: =SUM(I13,S13) -> 0 | H13: =G13-M13 -> 0 | I13: =SUM(J13,O13,R13,P13,Q13) -> 0 | J13: =L13+N13 -> 0 | K13: =J13-M13 -> 0 | L13: 0 | N13: 0 | O13: 0 | P13: 0 | Q13: 0 | R13: 0 | S13: ='3. 외주비&재료비'!$J$21 -> 0 | U13: =IFERROR($O$12/$G$12,"0%") -> 0 | V13: =IFERROR(O12/I12,"0%") -> 0
D14: 인건비 | G14: =SUM(I14,S14) -> 9220418 | H14: =G14-M14 -> 9220418 | I14: =SUM(I15:I18) -> 9220418 | J14: =L14+N14 -> 9220418 | K14: =J14-M14 -> 9220418 | L14: =SUM(L15:L18) -> 9220418 | N14: =SUM(N15:N18) -> 0 | O14: 0 | P14: =SUM(P15:P18) -> 0 | Q14: =SUM(Q15:Q18) -> 0 | R14: =SUM(R15:R18) -> 0 | S14: =SUM(S15:S18) -> 0
E15: 이사 | F15: 특급II | G15: =SUM(I15,S15) -> 0 | H15: =G15-M15 -> 0 | I15: =SUMIF('2. 인건비'!$F:$F,손익시뮬레이션!$E15,'2. 인건비'!$I:$I)-S15 -> 0 | J15: =L15+N15 -> 0 | K15: =J15-M15 -> 0 | L15: =I15-P15-Q15-R15-S15 -> 0 | P15: =SUMIFS('2. 인건비'!$I$13:$I$52,'2. 인건비'!$E$13:$E$52,"유지보수",'2. 인건비'!$F$13:$F$52,손익시뮬레이션!$E15) -> 0 | Q15: =SUMIFS('2. 인건비'!$I$13:$I$52,'2. 인건비'!$E$13:$E$52,"ITO/원격운영",'2. 인건비'!$F$13:$F$52,손익시뮬레이션!$E15)-R15 -> 0 | R15: =SUMIFS('2. 인건비'!$I:$I,'2. 인건비'!C:C,"Nexplant MESplus CE",'2. 인건비'!$D:$D,"고객서비스그룹",'2. 인건비'!$E:$E,"ITO/원격운영",'2. 인건비'!$F:$F,손익시뮬레이션!$E15) -> 0 | S15: =SUMIFS('2. 인건비'!$I:$I,'2. 인건비'!$E:$E,"인프라TA",'2. 인건비'!$F:$F,손익시뮬레이션!$E15) -> 0
E16: CL4(수석) | F16: 특급II | G16: =SUM(I16,S16) -> 0 | H16: =G16-M16 -> 0 | I16: =SUMIF('2. 인건비'!$F:$F,손익시뮬레이션!$E16,'2. 인건비'!$I:$I)-S16 -> 0 | J16: =L16+N16 -> 0 | K16: =J16-M16 -> 0 | L16: =I16-P16-Q16-R16-S16 -> 0 | P16: =SUMIFS('2. 인건비'!$I$13:$I$52,'2. 인건비'!$E$13:$E$52,"유지보수",'2. 인건비'!$F$13:$F$52,손익시뮬레이션!$E16) -> 0 | Q16: =SUMIFS('2. 인건비'!$I$13:$I$52,'2. 인건비'!$E$13:$E$52,"ITO/원격운영",'2. 인건비'!$F$13:$F$52,손익시뮬레이션!$E16)-R16 -> 0 | R16: =SUMIFS('2. 인건비'!$I:$I,'2. 인건비'!C:C,"Nexplant MESplus CE",'2. 인건비'!$D:$D,"고객서비스그룹",'2. 인건비'!$E:$E,"ITO/원격운영",'2. 인건비'!$F:$F,손익시뮬레이션!$E16) -> 0 | S16: =SUMIFS('2. 인건비'!$I:$I,'2. 인건비'!$E:$E,"인프라TA",'2. 인건비'!$F:$F,손익시뮬레이션!$E16) -> 0
E17: CL3(책임-수석보) | F17: 고급II-특급II | G17: =SUM(I17,S17) -> 9220418 | H17: =G17-M17 -> 9220418 | I17: =SUMIF('2. 인건비'!$F:$F,손익시뮬레이션!$E17,'2. 인건비'!$I:$I)-S17 -> 9220418 | J17: =L17+N17 -> 9220418 | K17: =J17-M17 -> 9220418 | L17: =I17-P17-Q17-R17-S17 -> 9220418 | P17: =SUMIFS('2. 인건비'!$I$13:$I$52,'2. 인건비'!$E$13:$E$52,"유지보수",'2. 인건비'!$F$13:$F$52,손익시뮬레이션!$E17) -> 0 | Q17: =SUMIFS('2. 인건비'!$I$13:$I$52,'2. 인건비'!$E$13:$E$52,"ITO/원격운영",'2. 인건비'!$F$13:$F$52,손익시뮬레이션!$E17)-R17 -> 0 | R17: =SUMIFS('2. 인건비'!$I:$I,'2. 인건비'!C:C,"Nexplant MESplus CE",'2. 인건비'!$D:$D,"고객서비스그룹",'2. 인건비'!$E:$E,"ITO/원격운영",'2. 인건비'!$F:$F,손익시뮬레이션!$E17) -> 0 | S17: =SUMIFS('2. 인건비'!$I:$I,'2. 인건비'!$E:$E,"인프라TA",'2. 인건비'!$F:$F,손익시뮬레이션!$E17) -> 0
E18: CL2(사원-선임) | F18: 초급II-고급I | G18: =SUM(I18,S18) -> 0 | H18: =G18-M18 -> 0 | I18: =SUMIF('2. 인건비'!$F:$F,손익시뮬레이션!$E18,'2. 인건비'!$I:$I)-S18 -> 0 | J18: =L18+N18 -> 0 | K18: =J18-M18 -> 0 | L18: =I18-P18-Q18-R18-S18 -> 0 | P18: =SUMIFS('2. 인건비'!$I$13:$I$52,'2. 인건비'!$E$13:$E$52,"유지보수",'2. 인건비'!$F$13:$F$52,손익시뮬레이션!$E18) -> 0 | Q18: =SUMIFS('2. 인건비'!$I$13:$I$52,'2. 인건비'!$E$13:$E$52,"ITO/원격운영",'2. 인건비'!$F$13:$F$52,손익시뮬레이션!$E18)-R18 -> 0 | R18: =SUMIFS('2. 인건비'!$I:$I,'2. 인건비'!C:C,"Nexplant MESplus CE",'2. 인건비'!$D:$D,"고객서비스그룹",'2. 인건비'!$E:$E,"ITO/원격운영",'2. 인건비'!$F:$F,손익시뮬레이션!$E18) -> 0 | S18: =SUMIFS('2. 인건비'!$I:$I,'2. 인건비'!$E:$E,"인프라TA",'2. 인건비'!$F:$F,손익시뮬레이션!$E18) -> 0
E19: M/M | G19: =SUM(I19,S19) -> 1 | H19: =G19-M19 -> 1 | I19: =SUM(I20:I23) -> 1 | J19: =L19+N19 -> 1 | K19: =SUM(K20:K23) -> 1 | L19: =SUM(L20:L23) -> 1 | M19: =SUM(M20:M23) -> 0 | N19: ='3. 외주비&재료비'!$H$3 -> 0 | O19: =SUM(O20:O23) -> 0 | P19: =SUM(P20:P23) -> 0 | Q19: =SUM(Q20:Q23) -> 0 | R19: =SUM(R20:R23) -> 0 | S19: =SUM(S20:S23) -> 0
E20: 이사 | F20: 특급II | G20: =SUM(I20,S20) -> 0 | H20: =G20-M20 -> 0 | I20: =SUM(J20,P20,Q20,R20) -> 0 | J20: =L20+N20 -> 0 | K20: =J20-M20 -> 0 | L20: =SUMIF('2. 인건비'!$F:$F,손익시뮬레이션!$E20,'2. 인건비'!$H:$H)-P20-Q20-R20-S20 -> 0 | P20: =SUMIFS('2. 인건비'!$H$13:$H$52,'2. 인건비'!$E$13:$E$52,"유지보수",'2. 인건비'!$F$13:$F$52,손익시뮬레이션!$E20) -> 0 | Q20: =SUMIFS('2. 인건비'!$H$13:$H$52,'2. 인건비'!$E$13:$E$52,"ITO/원격운영",'2. 인건비'!$F$13:$F$52,손익시뮬레이션!$E20)-R20 -> 0 | R20: =SUMIFS('2. 인건비'!$H:$H,'2. 인건비'!C:C,"Nexplant MESplus CE",'2. 인건비'!$D:$D,"고객서비스그룹",'2. 인건비'!$E:$E,"ITO/원격운영",'2. 인건비'!$F:$F,손익시뮬레이션!$E20) -> 0 | S20: =SUMIFS('2. 인건비'!$H:$H,'2. 인건비'!$E:$E,"인프라TA",'2. 인건비'!$F:$F,손익시뮬레이션!$E20) -> 0
E21: CL4(수석) | F21: 특급II | G21: =SUM(I21,S21) -> 0 | H21: =G21-M21 -> 0 | I21: =SUM(J21,P21,Q21,R21) -> 0 | J21: =L21+N21 -> 0 | K21: =J21-M21 -> 0 | L21: =SUMIF('2. 인건비'!$F:$F,손익시뮬레이션!$E21,'2. 인건비'!$H:$H)-P21-Q21-R21-S21 -> 0 | P21: =SUMIFS('2. 인건비'!$H$13:$H$52,'2. 인건비'!$E$13:$E$52,"유지보수",'2. 인건비'!$F$13:$F$52,손익시뮬레이션!$E21) -> 0 | Q21: =SUMIFS('2. 인건비'!$H$13:$H$52,'2. 인건비'!$E$13:$E$52,"ITO/원격운영",'2. 인건비'!$F$13:$F$52,손익시뮬레이션!$E21)-R21 -> 0 | R21: =SUMIFS('2. 인건비'!$H:$H,'2. 인건비'!C:C,"Nexplant MESplus CE",'2. 인건비'!$D:$D,"고객서비스그룹",'2. 인건비'!$E:$E,"ITO/원격운영",'2. 인건비'!$F:$F,손익시뮬레이션!$E21) -> 0 | S21: =SUMIFS('2. 인건비'!$H:$H,'2. 인건비'!$E:$E,"인프라TA",'2. 인건비'!$F:$F,손익시뮬레이션!$E21) -> 0
E22: CL3(책임-수석보) | F22: 고급II-특급II | G22: =SUM(I22,S22) -> 1 | H22: =G22-M22 -> 1 | I22: =SUM(J22,P22,Q22,R22) -> 1 | J22: =L22+N22 -> 1 | K22: =J22-M22 -> 1 | L22: =SUMIF('2. 인건비'!$F:$F,손익시뮬레이션!$E22,'2. 인건비'!$H:$H)-P22-Q22-R22-S22 -> 1 | P22: =SUMIFS('2. 인건비'!$H$13:$H$52,'2. 인건비'!$E$13:$E$52,"유지보수",'2. 인건비'!$F$13:$F$52,손익시뮬레이션!$E22) -> 0 | Q22: =SUMIFS('2. 인건비'!$H$13:$H$52,'2. 인건비'!$E$13:$E$52,"ITO/원격운영",'2. 인건비'!$F$13:$F$52,손익시뮬레이션!$E22)-R22 -> 0 | R22: =SUMIFS('2. 인건비'!$H:$H,'2. 인건비'!C:C,"Nexplant MESplus CE",'2. 인건비'!$D:$D,"고객서비스그룹",'2. 인건비'!$E:$E,"ITO/원격운영",'2. 인건비'!$F:$F,손익시뮬레이션!$E22) -> 0 | S22: =SUMIFS('2. 인건비'!$H:$H,'2. 인건비'!$E:$E,"인프라TA",'2. 인건비'!$F:$F,손익시뮬레이션!$E22) -> 0
E23: CL2(사원-선임) | F23: 초급II-고급I | G23: =SUM(I23,S23) -> 0 | H23: =G23-M23 -> 0 | I23: =SUM(J23,P23,Q23,R23) -> 0 | J23: =L23+N23 -> 0 | K23: =J23-M23 -> 0 | L23: =SUMIF('2. 인건비'!$F:$F,손익시뮬레이션!$E23,'2. 인건비'!$H:$H)-P23-Q23-R23-S23 -> 0 | P23: =SUMIFS('2. 인건비'!$H$13:$H$52,'2. 인건비'!$E$13:$E$52,"유지보수",'2. 인건비'!$F$13:$F$52,손익시뮬레이션!$E23) -> 0 | Q23: =SUMIFS('2. 인건비'!$H$13:$H$52,'2. 인건비'!$E$13:$E$52,"ITO/원격운영",'2. 인건비'!$F$13:$F$52,손익시뮬레이션!$E23)-R23 -> 0 | R23: =SUMIFS('2. 인건비'!$H:$H,'2. 인건비'!C:C,"Nexplant MESplus CE",'2. 인건비'!$D:$D,"고객서비스그룹",'2. 인건비'!$E:$E,"ITO/원격운영",'2. 인건비'!$F:$F,손익시뮬레이션!$E23) -> 0 | S23: =SUMIFS('2. 인건비'!$H:$H,'2. 인건비'!$E:$E,"인프라TA",'2. 인건비'!$F:$F,손익시뮬레이션!$E23) -> 0
D24: 인건비성 복리후생비 | G24: ='2. 인건비'!$J$12 -> 817567 | H24: =G24-M24 -> 817567 | I24: =G24-S24 -> 817567 | J24: =L24+N24 -> 817567 | K24: =J24-M24 -> 817567 | L24: =I24-P24-Q24-R24-S24 -> 817567 | N24: 0 | O24: 0 | P24: =SUMIF('2. 인건비'!$E$13:$E$52,"유지보수",'2. 인건비'!$J$13:$J$52) -> 0 | Q24: =SUMIF('2. 인건비'!$E$13:$E$52,"ITO/원격운영",'2. 인건비'!$J$13:$J$52)-R24 -> 0 | R24: =SUMIFS('2. 인건비'!$J:$J,'2. 인건비'!C:C,"Nexplant MESplus CE",'2. 인건비'!$D:$D,"고객서비스그룹",'2. 인건비'!$E:$E,"ITO/원격운영") -> 0 | S24: =SUMIFS('2. 인건비'!$J:$J,'2. 인건비'!$E:$E,"인프라TA",'2. 인건비'!$F:$F,손익시뮬레이션!$E24) -> 0
D25: 외주비 | G25: =SUM(I25,S25) -> 0 | H25: =G25-M25 -> 0 | I25: =SUM(J25,O25,R25,P25,Q25) -> 0 | J25: =L25+N25 -> 0 | K25: =J25-M25 -> 0 | L25: 0 | N25: =SUMIF('3. 외주비&재료비'!$E$6:$E$17,"서비스",'3. 외주비&재료비'!$I$6:$I$17) -> 0 | O25: 0 | P25: =SUMIF('3. 외주비&재료비'!$G$6:$G$17,"maintenance",'3. 외주비&재료비'!$I$6:$I$17) -> 0 | Q25: =SUMIFS('3. 외주비&재료비'!$I$6:$I$17,'3. 외주비&재료비'!$E$6:$E$17,"ITO/원격운영",'3. 외주비&재료비'!$G$6:$G$17,"Development") -> 0 | R25: 0 | S25: 0
D26: 경비 | G26: =SUM(I26,S26) -> 3545000 | H26: =G26-M26 -> 3545000 | I26: =SUM(J26,O26,R26,P26,Q26) -> 3545000 | J26: =L26+N26 -> 3545000 | K26: =J26-M26 -> 3545000 | L26: ='4. 경비(실비정산성경비)'!E21-R26-Q26-P26 -> 3545000 | M26: =$M$12 -> 0 | N26: 0 | O26: 0 | P26: =IF(AND('5. 수주액 상세'!D4<>"",'5. 수주액 상세'!$D$4="유지보수"),'4. 경비(실비정산성경비)'!$N$21,0) -> 0 | Q26: =IF(AND('5. 수주액 상세'!D4<>"",'5. 수주액 상세'!$D$4="ITO/원격운영"),'4. 경비(실비정산성경비)'!$N$21,0) -> 0 | R26: =IF($R$12>0,'4. 경비(실비정산성경비)'!$N$21) -> FALSE | S26: 0
E27: 추가 시간외수당 | G27: =SUM(I27,S27) -> 0 | H27: =G27-M27 -> 0 | I27: =SUM(J27,O27,R27,P27,Q27) -> 0 | J27: =L27+N27 -> 0 | K27: =J27-M27 -> 0 | L27: ='4. 경비(실비정산성경비)'!$E$22-R27-Q27 -> 0 | N27: 0 | O27: 0 | P27: 0 | Q27: =IF('4. 경비(실비정산성경비)'!$D$22="반영",IFERROR(Q14*3%,0),0) -> 0 | R27: 0 | S27: 0 | U27: 위험비용 비율
D28: ="위험비용("&(TEXT('5. 수주액 상세'!D43,"0.0%")&")") -> 위험비용(1.0%) | G28: =SUM(I28,S28) -> 246000 | H28: =G28-M28 -> 246000 | I28: =SUM(J28,O28,R28,P28,Q28) -> 246000 | J28: =L28+N28 -> 246000 | K28: =J28-M28 -> 246000 | L28: =$L$12*$U$29 -> 246000 | N28: =$N$12*$U$29 -> 0 | O28: 0 | P28: 0 | Q28: =Q12*U29 -> 0 | R28: =R12*U29 -> 0 | S28: =$S$12*$V$29 -> 0 | U28: 서비스 | V28: HW
C29: 계 | G29: =G28+G26+G25+G24+G14+G13 -> 13828985 | H29: =G29-M29 -> 13828985 | I29: =I28+I26+I25+I24+I14+I13 -> 13828985 | J29: =J28+J26+J25+J24+J14+J13 -> 13828985 | K29: =K28+K26+K25+K24+K14+K13 -> 13828985 | L29: =L28+L26+L25+L24+L14+L13 -> 13828985 | M29: =M28+M26+M25+M24+M14+M13 -> 0 | N29: =N28+N26+N25+N24+N14+N13 -> 0 | O29: =O28+O26+O25+O24+O14+O13 -> 0 | P29: =P28+P26+P25+P24+P14+P13 -> 0 | ... S29: =S28+S26+S25+S24+S14+S13 -> 0 | U29: ='5. 수주액 상세'!$I$4 -> 0.01 | V29: ='5. 수주액 상세'!$I$5 -> 0
C30: 한계이익 | G30: =G12-G29 -> 10771015 | H30: =H12-H29 -> 10771015 | I30: =I12-I29 -> 10771015 | J30: =J12-J29 -> 10771015 | K30: =K12-K29 -> 10771015 | L30: =L12-L29 -> 10771015 | M30: =M12-M29 -> 0 | N30: =N12-N29 -> 0 | ... S30: =S12-S29 -> 0
C31: (%) | G31: =IFERROR(G30/G12,0) -> 0.43784614 | H31: =IFERROR(H30/H12,0) -> 0.43784614 | I31: =IFERROR(I30/I12,0) -> 0.43784614 | J31: =IFERROR(J30/J12,0) -> 0.43784614 | K31: =IFERROR(K30/K12,0) -> 0.43784614 | L31: =IFERROR(L30/L12,0) -> 0.43784614 | M31: =IFERROR(M30/M12,0) -> 0 | N31: =IFERROR(N30/N12,0) -> 0 | ... S31: =IFERROR(S30/S12,0) -> 0
C32: 사전영업비 | G32: =SUM(I32,S32) -> 0 | H32: =G32-M32 -> 0 | I32: =SUM(J32,O32,R32,P32,Q32) -> 0 | J32: =L32+N32 -> 0 | K32: =J32-M32 -> 0 | L32: ='2-1. 사전영업비'!E2 -> 0 | M32: 0 | N32: 0 | O32: 0 | P32: 0 | Q32: 0 | R32: 0 | S32: 0
C33: 간접비 | G33: =SUM(I33,S33) -> 3445776 | H33: =G33-M33 -> 3445776 | I33: =SUM(J33,O33,R33,P33,Q33) -> 3445776 | J33: =L33+N33 -> 3445776 | K33: =J33-M33 -> 3445776 | L33: ='간접비 계산'!F23 -> 3445776 | M33: 0 | N33: ='간접비 계산'!G23 -> 0 | O33: 0 | P33: ='간접비 계산'!J23 -> 0 | Q33: ='간접비 계산'!K23 -> 0 | R33: ='간접비 계산'!L23 -> 0 | S33: ='간접비 계산'!M23 -> 0
C34: 판매비 | G34: =SUM(I34,S34) -> 2214000 | H34: =G34-M34 -> 2214000 | I34: =SUM(J34,O34,R34,P34,Q34) -> 2214000 | J34: =L34+N34 -> 2214000 | K34: =J34-M34 -> 2214000 | L34: ='간접비 계산'!F44 -> 2214000 | M34: 0 | N34: ='간접비 계산'!G44 -> 0 | O34: 0 | P34: ='간접비 계산'!J44 -> 0 | Q34: ='간접비 계산'!K44 -> 0 | R34: ='간접비 계산'!L44 -> 0 | S34: ='간접비 계산'!M44 -> 0
C35: 공헌이익 | G35: =G30-G32-G33-G34 -> 5111239 | H35: =H30-H32-H33-H34 -> 5111239 | I35: =I30-I32-I33-I34 -> 5111239 | J35: =J30-J32-J33-J34 -> 5111239 | K35: =K30-K32-K33-K34 -> 5111239 | L35: =L30-L32-L33-L34 -> 5111239 | M35: =M30-M32-M33-M34 -> 0 | N35: =N30-N32-N33-N34 -> 0 | ... S35: =S30-S32-S33-S34 -> 0
C36: (%) | G36: =IFERROR(G35/G12,0) -> 0.20777394 | H36: =IFERROR(H35/H12,0) -> 0.20777394 | I36: =IFERROR(I35/I12,0) -> 0.20777394 | J36: =IFERROR(J35/J12,0) -> 0.20777394 | K36: =IFERROR(K35/K12,0) -> 0.20777394 | L36: =IFERROR(L35/L12,0) -> 0.20777394 | M36: =IFERROR(M35/M12,0) -> 0 | N36: =IFERROR(N35/N12,0) -> 0 | ... S36: =IFERROR(S35/S12,0) -> 0
C37: 일반비 | G37: =SUM(I37,S37) -> 1890410 | H37: =G37-M37 -> 1890410 | I37: =SUM(J37,O37,R37,P37,Q37) -> 1890410 | J37: =L37+N37 -> 1890410 | K37: =J37-M37 -> 1890410 | L37: ='간접비 계산'!F65 -> 1890410 | M37: 0 | N37: ='간접비 계산'!G65+'간접비 계산'!H65 -> 0 | O37: 0 | P37: ='간접비 계산'!J65 -> 0 | Q37: ='간접비 계산'!K65 -> 0 | R37: ='간접비 계산'!L65 -> 0 | S37: ='간접비 계산'!M65 -> 0
C38: 솔루션표준원가(28%) | G38: =SUM(I38,S38) -> 0 | H38: =G38-M38 -> 0 | I38: =SUM(J38,O38,R38,P38,Q38) -> 0 | J38: 0 | K38: 0 | L38: 0 | M38: 0 | N38: 0 | O38: =O12*0.28 -> 0 | P38: 0 | Q38: 0 | R38: =(R12-R14-R24-R26)*0.28 -> 0 | S38: 0
C39: 영업이익 | G39: =G35-G38-G37 -> 3220829 | H39: =H35-H38-H37 -> 3220829 | I39: =I35-I38-I37 -> 3220829 | J39: =J35-J38-J37 -> 3220829 | K39: =K35-K38-K37 -> 3220829 | L39: =L35-L38-L37 -> 3220829 | M39: =M35-M38-M37 -> 0 | N39: =N35-N38-N37 -> 0 | ... S39: =S35-S38-S37 -> 0
C40: (%) | G40: =IFERROR(G39/G12,0) -> 0.13092801 | H40: =IFERROR(H39/H12,0) -> 0.13092801 | I40: =IFERROR(I39/I12,0) -> 0.13092801 | J40: =IFERROR(J39/J12,0) -> 0.13092801 | K40: =IFERROR(K39/K12,0) -> 0.13092801 | L40: =IFERROR(L39/L12,0) -> 0.13092801 | M40: =IFERROR(M39/M12,0) -> 0 | N40: =IFERROR(N39/N12,0) -> 0 | ... S40: =IFERROR(S39/S12,0) -> 0
D41: 표준원가 제외 영업이익 | G41: =G39+G38 -> 3220829 | H41: =H39+H38 -> 3220829 | I41: =I39+I38 -> 3220829 | J41: =J39+J38 -> 3220829 | K41: =K39+K38 -> 3220829 | L41: =L39+L38 -> 3220829 | M41: =M39+M38 -> 0 | N41: =N39+N38 -> 0 | ... S41: =S39+S38 -> 0
D42: (%) | G42: =G41/G12 -> 0.13092801 | H42: =H41/H12 -> 0.13092801 | I42: =I41/I12 -> 0.13092801 | J42: =J41/J12 -> 0.13092801 | K42: =K41/K12 -> 0.13092801 | L42: =L41/L12 -> 0.13092801 | M42: =M41/M12 -> #DIV/0! | N42: =N41/N12 -> #DIV/0! | ... S42: =S41/S12 -> #DIV/0!
C44: 총간접원가 | G44: =SUM(G32,G33,G34,G38,G37) -> 7550186 | H44: =SUM(H32,H33,H34,H38,H37) -> 7550186 | I44: =SUM(I32,I33,I34,I38,I37) -> 7550186 | J44: =SUM(J32,J33,J34,J38,J37) -> 7550186 | K44: =SUM(K32,K33,K34,K38,K37) -> 7550186 | L44: =SUM(L32,L33,L34,L38,L37) -> 7550186 | M44: =SUM(M32,M33,M34,M38,M37) -> 0 | N44: =SUM(N32,N33,N34,N38,N37) -> 0 | ... S44: =SUM(S32,S33,S34,S38,S37) -> 0

Sheet input=>

Sheet 1. 판매품의서
B2: 판매(계약)품의서
B4: 1. 사업정보
B5: 수주부서 | F5: 솔루션사업3파트 | O5: 영업대표 | U5: 장세훈
B6: PROJECT 명 | F6: [스태츠칩팩코리아] 인천공장 Defect E-Test 자동 분석 시스템 구축 POC | O6: PROJECT CODE | U6: SIC-26159711-A5
B7: 계약기간 | F7: 2026.10.01 | J7: ~ | L7: 2026.10.31 | O7: BO CODE | U7: SDS-26159710
B8: PJT유형 | F8: 구축 | O8: 대내외 | U8: 대외
B10: 구분 | G10: 회사이름 | N10: 사업자번호 | T10: 회사 주소지
B11: 고객사 | G11: 스태츠칩팩코리아 | T11: 인천 영종도
B12: 원청사 | G12: 스태츠칩팩코리아 | T12: 인천 영종도
B14: 2. 수주정보
B15: 총계 | G15: 계약금액 | N15: 한계이익 | T15: 한계이익률 | W15: 비고
G16: =SUM(G17:M22) -> 24600000 | N16: =SUM(N17:S22) -> 10771015 | T16: =IFERROR(N16/G16,0) -> 0.43784614
C17: 자사솔루션 | G17: =손익시뮬레이션!O12 -> 0 | N17: =손익시뮬레이션!O30 -> 0 | T17: =IFERROR(N17/G17,0) -> 0 | W17: 자체솔루션
C18: 서비스 | G18: =손익시뮬레이션!J12 -> 24600000 | N18: =손익시뮬레이션!J30 -> 10771015 | T18: =IFERROR(N18/G18,0) -> 0.43784614 | W18: 자체 / 외주 용역
C19: 유지보수 | G19: =손익시뮬레이션!P12 -> 0 | N19: =손익시뮬레이션!P30 -> 0 | T19: =IFERROR(N19/G19,0) -> 0 | W19: 유지보수(MA)
C20: 운영 | G20: =손익시뮬레이션!Q12 -> 0 | N20: =손익시뮬레이션!Q30 -> 0 | T20: =IFERROR(N20/G20,0) -> 0 | W20: ITO / 원격운영
C21: HW/도입솔루션 | G21: =손익시뮬레이션!S12 -> 0 | N21: =손익시뮬레이션!S30 -> 0 | T21: =IFERROR(N21/G21,0) -> 0 | W21: H/W 및 S/W
C22: =손익시뮬레이션!$R$8 -> MES CE 구독료 | G22: =손익시뮬레이션!R12 -> 0 | N22: =손익시뮬레이션!R30 -> 0 | T22: =IFERROR(N22/G22,0) -> 0 | W22: MES CE 구독료
B24: 3. 대금조건
B25: 수금조건 | G25: 현금화예정일 | N25: 지급조건 | U25: 비고 | V25: 보통 현금 60일 결제조건
B26: 현금 | G26: 60 | M26: day | N26: 수금후 결제
B28: 4. 무상유지보수조건
B29: Warranty - In | G29: H/W | S29: 용역(기타)
B30: 기간
B31: 요율
B33: 5. 수행인원 | H33: Nexplant MESplus MES | J33: Nexplant MESplus SR | L33: Nexplant MESplus MC | N33: Nexplant MESplus QMS | P33: Nexplant MESplus CE | R33: Nexplant MESplus FMB | T33: Nexplant MESplus H101 | V33: AX/RX | X33: ERP | Z33: MSP | AB33: 기타
D34: 성명 | F34: 총투입MM | H34: MES | J34: SR | L34: MC | N34: QMS | P34: CE | R34: FMB | T34: H101 | V34: AX/RX | X34: ERP | Z34: MSP | AB34: 기타 | AD34: 비고
B35: PM | D35: 정병주
B36: 정규인력 | F36: =SUM(H36:AE36) -> 1 | H36: =SUMIF('2. 인건비'!$C$13:$C$52,'1. 판매품의서'!H$33,'2. 인건비'!$H$13:$H$52) -> 0 | J36: =SUMIF('2. 인건비'!$C$13:$C$52,'1. 판매품의서'!J$33,'2. 인건비'!$H$13:$H$52) -> 0 | L36: =SUMIF('2. 인건비'!$C$13:$C$52,'1. 판매품의서'!L$33,'2. 인건비'!$H$13:$H$52) -> 0 | N36: =SUMIF('2. 인건비'!$C$13:$C$52,'1. 판매품의서'!N$33,'2. 인건비'!$H$13:$H$52) -> 1 | P36: =SUMIF('2. 인건비'!$C$13:$C$52,'1. 판매품의서'!P$33,'2. 인건비'!$H$13:$H$52) -> 0 | R36: =SUMIF('2. 인건비'!$C$13:$C$52,'1. 판매품의서'!R$33,'2. 인건비'!$H$13:$H$52) -> 0 | T36: =SUMIF('2. 인건비'!$C$13:$C$52,'1. 판매품의서'!T$33,'2. 인건비'!$H$13:$H$52) -> 0 | V36: =SUMIF('2. 인건비'!$C$13:$C$52,'1. 판매품의서'!V$33,'2. 인건비'!$H$13:$H$52) -> 0 | X36: =SUMIF('2. 인건비'!$C$13:$C$52,'1. 판매품의서'!X$33,'2. 인건비'!$H$13:$H$52) -> 0 | Z36: =SUMIF('2. 인건비'!$C$13:$C$52,'1. 판매품의서'!Z$33,'2. 인건비'!$H$13:$H$52) -> 0 | AB36: =SUMIF('2. 인건비'!$C$13:$C$52,'1. 판매품의서'!AB$33,'2. 인건비'!$H$13:$H$52) -> 0 | AD36: =SUMIF('2. 인건비'!$C$13:$C$52,'1. 판매품의서'!AD$33,'2. 인건비'!$H$13:$H$52) -> 0
B37: 외주인력 | F37: =SUM(H37:AE37) -> 0 | H37: =SUMIF('3. 외주비&재료비'!$C$6:$C$17,'1. 판매품의서'!H$33,'3. 외주비&재료비'!$H$6:$H$17) -> 0 | J37: =SUMIF('3. 외주비&재료비'!$C$6:$C$17,'1. 판매품의서'!J$33,'3. 외주비&재료비'!$H$6:$H$17) -> 0 | L37: =SUMIF('3. 외주비&재료비'!$C$6:$C$17,'1. 판매품의서'!L$33,'3. 외주비&재료비'!$H$6:$H$17) -> 0 | N37: =SUMIF('3. 외주비&재료비'!$C$6:$C$17,'1. 판매품의서'!N$33,'3. 외주비&재료비'!$H$6:$H$17) -> 0 | P37: =SUMIF('3. 외주비&재료비'!$C$6:$C$17,'1. 판매품의서'!P$33,'3. 외주비&재료비'!$H$6:$H$17) -> 0 | R37: =SUMIF('3. 외주비&재료비'!$C$6:$C$17,'1. 판매품의서'!R$33,'3. 외주비&재료비'!$H$6:$H$17) -> 0 | T37: =SUMIF('3. 외주비&재료비'!$C$6:$C$17,'1. 판매품의서'!T$33,'3. 외주비&재료비'!$H$6:$H$17) -> 0 | V37: =SUMIF('3. 외주비&재료비'!$C$6:$C$17,'1. 판매품의서'!V$33,'3. 외주비&재료비'!$H$6:$H$17) -> 0 | X37: =SUMIF('3. 외주비&재료비'!$C$6:$C$17,'1. 판매품의서'!X$33,'3. 외주비&재료비'!$H$6:$H$17) -> 0 | Z37: =SUMIF('3. 외주비&재료비'!$C$6:$C$17,'1. 판매품의서'!Z$33,'3. 외주비&재료비'!$H$6:$H$17) -> 0 | AB37: =SUMIF('3. 외주비&재료비'!$C$6:$C$17,'1. 판매품의서'!AB$33,'3. 외주비&재료비'!$H$6:$H$17) -> 0 | AD37: =SUMIF('3. 외주비&재료비'!$C$6:$C$17,'1. 판매품의서'!AD$33,'3. 외주비&재료비'!$H$6:$H$17) -> 0
B40: 6. 프로젝트 수행지역
B41: 인천 영종도
B43: * 기타사항
B44: 해당 프로젝트는 본사 기준 | L44: 70 | O44: KM 의 프로젝트 입니다.

Sheet 2. 인건비
B1: ◆ 인건비 내역
B2: 구분 | D2: M/M | E2: 인건비 | F2: 복리후생비
B3: On-Site | D3: =D7-D4-D6-D5 -> 1 | E3: =E7-E4-E6 -> 9220418 | F3: =F7-F4-F6 -> 817567
B4: Remote Development Center | D4: =SUMIF($D$13:$D$52,$B$4,$H$13:$H$52) -> 0 | E4: =SUMIF($D$13:$D$52,$B$4,$I$13:$I$52) -> 0 | F4: =SUMIF($D$13:$D$52,$B$4,$J$13:$J$52) -> 0 | DC4: 인상률
D5: 0 | DC5: 0.05
D6: =SUMIF($D$13:$D$52,$B$6,$H$13:$H$52) -> 0
B7: 합계 | D7: =SUBTOTAL(9,H13:H52) -> 1 | E7: =SUBTOTAL(9,$I13:$I52) -> 9220418 | F7: =SUBTOTAL(9,$J13:$J52) -> 817567
BN8: 산출인건비 | DO8: 복리후생비
C9: input only yellow cells | J9: *인건비성 복리후생비 (4대보험 및 국민연금) | M9: 투입공수(M/M) | BN9: 202601 | BO9: 202602 | BP9: 202603 | BQ9: 202604 | BR9: 202605 | BS9: 202606 | BT9: 202607 | BU9: 202608 | BV9: 202609 | BW9: 202610 | BX9: 202611 | BY9: 202612 | CA9: 202701 | CB9: 202702 | CC9: 202703 | CD9: 202704 | CE9: 202705 | CF9: 202706 | CG9: 202707 | CH9: 202708 | CI9: 202709 | CJ9: 202710 | CK9: 202711 | CL9: 202712 | CN9: 202801 | CO9: 202802 | CP9: 202803 | CQ9: 202804 | CR9: 202805 | CS9: 202806 | CT9: 202807 | CU9: 202808 | CV9: 202809 | CW9: 202810 | CX9: 202811 | CY9: 202812 | DA9: 202812 | DB9: 202812 | DC9: 202812 | DD9: 202812 | DE9: 202812 | DF9: 202812 | DG9: 202812 | DH9: 202812 | DI9: 202812 | DJ9: 202812 | DK9: 202812 | DL9: 202812 | DO9: 202601 | DP9: 202602 | DQ9: 202603 | DR9: 202604 | DS9: 202605 | DT9: 202606 | DU9: 202607 | DV9: 202608 | DW9: 202609 | DX9: 202610 | DY9: 202611 | DZ9: 202612 | EB9: 202701 | EC9: 202702 | ED9: 202703 | EE9: 202704 | EF9: 202705 | EG9: 202706 | EH9: 202707 | EI9: 202708 | EJ9: 202709 | EK9: 202710 | EL9: 202711 | EM9: 202712 | EO9: 202801 | EP9: 202802 | EQ9: 202803 | ER9: 202804 | ES9: 202805 | ET9: 202806 | EU9: 202807 | EV9: 202808 | EW9: 202809 | EX9: 202810 | EY9: 202811 | EZ9: 202812 | FB9: 202812 | FC9: 202812 | FD9: 202812 | FE9: 202812 | FF9: 202812 | FG9: 202812 | FH9: 202812 | FI9: 202812 | FJ9: 202812 | FK9: 202812 | FL9: 202812 | FM9: 202812
B10: No | C10: 사업구분 | D10: 조직 | E10: 투입유형 | F10: 新직급 ('20.6월~) | G10: 등급 | H10: M/M 합계 | I10: 인건비 | J10: 복리후생비* | K10: 비고 | M10: 2026 | Z10: 2027 | AM10: 2028 | AZ10: =AM10+1 -> 2029 | BN10: 2026 | CA10: 2027 | CN10: 2028 | DA10: 2029 | DU10: 2026 | EH10: 2027 | EU10: =EH10+1 -> 2028 | FH10: =EU10+1 -> 2029
M11: 1월 | N11: 2월 | O11: 3월 | P11: 4월 | Q11: 5월 | R11: 6월 | S11: 7월 | T11: 8월 | U11: 9월 | V11: 10월 | W11: 11월 | X11: 12월 | Y11: 계 | Z11: 1월 | AA11: 2월 | AB11: 3월 | AC11: 4월 | AD11: 5월 | AE11: 6월 | AF11: 7월 | AG11: 8월 | AH11: 9월 | AI11: 10월 | AJ11: 11월 | AK11: 12월 | AL11: 계 | AM11: 1월 | AN11: 2월 | AO11: 3월 | AP11: 4월 | AQ11: 5월 | AR11: 6월 | AS11: 7월 | AT11: 8월 | AU11: 9월 | AV11: 10월 | AW11: 11월 | AX11: 12월 | AY11: 계 | AZ11: 1월 | BA11: 2월 | BB11: 3월 | BC11: 4월 | BD11: 5월 | BE11: 6월 | BF11: 7월 | BG11: 8월 | BH11: 9월 | BI11: 10월 | BJ11: 11월 | BK11: 12월 | BL11: 계 | BN11: 1월 | BO11: 2월 | BP11: 3월 | BQ11: 4월 | BR11: 5월 | BS11: 6월 | BT11: 7월 | BU11: 8월 | BV11: 9월 | BW11: 10월 | BX11: 11월 | BY11: 12월 | BZ11: 계 | CA11: 1월 | CB11: 2월 | CC11: 3월 | CD11: 4월 | CE11: 5월 | CF11: 6월 | CG11: 7월 | CH11: 8월 | CI11: 9월 | CJ11: 10월 | CK11: 11월 | CL11: 12월 | CM11: 계 | CN11: 1월 | CO11: 2월 | CP11: 3월 | CQ11: 4월 | CR11: 5월 | CS11: 6월 | CT11: 7월 | CU11: 8월 | CV11: 9월 | CW11: 10월 | CX11: 11월 | CY11: 12월 | CZ11: 계 | DA11: 1월 | DB11: 2월 | DC11: 3월 | DD11: 4월 | DE11: 5월 | DF11: 6월 | DG11: 7월 | DH11: 8월 | DI11: 9월 | DJ11: 10월 | DK11: 11월 | DL11: 12월 | DM11: 계 | DO11: 1월 | DP11: 2월 | DQ11: 3월 | DR11: 4월 | DS11: 5월 | DT11: 6월 | DU11: 7월 | DV11: 8월 | DW11: 9월 | DX11: 10월 | DY11: 11월 | DZ11: 12월 | EA11: 계 | EB11: 1월 | EC11: 2월 | ED11: 3월 | EE11: 4월 | EF11: 5월 | EG11: 6월 | EH11: 7월 | EI11: 8월 | EJ11: 9월 | EK11: 10월 | EL11: 11월 | EM11: 12월 | EN11: 계 | EO11: 1월 | EP11: 2월 | EQ11: 3월 | ER11: 4월 | ES11: 5월 | ET11: 6월 | EU11: 7월 | EV11: 8월 | EW11: 9월 | EX11: 10월 | EY11: 11월 | EZ11: 12월 | FA11: 계 | FB11: 1월 | FC11: 2월 | FD11: 3월 | FE11: 4월 | FF11: 5월 | FG11: 6월 | FH11: 7월 | FI11: 8월 | FJ11: 9월 | FK11: 10월 | FL11: 11월 | FM11: 12월 | FN11: 계
B12: 합계 | H12: =SUM(H13:H52) -> 1 | I12: =SUM(I13:I52) -> 9220418 | J12: =SUM(J13:J52) -> 817567 | M12: =SUM(M13:M52) -> 0 | N12: =SUM(N13:N52) -> 0 | O12: =SUM(O13:O52) -> 0 | P12: =SUM(P13:P52) -> 0 | Q12: =SUM(Q13:Q52) -> 0 | R12: =SUM(R13:R52) -> 0 | S12: =SUM(S13:S52) -> 0 | T12: =SUM(T13:T52) -> 0 | ... BL12: =SUM(BL13:BL52) -> 0 | BN12: =SUM(BN13:BN52) -> 0 | BO12: =SUM(BO13:BO52) -> 0 | BP12: =SUM(BP13:BP52) -> 0 | BQ12: =SUM(BQ13:BQ52) -> 0 | BR12: =SUM(BR13:BR52) -> 0 | BS12: =SUM(BS13:BS52) -> 0 | BT12: =SUM(BT13:BT52) -> 0 | BU12: =SUM(BU13:BU52) -> 0 | ... DM12: =SUM(DM13:DM52) -> 0 | DO12: =SUM(DO13:DO52) -> 0 | DP12: =SUM(DP13:DP52) -> 0 | DQ12: =SUM(DQ13:DQ52) -> 0 | DR12: =SUM(DR13:DR52) -> 0 | DS12: =SUM(DS13:DS52) -> 0 | DT12: =SUM(DT13:DT52) -> 0 | DU12: =SUM(DU13:DU52) -> 0 | DV12: =SUM(DV13:DV52) -> 0 | ... FN12: =SUM(FN13:FN52) -> 0
B13: 1 | C13: Nexplant MESplus QMS | D13: MES실행그룹 | E13: 서비스 | F13: CL3(책임-수석보) | G13: =IFERROR(VLOOKUP($F13,Master!$B$1:$C$7,2,0),"-") -> 고급II-특급II | H13: =Y13+AL13+AY13+BL13 -> 1 | I13: =SUM(BZ13,CM13,CZ13,DM13) -> 9220418 | J13: =SUM(,EA13,EN13,FA13,FN13) -> 817567 | V13: 1 | Y13: =SUM(M13:X13) -> 1 | AL13: =SUM(Z13:AK13) -> 0 | AY13: =SUM(AM13:AX13) -> 0 | BL13: =SUM(AZ13:BK13) -> 0 | BN13: =ROUND(IFERROR(INDEX('Labor Cost_Master'!$G$4:$BC$135,MATCH($DN13,'Labor Cost_Master'!$BD$4:$BD$135,0),MATCH(BN$9,'Labor Cost_Master'!$G$3:$BC$3,0)),0)*M13,0) -> 0 | BO13: =ROUND(IFERROR(INDEX('Labor Cost_Master'!$G$4:$BC$135,MATCH($DN13,'Labor Cost_Master'!$BD$4:$BD$135,0),MATCH(BO$9,'Labor Cost_Master'!$G$3:$BC$3,0)),0)*N13,0) -> 0 | BP13: =ROUND(IFERROR(INDEX('Labor Cost_Master'!$G$4:$BC$135,MATCH($DN13,'Labor Cost_Master'!$BD$4:$BD$135,0),MATCH(BP$9,'Labor Cost_Master'!$G$3:$BC$3,0)),0)*O13,0) -> 0 | BQ13: =ROUND(IFERROR(INDEX('Labor Cost_Master'!$G$4:$BC$135,MATCH($DN13,'Labor Cost_Master'!$BD$4:$BD$135,0),MATCH(BQ$9,'Labor Cost_Master'!$G$3:$BC$3,0)),0)*P13,0) -> 0 | BR13: =ROUND(IFERROR(INDEX('Labor Cost_Master'!$G$4:$BC$135,MATCH($DN13,'Labor Cost_Master'!$BD$4:$BD$135,0),MATCH(BR$9,'Labor Cost_Master'!$G$3:$BC$3,0)),0)*Q13,0) -> 0 | BS13: =ROUND(IFERROR(INDEX('Labor Cost_Master'!$G$4:$BC$135,MATCH($DN13,'Labor Cost_Master'!$BD$4:$BD$135,0),MATCH(BS$9,'Labor Cost_Master'!$G$3:$BC$3,0)),0)*R13,0) -> 0 | BT13: =ROUND(IFERROR(INDEX('Labor Cost_Master'!$G$4:$BC$135,MATCH($DN13,'Labor Cost_Master'!$BD$4:$BD$135,0),MATCH(BT$9,'Labor Cost_Master'!$G$3:$BC$3,0)),0)*S13,0) -> 0 | BU13: =ROUND(IFERROR(INDEX('Labor Cost_Master'!$G$4:$BC$135,MATCH($DN13,'Labor Cost_Master'!$BD$4:$BD$135,0),MATCH(BU$9,'Labor Cost_Master'!$G$3:$BC$3,0)),0)*T13,0) -> 0 | ... BY13: =ROUND(IFERROR(INDEX('Labor Cost_Master'!$G$4:$BC$135,MATCH($DN13,'Labor Cost_Master'!$BD$4:$BD$135,0),MATCH(BY$9,'Labor Cost_Master'!$G$3:$BC$3,0)),0)*X13,0) -> 0 | BZ13: =SUM(BN13:BY13) -> 9220418 | CA13: =ROUND(IFERROR(INDEX('Labor Cost_Master'!$G$4:$BC$135,MATCH($DN13,'Labor Cost_Master'!$BD$4:$BD$135,0),MATCH(CA$9,'Labor Cost_Master'!$G$3:$BC$3,0)),0)*Z13,0) -> 0 | CB13: =ROUND(IFERROR(INDEX('Labor Cost_Master'!$G$4:$BC$135,MATCH($DN13,'Labor Cost_Master'!$BD$4:$BD$135,0),MATCH(CB$9,'Labor Cost_Master'!$G$3:$BC$3,0)),0)*AA13,0) -> 0 | CC13: =ROUND(IFERROR(INDEX('Labor Cost_Master'!$G$4:$BC$135,MATCH($DN13,'Labor Cost_Master'!$BD$4:$BD$135,0),MATCH(CC$9,'Labor Cost_Master'!$G$3:$BC$3,0)),0)*AB13,0) -> 0 | CD13: =ROUND(IFERROR(INDEX('Labor Cost_Master'!$G$4:$BC$135,MATCH($DN13,'Labor Cost_Master'!$BD$4:$BD$135,0),MATCH(CD$9,'Labor Cost_Master'!$G$3:$BC$3,0)),0)*AC13,0) -> 0 | CE13: =ROUND(IFERROR(INDEX('Labor Cost_Master'!$G$4:$BC$135,MATCH($DN13,'Labor Cost_Master'!$BD$4:$BD$135,0),MATCH(CE$9,'Labor Cost_Master'!$G$3:$BC$3,0)),0)*AD13,0) -> 0 | CF13: =ROUND(IFERROR(INDEX('Labor Cost_Master'!$G$4:$BC$135,MATCH($DN13,'Labor Cost_Master'!$BD$4:$BD$135,0),MATCH(CF$9,'Labor Cost_Master'!$G$3:$BC$3,0)),0)*AE13,0) -> 0 | CG13: =ROUND(IFERROR(INDEX('Labor Cost_Master'!$G$4:$BC$135,MATCH($DN13,'Labor Cost_Master'!$BD$4:$BD$135,0),MATCH(CG$9,'Labor Cost_Master'!$G$3:$BC$3,0)),0)*AF13,0) -> 0 | CH13: =ROUND(IFERROR(INDEX('Labor Cost_Master'!$G$4:$BC$135,MATCH($DN13,'Labor Cost_Master'!$BD$4:$BD$135,0),MATCH(CH$9,'Labor Cost_Master'!$G$3:$BC$3,0)),0)*AG13,0) -> 0 | ... CL13: =ROUND(IFERROR(INDEX('Labor Cost_Master'!$G$4:$BC$135,MATCH($DN13,'Labor Cost_Master'!$BD$4:$BD$135,0),MATCH(CL$9,'Labor Cost_Master'!$G$3:$BC$3,0)),0)*AK13,0) -> 0 | CM13: =SUM(CA13:CL13) -> 0 | CN13: =ROUND(IFERROR(INDEX('Labor Cost_Master'!$G$4:$BC$135,MATCH($DN13,'Labor Cost_Master'!$BD$4:$BD$135,0),MATCH(CN$9,'Labor Cost_Master'!$G$3:$BC$3,0)),0)*AM13,0) -> 0 | CO13: =ROUND(IFERROR(INDEX('Labor Cost_Master'!$G$4:$BC$135,MATCH($DN13,'Labor Cost_Master'!$BD$4:$BD$135,0),MATCH(CO$9,'Labor Cost_Master'!$G$3:$BC$3,0)),0)*AN13,0) -> 0 | CP13: =ROUND(IFERROR(INDEX('Labor Cost_Master'!$G$4:$BC$135,MATCH($DN13,'Labor Cost_Master'!$BD$4:$BD$135,0),MATCH(CP$9,'Labor Cost_Master'!$G$3:$BC$3,0)),0)*AO13,0) -> 0 | CQ13: =ROUND(IFERROR(INDEX('Labor Cost_Master'!$G$4:$BC$135,MATCH($DN13,'Labor Cost_Master'!$BD$4:$BD$135,0),MATCH(CQ$9,'Labor Cost_Master'!$G$3:$BC$3,0)),0)*AP13,0) -> 0 | CR13: =ROUND(IFERROR(INDEX('Labor Cost_Master'!$G$4:$BC$135,MATCH($DN13,'Labor Cost_Master'!$BD$4:$BD$135,0),MATCH(CR$9,'Labor Cost_Master'!$G$3:$BC$3,0)),0)*AQ13,0) -> 0 | CS13: =ROUND(IFERROR(INDEX('Labor Cost_Master'!$G$4:$BC$135,MATCH($DN13,'Labor Cost_Master'!$BD$4:$BD$135,0),MATCH(CS$9,'Labor Cost_Master'!$G$3:$BC$3,0)),0)*AR13,0) -> 0 | CT13: =ROUND(IFERROR(INDEX('Labor Cost_Master'!$G$4:$BC$135,MATCH($DN13,'Labor Cost_Master'!$BD$4:$BD$135,0),MATCH(CT$9,'Labor Cost_Master'!$G$3:$BC$3,0)),0)*AS13,0) -> 0 | CU13: =ROUND(IFERROR(INDEX('Labor Cost_Master'!$G$4:$BC$135,MATCH($DN13,'Labor Cost_Master'!$BD$4:$BD$135,0),MATCH(CU$9,'Labor Cost_Master'!$G$3:$BC$3,0)),0)*AT13,0) -> 0 | ... CY13: =ROUND(IFERROR(INDEX('Labor Cost_Master'!$G$4:$BC$135,MATCH($DN13,'Labor Cost_Master'!$BD$4:$BD$135,0),MATCH(CY$9,'Labor Cost_Master'!$G$3:$BC$3,0)),0)*AX13,0) -> 0 | CZ13: =SUM(CN13:CY13) -> 0 | DA13: =ROUND(IFERROR(INDEX('Labor Cost_Master'!$G$4:$BC$135,MATCH($DN13,'Labor Cost_Master'!$BD$4:$BD$135,0),MATCH(DA$9,'Labor Cost_Master'!$G$3:$BC$3,0)),0)*AZ13,0) -> 0 | DB13: =ROUND(IFERROR(INDEX('Labor Cost_Master'!$G$4:$BC$135,MATCH($DN13,'Labor Cost_Master'!$BD$4:$BD$135,0),MATCH(DB$9,'Labor Cost_Master'!$G$3:$BC$3,0)),0)*BA13,0) -> 0 | DC13: =ROUND(IFERROR(INDEX('Labor Cost_Master'!$G$4:$BC$135,MATCH($DN13,'Labor Cost_Master'!$BD$4:$BD$135,0),MATCH(DC$9,'Labor Cost_Master'!$G$3:$BC$3,0)),0)*BB13,0)*1.05 -> 0 | DD13: =ROUND(IFERROR(INDEX('Labor Cost_Master'!$G$4:$BC$135,MATCH($DN13,'Labor Cost_Master'!$BD$4:$BD$135,0),MATCH(DD$9,'Labor Cost_Master'!$G$3:$BC$3,0)),0)*BC13,0)*1.05 -> 0 | DE13: =ROUND(IFERROR(INDEX('Labor Cost_Master'!$G$4:$BC$135,MATCH($DN13,'Labor Cost_Master'!$BD$4:$BD$135,0),MATCH(DE$9,'Labor Cost_Master'!$G$3:$BC$3,0)),0)*BD13,0)*1.05 -> 0 | DF13: =ROUND(IFERROR(INDEX('Labor Cost_Master'!$G$4:$BC$135,MATCH($DN13,'Labor Cost_Master'!$BD$4:$BD$135,0),MATCH(DF$9,'Labor Cost_Master'!$G$3:$BC$3,0)),0)*BE13,0)*1.05 -> 0 | DG13: =ROUND(IFERROR(INDEX('Labor Cost_Master'!$G$4:$BC$135,MATCH($DN13,'Labor Cost_Master'!$BD$4:$BD$135,0),MATCH(DG$9,'Labor Cost_Master'!$G$3:$BC$3,0)),0)*BF13,0)*1.05 -> 0 | DH13: =ROUND(IFERROR(INDEX('Labor Cost_Master'!$G$4:$BC$135,MATCH($DN13,'Labor Cost_Master'!$BD$4:$BD$135,0),MATCH(DH$9,'Labor Cost_Master'!$G$3:$BC$3,0)),0)*BG13,0)*1.05 -> 0 | DI13: =ROUND(IFERROR(INDEX('Labor Cost_Master'!$G$4:$BC$135,MATCH($DN13,'Labor Cost_Master'!$BD$4:$BD$135,0),MATCH(DI$9,'Labor Cost_Master'!$G$3:$BC$3,0)),0)*BH13,0)*1.05 -> 0 | DJ13: =ROUND(IFERROR(INDEX('Labor Cost_Master'!$G$4:$BC$135,MATCH($DN13,'Labor Cost_Master'!$BD$4:$BD$135,0),MATCH(DJ$9,'Labor Cost_Master'!$G$3:$BC$3,0)),0)*BI13,0)*1.05 -> 0 | ... DL13: =ROUND(IFERROR(INDEX('Labor Cost_Master'!$G$4:$BC$135,MATCH($DN13,'Labor Cost_Master'!$BD$4:$BD$135,0),MATCH(DL$9,'Labor Cost_Master'!$G$3:$BC$3,0)),0)*BK13,0)*1.05 -> 0 | DM13: =SUM(DA13:DL13) -> 0 | DN13: =D13&F13 -> MES실행그룹CL3(책임-수석보) | DO13: =ROUND(IFERROR(INDEX(Benefit_Master!$G$4:$BC$135,MATCH($DN13,Benefit_Master!$BD$4:$BD$135,0),MATCH(DO$9,Benefit_Master!$G$3:$BC$3,0)),0)*M13,0) -> 0 | DP13: =ROUND(IFERROR(INDEX(Benefit_Master!$G$4:$BC$135,MATCH($DN13,Benefit_Master!$BD$4:$BD$135,0),MATCH(DP$9,Benefit_Master!$G$3:$BC$3,0)),0)*N13,0) -> 0 | DQ13: =ROUND(IFERROR(INDEX(Benefit_Master!$G$4:$BC$135,MATCH($DN13,Benefit_Master!$BD$4:$BD$135,0),MATCH(DQ$9,Benefit_Master!$G$3:$BC$3,0)),0)*O13,0) -> 0 | DR13: =ROUND(IFERROR(INDEX(Benefit_Master!$G$4:$BC$135,MATCH($DN13,Benefit_Master!$BD$4:$BD$135,0),MATCH(DR$9,Benefit_Master!$G$3:$BC$3,0)),0)*P13,0) -> 0 | DS13: =ROUND(IFERROR(INDEX(Benefit_Master!$G$4:$BC$135,MATCH($DN13,Benefit_Master!$BD$4:$BD$135,0),MATCH(DS$9,Benefit_Master!$G$3:$BC$3,0)),0)*Q13,0) -> 0 | DT13: =ROUND(IFERROR(INDEX(Benefit_Master!$G$4:$BC$135,MATCH($DN13,Benefit_Master!$BD$4:$BD$135,0),MATCH(DT$9,Benefit_Master!$G$3:$BC$3,0)),0)*R13,0) -> 0 | DU13: =ROUND(IFERROR(INDEX(Benefit_Master!$G$4:$BC$135,MATCH($DN13,Benefit_Master!$BD$4:$BD$135,0),MATCH(DU$9,Benefit_Master!$G$3:$BC$3,0)),0)*S13,0) -> 0 | DV13: =ROUND(IFERROR(INDEX(Benefit_Master!$G$4:$BC$135,MATCH($DN13,Benefit_Master!$BD$4:$BD$135,0),MATCH(DV$9,Benefit_Master!$G$3:$BC$3,0)),0)*T13,0) -> 0 | ... DZ13: =ROUND(IFERROR(INDEX(Benefit_Master!$G$4:$BC$135,MATCH($DN13,Benefit_Master!$BD$4:$BD$135,0),MATCH(DZ$9,Benefit_Master!$G$3:$BC$3,0)),0)*X13,0) -> 0 | EA13: =SUM(DO13:DZ13) -> 817567 | EB13: =ROUND(IFERROR(INDEX(Benefit_Master!$G$4:$BC$135,MATCH($DN13,Benefit_Master!$BD$4:$BD$135,0),MATCH(EB$9,Benefit_Master!$G$3:$BC$3,0)),0)*Z13,0) -> 0 | EC13: =ROUND(IFERROR(INDEX(Benefit_Master!$G$4:$BC$135,MATCH($DN13,Benefit_Master!$BD$4:$BD$135,0),MATCH(EC$9,Benefit_Master!$G$3:$BC$3,0)),0)*AA13,0) -> 0 | ED13: =ROUND(IFERROR(INDEX(Benefit_Master!$G$4:$BC$135,MATCH($DN13,Benefit_Master!$BD$4:$BD$135,0),MATCH(ED$9,Benefit_Master!$G$3:$BC$3,0)),0)*AB13,0) -> 0 | EE13: =ROUND(IFERROR(INDEX(Benefit_Master!$G$4:$BC$135,MATCH($DN13,Benefit_Master!$BD$4:$BD$135,0),MATCH(EE$9,Benefit_Master!$G$3:$BC$3,0)),0)*AC13,0) -> 0 | EF13: =ROUND(IFERROR(INDEX(Benefit_Master!$G$4:$BC$135,MATCH($DN13,Benefit_Master!$BD$4:$BD$135,0),MATCH(EF$9,Benefit_Master!$G$3:$BC$3,0)),0)*AD13,0) -> 0 | EG13: =ROUND(IFERROR(INDEX(Benefit_Master!$G$4:$BC$135,MATCH($DN13,Benefit_Master!$BD$4:$BD$135,0),MATCH(EG$9,Benefit_Master!$G$3:$BC$3,0)),0)*AE13,0) -> 0 | EH13: =ROUND(IFERROR(INDEX(Benefit_Master!$G$4:$BC$135,MATCH($DN13,Benefit_Master!$BD$4:$BD$135,0),MATCH(EH$9,Benefit_Master!$G$3:$BC$3,0)),0)*AF13,0) -> 0 | EI13: =ROUND(IFERROR(INDEX(Benefit_Master!$G$4:$BC$135,MATCH($DN13,Benefit_Master!$BD$4:$BD$135,0),MATCH(EI$9,Benefit_Master!$G$3:$BC$3,0)),0)*AG13,0) -> 0 | ... EM13: =ROUND(IFERROR(INDEX(Benefit_Master!$G$4:$BC$135,MATCH($DN13,Benefit_Master!$BD$4:$BD$135,0),MATCH(EM$9,Benefit_Master!$G$3:$BC$3,0)),0)*AK13,0) -> 0 | EN13: =SUM(EB13:EM13) -> 0 | EO13: =ROUND(IFERROR(INDEX(Benefit_Master!$G$4:$BC$135,MATCH($DN13,Benefit_Master!$BD$4:$BD$135,0),MATCH(EO$9,Benefit_Master!$G$3:$BC$3,0)),0)*AM13,0) -> 0 | EP13: =ROUND(IFERROR(INDEX(Benefit_Master!$G$4:$BC$135,MATCH($DN13,Benefit_Master!$BD$4:$BD$135,0),MATCH(EP$9,Benefit_Master!$G$3:$BC$3,0)),0)*AN13,0) -> 0 | EQ13: =ROUND(IFERROR(INDEX(Benefit_Master!$G$4:$BC$135,MATCH($DN13,Benefit_Master!$BD$4:$BD$135,0),MATCH(EQ$9,Benefit_Master!$G$3:$BC$3,0)),0)*AO13,0) -> 0 | ER13: =ROUND(IFERROR(INDEX(Benefit_Master!$G$4:$BC$135,MATCH($DN13,Benefit_Master!$BD$4:$BD$135,0),MATCH(ER$9,Benefit_Master!$G$3:$BC$3,0)),0)*AP13,0) -> 0 | ES13: =ROUND(IFERROR(INDEX(Benefit_Master!$G$4:$BC$135,MATCH($DN13,Benefit_Master!$BD$4:$BD$135,0),MATCH(ES$9,Benefit_Master!$G$3:$BC$3,0)),0)*AQ13,0) -> 0 | ET13: =ROUND(IFERROR(INDEX(Benefit_Master!$G$4:$BC$135,MATCH($DN13,Benefit_Master!$BD$4:$BD$135,0),MATCH(ET$9,Benefit_Master!$G$3:$BC$3,0)),0)*AR13,0) -> 0 | EU13: =ROUND(IFERROR(INDEX(Benefit_Master!$G$4:$BC$135,MATCH($DN13,Benefit_Master!$BD$4:$BD$135,0),MATCH(EU$9,Benefit_Master!$G$3:$BC$3,0)),0)*AS13,0) -> 0 | EV13: =ROUND(IFERROR(INDEX(Benefit_Master!$G$4:$BC$135,MATCH($DN13,Benefit_Master!$BD$4:$BD$135,0),MATCH(EV$9,Benefit_Master!$G$3:$BC$3,0)),0)*AT13,0) -> 0 | ... EZ13: =ROUND(IFERROR(INDEX(Benefit_Master!$G$4:$BC$135,MATCH($DN13,Benefit_Master!$BD$4:$BD$135,0),MATCH(EZ$9,Benefit_Master!$G$3:$BC$3,0)),0)*AX13,0) -> 0 | FA13: =SUM(EO13:EZ13) -> 0 | FB13: =ROUND(IFERROR(INDEX(Benefit_Master!$G$4:$BC$135,MATCH($DN13,Benefit_Master!$BD$4:$BD$135,0),MATCH(FB$9,Benefit_Master!$G$3:$BC$3,0)),0)*AZ13,0) -> 0 | FC13: =ROUND(IFERROR(INDEX(Benefit_Master!$G$4:$BC$135,MATCH($DN13,Benefit_Master!$BD$4:$BD$135,0),MATCH(FC$9,Benefit_Master!$G$3:$BC$3,0)),0)*BA13,0) -> 0 | FD13: =ROUND(IFERROR(INDEX(Benefit_Master!$G$4:$BC$135,MATCH($DN13,Benefit_Master!$BD$4:$BD$135,0),MATCH(FD$9,Benefit_Master!$G$3:$BC$3,0)),0)*BB13,0) -> 0 | FE13: =ROUND(IFERROR(INDEX(Benefit_Master!$G$4:$BC$135,MATCH($DN13,Benefit_Master!$BD$4:$BD$135,0),MATCH(FE$9,Benefit_Master!$G$3:$BC$3,0)),0)*BC13,0) -> 0 | FF13: =ROUND(IFERROR(INDEX(Benefit_Master!$G$4:$BC$135,MATCH($DN13,Benefit_Master!$BD$4:$BD$135,0),MATCH(FF$9,Benefit_Master!$G$3:$BC$3,0)),0)*BD13,0) -> 0 | FG13: =ROUND(IFERROR(INDEX(Benefit_Master!$G$4:$BC$135,MATCH($DN13,Benefit_Master!$BD$4:$BD$135,0),MATCH(FG$9,Benefit_Master!$G$3:$BC$3,0)),0)*BE13,0) -> 0 | FH13: =ROUND(IFERROR(INDEX(Benefit_Master!$G$4:$BC$135,MATCH($DN13,Benefit_Master!$BD$4:$BD$135,0),MATCH(FH$9,Benefit_Master!$G$3:$BC$3,0)),0)*BF13,0) -> 0 | FI13: =ROUND(IFERROR(INDEX(Benefit_Master!$G$4:$BC$135,MATCH($DN13,Benefit_Master!$BD$4:$BD$135,0),MATCH(FI$9,Benefit_Master!$G$3:$BC$3,0)),0)*BG13,0) -> 0 | ... FM13: =ROUND(IFERROR(INDEX(Benefit_Master!$G$4:$BC$135,MATCH($DN13,Benefit_Master!$BD$4:$BD$135,0),MATCH(FM$9,Benefit_Master!$G$3:$BC$3,0)),0)*BK13,0) -> 0 | FN13: =SUM(FB13:FM13) -> 0
B14: =+B13+1 -> 2 | G14: =IFERROR(VLOOKUP($F14,Master!$B$1:$C$7,2,0),"-") -> - | H14: =Y14+AL14+AY14+BL14 -> 0 | I14: =SUM(BZ14,CM14,CZ14,DM14) -> 0 | J14: =SUM(,EA14,EN14,FA14,FN14) -> 0 | Y14: =SUM(M14:X14) -> 0 | AL14: =SUM(Z14:AK14) -> 0 | AY14: =SUM(AM14:AX14) -> 0 | BL14: =SUM(AZ14:BK14) -> 0 | BN14: =ROUND(IFERROR(INDEX('Labor Cost_Master'!$G$4:$BC$135,MATCH($DN14,'Labor Cost_Master'!$BD$4:$BD$135,0),MATCH(BN$9,'Labor Cost_Master'!$G$3:$BC$3,0)),0)*M14,0) -> 0 | BO14: =ROUND(IFERROR(INDEX('Labor Cost_Master'!$G$4:$BC$135,MATCH($DN14,'Labor Cost_Master'!$BD$4:$BD$135,0),MATCH(BO$9,'Labor Cost_Master'!$G$3:$BC$3,0)),0)*N14,0) -> 0 | BP14: =ROUND(IFERROR(INDEX('Labor Cost_Master'!$G$4:$BC$135,MATCH($DN14,'Labor Cost_Master'!$BD$4:$BD$135,0),MATCH(BP$9,'Labor Cost_Master'!$G$3:$BC$3,0)),0)*O14,0) -> 0 | BQ14: =ROUND(IFERROR(INDEX('Labor Cost_Master'!$G$4:$BC$135,MATCH($DN14,'Labor Cost_Master'!$BD$4:$BD$135,0),MATCH(BQ$9,'Labor Cost_Master'!$G$3:$BC$3,0)),0)*P14,0) -> 0 | BR14: =ROUND(IFERROR(INDEX('Labor Cost_Master'!$G$4:$BC$135,MATCH($DN14,'Labor Cost_Master'!$BD$4:$BD$135,0),MATCH(BR$9,'Labor Cost_Master'!$G$3:$BC$3,0)),0)*Q14,0) -> 0 | BS14: =ROUND(IFERROR(INDEX('Labor Cost_Master'!$G$4:$BC$135,MATCH($DN14,'Labor Cost_Master'!$BD$4:$BD$135,0),MATCH(BS$9,'Labor Cost_Master'!$G$3:$BC$3,0)),0)*R14,0) -> 0 | BT14: =ROUND(IFERROR(INDEX('Labor Cost_Master'!$G$4:$BC$135,MATCH($DN14,'Labor Cost_Master'!$BD$4:$BD$135,0),MATCH(BT$9,'Labor Cost_Master'!$G$3:$BC$3,0)),0)*S14,0) -> 0 | BU14: =ROUND(IFERROR(INDEX('Labor Cost_Master'!$G$4:$BC$135,MATCH($DN14,'Labor Cost_Master'!$BD$4:$BD$135,0),MATCH(BU$9,'Labor Cost_Master'!$G$3:$BC$3,0)),0)*T14,0) -> 0 | ... BY14: =ROUND(IFERROR(INDEX('Labor Cost_Master'!$G$4:$BC$135,MATCH($DN14,'Labor Cost_Master'!$BD$4:$BD$135,0),MATCH(BY$9,'Labor Cost_Master'!$G$3:$BC$3,0)),0)*X14,0) -> 0 | BZ14: =SUM(BN14:BY14) -> 0 | CA14: =ROUND(IFERROR(INDEX('Labor Cost_Master'!$G$4:$BC$135,MATCH($DN14,'Labor Cost_Master'!$BD$4:$BD$135,0),MATCH(CA$9,'Labor Cost_Master'!$G$3:$BC$3,0)),0)*Z14,0) -> 0 | CB14: =ROUND(IFERROR(INDEX('Labor Cost_Master'!$G$4:$BC$135,MATCH($DN14,'Labor Cost_Master'!$BD$4:$BD$135,0),MATCH(CB$9,'Labor Cost_Master'!$G$3:$BC$3,0)),0)*AA14,0) -> 0 | CC14: =ROUND(IFERROR(INDEX('Labor Cost_Master'!$G$4:$BC$135,MATCH($DN14,'Labor Cost_Master'!$BD$4:$BD$135,0),MATCH(CC$9,'Labor Cost_Master'!$G$3:$BC$3,0)),0)*AB14,0) -> 0 | CD14: =ROUND(IFERROR(INDEX('Labor Cost_Master'!$G$4:$BC$135,MATCH($DN14,'Labor Cost_Master'!$BD$4:$BD$135,0),MATCH(CD$9,'Labor Cost_Master'!$G$3:$BC$3,0)),0)*AC14,0) -> 0 | CE14: =ROUND(IFERROR(INDEX('Labor Cost_Master'!$G$4:$BC$135,MATCH($DN14,'Labor Cost_Master'!$BD$4:$BD$135,0),MATCH(CE$9,'Labor Cost_Master'!$G$3:$BC$3,0)),0)*AD14,0) -> 0 | CF14: =ROUND(IFERROR(INDEX('Labor Cost_Master'!$G$4:$BC$135,MATCH($DN14,'Labor Cost_Master'!$BD$4:$BD$135,0),MATCH(CF$9,'Labor Cost_Master'!$G$3:$BC$3,0)),0)*AE14,0) -> 0 | CG14: =ROUND(IFERROR(INDEX('Labor Cost_Master'!$G$4:$BC$135,MATCH($DN14,'Labor Cost_Master'!$BD$4:$BD$135,0),MATCH(CG$9,'Labor Cost_Master'!$G$3:$BC$3,0)),0)*AF14,0) -> 0 | CH14: =ROUND(IFERROR(INDEX('Labor Cost_Master'!$G$4:$BC$135,MATCH($DN14,'Labor Cost_Master'!$BD$4:$BD$135,0),MATCH(CH$9,'Labor Cost_Master'!$G$3:$BC$3,0)),0)*AG14,0) -> 0 | ... CL14: =ROUND(IFERROR(INDEX('Labor Cost_Master'!$G$4:$BC$135,MATCH($DN14,'Labor Cost_Master'!$BD$4:$BD$135,0),MATCH(CL$9,'Labor Cost_Master'!$G$3:$BC$3,0)),0)*AK14,0) -> 0 | CM14: =SUM(CA14:CL14) -> 0 | CN14: =ROUND(IFERROR(INDEX('Labor Cost_Master'!$G$4:$BC$135,MATCH($DN14,'Labor Cost_Master'!$BD$4:$BD$135,0),MATCH(CN$9,'Labor Cost_Master'!$G$3:$BC$3,0)),0)*AM14,0) -> 0 | CO14: =ROUND(IFERROR(INDEX('Labor Cost_Master'!$G$4:$BC$135,MATCH($DN14,'Labor Cost_Master'!$BD$4:$BD$135,0),MATCH(CO$9,'Labor Cost_Master'!$G$3:$BC$3,0)),0)*AN14,0) -> 0 | CP14: =ROUND(IFERROR(INDEX('Labor Cost_Master'!$G$4:$BC$135,MATCH($DN14,'Labor Cost_Master'!$BD$4:$BD$135,0),MATCH(CP$9,'Labor Cost_Master'!$G$3:$BC$3,0)),0)*AO14,0) -> 0 | CQ14: =ROUND(IFERROR(INDEX('Labor Cost_Master'!$G$4:$BC$135,MATCH($DN14,'Labor Cost_Master'!$BD$4:$BD$135,0),MATCH(CQ$9,'Labor Cost_Master'!$G$3:$BC$3,0)),0)*AP14,0) -> 0 | CR14: =ROUND(IFERROR(INDEX('Labor Cost_Master'!$G$4:$BC$135,MATCH($DN14,'Labor Cost_Master'!$BD$4:$BD$135,0),MATCH(CR$9,'Labor Cost_Master'!$G$3:$BC$3,0)),0)*AQ14,0) -> 0 | CS14: =ROUND(IFERROR(INDEX('Labor Cost_Master'!$G$4:$BC$135,MATCH($DN14,'Labor Cost_Master'!$BD$4:$BD$135,0),MATCH(CS$9,'Labor Cost_Master'!$G$3:$BC$3,0)),0)*AR14,0) -> 0 | CT14: =ROUND(IFERROR(INDEX('Labor Cost_Master'!$G$4:$BC$135,MATCH($DN14,'Labor Cost_Master'!$BD$4:$BD$135,0),MATCH(CT$9,'Labor Cost_Master'!$G$3:$BC$3,0)),0)*AS14,0) -> 0 | CU14: =ROUND(IFERROR(INDEX('Labor Cost_Master'!$G$4:$BC$135,MATCH($DN14,'Labor Cost_Master'!$BD$4:$BD$135,0),MATCH(CU$9,'Labor Cost_Master'!$G$3:$BC$3,0)),0)*AT14,0) -> 0 | ... CY14: =ROUND(IFERROR(INDEX('Labor Cost_Master'!$G$4:$BC$135,MATCH($DN14,'Labor Cost_Master'!$BD$4:$BD$135,0),MATCH(CY$9,'Labor Cost_Master'!$G$3:$BC$3,0)),0)*AX14,0) -> 0 | CZ14: =SUM(CN14:CY14) -> 0 | DA14: =ROUND(IFERROR(INDEX('Labor Cost_Master'!$G$4:$BC$135,MATCH($DN14,'Labor Cost_Master'!$BD$4:$BD$135,0),MATCH(DA$9,'Labor Cost_Master'!$G$3:$BC$3,0)),0)*AZ14,0) -> 0 | DB14: =ROUND(IFERROR(INDEX('Labor Cost_Master'!$G$4:$BC$135,MATCH($DN14,'Labor Cost_Master'!$BD$4:$BD$135,0),MATCH(DB$9,'Labor Cost_Master'!$G$3:$BC$3,0)),0)*BA14,0) -> 0 | DC14: =ROUND(IFERROR(INDEX('Labor Cost_Master'!$G$4:$BC$135,MATCH($DN14,'Labor Cost_Master'!$BD$4:$BD$135,0),MATCH(DC$9,'Labor Cost_Master'!$G$3:$BC$3,0)),0)*BB14,0)*1.05 -> 0 | DD14: =ROUND(IFERROR(INDEX('Labor Cost_Master'!$G$4:$BC$135,MATCH($DN14,'Labor Cost_Master'!$BD$4:$BD$135,0),MATCH(DD$9,'Labor Cost_Master'!$G$3:$BC$3,0)),0)*BC14,0)*1.05 -> 0 | DE14: =ROUND(IFERROR(INDEX('Labor Cost_Master'!$G$4:$BC$135,MATCH($DN14,'Labor Cost_Master'!$BD$4:$BD$135,0),MATCH(DE$9,'Labor Cost_Master'!$G$3:$BC$3,0)),0)*BD14,0)*1.05 -> 0 | DF14: =ROUND(IFERROR(INDEX('Labor Cost_Master'!$G$4:$BC$135,MATCH($DN14,'Labor Cost_Master'!$BD$4:$BD$135,0),MATCH(DF$9,'Labor Cost_Master'!$G$3:$BC$3,0)),0)*BE14,0)*1.05 -> 0 | DG14: =ROUND(IFERROR(INDEX('Labor Cost_Master'!$G$4:$BC$135,MATCH($DN14,'Labor Cost_Master'!$BD$4:$BD$135,0),MATCH(DG$9,'Labor Cost_Master'!$G$3:$BC$3,0)),0)*BF14,0)*1.05 -> 0 | DH14: =ROUND(IFERROR(INDEX('Labor Cost_Master'!$G$4:$BC$135,MATCH($DN14,'Labor Cost_Master'!$BD$4:$BD$135,0),MATCH(DH$9,'Labor Cost_Master'!$G$3:$BC$3,0)),0)*BG14,0)*1.05 -> 0 | DI14: =ROUND(IFERROR(INDEX('Labor Cost_Master'!$G$4:$BC$135,MATCH($DN14,'Labor Cost_Master'!$BD$4:$BD$135,0),MATCH(DI$9,'Labor Cost_Master'!$G$3:$BC$3,0)),0)*BH14,0)*1.05 -> 0 | DJ14: =ROUND(IFERROR(INDEX('Labor Cost_Master'!$G$4:$BC$135,MATCH($DN14,'Labor Cost_Master'!$BD$4:$BD$135,0),MATCH(DJ$9,'Labor Cost_Master'!$G$3:$BC$3,0)),0)*BI14,0)*1.05 -> 0 | ... DL14: =ROUND(IFERROR(INDEX('Labor Cost_Master'!$G$4:$BC$135,MATCH($DN14,'Labor Cost_Master'!$BD$4:$BD$135,0),MATCH(DL$9,'Labor Cost_Master'!$G$3:$BC$3,0)),0)*BK14,0)*1.05 -> 0 | DM14: =SUM(DA14:DL14) -> 0 | DN14: =D14&F14 | DO14: =ROUND(IFERROR(INDEX(Benefit_Master!$G$4:$BC$135,MATCH($DN14,Benefit_Master!$BD$4:$BD$135,0),MATCH(DO$9,Benefit_Master!$G$3:$BC$3,0)),0)*M14,0) -> 0 | DP14: =ROUND(IFERROR(INDEX(Benefit_Master!$G$4:$BC$135,MATCH($DN14,Benefit_Master!$BD$4:$BD$135,0),MATCH(DP$9,Benefit_Master!$G$3:$BC$3,0)),0)*N14,0) -> 0 | DQ14: =ROUND(IFERROR(INDEX(Benefit_Master!$G$4:$BC$135,MATCH($DN14,Benefit_Master!$BD$4:$BD$135,0),MATCH(DQ$9,Benefit_Master!$G$3:$BC$3,0)),0)*O14,0) -> 0 | DR14: =ROUND(IFERROR(INDEX(Benefit_Master!$G$4:$BC$135,MATCH($DN14,Benefit_Master!$BD$4:$BD$135,0),MATCH(DR$9,Benefit_Master!$G$3:$BC$3,0)),0)*P14,0) -> 0 | DS14: =ROUND(IFERROR(INDEX(Benefit_Master!$G$4:$BC$135,MATCH($DN14,Benefit_Master!$BD$4:$BD$135,0),MATCH(DS$9,Benefit_Master!$G$3:$BC$3,0)),0)*Q14,0) -> 0 | DT14: =ROUND(IFERROR(INDEX(Benefit_Master!$G$4:$BC$135,MATCH($DN14,Benefit_Master!$BD$4:$BD$135,0),MATCH(DT$9,Benefit_Master!$G$3:$BC$3,0)),0)*R14,0) -> 0 | DU14: =ROUND(IFERROR(INDEX(Benefit_Master!$G$4:$BC$135,MATCH($DN14,Benefit_Master!$BD$4:$BD$135,0),MATCH(DU$9,Benefit_Master!$G$3:$BC$3,0)),0)*S14,0) -> 0 | DV14: =ROUND(IFERROR(INDEX(Benefit_Master!$G$4:$BC$135,MATCH($DN14,Benefit_Master!$BD$4:$BD$135,0),MATCH(DV$9,Benefit_Master!$G$3:$BC$3,0)),0)*T14,0) -> 0 | ... DZ14: =ROUND(IFERROR(INDEX(Benefit_Master!$G$4:$BC$135,MATCH($DN14,Benefit_Master!$BD$4:$BD$135,0),MATCH(DZ$9,Benefit_Master!$G$3:$BC$3,0)),0)*X14,0) -> 0 | EA14: =SUM(DO14:DZ14) -> 0 | EB14: =ROUND(IFERROR(INDEX(Benefit_Master!$G$4:$BC$135,MATCH($DN14,Benefit_Master!$BD$4:$BD$135,0),MATCH(EB$9,Benefit_Master!$G$3:$BC$3,0)),0)*Z14,0) -> 0 | EC14: =ROUND(IFERROR(INDEX(Benefit_Master!$G$4:$BC$135,MATCH($DN14,Benefit_Master!$BD$4:$BD$135,0),MATCH(EC$9,Benefit_Master!$G$3:$BC$3,0)),0)*AA14,0) -> 0 | ED14: =ROUND(IFERROR(INDEX(Benefit_Master!$G$4:$BC$135,MATCH($DN14,Benefit_Master!$BD$4:$BD$135,0),MATCH(ED$9,Benefit_Master!$G$3:$BC$3,0)),0)*AB14,0) -> 0 | EE14: =ROUND(IFERROR(INDEX(Benefit_Master!$G$4:$BC$135,MATCH($DN14,Benefit_Master!$BD$4:$BD$135,0),MATCH(EE$9,Benefit_Master!$G$3:$BC$3,0)),0)*AC14,0) -> 0 | EF14: =ROUND(IFERROR(INDEX(Benefit_Master!$G$4:$BC$135,MATCH($DN14,Benefit_Master!$BD$4:$BD$135,0),MATCH(EF$9,Benefit_Master!$G$3:$BC$3,0)),0)*AD14,0) -> 0 | EG14: =ROUND(IFERROR(INDEX(Benefit_Master!$G$4:$BC$135,MATCH($DN14,Benefit_Master!$BD$4:$BD$135,0),MATCH(EG$9,Benefit_Master!$G$3:$BC$3,0)),0)*AE14,0) -> 0 | EH14: =ROUND(IFERROR(INDEX(Benefit_Master!$G$4:$BC$135,MATCH($DN14,Benefit_Master!$BD$4:$BD$135,0),MATCH(EH$9,Benefit_Master!$G$3:$BC$3,0)),0)*AF14,0) -> 0 | EI14: =ROUND(IFERROR(INDEX(Benefit_Master!$G$4:$BC$135,MATCH($DN14,Benefit_Master!$BD$4:$BD$135,0),MATCH(EI$9,Benefit_Master!$G$3:$BC$3,0)),0)*AG14,0) -> 0 | ... EM14: =ROUND(IFERROR(INDEX(Benefit_Master!$G$4:$BC$135,MATCH($DN14,Benefit_Master!$BD$4:$BD$135,0),MATCH(EM$9,Benefit_Master!$G$3:$BC$3,0)),0)*AK14,0) -> 0 | EN14: =SUM(EB14:EM14) -> 0 | EO14: =ROUND(IFERROR(INDEX(Benefit_Master!$G$4:$BC$135,MATCH($DN14,Benefit_Master!$BD$4:$BD$135,0),MATCH(EO$9,Benefit_Master!$G$3:$BC$3,0)),0)*AM14,0) -> 0 | EP14: =ROUND(IFERROR(INDEX(Benefit_Master!$G$4:$BC$135,MATCH($DN14,Benefit_Master!$BD$4:$BD$135,0),MATCH(EP$9,Benefit_Master!$G$3:$BC$3,0)),0)*AN14,0) -> 0 | EQ14: =ROUND(IFERROR(INDEX(Benefit_Master!$G$4:$BC$135,MATCH($DN14,Benefit_Master!$BD$4:$BD$135,0),MATCH(EQ$9,Benefit_Master!$G$3:$BC$3,0)),0)*AO14,0) -> 0 | ER14: =ROUND(IFERROR(INDEX(Benefit_Master!$G$4:$BC$135,MATCH($DN14,Benefit_Master!$BD$4:$BD$135,0),MATCH(ER$9,Benefit_Master!$G$3:$BC$3,0)),0)*AP14,0) -> 0 | ES14: =ROUND(IFERROR(INDEX(Benefit_Master!$G$4:$BC$135,MATCH($DN14,Benefit_Master!$BD$4:$BD$135,0),MATCH(ES$9,Benefit_Master!$G$3:$BC$3,0)),0)*AQ14,0) -> 0 | ET14: =ROUND(IFERROR(INDEX(Benefit_Master!$G$4:$BC$135,MATCH($DN14,Benefit_Master!$BD$4:$BD$135,0),MATCH(ET$9,Benefit_Master!$G$3:$BC$3,0)),0)*AR14,0) -> 0 | EU14: =ROUND(IFERROR(INDEX(Benefit_Master!$G$4:$BC$135,MATCH($DN14,Benefit_Master!$BD$4:$BD$135,0),MATCH(EU$9,Benefit_Master!$G$3:$BC$3,0)),0)*AS14,0) -> 0 | EV14: =ROUND(IFERROR(INDEX(Benefit_Master!$G$4:$BC$135,MATCH($DN14,Benefit_Master!$BD$4:$BD$135,0),MATCH(EV$9,Benefit_Master!$G$3:$BC$3,0)),0)*AT14,0) -> 0 | ... EZ14: =ROUND(IFERROR(INDEX(Benefit_Master!$G$4:$BC$135,MATCH($DN14,Benefit_Master!$BD$4:$BD$135,0),MATCH(EZ$9,Benefit_Master!$G$3:$BC$3,0)),0)*AX14,0) -> 0 | FA14: =SUM(EO14:EZ14) -> 0 | FB14: =ROUND(IFERROR(INDEX(Benefit_Master!$G$4:$BC$135,MATCH($DN14,Benefit_Master!$BD$4:$BD$135,0),MATCH(FB$9,Benefit_Master!$G$3:$BC$3,0)),0)*AZ14,0) -> 0 | FC14: =ROUND(IFERROR(INDEX(Benefit_Master!$G$4:$BC$135,MATCH($DN14,Benefit_Master!$BD$4:$BD$135,0),MATCH(FC$9,Benefit_Master!$G$3:$BC$3,0)),0)*BA14,0) -> 0 | FD14: =ROUND(IFERROR(INDEX(Benefit_Master!$G$4:$BC$135,MATCH($DN14,Benefit_Master!$BD$4:$BD$135,0),MATCH(FD$9,Benefit_Master!$G$3:$BC$3,0)),0)*BB14,0) -> 0 | FE14: =ROUND(IFERROR(INDEX(Benefit_Master!$G$4:$BC$135,MATCH($DN14,Benefit_Master!$BD$4:$BD$135,0),MATCH(FE$9,Benefit_Master!$G$3:$BC$3,0)),0)*BC14,0) -> 0 | FF14: =ROUND(IFERROR(INDEX(Benefit_Master!$G$4:$BC$135,MATCH($DN14,Benefit_Master!$BD$4:$BD$135,0),MATCH(FF$9,Benefit_Master!$G$3:$BC$3,0)),0)*BD14,0) -> 0 | FG14: =ROUND(IFERROR(INDEX(Benefit_Master!$G$4:$BC$135,MATCH($DN14,Benefit_Master!$BD$4:$BD$135,0),MATCH(FG$9,Benefit_Master!$G$3:$BC$3,0)),0)*BE14,0) -> 0 | FH14: =ROUND(IFERROR(INDEX(Benefit_Master!$G$4:$BC$135,MATCH($DN14,Benefit_Master!$BD$4:$BD$135,0),MATCH(FH$9,Benefit_Master!$G$3:$BC$3,0)),0)*BF14,0) -> 0 | FI14: =ROUND(IFERROR(INDEX(Benefit_Master!$G$4:$BC$135,MATCH($DN14,Benefit_Master!$BD$4:$BD$135,0),MATCH(FI$9,Benefit_Master!$G$3:$BC$3,0)),0)*BG14,0) -> 0 | ... FM14: =ROUND(IFERROR(INDEX(Benefit_Master!$G$4:$BC$135,MATCH($DN14,Benefit_Master!$BD$4:$BD$135,0),MATCH(FM$9,Benefit_Master!$G$3:$BC$3,0)),0)*BK14,0) -> 0 | FN14: =SUM(FB14:FM14) -> 0
