Workbook
Name _APP1: #REF!
Name _APP1: #REF!
Name _APP2: #REF!
Name _APP2: #REF!
Name _APP3: #REF!
Name _APP3: #REF!
Name _APP4: '[1]1-1. Interface list'!$B$1
Name _IRP1: #REF!
Name _IRP1: #REF!
Name _SYS2: '[2]1-3. 참조_애플리케이션'!$F$6:$F$65536
Name _SYS3: '[3]1-3. Reference_Applications'!$F$6:$F$1350
Name APP: #REF!
Name APP: #REF!
Name APP_1: '[4]1-1. Interface list'!$B$1
Name APPGRP: #REF!
Name APPGRP: #REF!
Name APPGRP2: #REF!
Name APPGRP2: #REF!
Name APPSYS: #REF!
Name APPSYS: #REF!
Name b: #REF!
Name b: #REF!
Name csDesignMode: 1
Name d: #REF!
Name d: #REF!
Name EW_withLink_lines: COUNTA(#REF!)
Name GBM: [5]조직코드!$D$3:$D$129
Name GG: [5]조직코드!$C$136:$C$152
Name INFO: [6]참조_정보분류!$E$6:$E$65536
Name INFO2: [5]참조_정보분류!$E$6:$E$320
Name IRP: #REF!
Name IRP: #REF!
Name PKGIN_IN_REV1_List: #REF!
Name PKGIN_IN_REV1_List: #REF!
Name PRINT_AREA_MI: #REF!
Name PRINT_AREA_MI: #REF!
Name s: [7]참조_애플리케이션!$G$6:$G$1350
Name SYS: #REF!
Name SYS: #REF!
Name SYSA: #REF!
Name SYSA: #REF!
Name ㄴㅇㄴ: [8]참조_애플리케이션!$G$6:$G$1350
Name ㅁ: #REF!
Name ㅁ: #REF!
Name 목록: [9]기초코드!$B$4:$E$4
Name 분류: #REF!
Name 분류: #REF!
Name ㅇㅇ: #REF!
Name ㅇㅇ: #REF!
Name 啊啊啊啊啊啊啊啊啊: '[10]1-3. Reference_Applications'!$F$6:$F$1350
Name 전체Checklist_lines: ADDRESS(COUNTA(#REF!),1,2,1)
Name 전체EW_lines: COUNTA(#REF!)
Name 정보분류: #REF!
Name 정보분류: #REF!

Sheet 표지

Sheet 개정이력
A1: 개정이력
A2: 버전 | B2: 날짜 | C2: 개정내용 | D2: 작성자
A3: 1.0 | B3: 2026.09.21 | C3: 최초생성 | D3: 정병주

Sheet 주별 진척률
A1: 날짜 | C1: 주차 | D1: 착수 | G1: 분석 | J1: 설계 | M1: 구축 | P1: 이행 | S1: 종료 | V1: 종합
A2: 시작 | B2: 종료 | D2: 계획 | E2: 실적 | F2: 진척률 | G2: 계획 | H2: 실적 | I2: 진척률 | J2: 계획 | K2: 실적 | L2: 진척률 | M2: 계획 | N2: 실적 | O2: 진척률 | P2: 계획 | Q2: 실적 | R2: 진척률 | S2: 계획 | T2: 실적 | U2: 진척률 | V2: 주차별 | Y2: 누적
V3: 계획 | W3: 실적 | X3: 진척률 | Y3: 계획 | Z3: 실적 | AA3: 진척률
A4: =MIN(A5:A9) -> 46296 | B4: =MAX(B5:B9) -> 46325 | C4: 종합 | D4: =Main!U5 -> 0.066666667 | E4: =SUM(E5:E9) -> 0 | F4: =IF(E4<>"", TEXT((E4/D4)*100, "##0.00") & "%", "") -> 0.00% | G4: =Main!U12 -> 0.066666667 | H4: =SUM(H5:H9) -> 0 | I4: =IF(H4<>"", TEXT((H4/G4)*100, "##0.00") & "%", "") -> 0.00% | J4: =Main!U21 -> 0.1 | K4: =SUM(K5:K9) -> 0 | L4: =IF(K4<>"", TEXT((K4/J4)*100, "##0.00") & "%", "") -> 0.00% | M4: =Main!U30 -> 0.53333333 | N4: =SUM(N5:N9) -> 0 | O4: =IF(N4<>"", TEXT((N4/M4)*100, "##0.00") & "%", "") -> 0.00% | P4: =Main!U50 -> 0.1 | Q4: =SUM(Q5:Q9) -> 0 | R4: =IF(Q4<>"", TEXT((Q4/P4)*100, "##0.00") & "%", "") -> 0.00% | S4: =Main!U60 -> 0.13333333 | T4: =SUM(T5:T9) -> 0 | U4: =IF(T4<>"", TEXT((T4/S4)*100, "##0.00") & "%", "") -> 0.00% | V4: =INDIRECT("V"&MATCH(VLOOKUP(TODAY(), $A11:$B169, 2, 0), $C1:$C9, 0)) -> #N/A | W4: =INDIRECT("W"&MATCH(VLOOKUP(TODAY(), $A11:$B169, 2, 0), $C1:$C9, 0)) -> #N/A | X4: =IF(W4<>"", TEXT((W4/V4)*100, "##0.00") & "%", "") -> #N/A | Y4: =INDIRECT("Y"&MATCH(VLOOKUP(TODAY(), $A11:$B169, 2, 0), $C1:$C9, 0)) -> #N/A | Z4: =INDIRECT("Z"&MATCH(VLOOKUP(TODAY(), $A11:$B169, 2, 0), $C1:$C9, 0)) -> #N/A | AA4: =X4 -> #N/A
A5: 46296 | B5: 46297 | C5: W01 | D5: =SUMIFS(Main!U:U, Main!R:R, '주별 진척률'!C5, Main!Q:Q, '주별 진척률'!D$1) -> 0.26666667 | E5: =SUMIFS(Main!U:U, Main!S:S, '주별 진척률'!C5, Main!Q:Q, '주별 진척률'!D$1) -> 0 | F5: =IF(E5<>"", IF(D5=0, "", E5/D5), "") -> 0 | G5: =SUMIFS(Main!U:U, Main!R:R, '주별 진척률'!C5, Main!Q:Q, '주별 진척률'!G$1) -> 0.26666667 | H5: =SUMIFS(Main!U:U, Main!S:S, '주별 진척률'!C5, Main!Q:Q, '주별 진척률'!G$1) -> 0 | I5: =IF(H5<>"", IF(G5=0, "", H5/G5), "") -> 0 | J5: =SUMIFS(Main!U:U, Main!R:R, '주별 진척률'!C5, Main!Q:Q, '주별 진척률'!J$1) -> 0 | K5: =SUMIFS(Main!U:U, Main!S:S, '주별 진척률'!C5, Main!Q:Q, '주별 진척률'!J$1) -> 0 | L5: =IF(K5<>"", IF(J5=0, "", K5/J5), "") | M5: =SUMIFS(Main!U:U, Main!R:R, '주별 진척률'!C5, Main!Q:Q, '주별 진척률'!M$1) -> 0 | N5: =SUMIFS(Main!U:U, Main!S:S, '주별 진척률'!C5, Main!Q:Q, '주별 진척률'!M$1) -> 0 | O5: =IF(N5<>"", IF(M5=0, "", N5/M5), "") | P5: =SUMIFS(Main!U:U, Main!R:R, '주별 진척률'!C5, Main!Q:Q, '주별 진척률'!P$1) -> 0 | Q5: =SUMIFS(Main!U:U, Main!S:S, '주별 진척률'!C5, Main!Q:Q, '주별 진척률'!P$1) -> 0 | R5: =IF(Q5<>"", IF(P5=0, "", Q5/P5), "") | S5: =SUMIFS(Main!U:U, Main!R:R, '주별 진척률'!C5, Main!Q:Q, '주별 진척률'!S$1) -> 0 | T5: =SUMIFS(Main!U:U, Main!S:S, '주별 진척률'!C5, Main!Q:Q, '주별 진척률'!S$1) -> 0 | U5: =IF(T5<>"", IF(S5=0, "", T5/S5), "") | V5: =SUMIF(Main!R:R, '주별 진척률'!C5, Main!U:U) -> 0.53333333 | W5: =SUMIF(Main!S:S, '주별 진척률'!C5, Main!U:U) -> 0 | X5: =IF(W5<>"", IF(V5=0, "-", TEXT((W5/V5)*100, "###.0") & "%"), "") -> .0% | Y5: =SUM(V5:V5) -> 0.53333333 | Z5: =IF(TODAY()<A5, NA(), SUM(W$5:W5)) -> #N/A | AA5: =IF(Z5<>"", IF(Y5=0, "", TEXT((Z5/Y5)*100, "###.0") & "%"), "") -> #N/A | AB5: =IFERROR(Z5, "X") -> X | AD5: 계획 | AE5: 실적 | AF5: 진척율
A6: 46300 | B6: =B5+7 -> 46304 | C6: W02 | D6: =SUMIFS(Main!U:U, Main!R:R, '주별 진척률'!C6, Main!Q:Q, '주별 진척률'!D$1) -> 0 | E6: =SUMIFS(Main!U:U, Main!S:S, '주별 진척률'!C6, Main!Q:Q, '주별 진척률'!D$1) -> 0 | F6: =IF(E6<>"", IF(D6=0, "", E6/D6), "") | G6: =SUMIFS(Main!U:U, Main!R:R, '주별 진척률'!C6, Main!Q:Q, '주별 진척률'!G$1) -> 0 | H6: =SUMIFS(Main!U:U, Main!S:S, '주별 진척률'!C6, Main!Q:Q, '주별 진척률'!G$1) -> 0 | I6: =IF(H6<>"", IF(G6=0, "", H6/G6), "") | J6: =SUMIFS(Main!U:U, Main!R:R, '주별 진척률'!C6, Main!Q:Q, '주별 진척률'!J$1) -> 0.4 | K6: =SUMIFS(Main!U:U, Main!S:S, '주별 진척률'!C6, Main!Q:Q, '주별 진척률'!J$1) -> 0 | L6: =IF(K6<>"", IF(J6=0, "", K6/J6), "") -> 0 | M6: =SUMIFS(Main!U:U, Main!R:R, '주별 진척률'!C6, Main!Q:Q, '주별 진척률'!M$1) -> 0 | N6: =SUMIFS(Main!U:U, Main!S:S, '주별 진척률'!C6, Main!Q:Q, '주별 진척률'!M$1) -> 0 | O6: =IF(N6<>"", IF(M6=0, "", N6/M6), "") | P6: =SUMIFS(Main!U:U, Main!R:R, '주별 진척률'!C6, Main!Q:Q, '주별 진척률'!P$1) -> 0 | Q6: =SUMIFS(Main!U:U, Main!S:S, '주별 진척률'!C6, Main!Q:Q, '주별 진척률'!P$1) -> 0 | R6: =IF(Q6<>"", IF(P6=0, "", Q6/P6), "") | S6: =SUMIFS(Main!U:U, Main!R:R, '주별 진척률'!C6, Main!Q:Q, '주별 진척률'!S$1) -> 0 | T6: =SUMIFS(Main!U:U, Main!S:S, '주별 진척률'!C6, Main!Q:Q, '주별 진척률'!S$1) -> 0 | U6: =IF(T6<>"", IF(S6=0, "", T6/S6), "") | V6: =SUMIF(Main!R:R, '주별 진척률'!C6, Main!U:U) -> 0.4 | W6: =SUMIF(Main!S:S, '주별 진척률'!C6, Main!U:U) -> 0 | X6: =IF(W6<>"", IF(V6=0, "-", TEXT((W6/V6)*100, "###.0") & "%"), "") -> .0% | Y6: =SUM(V6:V6) -> 0.4 | Z6: =IF(TODAY()<A6, NA(), SUM(W$5:W6)) -> #N/A | AA6: =IF(Z6<>"", IF(Y6=0, "", TEXT((Z6/Y6)*100, "###.0") & "%"), "") -> #N/A | AB6: =IFERROR(Z6, "X") -> X | AC6: 전체 | AD6: =SUM(D4,G4,J4,M4,P4,S4) -> 1 | AE6: =SUM(E4,H4,K4,N4,Q4,T4) -> 0 | AF6: =AE6/AD6 -> 0
A7: =A6+7 -> 46307 | B7: =B6+7 -> 46311 | C7: W03 | D7: =SUMIFS(Main!U:U, Main!R:R, '주별 진척률'!C7, Main!Q:Q, '주별 진척률'!D$1) -> 0 | E7: =SUMIFS(Main!U:U, Main!S:S, '주별 진척률'!C7, Main!Q:Q, '주별 진척률'!D$1) -> 0 | F7: =IF(E7<>"", IF(D7=0, "", E7/D7), "") | G7: =SUMIFS(Main!U:U, Main!R:R, '주별 진척률'!C7, Main!Q:Q, '주별 진척률'!G$1) -> 0 | H7: =SUMIFS(Main!U:U, Main!S:S, '주별 진척률'!C7, Main!Q:Q, '주별 진척률'!G$1) -> 0 | I7: =IF(H7<>"", IF(G7=0, "", H7/G7), "") | J7: =SUMIFS(Main!U:U, Main!R:R, '주별 진척률'!C7, Main!Q:Q, '주별 진척률'!J$1) -> 0 | K7: =SUMIFS(Main!U:U, Main!S:S, '주별 진척률'!C7, Main!Q:Q, '주별 진척률'!J$1) -> 0 | L7: =IF(K7<>"", IF(J7=0, "", K7/J7), "") | M7: =SUMIFS(Main!U:U, Main!R:R, '주별 진척률'!C7, Main!Q:Q, '주별 진척률'!M$1) -> 0 | N7: =SUMIFS(Main!U:U, Main!S:S, '주별 진척률'!C7, Main!Q:Q, '주별 진척률'!M$1) -> 0 | O7: =IF(N7<>"", IF(M7=0, "", N7/M7), "") | P7: =SUMIFS(Main!U:U, Main!R:R, '주별 진척률'!C7, Main!Q:Q, '주별 진척률'!P$1) -> 0 | Q7: =SUMIFS(Main!U:U, Main!S:S, '주별 진척률'!C7, Main!Q:Q, '주별 진척률'!P$1) -> 0 | R7: =IF(Q7<>"", IF(P7=0, "", Q7/P7), "") | S7: =SUMIFS(Main!U:U, Main!R:R, '주별 진척률'!C7, Main!Q:Q, '주별 진척률'!S$1) -> 0 | T7: =SUMIFS(Main!U:U, Main!S:S, '주별 진척률'!C7, Main!Q:Q, '주별 진척률'!S$1) -> 0 | U7: =IF(T7<>"", IF(S7=0, "", T7/S7), "") | V7: =SUMIF(Main!R:R, '주별 진척률'!C7, Main!U:U) -> 0 | W7: =SUMIF(Main!S:S, '주별 진척률'!C7, Main!U:U) -> 0 | X7: =IF(W7<>"", IF(V7=0, "-", TEXT((W7/V7)*100, "###.0") & "%"), "") -> - | Y7: =SUM(V7:V7) -> 0 | Z7: =IF(TODAY()<A7, NA(), SUM(W$5:W7)) -> #N/A | AA7: =IF(Z7<>"", IF(Y7=0, "", TEXT((Z7/Y7)*100, "###.0") & "%"), "") -> #N/A | AB7: =IFERROR(Z7, "X") -> X
A8: =A7+7 -> 46314 | B8: =B7+7 -> 46318 | C8: W04 | D8: =SUMIFS(Main!U:U, Main!R:R, '주별 진척률'!C8, Main!Q:Q, '주별 진척률'!D$1) -> 0 | E8: =SUMIFS(Main!U:U, Main!S:S, '주별 진척률'!C8, Main!Q:Q, '주별 진척률'!D$1) -> 0 | F8: =IF(E8<>"", IF(D8=0, "", E8/D8), "") | G8: =SUMIFS(Main!U:U, Main!R:R, '주별 진척률'!C8, Main!Q:Q, '주별 진척률'!G$1) -> 0 | H8: =SUMIFS(Main!U:U, Main!S:S, '주별 진척률'!C8, Main!Q:Q, '주별 진척률'!G$1) -> 0 | I8: =IF(H8<>"", IF(G8=0, "", H8/G8), "") | J8: =SUMIFS(Main!U:U, Main!R:R, '주별 진척률'!C8, Main!Q:Q, '주별 진척률'!J$1) -> 0 | K8: =SUMIFS(Main!U:U, Main!S:S, '주별 진척률'!C8, Main!Q:Q, '주별 진척률'!J$1) -> 0 | L8: =IF(K8<>"", IF(J8=0, "", K8/J8), "") | M8: =SUMIFS(Main!U:U, Main!R:R, '주별 진척률'!C8, Main!Q:Q, '주별 진척률'!M$1) -> 3.2 | N8: =SUMIFS(Main!U:U, Main!S:S, '주별 진척률'!C8, Main!Q:Q, '주별 진척률'!M$1) -> 0 | O8: =IF(N8<>"", IF(M8=0, "", N8/M8), "") -> 0 | P8: =SUMIFS(Main!U:U, Main!R:R, '주별 진척률'!C8, Main!Q:Q, '주별 진척률'!P$1) -> 0 | Q8: =SUMIFS(Main!U:U, Main!S:S, '주별 진척률'!C8, Main!Q:Q, '주별 진척률'!P$1) -> 0 | R8: =IF(Q8<>"", IF(P8=0, "", Q8/P8), "") | S8: =SUMIFS(Main!U:U, Main!R:R, '주별 진척률'!C8, Main!Q:Q, '주별 진척률'!S$1) -> 0 | T8: =SUMIFS(Main!U:U, Main!S:S, '주별 진척률'!C8, Main!Q:Q, '주별 진척률'!S$1) -> 0 | U8: =IF(T8<>"", IF(S8=0, "", T8/S8), "") | V8: =SUMIF(Main!R:R, '주별 진척률'!C8, Main!U:U) -> 3.2 | W8: =SUMIF(Main!S:S, '주별 진척률'!C8, Main!U:U) -> 0 | X8: =IF(W8<>"", IF(V8=0, "-", TEXT((W8/V8)*100, "###.0") & "%"), "") -> .0% | Y8: =SUM(V8:V8) -> 3.2 | Z8: =IF(TODAY()<A8, NA(), SUM(W$5:W8)) -> #N/A | AA8: =IF(Z8<>"", IF(Y8=0, "", TEXT((Z8/Y8)*100, "###.0") & "%"), "") -> #N/A | AB8: =IFERROR(Z8, "X") -> X
A9: =A8+7 -> 46321 | B9: =B8+7 -> 46325 | C9: W05 | D9: =SUMIFS(Main!U:U, Main!R:R, '주별 진척률'!C9, Main!Q:Q, '주별 진척률'!D$1) -> 0 | E9: =SUMIFS(Main!U:U, Main!S:S, '주별 진척률'!C9, Main!Q:Q, '주별 진척률'!D$1) -> 0 | F9: =IF(E9<>"", IF(D9=0, "", E9/D9), "") | G9: =SUMIFS(Main!U:U, Main!R:R, '주별 진척률'!C9, Main!Q:Q, '주별 진척률'!G$1) -> 0 | H9: =SUMIFS(Main!U:U, Main!S:S, '주별 진척률'!C9, Main!Q:Q, '주별 진척률'!G$1) -> 0 | I9: =IF(H9<>"", IF(G9=0, "", H9/G9), "") | J9: =SUMIFS(Main!U:U, Main!R:R, '주별 진척률'!C9, Main!Q:Q, '주별 진척률'!J$1) -> 0 | K9: =SUMIFS(Main!U:U, Main!S:S, '주별 진척률'!C9, Main!Q:Q, '주별 진척률'!J$1) -> 0 | L9: =IF(K9<>"", IF(J9=0, "", K9/J9), "") | M9: =SUMIFS(Main!U:U, Main!R:R, '주별 진척률'!C9, Main!Q:Q, '주별 진척률'!M$1) -> 0.6 | N9: =SUMIFS(Main!U:U, Main!S:S, '주별 진척률'!C9, Main!Q:Q, '주별 진척률'!M$1) -> 0 | O9: =IF(N9<>"", IF(M9=0, "", N9/M9), "") -> 0 | P9: =SUMIFS(Main!U:U, Main!R:R, '주별 진척률'!C9, Main!Q:Q, '주별 진척률'!P$1) -> 0.2 | Q9: =SUMIFS(Main!U:U, Main!S:S, '주별 진척률'!C9, Main!Q:Q, '주별 진척률'!P$1) -> 0 | R9: =IF(Q9<>"", IF(P9=0, "", Q9/P9), "") -> 0 | S9: =SUMIFS(Main!U:U, Main!R:R, '주별 진척률'!C9, Main!Q:Q, '주별 진척률'!S$1) -> 0.13333333 | T9: =SUMIFS(Main!U:U, Main!S:S, '주별 진척률'!C9, Main!Q:Q, '주별 진척률'!S$1) -> 0 | U9: =IF(T9<>"", IF(S9=0, "", T9/S9), "") -> 0 | V9: =SUMIF(Main!R:R, '주별 진척률'!C9, Main!U:U) -> 0.93333333 | W9: =SUMIF(Main!S:S, '주별 진척률'!C9, Main!U:U) -> 0 | X9: =IF(W9<>"", IF(V9=0, "-", TEXT((W9/V9)*100, "###.0") & "%"), "") -> .0% | Y9: =SUM(V9:V9) -> 0.93333333 | Z9: =IF(TODAY()<A9, NA(), SUM(W$5:W9)) -> #N/A | AA9: =IF(Z9<>"", IF(Y9=0, "", TEXT((Z9/Y9)*100, "###.0") & "%"), "") -> #N/A | AB9: =IFERROR(Z9, "X") -> X
A11: 46282 | B11: =IFERROR(VLOOKUP(A11,A$5:C$9, 3, 0),B10) -> 0
A12: 46283 | B12: =IFERROR(VLOOKUP(A12,A$5:C$9, 3, 0),B11) -> 0
A13: 46284 | B13: =IFERROR(VLOOKUP(A13,A$5:C$9, 3, 0),B12) -> 0
A14: 46285 | B14: =IFERROR(VLOOKUP(A14,A$5:C$9, 3, 0),B13) -> 0
A15: 46286 | B15: =IFERROR(VLOOKUP(A15,A$5:C$9, 3, 0),B14) -> 0
A16: 46287 | B16: =IFERROR(VLOOKUP(A16,A$5:C$9, 3, 0),B15) -> 0
A17: 46288 | B17: =IFERROR(VLOOKUP(A17,A$5:C$9, 3, 0),B16) -> 0
A18: 46289 | B18: =IFERROR(VLOOKUP(A18,A$5:C$9, 3, 0),B17) -> 0
A19: 46290 | B19: =IFERROR(VLOOKUP(A19,A$5:C$9, 3, 0),B18) -> 0
A20: 46291 | B20: =IFERROR(VLOOKUP(A20,A$5:C$9, 3, 0),B19) -> 0
A21: 46292 | B21: =IFERROR(VLOOKUP(A21,A$5:C$9, 3, 0),B20) -> 0
A22: 46293 | B22: =IFERROR(VLOOKUP(A22,A$5:C$9, 3, 0),B21) -> 0
... A232: 46503 | B232: =IFERROR(VLOOKUP(A232,A$5:C$9, 3, 0),B231) -> W05

Sheet Main
B1: ID | C1: Phase | D1: Activities | G1: Remark | H1: Output | J1: 주관 (R&R) | M1: Activity별 대응 매뉴얼 | N1: Plan | Q1: TBD | R1: Plan Week | S1: Actual Week | T1: Level | U1: Ratio | V1: Actual | Y1: 착수단계 | AD1: 분석단계 | AI1: 설계단계 | AS1: 구축단계
Y2: W1 | AD2: W2 | AI2: W3 | AN2: W4 | AS2: W5
Y3: 46293 | AD3: =Y3+7 -> 46300 | AI3: =AD3+7 -> 46307 | AN3: =AI3+7 -> 46314 | AS3: =AN3+7 -> 46321
D4: Activity | E4: Work | F4: Step | H4: 보조산출물 | I4: 공식산출물 | J4: 고객사 | K4: 공통 | L4: 수행사 | N4: Start date | O4: End date | P4: Duration | V4: Start date | W4: End date | X4: Duration | Y4: 46297 | AD4: =Y4+7 -> 46304 | AI4: =AD4+7 -> 46311 | AN4: =AI4+7 -> 46318 | AS4: =AN4+7 -> 46325
B5: 1000 | C5: 착수단계 | N5: =MIN(N6:N11) -> 46296 | O5: =MAX(O6:O11) -> 46297 | P5: =IF(O5<>"", NETWORKDAYS(N5,O5,Calendar!$L$2:$L$43), "") -> 2 | Q5: =IF(C5<=9999, Q4, LEFT(C5, 2)) -> 착수 | R5: =IF(T5=4, VLOOKUP(O5, '주별 진척률'!$A$11:$B$169, 2, 0), "") | S5: =IF(T5=4, IFERROR(VLOOKUP(W5, '주별 진척률'!$A$11:$B$169, 2, 0), ""), "") | T5: =IF(IFERROR(VALUE(E5), 0)>=1000, IF(IFERROR(VALUE(E5), 0)<=9999, 4, IF(RIGHT(D5,1)="0", 3, IF(RIGHT(C5,2)="00", 2, IF(RIGHT(B5,3)="000", 1, 0)))), IF(RIGHT(D5,1)="0", 3, IF(RIGHT(C5,2)="00", 2, IF(RIGHT(B5,3)="000", 1, 0)))) -> 1 | U5: =((1+(O5-N5))/(1+(MAX($O$5:$O$65)-MIN($N$5:$N$65)))) -> 0.066666667 | V5: =MIN(V6:V11) -> 0 | W5: =MAX(W6:W11) -> 0 | X5: =IF(W5<>"", NETWORKDAYS(V5,W5,Calendar!$L$2:$L$43), "") -> 0 | Y5: =IF($N5<=Y$3+MOD(COLUMN()-Calendar!$O$2, 5), IF(Y$3+MOD(COLUMN()-Calendar!$O$2, 5)<=$O5, 1, 0), 0) -> 0 | Z5: =IF($N5<=Y$3+MOD(COLUMN()-Calendar!$O$2, 5), IF(Y$3+MOD(COLUMN()-Calendar!$O$2, 5)<=$O5, 1, 0), 0) -> 0 | AA5: =IF($N5<=Y$3+MOD(COLUMN()-Calendar!$O$2, 5), IF(Y$3+MOD(COLUMN()-Calendar!$O$2, 5)<=$O5, 1, 0), 0) -> 0 | AB5: =IF($N5<=Y$3+MOD(COLUMN()-Calendar!$O$2, 5), IF(Y$3+MOD(COLUMN()-Calendar!$O$2, 5)<=$O5, 1, 0), 0) -> 1 | AC5: =IF($N5<=Y$3+MOD(COLUMN()-Calendar!$O$2, 5), IF(Y$3+MOD(COLUMN()-Calendar!$O$2, 5)<=$O5, 1, 0), 0) -> 1 | AD5: =IF($N5<=AD$3+MOD(COLUMN()-Calendar!$O$2, 5), IF(AD$3+MOD(COLUMN()-Calendar!$O$2, 5)<=$O5, 1, 0), 0) -> 0 | AE5: =IF($N5<=AD$3+MOD(COLUMN()-Calendar!$O$2, 5), IF(AD$3+MOD(COLUMN()-Calendar!$O$2, 5)<=$O5, 1, 0), 0) -> 0 | AF5: =IF($N5<=AD$3+MOD(COLUMN()-Calendar!$O$2, 5), IF(AD$3+MOD(COLUMN()-Calendar!$O$2, 5)<=$O5, 1, 0), 0) -> 0 | AG5: =IF($N5<=AD$3+MOD(COLUMN()-Calendar!$O$2, 5), IF(AD$3+MOD(COLUMN()-Calendar!$O$2, 5)<=$O5, 1, 0), 0) -> 0 | AH5: =IF($N5<=AD$3+MOD(COLUMN()-Calendar!$O$2, 5), IF(AD$3+MOD(COLUMN()-Calendar!$O$2, 5)<=$O5, 1, 0), 0) -> 0 | AI5: =IF($N5<=AI$3+MOD(COLUMN()-Calendar!$O$2, 5), IF(AI$3+MOD(COLUMN()-Calendar!$O$2, 5)<=$O5, 1, 0), 0) -> 0 | AJ5: =IF($N5<=AI$3+MOD(COLUMN()-Calendar!$O$2, 5), IF(AI$3+MOD(COLUMN()-Calendar!$O$2, 5)<=$O5, 1, 0), 0) -> 0 | AK5: =IF($N5<=AI$3+MOD(COLUMN()-Calendar!$O$2, 5), IF(AI$3+MOD(COLUMN()-Calendar!$O$2, 5)<=$O5, 1, 0), 0) -> 0 | AL5: =IF($N5<=AI$3+MOD(COLUMN()-Calendar!$O$2, 5), IF(AI$3+MOD(COLUMN()-Calendar!$O$2, 5)<=$O5, 1, 0), 0) -> 0 | AM5: =IF($N5<=AI$3+MOD(COLUMN()-Calendar!$O$2, 5), IF(AI$3+MOD(COLUMN()-Calendar!$O$2, 5)<=$O5, 1, 0), 0) -> 0 | AN5: =IF($N5<=AN$3+MOD(COLUMN()-Calendar!$O$2, 5), IF(AN$3+MOD(COLUMN()-Calendar!$O$2, 5)<=$O5, 1, 0), 0) -> 0 | AO5: =IF($N5<=AN$3+MOD(COLUMN()-Calendar!$O$2, 5), IF(AN$3+MOD(COLUMN()-Calendar!$O$2, 5)<=$O5, 1, 0), 0) -> 0 | AP5: =IF($N5<=AN$3+MOD(COLUMN()-Calendar!$O$2, 5), IF(AN$3+MOD(COLUMN()-Calendar!$O$2, 5)<=$O5, 1, 0), 0) -> 0 | AQ5: =IF($N5<=AN$3+MOD(COLUMN()-Calendar!$O$2, 5), IF(AN$3+MOD(COLUMN()-Calendar!$O$2, 5)<=$O5, 1, 0), 0) -> 0 | AR5: =IF($N5<=AN$3+MOD(COLUMN()-Calendar!$O$2, 5), IF(AN$3+MOD(COLUMN()-Calendar!$O$2, 5)<=$O5, 1, 0), 0) -> 0 | AS5: =IF($N5<=AS$3+MOD(COLUMN()-Calendar!$O$2, 5), IF(AS$3+MOD(COLUMN()-Calendar!$O$2, 5)<=$O5, 1, 0), 0) -> 0 | AT5: =IF($N5<=AS$3+MOD(COLUMN()-Calendar!$O$2, 5), IF(AS$3+MOD(COLUMN()-Calendar!$O$2, 5)<=$O5, 1, 0), 0) -> 0 | AU5: =IF($N5<=AS$3+MOD(COLUMN()-Calendar!$O$2, 5), IF(AS$3+MOD(COLUMN()-Calendar!$O$2, 5)<=$O5, 1, 0), 0) -> 0 | AV5: =IF($N5<=AS$3+MOD(COLUMN()-Calendar!$O$2, 5), IF(AS$3+MOD(COLUMN()-Calendar!$O$2, 5)<=$O5, 1, 0), 0) -> 0 | AW5: =IF($N5<=AS$3+MOD(COLUMN()-Calendar!$O$2, 5), IF(AS$3+MOD(COLUMN()-Calendar!$O$2, 5)<=$O5, 1, 0), 0) -> 0
B6: 1000 | C6: 1100 | D6: 프로젝트 준비 및 착수보고 | N6: =MIN(N7:N11) -> 46296 | O6: =MAX(O7:O11) -> 46297 | P6: =IF(O6<>"", NETWORKDAYS(N6,O6,Calendar!$L$2:$L$43), "") -> 2 | Q6: =IF(C6<=9999, Q5, LEFT(C6, 2)) -> 착수 | R6: =IF(T6=4, VLOOKUP(O6, '주별 진척률'!$A$11:$B$169, 2, 0), "") | S6: =IF(T6=4, IFERROR(VLOOKUP(W6, '주별 진척률'!$A$11:$B$169, 2, 0), ""), "") | T6: =IF(IFERROR(VALUE(E6), 0)>=1000, IF(IFERROR(VALUE(E6), 0)<=9999, 4, IF(RIGHT(D6,1)="0", 3, IF(RIGHT(C6,2)="00", 2, IF(RIGHT(B6,3)="000", 1, 0)))), IF(RIGHT(D6,1)="0", 3, IF(RIGHT(C6,2)="00", 2, IF(RIGHT(B6,3)="000", 1, 0)))) -> 2 | U6: =((1+(O6-N6))/(1+(MAX($O$5:$O$65)-MIN($N$5:$N$65)))) -> 0.066666667 | V6: =MIN(V7:V11) -> 0 | W6: =MAX(W7:W11) -> 0 | X6: =IF(W6<>"", NETWORKDAYS(V6,W6,Calendar!$L$2:$L$43), "") -> 0 | Y6: =IF($N6<=Y$3+MOD(COLUMN()-Calendar!$O$2, 5), IF(Y$3+MOD(COLUMN()-Calendar!$O$2, 5)<=$O6, 1, 0), 0) -> 0 | Z6: =IF($N6<=Y$3+MOD(COLUMN()-Calendar!$O$2, 5), IF(Y$3+MOD(COLUMN()-Calendar!$O$2, 5)<=$O6, 1, 0), 0) -> 0 | AA6: =IF($N6<=Y$3+MOD(COLUMN()-Calendar!$O$2, 5), IF(Y$3+MOD(COLUMN()-Calendar!$O$2, 5)<=$O6, 1, 0), 0) -> 0 | AB6: =IF($N6<=Y$3+MOD(COLUMN()-Calendar!$O$2, 5), IF(Y$3+MOD(COLUMN()-Calendar!$O$2, 5)<=$O6, 1, 0), 0) -> 1 | AC6: =IF($N6<=Y$3+MOD(COLUMN()-Calendar!$O$2, 5), IF(Y$3+MOD(COLUMN()-Calendar!$O$2, 5)<=$O6, 1, 0), 0) -> 1 | AD6: =IF($N6<=AD$3+MOD(COLUMN()-Calendar!$O$2, 5), IF(AD$3+MOD(COLUMN()-Calendar!$O$2, 5)<=$O6, 1, 0), 0) -> 0 | AE6: =IF($N6<=AD$3+MOD(COLUMN()-Calendar!$O$2, 5), IF(AD$3+MOD(COLUMN()-Calendar!$O$2, 5)<=$O6, 1, 0), 0) -> 0 | AF6: =IF($N6<=AD$3+MOD(COLUMN()-Calendar!$O$2, 5), IF(AD$3+MOD(COLUMN()-Calendar!$O$2, 5)<=$O6, 1, 0), 0) -> 0 | AG6: =IF($N6<=AD$3+MOD(COLUMN()-Calendar!$O$2, 5), IF(AD$3+MOD(COLUMN()-Calendar!$O$2, 5)<=$O6, 1, 0), 0) -> 0 | AH6: =IF($N6<=AD$3+MOD(COLUMN()-Calendar!$O$2, 5), IF(AD$3+MOD(COLUMN()-Calendar!$O$2, 5)<=$O6, 1, 0), 0) -> 0 | AI6: =IF($N6<=AI$3+MOD(COLUMN()-Calendar!$O$2, 5), IF(AI$3+MOD(COLUMN()-Calendar!$O$2, 5)<=$O6, 1, 0), 0) -> 0 | AJ6: =IF($N6<=AI$3+MOD(COLUMN()-Calendar!$O$2, 5), IF(AI$3+MOD(COLUMN()-Calendar!$O$2, 5)<=$O6, 1, 0), 0) -> 0 | AK6: =IF($N6<=AI$3+MOD(COLUMN()-Calendar!$O$2, 5), IF(AI$3+MOD(COLUMN()-Calendar!$O$2, 5)<=$O6, 1, 0), 0) -> 0 | AL6: =IF($N6<=AI$3+MOD(COLUMN()-Calendar!$O$2, 5), IF(AI$3+MOD(COLUMN()-Calendar!$O$2, 5)<=$O6, 1, 0), 0) -> 0 | AM6: =IF($N6<=AI$3+MOD(COLUMN()-Calendar!$O$2, 5), IF(AI$3+MOD(COLUMN()-Calendar!$O$2, 5)<=$O6, 1, 0), 0) -> 0 | AN6: =IF($N6<=AN$3+MOD(COLUMN()-Calendar!$O$2, 5), IF(AN$3+MOD(COLUMN()-Calendar!$O$2, 5)<=$O6, 1, 0), 0) -> 0 | AO6: =IF($N6<=AN$3+MOD(COLUMN()-Calendar!$O$2, 5), IF(AN$3+MOD(COLUMN()-Calendar!$O$2, 5)<=$O6, 1, 0), 0) -> 0 | AP6: =IF($N6<=AN$3+MOD(COLUMN()-Calendar!$O$2, 5), IF(AN$3+MOD(COLUMN()-Calendar!$O$2, 5)<=$O6, 1, 0), 0) -> 0 | AQ6: =IF($N6<=AN$3+MOD(COLUMN()-Calendar!$O$2, 5), IF(AN$3+MOD(COLUMN()-Calendar!$O$2, 5)<=$O6, 1, 0), 0) -> 0 | AR6: =IF($N6<=AN$3+MOD(COLUMN()-Calendar!$O$2, 5), IF(AN$3+MOD(COLUMN()-Calendar!$O$2, 5)<=$O6, 1, 0), 0) -> 0 | AS6: =IF($N6<=AS$3+MOD(COLUMN()-Calendar!$O$2, 5), IF(AS$3+MOD(COLUMN()-Calendar!$O$2, 5)<=$O6, 1, 0), 0) -> 0 | AT6: =IF($N6<=AS$3+MOD(COLUMN()-Calendar!$O$2, 5), IF(AS$3+MOD(COLUMN()-Calendar!$O$2, 5)<=$O6, 1, 0), 0) -> 0 | AU6: =IF($N6<=AS$3+MOD(COLUMN()-Calendar!$O$2, 5), IF(AS$3+MOD(COLUMN()-Calendar!$O$2, 5)<=$O6, 1, 0), 0) -> 0 | AV6: =IF($N6<=AS$3+MOD(COLUMN()-Calendar!$O$2, 5), IF(AS$3+MOD(COLUMN()-Calendar!$O$2, 5)<=$O6, 1, 0), 0) -> 0 | AW6: =IF($N6<=AS$3+MOD(COLUMN()-Calendar!$O$2, 5), IF(AS$3+MOD(COLUMN()-Calendar!$O$2, 5)<=$O6, 1, 0), 0) -> 0
B7: 1000 | C7: 1100 | D7: 1110 | E7: 수행환경 구축 | N7: =MIN(N8:N11) -> 46296 | O7: =MAX(O8:O11) -> 46297 | P7: =IF(O7<>"", NETWORKDAYS(N7,O7,Calendar!$L$2:$L$43), "") -> 2 | Q7: =IF(C7<=9999, Q6, LEFT(C7, 2)) -> 착수 | R7: =IF(T7=4, VLOOKUP(O7, '주별 진척률'!$A$11:$B$169, 2, 0), "") | S7: =IF(T7=4, IFERROR(VLOOKUP(W7, '주별 진척률'!$A$11:$B$169, 2, 0), ""), "") | T7: =IF(IFERROR(VALUE(E7), 0)>=1000, IF(IFERROR(VALUE(E7), 0)<=9999, 4, IF(RIGHT(D7,1)="0", 3, IF(RIGHT(C7,2)="00", 2, IF(RIGHT(B7,3)="000", 1, 0)))), IF(RIGHT(D7,1)="0", 3, IF(RIGHT(C7,2)="00", 2, IF(RIGHT(B7,3)="000", 1, 0)))) -> 3 | U7: =((1+(O7-N7))/(1+(MAX($O$5:$O$65)-MIN($N$5:$N$65)))) -> 0.066666667 | V7: =MIN(V8:V11) -> 0 | W7: =MAX(W8:W11) -> 0 | X7: =IF(W7<>"", NETWORKDAYS(V7,W7,Calendar!$L$2:$L$43), "") -> 0 | Y7: =IF($N7<=Y$3+MOD(COLUMN()-Calendar!$O$2, 5), IF(Y$3+MOD(COLUMN()-Calendar!$O$2, 5)<=$O7, 1, 0), 0) -> 0 | Z7: =IF($N7<=Y$3+MOD(COLUMN()-Calendar!$O$2, 5), IF(Y$3+MOD(COLUMN()-Calendar!$O$2, 5)<=$O7, 1, 0), 0) -> 0 | AA7: =IF($N7<=Y$3+MOD(COLUMN()-Calendar!$O$2, 5), IF(Y$3+MOD(COLUMN()-Calendar!$O$2, 5)<=$O7, 1, 0), 0) -> 0 | AB7: =IF($N7<=Y$3+MOD(COLUMN()-Calendar!$O$2, 5), IF(Y$3+MOD(COLUMN()-Calendar!$O$2, 5)<=$O7, 1, 0), 0) -> 1 | AC7: =IF($N7<=Y$3+MOD(COLUMN()-Calendar!$O$2, 5), IF(Y$3+MOD(COLUMN()-Calendar!$O$2, 5)<=$O7, 1, 0), 0) -> 1 | AD7: =IF($N7<=AD$3+MOD(COLUMN()-Calendar!$O$2, 5), IF(AD$3+MOD(COLUMN()-Calendar!$O$2, 5)<=$O7, 1, 0), 0) -> 0 | AE7: =IF($N7<=AD$3+MOD(COLUMN()-Calendar!$O$2, 5), IF(AD$3+MOD(COLUMN()-Calendar!$O$2, 5)<=$O7, 1, 0), 0) -> 0 | AF7: =IF($N7<=AD$3+MOD(COLUMN()-Calendar!$O$2, 5), IF(AD$3+MOD(COLUMN()-Calendar!$O$2, 5)<=$O7, 1, 0), 0) -> 0 | AG7: =IF($N7<=AD$3+MOD(COLUMN()-Calendar!$O$2, 5), IF(AD$3+MOD(COLUMN()-Calendar!$O$2, 5)<=$O7, 1, 0), 0) -> 0 | AH7: =IF($N7<=AD$3+MOD(COLUMN()-Calendar!$O$2, 5), IF(AD$3+MOD(COLUMN()-Calendar!$O$2, 5)<=$O7, 1, 0), 0) -> 0 | AI7: =IF($N7<=AI$3+MOD(COLUMN()-Calendar!$O$2, 5), IF(AI$3+MOD(COLUMN()-Calendar!$O$2, 5)<=$O7, 1, 0), 0) -> 0 | AJ7: =IF($N7<=AI$3+MOD(COLUMN()-Calendar!$O$2, 5), IF(AI$3+MOD(COLUMN()-Calendar!$O$2, 5)<=$O7, 1, 0), 0) -> 0 | AK7: =IF($N7<=AI$3+MOD(COLUMN()-Calendar!$O$2, 5), IF(AI$3+MOD(COLUMN()-Calendar!$O$2, 5)<=$O7, 1, 0), 0) -> 0 | AL7: =IF($N7<=AI$3+MOD(COLUMN()-Calendar!$O$2, 5), IF(AI$3+MOD(COLUMN()-Calendar!$O$2, 5)<=$O7, 1, 0), 0) -> 0 | AM7: =IF($N7<=AI$3+MOD(COLUMN()-Calendar!$O$2, 5), IF(AI$3+MOD(COLUMN()-Calendar!$O$2, 5)<=$O7, 1, 0), 0) -> 0 | AN7: =IF($N7<=AN$3+MOD(COLUMN()-Calendar!$O$2, 5), IF(AN$3+MOD(COLUMN()-Calendar!$O$2, 5)<=$O7, 1, 0), 0) -> 0 | AO7: =IF($N7<=AN$3+MOD(COLUMN()-Calendar!$O$2, 5), IF(AN$3+MOD(COLUMN()-Calendar!$O$2, 5)<=$O7, 1, 0), 0) -> 0 | AP7: =IF($N7<=AN$3+MOD(COLUMN()-Calendar!$O$2, 5), IF(AN$3+MOD(COLUMN()-Calendar!$O$2, 5)<=$O7, 1, 0), 0) -> 0 | AQ7: =IF($N7<=AN$3+MOD(COLUMN()-Calendar!$O$2, 5), IF(AN$3+MOD(COLUMN()-Calendar!$O$2, 5)<=$O7, 1, 0), 0) -> 0 | AR7: =IF($N7<=AN$3+MOD(COLUMN()-Calendar!$O$2, 5), IF(AN$3+MOD(COLUMN()-Calendar!$O$2, 5)<=$O7, 1, 0), 0) -> 0 | AS7: =IF($N7<=AS$3+MOD(COLUMN()-Calendar!$O$2, 5), IF(AS$3+MOD(COLUMN()-Calendar!$O$2, 5)<=$O7, 1, 0), 0) -> 0 | AT7: =IF($N7<=AS$3+MOD(COLUMN()-Calendar!$O$2, 5), IF(AS$3+MOD(COLUMN()-Calendar!$O$2, 5)<=$O7, 1, 0), 0) -> 0 | AU7: =IF($N7<=AS$3+MOD(COLUMN()-Calendar!$O$2, 5), IF(AS$3+MOD(COLUMN()-Calendar!$O$2, 5)<=$O7, 1, 0), 0) -> 0 | AV7: =IF($N7<=AS$3+MOD(COLUMN()-Calendar!$O$2, 5), IF(AS$3+MOD(COLUMN()-Calendar!$O$2, 5)<=$O7, 1, 0), 0) -> 0 | AW7: =IF($N7<=AS$3+MOD(COLUMN()-Calendar!$O$2, 5), IF(AS$3+MOD(COLUMN()-Calendar!$O$2, 5)<=$O7, 1, 0), 0) -> 0
B8: 1000 | C8: 1100 | D8: 1110 | E8: 1111 | F8: 사이트 이동 및 프로젝트룸 준비 | N8: 46296 | O8: 46297 | P8: =IF(O8<>"", NETWORKDAYS(N8,O8,Calendar!$L$2:$L$43), "") -> 2 | Q8: =IF(C8<=9999, Q7, LEFT(C8, 2)) -> 착수 | R8: =IF(T8=4, VLOOKUP(O8, '주별 진척률'!$A$11:$B$169, 2, 0), "") -> W01 | S8: =IF(T8=4, IFERROR(VLOOKUP(W8, '주별 진척률'!$A$11:$B$169, 2, 0), ""), "") | T8: =IF(IFERROR(VALUE(E8), 0)>=1000, IF(IFERROR(VALUE(E8), 0)<=9999, 4, IF(RIGHT(D8,1)="0", 3, IF(RIGHT(C8,2)="00", 2, IF(RIGHT(B8,3)="000", 1, 0)))), IF(RIGHT(D8,1)="0", 3, IF(RIGHT(C8,2)="00", 2, IF(RIGHT(B8,3)="000", 1, 0)))) -> 4 | U8: =((1+(O8-N8))/(1+(MAX($O$5:$O$65)-MIN($N$5:$N$65)))) -> 0.066666667 | X8: =IF(W8<>"", NETWORKDAYS(V8,W8,Calendar!$L$2:$L$43), "") | Y8: =IF($N8<=Y$3+MOD(COLUMN()-Calendar!$O$2, 5), IF(Y$3+MOD(COLUMN()-Calendar!$O$2, 5)<=$O8, 1, 0), 0) -> 0 | Z8: =IF($N8<=Y$3+MOD(COLUMN()-Calendar!$O$2, 5), IF(Y$3+MOD(COLUMN()-Calendar!$O$2, 5)<=$O8, 1, 0), 0) -> 0 | AA8: =IF($N8<=Y$3+MOD(COLUMN()-Calendar!$O$2, 5), IF(Y$3+MOD(COLUMN()-Calendar!$O$2, 5)<=$O8, 1, 0), 0) -> 0 | AB8: =IF($N8<=Y$3+MOD(COLUMN()-Calendar!$O$2, 5), IF(Y$3+MOD(COLUMN()-Calendar!$O$2, 5)<=$O8, 1, 0), 0) -> 1 | AC8: =IF($N8<=Y$3+MOD(COLUMN()-Calendar!$O$2, 5), IF(Y$3+MOD(COLUMN()-Calendar!$O$2, 5)<=$O8, 1, 0), 0) -> 1 | AD8: =IF($N8<=AD$3+MOD(COLUMN()-Calendar!$O$2, 5), IF(AD$3+MOD(COLUMN()-Calendar!$O$2, 5)<=$O8, 1, 0), 0) -> 0 | AE8: =IF($N8<=AD$3+MOD(COLUMN()-Calendar!$O$2, 5), IF(AD$3+MOD(COLUMN()-Calendar!$O$2, 5)<=$O8, 1, 0), 0) -> 0 | AF8: =IF($N8<=AD$3+MOD(COLUMN()-Calendar!$O$2, 5), IF(AD$3+MOD(COLUMN()-Calendar!$O$2, 5)<=$O8, 1, 0), 0) -> 0 | AG8: =IF($N8<=AD$3+MOD(COLUMN()-Calendar!$O$2, 5), IF(AD$3+MOD(COLUMN()-Calendar!$O$2, 5)<=$O8, 1, 0), 0) -> 0 | AH8: =IF($N8<=AD$3+MOD(COLUMN()-Calendar!$O$2, 5), IF(AD$3+MOD(COLUMN()-Calendar!$O$2, 5)<=$O8, 1, 0), 0) -> 0 | AI8: =IF($N8<=AI$3+MOD(COLUMN()-Calendar!$O$2, 5), IF(AI$3+MOD(COLUMN()-Calendar!$O$2, 5)<=$O8, 1, 0), 0) -> 0 | AJ8: =IF($N8<=AI$3+MOD(COLUMN()-Calendar!$O$2, 5), IF(AI$3+MOD(COLUMN()-Calendar!$O$2, 5)<=$O8, 1, 0), 0) -> 0 | AK8: =IF($N8<=AI$3+MOD(COLUMN()-Calendar!$O$2, 5), IF(AI$3+MOD(COLUMN()-Calendar!$O$2, 5)<=$O8, 1, 0), 0) -> 0 | AL8: =IF($N8<=AI$3+MOD(COLUMN()-Calendar!$O$2, 5), IF(AI$3+MOD(COLUMN()-Calendar!$O$2, 5)<=$O8, 1, 0), 0) -> 0 | AM8: =IF($N8<=AI$3+MOD(COLUMN()-Calendar!$O$2, 5), IF(AI$3+MOD(COLUMN()-Calendar!$O$2, 5)<=$O8, 1, 0), 0) -> 0 | AN8: =IF($N8<=AN$3+MOD(COLUMN()-Calendar!$O$2, 5), IF(AN$3+MOD(COLUMN()-Calendar!$O$2, 5)<=$O8, 1, 0), 0) -> 0 | AO8: =IF($N8<=AN$3+MOD(COLUMN()-Calendar!$O$2, 5), IF(AN$3+MOD(COLUMN()-Calendar!$O$2, 5)<=$O8, 1, 0), 0) -> 0 | AP8: =IF($N8<=AN$3+MOD(COLUMN()-Calendar!$O$2, 5), IF(AN$3+MOD(COLUMN()-Calendar!$O$2, 5)<=$O8, 1, 0), 0) -> 0 | AQ8: =IF($N8<=AN$3+MOD(COLUMN()-Calendar!$O$2, 5), IF(AN$3+MOD(COLUMN()-Calendar!$O$2, 5)<=$O8, 1, 0), 0) -> 0 | AR8: =IF($N8<=AN$3+MOD(COLUMN()-Calendar!$O$2, 5), IF(AN$3+MOD(COLUMN()-Calendar!$O$2, 5)<=$O8, 1, 0), 0) -> 0 | AS8: =IF($N8<=AS$3+MOD(COLUMN()-Calendar!$O$2, 5), IF(AS$3+MOD(COLUMN()-Calendar!$O$2, 5)<=$O8, 1, 0), 0) -> 0 | AT8: =IF($N8<=AS$3+MOD(COLUMN()-Calendar!$O$2, 5), IF(AS$3+MOD(COLUMN()-Calendar!$O$2, 5)<=$O8, 1, 0), 0) -> 0 | AU8: =IF($N8<=AS$3+MOD(COLUMN()-Calendar!$O$2, 5), IF(AS$3+MOD(COLUMN()-Calendar!$O$2, 5)<=$O8, 1, 0), 0) -> 0 | AV8: =IF($N8<=AS$3+MOD(COLUMN()-Calendar!$O$2, 5), IF(AS$3+MOD(COLUMN()-Calendar!$O$2, 5)<=$O8, 1, 0), 0) -> 0 | AW8: =IF($N8<=AS$3+MOD(COLUMN()-Calendar!$O$2, 5), IF(AS$3+MOD(COLUMN()-Calendar!$O$2, 5)<=$O8, 1, 0), 0) -> 0
B9: 1000 | C9: 1100 | D9: 1110 | E9: 1112 | F9: 일정계획서(WBS) 작성 | I9: WBS | N9: 46296 | O9: 46297 | P9: =IF(O9<>"", NETWORKDAYS(N9,O9,Calendar!$L$2:$L$43), "") -> 2 | Q9: =IF(C9<=9999, Q8, LEFT(C9, 2)) -> 착수 | R9: =IF(T9=4, VLOOKUP(O9, '주별 진척률'!$A$11:$B$169, 2, 0), "") -> W01 | S9: =IF(T9=4, IFERROR(VLOOKUP(W9, '주별 진척률'!$A$11:$B$169, 2, 0), ""), "") | T9: =IF(IFERROR(VALUE(E9), 0)>=1000, IF(IFERROR(VALUE(E9), 0)<=9999, 4, IF(RIGHT(D9,1)="0", 3, IF(RIGHT(C9,2)="00", 2, IF(RIGHT(B9,3)="000", 1, 0)))), IF(RIGHT(D9,1)="0", 3, IF(RIGHT(C9,2)="00", 2, IF(RIGHT(B9,3)="000", 1, 0)))) -> 4 | U9: =((1+(O9-N9))/(1+(MAX($O$5:$O$65)-MIN($N$5:$N$65)))) -> 0.066666667 | X9: =IF(W9<>"", NETWORKDAYS(V9,W9,Calendar!$L$2:$L$43), "") | Y9: =IF($N9<=Y$3+MOD(COLUMN()-Calendar!$O$2, 5), IF(Y$3+MOD(COLUMN()-Calendar!$O$2, 5)<=$O9, 1, 0), 0) -> 0 | Z9: =IF($N9<=Y$3+MOD(COLUMN()-Calendar!$O$2, 5), IF(Y$3+MOD(COLUMN()-Calendar!$O$2, 5)<=$O9, 1, 0), 0) -> 0 | AA9: =IF($N9<=Y$3+MOD(COLUMN()-Calendar!$O$2, 5), IF(Y$3+MOD(COLUMN()-Calendar!$O$2, 5)<=$O9, 1, 0), 0) -> 0 | AB9: =IF($N9<=Y$3+MOD(COLUMN()-Calendar!$O$2, 5), IF(Y$3+MOD(COLUMN()-Calendar!$O$2, 5)<=$O9, 1, 0), 0) -> 1 | AC9: =IF($N9<=Y$3+MOD(COLUMN()-Calendar!$O$2, 5), IF(Y$3+MOD(COLUMN()-Calendar!$O$2, 5)<=$O9, 1, 0), 0) -> 1 | AD9: =IF($N9<=AD$3+MOD(COLUMN()-Calendar!$O$2, 5), IF(AD$3+MOD(COLUMN()-Calendar!$O$2, 5)<=$O9, 1, 0), 0) -> 0 | AE9: =IF($N9<=AD$3+MOD(COLUMN()-Calendar!$O$2, 5), IF(AD$3+MOD(COLUMN()-Calendar!$O$2, 5)<=$O9, 1, 0), 0) -> 0 | AF9: =IF($N9<=AD$3+MOD(COLUMN()-Calendar!$O$2, 5), IF(AD$3+MOD(COLUMN()-Calendar!$O$2, 5)<=$O9, 1, 0), 0) -> 0 | AG9: =IF($N9<=AD$3+MOD(COLUMN()-Calendar!$O$2, 5), IF(AD$3+MOD(COLUMN()-Calendar!$O$2, 5)<=$O9, 1, 0), 0) -> 0 | AH9: =IF($N9<=AD$3+MOD(COLUMN()-Calendar!$O$2, 5), IF(AD$3+MOD(COLUMN()-Calendar!$O$2, 5)<=$O9, 1, 0), 0) -> 0 | AI9: =IF($N9<=AI$3+MOD(COLUMN()-Calendar!$O$2, 5), IF(AI$3+MOD(COLUMN()-Calendar!$O$2, 5)<=$O9, 1, 0), 0) -> 0 | AJ9: =IF($N9<=AI$3+MOD(COLUMN()-Calendar!$O$2, 5), IF(AI$3+MOD(COLUMN()-Calendar!$O$2, 5)<=$O9, 1, 0), 0) -> 0 | AK9: =IF($N9<=AI$3+MOD(COLUMN()-Calendar!$O$2, 5), IF(AI$3+MOD(COLUMN()-Calendar!$O$2, 5)<=$O9, 1, 0), 0) -> 0 | AL9: =IF($N9<=AI$3+MOD(COLUMN()-Calendar!$O$2, 5), IF(AI$3+MOD(COLUMN()-Calendar!$O$2, 5)<=$O9, 1, 0), 0) -> 0 | AM9: =IF($N9<=AI$3+MOD(COLUMN()-Calendar!$O$2, 5), IF(AI$3+MOD(COLUMN()-Calendar!$O$2, 5)<=$O9, 1, 0), 0) -> 0 | AN9: =IF($N9<=AN$3+MOD(COLUMN()-Calendar!$O$2, 5), IF(AN$3+MOD(COLUMN()-Calendar!$O$2, 5)<=$O9, 1, 0), 0) -> 0 | AO9: =IF($N9<=AN$3+MOD(COLUMN()-Calendar!$O$2, 5), IF(AN$3+MOD(COLUMN()-Calendar!$O$2, 5)<=$O9, 1, 0), 0) -> 0 | AP9: =IF($N9<=AN$3+MOD(COLUMN()-Calendar!$O$2, 5), IF(AN$3+MOD(COLUMN()-Calendar!$O$2, 5)<=$O9, 1, 0), 0) -> 0 | AQ9: =IF($N9<=AN$3+MOD(COLUMN()-Calendar!$O$2, 5), IF(AN$3+MOD(COLUMN()-Calendar!$O$2, 5)<=$O9, 1, 0), 0) -> 0 | AR9: =IF($N9<=AN$3+MOD(COLUMN()-Calendar!$O$2, 5), IF(AN$3+MOD(COLUMN()-Calendar!$O$2, 5)<=$O9, 1, 0), 0) -> 0 | AS9: =IF($N9<=AS$3+MOD(COLUMN()-Calendar!$O$2, 5), IF(AS$3+MOD(COLUMN()-Calendar!$O$2, 5)<=$O9, 1, 0), 0) -> 0 | AT9: =IF($N9<=AS$3+MOD(COLUMN()-Calendar!$O$2, 5), IF(AS$3+MOD(COLUMN()-Calendar!$O$2, 5)<=$O9, 1, 0), 0) -> 0 | AU9: =IF($N9<=AS$3+MOD(COLUMN()-Calendar!$O$2, 5), IF(AS$3+MOD(COLUMN()-Calendar!$O$2, 5)<=$O9, 1, 0), 0) -> 0 | AV9: =IF($N9<=AS$3+MOD(COLUMN()-Calendar!$O$2, 5), IF(AS$3+MOD(COLUMN()-Calendar!$O$2, 5)<=$O9, 1, 0), 0) -> 0 | AW9: =IF($N9<=AS$3+MOD(COLUMN()-Calendar!$O$2, 5), IF(AS$3+MOD(COLUMN()-Calendar!$O$2, 5)<=$O9, 1, 0), 0) -> 0
B10: 1000 | C10: 1100 | D10: 1110 | E10: 1113 | F10: 고객사 TF (Key User) 대상 인터뷰 계획 수립 및 확정 | N10: 46296 | O10: 46297 | P10: =IF(O10<>"", NETWORKDAYS(N10,O10,Calendar!$L$2:$L$43), "") -> 2 | Q10: =IF(C10<=9999, Q9, LEFT(C10, 2)) -> 착수 | R10: =IF(T10=4, VLOOKUP(O10, '주별 진척률'!$A$11:$B$169, 2, 0), "") -> W01 | S10: =IF(T10=4, IFERROR(VLOOKUP(W10, '주별 진척률'!$A$11:$B$169, 2, 0), ""), "") | T10: =IF(IFERROR(VALUE(E10), 0)>=1000, IF(IFERROR(VALUE(E10), 0)<=9999, 4, IF(RIGHT(D10,1)="0", 3, IF(RIGHT(C10,2)="00", 2, IF(RIGHT(B10,3)="000", 1, 0)))), IF(RIGHT(D10,1)="0", 3, IF(RIGHT(C10,2)="00", 2, IF(RIGHT(B10,3)="000", 1, 0)))) -> 4 | U10: =((1+(O10-N10))/(1+(MAX($O$5:$O$65)-MIN($N$5:$N$65)))) -> 0.066666667 | X10: =IF(W10<>"", NETWORKDAYS(V10,W10,Calendar!$L$2:$L$43), "") | Y10: =IF($N10<=Y$3+MOD(COLUMN()-Calendar!$O$2, 5), IF(Y$3+MOD(COLUMN()-Calendar!$O$2, 5)<=$O10, 1, 0), 0) -> 0 | Z10: =IF($N10<=Y$3+MOD(COLUMN()-Calendar!$O$2, 5), IF(Y$3+MOD(COLUMN()-Calendar!$O$2, 5)<=$O10, 1, 0), 0) -> 0 | AA10: =IF($N10<=Y$3+MOD(COLUMN()-Calendar!$O$2, 5), IF(Y$3+MOD(COLUMN()-Calendar!$O$2, 5)<=$O10, 1, 0), 0) -> 0 | AB10: =IF($N10<=Y$3+MOD(COLUMN()-Calendar!$O$2, 5), IF(Y$3+MOD(COLUMN()-Calendar!$O$2, 5)<=$O10, 1, 0), 0) -> 1 | AC10: =IF($N10<=Y$3+MOD(COLUMN()-Calendar!$O$2, 5), IF(Y$3+MOD(COLUMN()-Calendar!$O$2, 5)<=$O10, 1, 0), 0) -> 1 | AD10: =IF($N10<=AD$3+MOD(COLUMN()-Calendar!$O$2, 5), IF(AD$3+MOD(COLUMN()-Calendar!$O$2, 5)<=$O10, 1, 0), 0) -> 0 | AE10: =IF($N10<=AD$3+MOD(COLUMN()-Calendar!$O$2, 5), IF(AD$3+MOD(COLUMN()-Calendar!$O$2, 5)<=$O10, 1, 0), 0) -> 0 | AF10: =IF($N10<=AD$3+MOD(COLUMN()-Calendar!$O$2, 5), IF(AD$3+MOD(COLUMN()-Calendar!$O$2, 5)<=$O10, 1, 0), 0) -> 0 | AG10: =IF($N10<=AD$3+MOD(COLUMN()-Calendar!$O$2, 5), IF(AD$3+MOD(COLUMN()-Calendar!$O$2, 5)<=$O10, 1, 0), 0) -> 0 | AH10: =IF($N10<=AD$3+MOD(COLUMN()-Calendar!$O$2, 5), IF(AD$3+MOD(COLUMN()-Calendar!$O$2, 5)<=$O10, 1, 0), 0) -> 0 | AI10: =IF($N10<=AI$3+MOD(COLUMN()-Calendar!$O$2, 5), IF(AI$3+MOD(COLUMN()-Calendar!$O$2, 5)<=$O10, 1, 0), 0) -> 0 | AJ10: =IF($N10<=AI$3+MOD(COLUMN()-Calendar!$O$2, 5), IF(AI$3+MOD(COLUMN()-Calendar!$O$2, 5)<=$O10, 1, 0), 0) -> 0 | AK10: =IF($N10<=AI$3+MOD(COLUMN()-Calendar!$O$2, 5), IF(AI$3+MOD(COLUMN()-Calendar!$O$2, 5)<=$O10, 1, 0), 0) -> 0 | AL10: =IF($N10<=AI$3+MOD(COLUMN()-Calendar!$O$2, 5), IF(AI$3+MOD(COLUMN()-Calendar!$O$2, 5)<=$O10, 1, 0), 0) -> 0 | AM10: =IF($N10<=AI$3+MOD(COLUMN()-Calendar!$O$2, 5), IF(AI$3+MOD(COLUMN()-Calendar!$O$2, 5)<=$O10, 1, 0), 0) -> 0 | AN10: =IF($N10<=AN$3+MOD(COLUMN()-Calendar!$O$2, 5), IF(AN$3+MOD(COLUMN()-Calendar!$O$2, 5)<=$O10, 1, 0), 0) -> 0 | AO10: =IF($N10<=AN$3+MOD(COLUMN()-Calendar!$O$2, 5), IF(AN$3+MOD(COLUMN()-Calendar!$O$2, 5)<=$O10, 1, 0), 0) -> 0 | AP10: =IF($N10<=AN$3+MOD(COLUMN()-Calendar!$O$2, 5), IF(AN$3+MOD(COLUMN()-Calendar!$O$2, 5)<=$O10, 1, 0), 0) -> 0 | AQ10: =IF($N10<=AN$3+MOD(COLUMN()-Calendar!$O$2, 5), IF(AN$3+MOD(COLUMN()-Calendar!$O$2, 5)<=$O10, 1, 0), 0) -> 0 | AR10: =IF($N10<=AN$3+MOD(COLUMN()-Calendar!$O$2, 5), IF(AN$3+MOD(COLUMN()-Calendar!$O$2, 5)<=$O10, 1, 0), 0) -> 0 | AS10: =IF($N10<=AS$3+MOD(COLUMN()-Calendar!$O$2, 5), IF(AS$3+MOD(COLUMN()-Calendar!$O$2, 5)<=$O10, 1, 0), 0) -> 0 | AT10: =IF($N10<=AS$3+MOD(COLUMN()-Calendar!$O$2, 5), IF(AS$3+MOD(COLUMN()-Calendar!$O$2, 5)<=$O10, 1, 0), 0) -> 0 | AU10: =IF($N10<=AS$3+MOD(COLUMN()-Calendar!$O$2, 5), IF(AS$3+MOD(COLUMN()-Calendar!$O$2, 5)<=$O10, 1, 0), 0) -> 0 | AV10: =IF($N10<=AS$3+MOD(COLUMN()-Calendar!$O$2, 5), IF(AS$3+MOD(COLUMN()-Calendar!$O$2, 5)<=$O10, 1, 0), 0) -> 0 | AW10: =IF($N10<=AS$3+MOD(COLUMN()-Calendar!$O$2, 5), IF(AS$3+MOD(COLUMN()-Calendar!$O$2, 5)<=$O10, 1, 0), 0) -> 0
B11: 1000 | C11: 1100 | D11: 1110 | E11: 1114 | F11: 업무범위 정의 | N11: 46296 | O11: 46297 | P11: =IF(O11<>"", NETWORKDAYS(N11,O11,Calendar!$L$2:$L$43), "") -> 2 | Q11: =IF(C11<=9999, Q10, LEFT(C11, 2)) -> 착수 | R11: =IF(T11=4, VLOOKUP(O11, '주별 진척률'!$A$11:$B$169, 2, 0), "") -> W01 | S11: =IF(T11=4, IFERROR(VLOOKUP(W11, '주별 진척률'!$A$11:$B$169, 2, 0), ""), "") | T11: =IF(IFERROR(VALUE(E11), 0)>=1000, IF(IFERROR(VALUE(E11), 0)<=9999, 4, IF(RIGHT(D11,1)="0", 3, IF(RIGHT(C11,2)="00", 2, IF(RIGHT(B11,3)="000", 1, 0)))), IF(RIGHT(D11,1)="0", 3, IF(RIGHT(C11,2)="00", 2, IF(RIGHT(B11,3)="000", 1, 0)))) -> 4 | U11: =((1+(O11-N11))/(1+(MAX($O$5:$O$65)-MIN($N$5:$N$65)))) -> 0.066666667 | X11: =IF(W11<>"", NETWORKDAYS(V11,W11,Calendar!$L$2:$L$43), "") | Y11: =IF($N11<=Y$3+MOD(COLUMN()-Calendar!$O$2, 5), IF(Y$3+MOD(COLUMN()-Calendar!$O$2, 5)<=$O11, 1, 0), 0) -> 0 | Z11: =IF($N11<=Y$3+MOD(COLUMN()-Calendar!$O$2, 5), IF(Y$3+MOD(COLUMN()-Calendar!$O$2, 5)<=$O11, 1, 0), 0) -> 0 | AA11: =IF($N11<=Y$3+MOD(COLUMN()-Calendar!$O$2, 5), IF(Y$3+MOD(COLUMN()-Calendar!$O$2, 5)<=$O11, 1, 0), 0) -> 0 | AB11: =IF($N11<=Y$3+MOD(COLUMN()-Calendar!$O$2, 5), IF(Y$3+MOD(COLUMN()-Calendar!$O$2, 5)<=$O11, 1, 0), 0) -> 1 | AC11: =IF($N11<=Y$3+MOD(COLUMN()-Calendar!$O$2, 5), IF(Y$3+MOD(COLUMN()-Calendar!$O$2, 5)<=$O11, 1, 0), 0) -> 1 | AD11: =IF($N11<=AD$3+MOD(COLUMN()-Calendar!$O$2, 5), IF(AD$3+MOD(COLUMN()-Calendar!$O$2, 5)<=$O11, 1, 0), 0) -> 0 | AE11: =IF($N11<=AD$3+MOD(COLUMN()-Calendar!$O$2, 5), IF(AD$3+MOD(COLUMN()-Calendar!$O$2, 5)<=$O11, 1, 0), 0) -> 0 | AF11: =IF($N11<=AD$3+MOD(COLUMN()-Calendar!$O$2, 5), IF(AD$3+MOD(COLUMN()-Calendar!$O$2, 5)<=$O11, 1, 0), 0) -> 0 | AG11: =IF($N11<=AD$3+MOD(COLUMN()-Calendar!$O$2, 5), IF(AD$3+MOD(COLUMN()-Calendar!$O$2, 5)<=$O11, 1, 0), 0) -> 0 | AH11: =IF($N11<=AD$3+MOD(COLUMN()-Calendar!$O$2, 5), IF(AD$3+MOD(COLUMN()-Calendar!$O$2, 5)<=$O11, 1, 0), 0) -> 0 | AI11: =IF($N11<=AI$3+MOD(COLUMN()-Calendar!$O$2, 5), IF(AI$3+MOD(COLUMN()-Calendar!$O$2, 5)<=$O11, 1, 0), 0) -> 0 | AJ11: =IF($N11<=AI$3+MOD(COLUMN()-Calendar!$O$2, 5), IF(AI$3+MOD(COLUMN()-Calendar!$O$2, 5)<=$O11, 1, 0), 0) -> 0 | AK11: =IF($N11<=AI$3+MOD(COLUMN()-Calendar!$O$2, 5), IF(AI$3+MOD(COLUMN()-Calendar!$O$2, 5)<=$O11, 1, 0), 0) -> 0 | AL11: =IF($N11<=AI$3+MOD(COLUMN()-Calendar!$O$2, 5), IF(AI$3+MOD(COLUMN()-Calendar!$O$2, 5)<=$O11, 1, 0), 0) -> 0 | AM11: =IF($N11<=AI$3+MOD(COLUMN()-Calendar!$O$2, 5), IF(AI$3+MOD(COLUMN()-Calendar!$O$2, 5)<=$O11, 1, 0), 0) -> 0 | AN11: =IF($N11<=AN$3+MOD(COLUMN()-Calendar!$O$2, 5), IF(AN$3+MOD(COLUMN()-Calendar!$O$2, 5)<=$O11, 1, 0), 0) -> 0 | AO11: =IF($N11<=AN$3+MOD(COLUMN()-Calendar!$O$2, 5), IF(AN$3+MOD(COLUMN()-Calendar!$O$2, 5)<=$O11, 1, 0), 0) -> 0 | AP11: =IF($N11<=AN$3+MOD(COLUMN()-Calendar!$O$2, 5), IF(AN$3+MOD(COLUMN()-Calendar!$O$2, 5)<=$O11, 1, 0), 0) -> 0 | AQ11: =IF($N11<=AN$3+MOD(COLUMN()-Calendar!$O$2, 5), IF(AN$3+MOD(COLUMN()-Calendar!$O$2, 5)<=$O11, 1, 0), 0) -> 0 | AR11: =IF($N11<=AN$3+MOD(COLUMN()-Calendar!$O$2, 5), IF(AN$3+MOD(COLUMN()-Calendar!$O$2, 5)<=$O11, 1, 0), 0) -> 0 | AS11: =IF($N11<=AS$3+MOD(COLUMN()-Calendar!$O$2, 5), IF(AS$3+MOD(COLUMN()-Calendar!$O$2, 5)<=$O11, 1, 0), 0) -> 0 | AT11: =IF($N11<=AS$3+MOD(COLUMN()-Calendar!$O$2, 5), IF(AS$3+MOD(COLUMN()-Calendar!$O$2, 5)<=$O11, 1, 0), 0) -> 0 | AU11: =IF($N11<=AS$3+MOD(COLUMN()-Calendar!$O$2, 5), IF(AS$3+MOD(COLUMN()-Calendar!$O$2, 5)<=$O11, 1, 0), 0) -> 0 | AV11: =IF($N11<=AS$3+MOD(COLUMN()-Calendar!$O$2, 5), IF(AS$3+MOD(COLUMN()-Calendar!$O$2, 5)<=$O11, 1, 0), 0) -> 0 | AW11: =IF($N11<=AS$3+MOD(COLUMN()-Calendar!$O$2, 5), IF(AS$3+MOD(COLUMN()-Calendar!$O$2, 5)<=$O11, 1, 0), 0) -> 0
B12: 2000 | C12: 분석단계 | N12: =MIN(N13:N20) -> 46296 | O12: =MAX(O13:O20) -> 46297 | P12: =IF(O12<>"", NETWORKDAYS(N12,O12,Calendar!$L$2:$L$43), "") -> 2 | Q12: =IF(C12<=9999,#REF!, LEFT( C12, 2)) -> 분석 | R12: =IF(T12=4, VLOOKUP(O12, '주별 진척률'!$A$11:$B$169, 2, 0), "") | S12: =IF(T12=4, IFERROR(VLOOKUP(W12, '주별 진척률'!$A$11:$B$169, 2, 0), ""), "") | T12: =IF(IFERROR(VALUE(E12), 0)>=1000, IF(IFERROR(VALUE(E12), 0)<=9999, 4, IF(RIGHT(D12,1)="0", 3, IF(RIGHT(C12,2)="00", 2, IF(RIGHT(B12,3)="000", 1, 0)))), IF(RIGHT(D12,1)="0", 3, IF(RIGHT(C12,2)="00", 2, IF(RIGHT(B12,3)="000", 1, 0)))) -> 1 | U12: =((1+(O12-N12))/(1+(MAX($O$5:$O$65)-MIN($N$5:$N$65)))) -> 0.066666667 | V12: =MIN(V13:V20) -> 0 | W12: =MAX(W13:W20) -> 0 | X12: =IF(W12<>"", NETWORKDAYS(V12,W12,Calendar!$L$2:$L$43), "") -> 0 | Y12: =IF($N12<=Y$3+MOD(COLUMN()-Calendar!$O$2, 5), IF(Y$3+MOD(COLUMN()-Calendar!$O$2, 5)<=$O12, 1, 0), 0) -> 0 | Z12: =IF($N12<=Y$3+MOD(COLUMN()-Calendar!$O$2, 5), IF(Y$3+MOD(COLUMN()-Calendar!$O$2, 5)<=$O12, 1, 0), 0) -> 0 | AA12: =IF($N12<=Y$3+MOD(COLUMN()-Calendar!$O$2, 5), IF(Y$3+MOD(COLUMN()-Calendar!$O$2, 5)<=$O12, 1, 0), 0) -> 0 | AB12: =IF($N12<=Y$3+MOD(COLUMN()-Calendar!$O$2, 5), IF(Y$3+MOD(COLUMN()-Calendar!$O$2, 5)<=$O12, 1, 0), 0) -> 1 | AC12: =IF($N12<=Y$3+MOD(COLUMN()-Calendar!$O$2, 5), IF(Y$3+MOD(COLUMN()-Calendar!$O$2, 5)<=$O12, 1, 0), 0) -> 1 | AD12: =IF($N12<=AD$3+MOD(COLUMN()-Calendar!$O$2, 5), IF(AD$3+MOD(COLUMN()-Calendar!$O$2, 5)<=$O12, 1, 0), 0) -> 0 | AE12: =IF($N12<=AD$3+MOD(COLUMN()-Calendar!$O$2, 5), IF(AD$3+MOD(COLUMN()-Calendar!$O$2, 5)<=$O12, 1, 0), 0) -> 0 | AF12: =IF($N12<=AD$3+MOD(COLUMN()-Calendar!$O$2, 5), IF(AD$3+MOD(COLUMN()-Calendar!$O$2, 5)<=$O12, 1, 0), 0) -> 0 | AG12: =IF($N12<=AD$3+MOD(COLUMN()-Calendar!$O$2, 5), IF(AD$3+MOD(COLUMN()-Calendar!$O$2, 5)<=$O12, 1, 0), 0) -> 0 | AH12: =IF($N12<=AD$3+MOD(COLUMN()-Calendar!$O$2, 5), IF(AD$3+MOD(COLUMN()-Calendar!$O$2, 5)<=$O12, 1, 0), 0) -> 0 | AI12: =IF($N12<=AI$3+MOD(COLUMN()-Calendar!$O$2, 5), IF(AI$3+MOD(COLUMN()-Calendar!$O$2, 5)<=$O12, 1, 0), 0) -> 0 | AJ12: =IF($N12<=AI$3+MOD(COLUMN()-Calendar!$O$2, 5), IF(AI$3+MOD(COLUMN()-Calendar!$O$2, 5)<=$O12, 1, 0), 0) -> 0 | AK12: =IF($N12<=AI$3+MOD(COLUMN()-Calendar!$O$2, 5), IF(AI$3+MOD(COLUMN()-Calendar!$O$2, 5)<=$O12, 1, 0), 0) -> 0 | AL12: =IF($N12<=AI$3+MOD(COLUMN()-Calendar!$O$2, 5), IF(AI$3+MOD(COLUMN()-Calendar!$O$2, 5)<=$O12, 1, 0), 0) -> 0 | AM12: =IF($N12<=AI$3+MOD(COLUMN()-Calendar!$O$2, 5), IF(AI$3+MOD(COLUMN()-Calendar!$O$2, 5)<=$O12, 1, 0), 0) -> 0 | AN12: =IF($N12<=AN$3+MOD(COLUMN()-Calendar!$O$2, 5), IF(AN$3+MOD(COLUMN()-Calendar!$O$2, 5)<=$O12, 1, 0), 0) -> 0 | AO12: =IF($N12<=AN$3+MOD(COLUMN()-Calendar!$O$2, 5), IF(AN$3+MOD(COLUMN()-Calendar!$O$2, 5)<=$O12, 1, 0), 0) -> 0 | AP12: =IF($N12<=AN$3+MOD(COLUMN()-Calendar!$O$2, 5), IF(AN$3+MOD(COLUMN()-Calendar!$O$2, 5)<=$O12, 1, 0), 0) -> 0 | AQ12: =IF($N12<=AN$3+MOD(COLUMN()-Calendar!$O$2, 5), IF(AN$3+MOD(COLUMN()-Calendar!$O$2, 5)<=$O12, 1, 0), 0) -> 0 | AR12: =IF($N12<=AN$3+MOD(COLUMN()-Calendar!$O$2, 5), IF(AN$3+MOD(COLUMN()-Calendar!$O$2, 5)<=$O12, 1, 0), 0) -> 0 | AS12: =IF($N12<=AS$3+MOD(COLUMN()-Calendar!$O$2, 5), IF(AS$3+MOD(COLUMN()-Calendar!$O$2, 5)<=$O12, 1, 0), 0) -> 0 | AT12: =IF($N12<=AS$3+MOD(COLUMN()-Calendar!$O$2, 5), IF(AS$3+MOD(COLUMN()-Calendar!$O$2, 5)<=$O12, 1, 0), 0) -> 0 | AU12: =IF($N12<=AS$3+MOD(COLUMN()-Calendar!$O$2, 5), IF(AS$3+MOD(COLUMN()-Calendar!$O$2, 5)<=$O12, 1, 0), 0) -> 0 | AV12: =IF($N12<=AS$3+MOD(COLUMN()-Calendar!$O$2, 5), IF(AS$3+MOD(COLUMN()-Calendar!$O$2, 5)<=$O12, 1, 0), 0) -> 0 | AW12: =IF($N12<=AS$3+MOD(COLUMN()-Calendar!$O$2, 5), IF(AS$3+MOD(COLUMN()-Calendar!$O$2, 5)<=$O12, 1, 0), 0) -> 0
B13: 2000 | C13: 2100 | D13: 요구사항 수집 | N13: =MIN(N14:N16) -> 46296 | O13: =MAX(O14:O16) -> 46297 | P13: =IF(O13<>"", NETWORKDAYS(N13,O13,Calendar!$L$2:$L$43), "") -> 2 | Q13: =IF(C13<=9999, Q12, LEFT(C13, 2)) -> 분석 | R13: =IF(T13=4, VLOOKUP(O13, '주별 진척률'!$A$11:$B$169, 2, 0), "") | S13: =IF(T13=4, IFERROR(VLOOKUP(W13, '주별 진척률'!$A$11:$B$169, 2, 0), ""), "") | T13: =IF(IFERROR(VALUE(E13), 0)>=1000, IF(IFERROR(VALUE(E13), 0)<=9999, 4, IF(RIGHT(D13,1)="0", 3, IF(RIGHT(C13,2)="00", 2, IF(RIGHT(B13,3)="000", 1, 0)))), IF(RIGHT(D13,1)="0", 3, IF(RIGHT(C13,2)="00", 2, IF(RIGHT(B13,3)="000", 1, 0)))) -> 2 | U13: =((1+(O13-N13))/(1+(MAX($O$5:$O$65)-MIN($N$5:$N$65)))) -> 0.066666667 | V13: =MIN(V14:V15) -> 0 | W13: =MAX(W14:W15) -> 0 | X13: =IF(W13<>"", NETWORKDAYS(V13,W13,Calendar!$L$2:$L$43), "") -> 0 | Y13: =IF($N13<=Y$3+MOD(COLUMN()-Calendar!$O$2, 5), IF(Y$3+MOD(COLUMN()-Calendar!$O$2, 5)<=$O13, 1, 0), 0) -> 0 | Z13: =IF($N13<=Y$3+MOD(COLUMN()-Calendar!$O$2, 5), IF(Y$3+MOD(COLUMN()-Calendar!$O$2, 5)<=$O13, 1, 0), 0) -> 0 | AA13: =IF($N13<=Y$3+MOD(COLUMN()-Calendar!$O$2, 5), IF(Y$3+MOD(COLUMN()-Calendar!$O$2, 5)<=$O13, 1, 0), 0) -> 0 | AB13: =IF($N13<=Y$3+MOD(COLUMN()-Calendar!$O$2, 5), IF(Y$3+MOD(COLUMN()-Calendar!$O$2, 5)<=$O13, 1, 0), 0) -> 1 | AC13: =IF($N13<=Y$3+MOD(COLUMN()-Calendar!$O$2, 5), IF(Y$3+MOD(COLUMN()-Calendar!$O$2, 5)<=$O13, 1, 0), 0) -> 1 | AD13: =IF($N13<=AD$3+MOD(COLUMN()-Calendar!$O$2, 5), IF(AD$3+MOD(COLUMN()-Calendar!$O$2, 5)<=$O13, 1, 0), 0) -> 0 | AE13: =IF($N13<=AD$3+MOD(COLUMN()-Calendar!$O$2, 5), IF(AD$3+MOD(COLUMN()-Calendar!$O$2, 5)<=$O13, 1, 0), 0) -> 0 | AF13: =IF($N13<=AD$3+MOD(COLUMN()-Calendar!$O$2, 5), IF(AD$3+MOD(COLUMN()-Calendar!$O$2, 5)<=$O13, 1, 0), 0) -> 0 | AG13: =IF($N13<=AD$3+MOD(COLUMN()-Calendar!$O$2, 5), IF(AD$3+MOD(COLUMN()-Calendar!$O$2, 5)<=$O13, 1, 0), 0) -> 0 | AH13: =IF($N13<=AD$3+MOD(COLUMN()-Calendar!$O$2, 5), IF(AD$3+MOD(COLUMN()-Calendar!$O$2, 5)<=$O13, 1, 0), 0) -> 0 | AI13: =IF($N13<=AI$3+MOD(COLUMN()-Calendar!$O$2, 5), IF(AI$3+MOD(COLUMN()-Calendar!$O$2, 5)<=$O13, 1, 0), 0) -> 0 | AJ13: =IF($N13<=AI$3+MOD(COLUMN()-Calendar!$O$2, 5), IF(AI$3+MOD(COLUMN()-Calendar!$O$2, 5)<=$O13, 1, 0), 0) -> 0 | AK13: =IF($N13<=AI$3+MOD(COLUMN()-Calendar!$O$2, 5), IF(AI$3+MOD(COLUMN()-Calendar!$O$2, 5)<=$O13, 1, 0), 0) -> 0 | AL13: =IF($N13<=AI$3+MOD(COLUMN()-Calendar!$O$2, 5), IF(AI$3+MOD(COLUMN()-Calendar!$O$2, 5)<=$O13, 1, 0), 0) -> 0 | AM13: =IF($N13<=AI$3+MOD(COLUMN()-Calendar!$O$2, 5), IF(AI$3+MOD(COLUMN()-Calendar!$O$2, 5)<=$O13, 1, 0), 0) -> 0 | AN13: =IF($N13<=AN$3+MOD(COLUMN()-Calendar!$O$2, 5), IF(AN$3+MOD(COLUMN()-Calendar!$O$2, 5)<=$O13, 1, 0), 0) -> 0 | AO13: =IF($N13<=AN$3+MOD(COLUMN()-Calendar!$O$2, 5), IF(AN$3+MOD(COLUMN()-Calendar!$O$2, 5)<=$O13, 1, 0), 0) -> 0 | AP13: =IF($N13<=AN$3+MOD(COLUMN()-Calendar!$O$2, 5), IF(AN$3+MOD(COLUMN()-Calendar!$O$2, 5)<=$O13, 1, 0), 0) -> 0 | AQ13: =IF($N13<=AN$3+MOD(COLUMN()-Calendar!$O$2, 5), IF(AN$3+MOD(COLUMN()-Calendar!$O$2, 5)<=$O13, 1, 0), 0) -> 0 | AR13: =IF($N13<=AN$3+MOD(COLUMN()-Calendar!$O$2, 5), IF(AN$3+MOD(COLUMN()-Calendar!$O$2, 5)<=$O13, 1, 0), 0) -> 0 | AS13: =IF($N13<=AS$3+MOD(COLUMN()-Calendar!$O$2, 5), IF(AS$3+MOD(COLUMN()-Calendar!$O$2, 5)<=$O13, 1, 0), 0) -> 0 | AT13: =IF($N13<=AS$3+MOD(COLUMN()-Calendar!$O$2, 5), IF(AS$3+MOD(COLUMN()-Calendar!$O$2, 5)<=$O13, 1, 0), 0) -> 0 | AU13: =IF($N13<=AS$3+MOD(COLUMN()-Calendar!$O$2, 5), IF(AS$3+MOD(COLUMN()-Calendar!$O$2, 5)<=$O13, 1, 0), 0) -> 0 | AV13: =IF($N13<=AS$3+MOD(COLUMN()-Calendar!$O$2, 5), IF(AS$3+MOD(COLUMN()-Calendar!$O$2, 5)<=$O13, 1, 0), 0) -> 0 | AW13: =IF($N13<=AS$3+MOD(COLUMN()-Calendar!$O$2, 5), IF(AS$3+MOD(COLUMN()-Calendar!$O$2, 5)<=$O13, 1, 0), 0) -> 0
B14: 2000 | C14: 2100 | D14: 2110 | E14: 인터뷰 계획 및 실시 | N14: =MIN(N15:N16) -> 46296 | O14: =MAX(O15:O16) -> 46297 | P14: =IF(O14<>"", NETWORKDAYS(N14,O14,Calendar!$L$2:$L$43), "") -> 2 | Q14: =IF(C14<=9999, Q13, LEFT(C14, 2)) -> 분석 | R14: =IF(T14=4, VLOOKUP(O14, '주별 진척률'!$A$11:$B$169, 2, 0), "") | S14: =IF(T14=4, IFERROR(VLOOKUP(W14, '주별 진척률'!$A$11:$B$169, 2, 0), ""), "") | T14: =IF(IFERROR(VALUE(E14), 0)>=1000, IF(IFERROR(VALUE(E14), 0)<=9999, 4, IF(RIGHT(D14,1)="0", 3, IF(RIGHT(C14,2)="00", 2, IF(RIGHT(B14,3)="000", 1, 0)))), IF(RIGHT(D14,1)="0", 3, IF(RIGHT(C14,2)="00", 2, IF(RIGHT(B14,3)="000", 1, 0)))) -> 3 | U14: =((1+(O14-N14))/(1+(MAX($O$5:$O$65)-MIN($N$5:$N$65)))) -> 0.066666667 | V14: =MIN(V15:V15) -> 0 | W14: =MAX(W15:W15) -> 0 | X14: =IF(W14<>"", NETWORKDAYS(V14,W14,Calendar!$L$2:$L$43), "") -> 0 | Y14: =IF($N14<=Y$3+MOD(COLUMN()-Calendar!$O$2, 5), IF(Y$3+MOD(COLUMN()-Calendar!$O$2, 5)<=$O14, 1, 0), 0) -> 0 | Z14: =IF($N14<=Y$3+MOD(COLUMN()-Calendar!$O$2, 5), IF(Y$3+MOD(COLUMN()-Calendar!$O$2, 5)<=$O14, 1, 0), 0) -> 0 | AA14: =IF($N14<=Y$3+MOD(COLUMN()-Calendar!$O$2, 5), IF(Y$3+MOD(COLUMN()-Calendar!$O$2, 5)<=$O14, 1, 0), 0) -> 0 | AB14: =IF($N14<=Y$3+MOD(COLUMN()-Calendar!$O$2, 5), IF(Y$3+MOD(COLUMN()-Calendar!$O$2, 5)<=$O14, 1, 0), 0) -> 1 | AC14: =IF($N14<=Y$3+MOD(COLUMN()-Calendar!$O$2, 5), IF(Y$3+MOD(COLUMN()-Calendar!$O$2, 5)<=$O14, 1, 0), 0) -> 1 | AD14: =IF($N14<=AD$3+MOD(COLUMN()-Calendar!$O$2, 5), IF(AD$3+MOD(COLUMN()-Calendar!$O$2, 5)<=$O14, 1, 0), 0) -> 0 | AE14: =IF($N14<=AD$3+MOD(COLUMN()-Calendar!$O$2, 5), IF(AD$3+MOD(COLUMN()-Calendar!$O$2, 5)<=$O14, 1, 0), 0) -> 0 | AF14: =IF($N14<=AD$3+MOD(COLUMN()-Calendar!$O$2, 5), IF(AD$3+MOD(COLUMN()-Calendar!$O$2, 5)<=$O14, 1, 0), 0) -> 0 | AG14: =IF($N14<=AD$3+MOD(COLUMN()-Calendar!$O$2, 5), IF(AD$3+MOD(COLUMN()-Calendar!$O$2, 5)<=$O14, 1, 0), 0) -> 0 | AH14: =IF($N14<=AD$3+MOD(COLUMN()-Calendar!$O$2, 5), IF(AD$3+MOD(COLUMN()-Calendar!$O$2, 5)<=$O14, 1, 0), 0) -> 0 | AI14: =IF($N14<=AI$3+MOD(COLUMN()-Calendar!$O$2, 5), IF(AI$3+MOD(COLUMN()-Calendar!$O$2, 5)<=$O14, 1, 0), 0) -> 0 | AJ14: =IF($N14<=AI$3+MOD(COLUMN()-Calendar!$O$2, 5), IF(AI$3+MOD(COLUMN()-Calendar!$O$2, 5)<=$O14, 1, 0), 0) -> 0 | AK14: =IF($N14<=AI$3+MOD(COLUMN()-Calendar!$O$2, 5), IF(AI$3+MOD(COLUMN()-Calendar!$O$2, 5)<=$O14, 1, 0), 0) -> 0 | AL14: =IF($N14<=AI$3+MOD(COLUMN()-Calendar!$O$2, 5), IF(AI$3+MOD(COLUMN()-Calendar!$O$2, 5)<=$O14, 1, 0), 0) -> 0 | AM14: =IF($N14<=AI$3+MOD(COLUMN()-Calendar!$O$2, 5), IF(AI$3+MOD(COLUMN()-Calendar!$O$2, 5)<=$O14, 1, 0), 0) -> 0 | AN14: =IF($N14<=AN$3+MOD(COLUMN()-Calendar!$O$2, 5), IF(AN$3+MOD(COLUMN()-Calendar!$O$2, 5)<=$O14, 1, 0), 0) -> 0 | AO14: =IF($N14<=AN$3+MOD(COLUMN()-Calendar!$O$2, 5), IF(AN$3+MOD(COLUMN()-Calendar!$O$2, 5)<=$O14, 1, 0), 0) -> 0 | AP14: =IF($N14<=AN$3+MOD(COLUMN()-Calendar!$O$2, 5), IF(AN$3+MOD(COLUMN()-Calendar!$O$2, 5)<=$O14, 1, 0), 0) -> 0 | AQ14: =IF($N14<=AN$3+MOD(COLUMN()-Calendar!$O$2, 5), IF(AN$3+MOD(COLUMN()-Calendar!$O$2, 5)<=$O14, 1, 0), 0) -> 0 | AR14: =IF($N14<=AN$3+MOD(COLUMN()-Calendar!$O$2, 5), IF(AN$3+MOD(COLUMN()-Calendar!$O$2, 5)<=$O14, 1, 0), 0) -> 0 | AS14: =IF($N14<=AS$3+MOD(COLUMN()-Calendar!$O$2, 5), IF(AS$3+MOD(COLUMN()-Calendar!$O$2, 5)<=$O14, 1, 0), 0) -> 0 | AT14: =IF($N14<=AS$3+MOD(COLUMN()-Calendar!$O$2, 5), IF(AS$3+MOD(COLUMN()-Calendar!$O$2, 5)<=$O14, 1, 0), 0) -> 0 | AU14: =IF($N14<=AS$3+MOD(COLUMN()-Calendar!$O$2, 5), IF(AS$3+MOD(COLUMN()-Calendar!$O$2, 5)<=$O14, 1, 0), 0) -> 0 | AV14: =IF($N14<=AS$3+MOD(COLUMN()-Calendar!$O$2, 5), IF(AS$3+MOD(COLUMN()-Calendar!$O$2, 5)<=$O14, 1, 0), 0) -> 0 | AW14: =IF($N14<=AS$3+MOD(COLUMN()-Calendar!$O$2, 5), IF(AS$3+MOD(COLUMN()-Calendar!$O$2, 5)<=$O14, 1, 0), 0) -> 0
B15: 2000 | C15: 2100 | D15: 2110 | E15: 2111 | F15: 고객사 TF (Key User) 담당별 인터뷰 실시(업무 프로세스 분석) | N15: 46296 | O15: 46297 | P15: =IF(O15<>"", NETWORKDAYS(N15,O15,Calendar!$L$2:$L$43), "") -> 2 | Q15: =IF(C15<=9999, Q14, LEFT(C15, 2)) -> 분석 | R15: =IF(T15=4, VLOOKUP(O15, '주별 진척률'!$A$11:$B$169, 2, 0), "") -> W01 | S15: =IF(T15=4, IFERROR(VLOOKUP(W15, '주별 진척률'!$A$11:$B$169, 2, 0), ""), "") | T15: =IF(IFERROR(VALUE(E15), 0)>=1000, IF(IFERROR(VALUE(E15), 0)<=9999, 4, IF(RIGHT(D15,1)="0", 3, IF(RIGHT(C15,2)="00", 2, IF(RIGHT(B15,3)="000", 1, 0)))), IF(RIGHT(D15,1)="0", 3, IF(RIGHT(C15,2)="00", 2, IF(RIGHT(B15,3)="000", 1, 0)))) -> 4 | U15: =((1+(O15-N15))/(1+(MAX($O$5:$O$65)-MIN($N$5:$N$65)))) -> 0.066666667 | X15: =IF(W15<>"", NETWORKDAYS(V15,W15,Calendar!$L$2:$L$43), "") | Y15: =IF($N15<=Y$3+MOD(COLUMN()-Calendar!$O$2, 5), IF(Y$3+MOD(COLUMN()-Calendar!$O$2, 5)<=$O15, 1, 0), 0) -> 0 | Z15: =IF($N15<=Y$3+MOD(COLUMN()-Calendar!$O$2, 5), IF(Y$3+MOD(COLUMN()-Calendar!$O$2, 5)<=$O15, 1, 0), 0) -> 0 | AA15: =IF($N15<=Y$3+MOD(COLUMN()-Calendar!$O$2, 5), IF(Y$3+MOD(COLUMN()-Calendar!$O$2, 5)<=$O15, 1, 0), 0) -> 0 | AB15: =IF($N15<=Y$3+MOD(COLUMN()-Calendar!$O$2, 5), IF(Y$3+MOD(COLUMN()-Calendar!$O$2, 5)<=$O15, 1, 0), 0) -> 1 | AC15: =IF($N15<=Y$3+MOD(COLUMN()-Calendar!$O$2, 5), IF(Y$3+MOD(COLUMN()-Calendar!$O$2, 5)<=$O15, 1, 0), 0) -> 1 | AD15: =IF($N15<=AD$3+MOD(COLUMN()-Calendar!$O$2, 5), IF(AD$3+MOD(COLUMN()-Calendar!$O$2, 5)<=$O15, 1, 0), 0) -> 0 | AE15: =IF($N15<=AD$3+MOD(COLUMN()-Calendar!$O$2, 5), IF(AD$3+MOD(COLUMN()-Calendar!$O$2, 5)<=$O15, 1, 0), 0) -> 0 | AF15: =IF($N15<=AD$3+MOD(COLUMN()-Calendar!$O$2, 5), IF(AD$3+MOD(COLUMN()-Calendar!$O$2, 5)<=$O15, 1, 0), 0) -> 0 | AG15: =IF($N15<=AD$3+MOD(COLUMN()-Calendar!$O$2, 5), IF(AD$3+MOD(COLUMN()-Calendar!$O$2, 5)<=$O15, 1, 0), 0) -> 0 | AH15: =IF($N15<=AD$3+MOD(COLUMN()-Calendar!$O$2, 5), IF(AD$3+MOD(COLUMN()-Calendar!$O$2, 5)<=$O15, 1, 0), 0) -> 0 | AI15: =IF($N15<=AI$3+MOD(COLUMN()-Calendar!$O$2, 5), IF(AI$3+MOD(COLUMN()-Calendar!$O$2, 5)<=$O15, 1, 0), 0) -> 0 | AJ15: =IF($N15<=AI$3+MOD(COLUMN()-Calendar!$O$2, 5), IF(AI$3+MOD(COLUMN()-Calendar!$O$2, 5)<=$O15, 1, 0), 0) -> 0 | AK15: =IF($N15<=AI$3+MOD(COLUMN()-Calendar!$O$2, 5), IF(AI$3+MOD(COLUMN()-Calendar!$O$2, 5)<=$O15, 1, 0), 0) -> 0 | AL15: =IF($N15<=AI$3+MOD(COLUMN()-Calendar!$O$2, 5), IF(AI$3+MOD(COLUMN()-Calendar!$O$2, 5)<=$O15, 1, 0), 0) -> 0 | AM15: =IF($N15<=AI$3+MOD(COLUMN()-Calendar!$O$2, 5), IF(AI$3+MOD(COLUMN()-Calendar!$O$2, 5)<=$O15, 1, 0), 0) -> 0 | AN15: =IF($N15<=AN$3+MOD(COLUMN()-Calendar!$O$2, 5), IF(AN$3+MOD(COLUMN()-Calendar!$O$2, 5)<=$O15, 1, 0), 0) -> 0 | AO15: =IF($N15<=AN$3+MOD(COLUMN()-Calendar!$O$2, 5), IF(AN$3+MOD(COLUMN()-Calendar!$O$2, 5)<=$O15, 1, 0), 0) -> 0 | AP15: =IF($N15<=AN$3+MOD(COLUMN()-Calendar!$O$2, 5), IF(AN$3+MOD(COLUMN()-Calendar!$O$2, 5)<=$O15, 1, 0), 0) -> 0 | AQ15: =IF($N15<=AN$3+MOD(COLUMN()-Calendar!$O$2, 5), IF(AN$3+MOD(COLUMN()-Calendar!$O$2, 5)<=$O15, 1, 0), 0) -> 0 | AR15: =IF($N15<=AN$3+MOD(COLUMN()-Calendar!$O$2, 5), IF(AN$3+MOD(COLUMN()-Calendar!$O$2, 5)<=$O15, 1, 0), 0) -> 0 | AS15: =IF($N15<=AS$3+MOD(COLUMN()-Calendar!$O$2, 5), IF(AS$3+MOD(COLUMN()-Calendar!$O$2, 5)<=$O15, 1, 0), 0) -> 0 | AT15: =IF($N15<=AS$3+MOD(COLUMN()-Calendar!$O$2, 5), IF(AS$3+MOD(COLUMN()-Calendar!$O$2, 5)<=$O15, 1, 0), 0) -> 0 | AU15: =IF($N15<=AS$3+MOD(COLUMN()-Calendar!$O$2, 5), IF(AS$3+MOD(COLUMN()-Calendar!$O$2, 5)<=$O15, 1, 0), 0) -> 0 | AV15: =IF($N15<=AS$3+MOD(COLUMN()-Calendar!$O$2, 5), IF(AS$3+MOD(COLUMN()-Calendar!$O$2, 5)<=$O15, 1, 0), 0) -> 0 | AW15: =IF($N15<=AS$3+MOD(COLUMN()-Calendar!$O$2, 5), IF(AS$3+MOD(COLUMN()-Calendar!$O$2, 5)<=$O15, 1, 0), 0) -> 0
B16: 2000 | C16: 2100 | D16: 2110 | E16: 2113 | F16: 요구사항 확정 | N16: 46296 | O16: 46297 | P16: =IF(O16<>"", NETWORKDAYS(N16,O16,Calendar!$L$2:$L$43), "") -> 2 | Q16: =IF(C16<=9999,Q15, LEFT( C16, 2)) -> 분석 | R16: =IF(T16=4, VLOOKUP(O16, '주별 진척률'!$A$11:$B$169, 2, 0), "") -> W01 | S16: =IF(T16=4, IFERROR(VLOOKUP(W16, '주별 진척률'!$A$11:$B$169, 2, 0), ""), "") | T16: =IF(IFERROR(VALUE(E16), 0)>=1000, IF(IFERROR(VALUE(E16), 0)<=9999, 4, IF(RIGHT(D16,1)="0", 3, IF(RIGHT(C16,2)="00", 2, IF(RIGHT(B16,3)="000", 1, 0)))), IF(RIGHT(D16,1)="0", 3, IF(RIGHT(C16,2)="00", 2, IF(RIGHT(B16,3)="000", 1, 0)))) -> 4 | U16: =((1+(O16-N16))/(1+(MAX($O$5:$O$65)-MIN($N$5:$N$65)))) -> 0.066666667 | X16: =IF(W16<>"", NETWORKDAYS(V16,W16,Calendar!$L$2:$L$43), "") | Y16: =IF($N16<=Y$3+MOD(COLUMN()-Calendar!$O$2, 5), IF(Y$3+MOD(COLUMN()-Calendar!$O$2, 5)<=$O16, 1, 0), 0) -> 0 | Z16: =IF($N16<=Y$3+MOD(COLUMN()-Calendar!$O$2, 5), IF(Y$3+MOD(COLUMN()-Calendar!$O$2, 5)<=$O16, 1, 0), 0) -> 0 | AA16: =IF($N16<=Y$3+MOD(COLUMN()-Calendar!$O$2, 5), IF(Y$3+MOD(COLUMN()-Calendar!$O$2, 5)<=$O16, 1, 0), 0) -> 0 | AB16: =IF($N16<=Y$3+MOD(COLUMN()-Calendar!$O$2, 5), IF(Y$3+MOD(COLUMN()-Calendar!$O$2, 5)<=$O16, 1, 0), 0) -> 1 | AC16: =IF($N16<=Y$3+MOD(COLUMN()-Calendar!$O$2, 5), IF(Y$3+MOD(COLUMN()-Calendar!$O$2, 5)<=$O16, 1, 0), 0) -> 1 | AD16: =IF($N16<=AD$3+MOD(COLUMN()-Calendar!$O$2, 5), IF(AD$3+MOD(COLUMN()-Calendar!$O$2, 5)<=$O16, 1, 0), 0) -> 0 | AE16: =IF($N16<=AD$3+MOD(COLUMN()-Calendar!$O$2, 5), IF(AD$3+MOD(COLUMN()-Calendar!$O$2, 5)<=$O16, 1, 0), 0) -> 0 | AF16: =IF($N16<=AD$3+MOD(COLUMN()-Calendar!$O$2, 5), IF(AD$3+MOD(COLUMN()-Calendar!$O$2, 5)<=$O16, 1, 0), 0) -> 0 | AG16: =IF($N16<=AD$3+MOD(COLUMN()-Calendar!$O$2, 5), IF(AD$3+MOD(COLUMN()-Calendar!$O$2, 5)<=$O16, 1, 0), 0) -> 0 | AH16: =IF($N16<=AD$3+MOD(COLUMN()-Calendar!$O$2, 5), IF(AD$3+MOD(COLUMN()-Calendar!$O$2, 5)<=$O16, 1, 0), 0) -> 0 | AI16: =IF($N16<=AI$3+MOD(COLUMN()-Calendar!$O$2, 5), IF(AI$3+MOD(COLUMN()-Calendar!$O$2, 5)<=$O16, 1, 0), 0) -> 0 | AJ16: =IF($N16<=AI$3+MOD(COLUMN()-Calendar!$O$2, 5), IF(AI$3+MOD(COLUMN()-Calendar!$O$2, 5)<=$O16, 1, 0), 0) -> 0 | AK16: =IF($N16<=AI$3+MOD(COLUMN()-Calendar!$O$2, 5), IF(AI$3+MOD(COLUMN()-Calendar!$O$2, 5)<=$O16, 1, 0), 0) -> 0 | AL16: =IF($N16<=AI$3+MOD(COLUMN()-Calendar!$O$2, 5), IF(AI$3+MOD(COLUMN()-Calendar!$O$2, 5)<=$O16, 1, 0), 0) -> 0 | AM16: =IF($N16<=AI$3+MOD(COLUMN()-Calendar!$O$2, 5), IF(AI$3+MOD(COLUMN()-Calendar!$O$2, 5)<=$O16, 1, 0), 0) -> 0 | AN16: =IF($N16<=AN$3+MOD(COLUMN()-Calendar!$O$2, 5), IF(AN$3+MOD(COLUMN()-Calendar!$O$2, 5)<=$O16, 1, 0), 0) -> 0 | AO16: =IF($N16<=AN$3+MOD(COLUMN()-Calendar!$O$2, 5), IF(AN$3+MOD(COLUMN()-Calendar!$O$2, 5)<=$O16, 1, 0), 0) -> 0 | AP16: =IF($N16<=AN$3+MOD(COLUMN()-Calendar!$O$2, 5), IF(AN$3+MOD(COLUMN()-Calendar!$O$2, 5)<=$O16, 1, 0), 0) -> 0 | AQ16: =IF($N16<=AN$3+MOD(COLUMN()-Calendar!$O$2, 5), IF(AN$3+MOD(COLUMN()-Calendar!$O$2, 5)<=$O16, 1, 0), 0) -> 0 | AR16: =IF($N16<=AN$3+MOD(COLUMN()-Calendar!$O$2, 5), IF(AN$3+MOD(COLUMN()-Calendar!$O$2, 5)<=$O16, 1, 0), 0) -> 0 | AS16: =IF($N16<=AS$3+MOD(COLUMN()-Calendar!$O$2, 5), IF(AS$3+MOD(COLUMN()-Calendar!$O$2, 5)<=$O16, 1, 0), 0) -> 0 | AT16: =IF($N16<=AS$3+MOD(COLUMN()-Calendar!$O$2, 5), IF(AS$3+MOD(COLUMN()-Calendar!$O$2, 5)<=$O16, 1, 0), 0) -> 0 | AU16: =IF($N16<=AS$3+MOD(COLUMN()-Calendar!$O$2, 5), IF(AS$3+MOD(COLUMN()-Calendar!$O$2, 5)<=$O16, 1, 0), 0) -> 0 | AV16: =IF($N16<=AS$3+MOD(COLUMN()-Calendar!$O$2, 5), IF(AS$3+MOD(COLUMN()-Calendar!$O$2, 5)<=$O16, 1, 0), 0) -> 0 | AW16: =IF($N16<=AS$3+MOD(COLUMN()-Calendar!$O$2, 5), IF(AS$3+MOD(COLUMN()-Calendar!$O$2, 5)<=$O16, 1, 0), 0) -> 0
B17: 2000 | C17: 2300 | D17: 개발 항목 확정 | N17: =MIN(N18:N20) -> 46296 | O17: =MAX(O18:O20) -> 46297 | P17: =IF(O17<>"", NETWORKDAYS(N17,O17,Calendar!$L$2:$L$43), "") -> 2 | Q17: =IF(C17<=9999,Q16, LEFT( C17, 2)) -> 분석 | R17: =IF(T17=4, VLOOKUP(O17, '주별 진척률'!$A$11:$B$169, 2, 0), "") | S17: =IF(T17=4, IFERROR(VLOOKUP(W17, '주별 진척률'!$A$11:$B$169, 2, 0), ""), "") | T17: =IF(IFERROR(VALUE(E17), 0)>=1000, IF(IFERROR(VALUE(E17), 0)<=9999, 4, IF(RIGHT(D17,1)="0", 3, IF(RIGHT(C17,2)="00", 2, IF(RIGHT(B17,3)="000", 1, 0)))), IF(RIGHT(D17,1)="0", 3, IF(RIGHT(C17,2)="00", 2, IF(RIGHT(B17,3)="000", 1, 0)))) -> 2 | U17: =((1+(O17-N17))/(1+(MAX($O$5:$O$65)-MIN($N$5:$N$65)))) -> 0.066666667 | V17: =MIN(V18:V20) -> 0 | W17: =MAX(W18:W20) -> 0 | X17: =IF(W17<>"", NETWORKDAYS(V17,W17,Calendar!$L$2:$L$43), "") -> 0 | Y17: =IF($N17<=Y$3+MOD(COLUMN()-Calendar!$O$2, 5), IF(Y$3+MOD(COLUMN()-Calendar!$O$2, 5)<=$O17, 1, 0), 0) -> 0 | Z17: =IF($N17<=Y$3+MOD(COLUMN()-Calendar!$O$2, 5), IF(Y$3+MOD(COLUMN()-Calendar!$O$2, 5)<=$O17, 1, 0), 0) -> 0 | AA17: =IF($N17<=Y$3+MOD(COLUMN()-Calendar!$O$2, 5), IF(Y$3+MOD(COLUMN()-Calendar!$O$2, 5)<=$O17, 1, 0), 0) -> 0 | AB17: =IF($N17<=Y$3+MOD(COLUMN()-Calendar!$O$2, 5), IF(Y$3+MOD(COLUMN()-Calendar!$O$2, 5)<=$O17, 1, 0), 0) -> 1 | AC17: =IF($N17<=Y$3+MOD(COLUMN()-Calendar!$O$2, 5), IF(Y$3+MOD(COLUMN()-Calendar!$O$2, 5)<=$O17, 1, 0), 0) -> 1 | AD17: =IF($N17<=AD$3+MOD(COLUMN()-Calendar!$O$2, 5), IF(AD$3+MOD(COLUMN()-Calendar!$O$2, 5)<=$O17, 1, 0), 0) -> 0 | AE17: =IF($N17<=AD$3+MOD(COLUMN()-Calendar!$O$2, 5), IF(AD$3+MOD(COLUMN()-Calendar!$O$2, 5)<=$O17, 1, 0), 0) -> 0 | AF17: =IF($N17<=AD$3+MOD(COLUMN()-Calendar!$O$2, 5), IF(AD$3+MOD(COLUMN()-Calendar!$O$2, 5)<=$O17, 1, 0), 0) -> 0 | AG17: =IF($N17<=AD$3+MOD(COLUMN()-Calendar!$O$2, 5), IF(AD$3+MOD(COLUMN()-Calendar!$O$2, 5)<=$O17, 1, 0), 0) -> 0 | AH17: =IF($N17<=AD$3+MOD(COLUMN()-Calendar!$O$2, 5), IF(AD$3+MOD(COLUMN()-Calendar!$O$2, 5)<=$O17, 1, 0), 0) -> 0 | AI17: =IF($N17<=AI$3+MOD(COLUMN()-Calendar!$O$2, 5), IF(AI$3+MOD(COLUMN()-Calendar!$O$2, 5)<=$O17, 1, 0), 0) -> 0 | AJ17: =IF($N17<=AI$3+MOD(COLUMN()-Calendar!$O$2, 5), IF(AI$3+MOD(COLUMN()-Calendar!$O$2, 5)<=$O17, 1, 0), 0) -> 0 | AK17: =IF($N17<=AI$3+MOD(COLUMN()-Calendar!$O$2, 5), IF(AI$3+MOD(COLUMN()-Calendar!$O$2, 5)<=$O17, 1, 0), 0) -> 0 | AL17: =IF($N17<=AI$3+MOD(COLUMN()-Calendar!$O$2, 5), IF(AI$3+MOD(COLUMN()-Calendar!$O$2, 5)<=$O17, 1, 0), 0) -> 0 | AM17: =IF($N17<=AI$3+MOD(COLUMN()-Calendar!$O$2, 5), IF(AI$3+MOD(COLUMN()-Calendar!$O$2, 5)<=$O17, 1, 0), 0) -> 0 | AN17: =IF($N17<=AN$3+MOD(COLUMN()-Calendar!$O$2, 5), IF(AN$3+MOD(COLUMN()-Calendar!$O$2, 5)<=$O17, 1, 0), 0) -> 0 | AO17: =IF($N17<=AN$3+MOD(COLUMN()-Calendar!$O$2, 5), IF(AN$3+MOD(COLUMN()-Calendar!$O$2, 5)<=$O17, 1, 0), 0) -> 0 | AP17: =IF($N17<=AN$3+MOD(COLUMN()-Calendar!$O$2, 5), IF(AN$3+MOD(COLUMN()-Calendar!$O$2, 5)<=$O17, 1, 0), 0) -> 0 | AQ17: =IF($N17<=AN$3+MOD(COLUMN()-Calendar!$O$2, 5), IF(AN$3+MOD(COLUMN()-Calendar!$O$2, 5)<=$O17, 1, 0), 0) -> 0 | AR17: =IF($N17<=AN$3+MOD(COLUMN()-Calendar!$O$2, 5), IF(AN$3+MOD(COLUMN()-Calendar!$O$2, 5)<=$O17, 1, 0), 0) -> 0 | AS17: =IF($N17<=AS$3+MOD(COLUMN()-Calendar!$O$2, 5), IF(AS$3+MOD(COLUMN()-Calendar!$O$2, 5)<=$O17, 1, 0), 0) -> 0 | AT17: =IF($N17<=AS$3+MOD(COLUMN()-Calendar!$O$2, 5), IF(AS$3+MOD(COLUMN()-Calendar!$O$2, 5)<=$O17, 1, 0), 0) -> 0 | AU17: =IF($N17<=AS$3+MOD(COLUMN()-Calendar!$O$2, 5), IF(AS$3+MOD(COLUMN()-Calendar!$O$2, 5)<=$O17, 1, 0), 0) -> 0 | AV17: =IF($N17<=AS$3+MOD(COLUMN()-Calendar!$O$2, 5), IF(AS$3+MOD(COLUMN()-Calendar!$O$2, 5)<=$O17, 1, 0), 0) -> 0 | AW17: =IF($N17<=AS$3+MOD(COLUMN()-Calendar!$O$2, 5), IF(AS$3+MOD(COLUMN()-Calendar!$O$2, 5)<=$O17, 1, 0), 0) -> 0
